Workbook

Sheet Charts
R2: AoI | S2: 30 | T2: 50 | U2: 100
R3: QUEST | S3: ='Data Age'!B41 -> 226725.55 | T3: ='Data Age'!C41 -> 256171.13 | U3: ='Data Age'!D41 -> 252776.27
R4: QUEST_NDVFS | S4: ='Data Age'!B42 -> 182768.3 | T4: ='Data Age'!C42 -> 201936.35 | U4: ='Data Age'!D42 -> 191748.41
R5: Fuzzy | S5: ='Data Age'!B43 -> 178014.45 | T5: ='Data Age'!C43 -> 193076.96 | U5: ='Data Age'!D43 -> 186748.35
R6: NSGA3 | S6: ='Data Age'!B44 -> 199180.37 | T6: ='Data Age'!C44 -> 220529 | U6: ='Data Age'!D44 -> 215579.73
R7: MQGA | S7: ='Data Age'!B45 -> 189670.05 | T7: ='Data Age'!C45 -> 212386.8 | U7: ='Data Age'!D45 -> 206804.82
R8: Greedy | S8: ='Data Age'!B46 -> 202365.05 | T8: ='Data Age'!C46 -> 222356.91 | U8: ='Data Age'!D46 -> 208500.6
R9: MOPSO | S9: ='Data Age'!B47 -> 197333.17 | T9: ='Data Age'!C47 -> 223315.1 | U9: ='Data Age'!D47 -> 209027.54
R10: RL | S10: ='Data Age'!B48 -> 198275.99 | T10: ='Data Age'!C48 -> 220990.42 | U10: ='Data Age'!D48 -> 214840.95
R17: AoI | S17: 30 | T17: 50 | U17: 100
R18: QUEST | S18: =S3/S3 -> 1 | T18: =T3/T3 -> 1 | U18: =U3/U3 -> 1
R19: QUEST_NDVFS | S19: =S4/S3 -> 0.80612132 | T19: =T4/T3 -> 0.78828692 | U19: =U4/U3 -> 0.75856966
R20: Fuzzy | S20: =S5/S3 -> 0.78515389 | T20: =T5/T3 -> 0.75370304 | U20: =U5/U3 -> 0.73878909
R21: NSGA3 | S21: =S6/S3 -> 0.87850871 | T21: =T6/T3 -> 0.86086594 | U21: =U6/U3 -> 0.85284797
R22: MQGA | S22: =S7/S3 -> 0.83656229 | T22: =T7/T3 -> 0.82908172 | U22: =U7/U3 -> 0.81813383
R23: Greedy | S23: =S8/S3 -> 0.89255509 | T23: =T8/T3 -> 0.86800143 | U23: =U8/U3 -> 0.82484247
R24: MOPSO | S24: =S9/S3 -> 0.87036138 | T24: =T9/T3 -> 0.87174187 | U24: =U9/U3 -> 0.82692706
R25: RL | S25: =S10/S3 -> 0.87451982 | T25: =T10/T3 -> 0.86266714 | U25: =U10/U3 -> 0.8499253
R36: Energy | S36: 30 | T36: 50 | U36: 100
R37: QUEST | S37: =Energy!B41 -> 1.2227249e+09 | T37: =Energy!C41 -> 1.3194119e+09 | U37: =Energy!D41 -> 1.2921245e+09
R38: QUEST_NDVFS | S38: =Energy!B42 -> 1.2635108e+09 | T38: =Energy!C42 -> 1.4702213e+09 | U38: =Energy!D42 -> 1.4772561e+09
R39: Fuzzy | S39: =Energy!B43 -> 1.2681604e+09 | T39: =Energy!C43 -> 1.4213567e+09 | U39: =Energy!D43 -> 1.405614e+09
R40: NSGA3 | S40: =Energy!B44 -> 1.4110384e+09 | T40: =Energy!C44 -> 1.6672214e+09 | U40: =Energy!D44 -> 1.9959407e+09
R41: MQGA | S41: =Energy!B45 -> 1.3527754e+09 | T41: =Energy!C45 -> 1.5529082e+09 | U41: =Energy!D45 -> 1.7384627e+09
R42: Greedy | S42: =Energy!B46 -> 1.4933059e+09 | T42: =Energy!C46 -> 1.7563347e+09 | U42: =Energy!D46 -> 1818529417
R43: MOPSO | S43: =Energy!B47 -> 1.4059674e+09 | T43: =Energy!C47 -> 1.632873e+09 | U43: =Energy!D47 -> 1.8995726e+09
R44: RL | S44: =Energy!B48 -> 1.3801106e+09 | T44: =Energy!C48 -> 1.731569e+09 | U44: =Energy!D48 -> 1.8772486e+09
R51: Energy | S51: 30 | T51: 50 | U51: 100
R52: QUEST | S52: =S37/S37 -> 1 | T52: =T37/T37 -> 1 | U52: =U37/U37 -> 1
R53: QUEST_NDVFS | S53: =S38/S37 -> 1.0333566 | T53: =T38/T37 -> 1.1143005 | U53: =U38/U37 -> 1.1432769
R54: Fuzzy | S54: =S39/S37 -> 1.0371593 | T54: =T39/T37 -> 1.0772653 | U54: =U39/U37 -> 1.0878317
R55: NSGA3 | S55: =S40/S37 -> 1.1540114 | T55: =T40/T37 -> 1.2636094 | U55: =U40/U37 -> 1.5446969
R56: MQGA | S56: =S41/S37 -> 1.1063613 | T56: =T41/T37 -> 1.1769699 | U56: =U41/U37 -> 1.3454296
R57: Greedy | S57: =S42/S37 -> 1.2212935 | T57: =T42/T37 -> 1.3311496 | U57: =U42/U37 -> 1.4073948
R58: MOPSO | S58: =S43/S37 -> 1.1498641 | T58: =T43/T37 -> 1.2375763 | U58: =U43/U37 -> 1.4701157
R59: RL | S59: =S44/S37 -> 1.1287172 | T59: =T44/T37 -> 1.3123793 | U59: =U44/U37 -> 1.4528388
R67: Makespan | S67: 30 | T67: 50 | U67: 100
R68: QUEST | S68: =Makespan!B41 -> 1136360.8 | T68: =Makespan!C41 -> 1225334.1 | U68: =Makespan!D41 -> 1242820.5
R69: QUEST_NDVFS | S69: =Makespan!B42 -> 1123188.1 | T69: =Makespan!C42 -> 1270395.6 | U69: =Makespan!D42 -> 1218447.7
R70: Fuzzy | S70: =Makespan!B43 -> 1113666.1 | T70: =Makespan!C43 -> 1181680.3 | U70: =Makespan!D43 -> 1111605.9
...

Sheet Sheet1

Sheet Data Age
A1: Algorithm | B1: Load | C1: Average | D1: Min | E1: Max | F1: Std Dev
A2: QUEST | B2: 1 | C2: 226725.55 | D2: 220485.55 | E2: 235000.32 | F2: 3360.4621
A3: QUEST | B3: 2 | C3: 256171.13 | D3: 244685.41 | E3: 273265.16 | F3: 7966.6619
A4: QUEST | B4: 3 | C4: 252776.27 | D4: 238021.34 | E4: 264273.6 | F4: 7496.9923
A5: QUEST_NDVFS | B5: 1 | C5: 182768.3 | D5: 180372.45 | E5: 184723.16 | F5: 968.35257
A6: QUEST_NDVFS | B6: 2 | C6: 201936.35 | D6: 198914.76 | E6: 203527.39 | F6: 1214.0609
A7: QUEST_NDVFS | B7: 3 | C7: 191748.41 | D7: 188506.47 | E7: 194955.09 | F7: 1474.0925
A8: Fuzzy | B8: 1 | C8: 178014.45 | D8: 178014.45 | E8: 178014.45 | F8: 0
A9: Fuzzy | B9: 2 | C9: 193076.96 | D9: 193076.96 | E9: 193076.96 | F9: 0
A10: Fuzzy | B10: 3 | C10: 186748.35 | D10: 186747.99 | E10: 186748.67 | F10: 0.19179
A11: NSGA3 | B11: 1 | C11: 199180.37 | D11: 188775.16 | E11: 213914.74 | F11: 7431.0296
A12: NSGA3 | B12: 2 | C12: 220529 | D12: 206757.2 | E12: 245094.02 | F12: 9408.9571
A13: NSGA3 | B13: 3 | C13: 215579.73 | D13: 195167.28 | E13: 240137.63 | F13: 9605.7961
... A25: RL | B25: 3 | C25: 214840.95 | D25: 196213.49 | E25: 243339.06 | F25: 13585.515
A28: Summary by Algorithm
A29: QUEST | C29: 245224.32 | D29: 220485.55 | E29: 273265.16 | F29: 14719.99
A30: QUEST_NDVFS | C30: 192151.02 | D30: 180372.45 | E30: 203527.39 | F30: 7927.4794
A31: Fuzzy | C31: 185946.59 | D31: 178014.45 | E31: 193076.96 | F31: 6175.3227
A32: NSGA3 | C32: 211763.04 | D32: 188775.16 | E32: 245094.02 | F32: 12724.684
A33: MQGA | C33: 202953.89 | D33: 183154.55 | E33: 223148.75 | F33: 11012.522
A34: Greedy | C34: 211074.19 | D34: 187409.68 | E34: 244255.29 | F34: 13609.828
A35: MOPSO | C35: 209891.94 | D35: 189018.52 | E35: 233668.65 | F35: 12257.025
A36: RL | C36: 211369.12 | D36: 189396.55 | E36: 246740.25 | F36: 14114.093
A39: Average data for chart
A40: Algorithms | B40: 1 | C40: 2 | D40: 3
A41: QUEST | B41: 226725.55 | C41: 256171.13 | D41: 252776.27
A42: QUEST_NDVFS | B42: 182768.3 | C42: 201936.35 | D42: 191748.41
A43: Fuzzy | B43: 178014.45 | C43: 193076.96 | D43: 186748.35
A44: NSGA3 | B44: 199180.37 | C44: 220529 | D44: 215579.73
A45: MQGA | B45: 189670.05 | C45: 212386.8 | D45: 206804.82
A46: Greedy | B46: 202365.05 | C46: 222356.91 | D46: 208500.6
A47: MOPSO | B47: 197333.17 | C47: 223315.1 | D47: 209027.54
A48: RL | B48: 198275.99 | C48: 220990.42 | D48: 214840.95
A51: All data for chart
A52: Algorithms | B52: 1 | C52: 1 | D52: 1 | E52: 1 | F52: 1 | G52: 1 | H52: 1 | I52: 1 | J52: 1 | K52: 1 | L52: 1 | M52: 1 | N52: 1 | O52: 1 | P52: 1 | Q52: 1 | R52: 1 | S52: 1 | T52: 1 | U52: 1 | V52: 2 | W52: 2 | X52: 2 | Y52: 2 | Z52: 2 | AA52: 2 | AB52: 2 | AC52: 2 | AD52: 2 | AE52: 2 | AF52: 2 | AG52: 2 | AH52: 2 | AI52: 2 | AJ52: 2 | AK52: 2 | AL52: 2 | AM52: 2 | AN52: 2 | AO52: 2 | AP52: 3 | AQ52: 3 | AR52: 3 | AS52: 3 | AT52: 3 | AU52: 3 | AV52: 3 | AW52: 3 | AX52: 3 | AY52: 3 | AZ52: 3 | BA52: 3 | BB52: 3 | BC52: 3 | BD52: 3 | BE52: 3 | BF52: 3 | BG52: 3 | BH52: 3 | BI52: 3
A53: QUEST | B53: 228418.55 | C53: 230363.48 | D53: 229386.68 | E53: 226261.9 | F53: 224351.84 | G53: 225041.32 | H53: 222897.81 | I53: 224503.42 | J53: 222262 | K53: 224774.29 | L53: 229965.9 | M53: 229465.9 | N53: 220485.55 | O53: 226313.06 | P53: 227666.68 | Q53: 223168 | R53: 226031.68 | S53: 229091.74 | T53: 229060.97 | U53: 235000.32 | V53: 249170.88 | W53: 269101.9 | X53: 256256.63 | Y53: 261850.94 | Z53: 247990.71 | AA53: 265499.57 | AB53: 253610.55 | AC53: 255377.16 | AD53: 265391.37 | AE53: 249396.94 | AF53: 245837.9 | AG53: 251020.69 | AH53: 244685.41 | AI53: 273265.16 | AJ53: 259128.33 | AK53: 250424.63 | AL53: 260893.65 | AM53: 249819.49 | AN53: 251683.57 | AO53: 263017.18 | AP53: 253980.97 | AQ53: 244787.07 | AR53: 255971.28 | AS53: 249580.57 | AT53: 263284.4 | AU53: 249362.1 | AV53: 253519.93 | AW53: 246204.63 | AX53: 250814.04 | AY53: 249518.28 | AZ53: 252193.22 | BA53: 264273.6 | BB53: 253395.93 | BC53: 246190.11 | BD53: 264194.5 | BE53: 244495.54 | BF53: 238021.34 | BG53: 263783.34 | BH53: 263836.18 | BI53: 248118.45
A54: QUEST_NDVFS | B54: 182036.52 | C54: 182769.03 | D54: 182463.97 | E54: 184723.16 | F54: 183231.06 | G54: 182795.71 | H54: 184218.03 | I54: 181446.81 | J54: 183163 | K54: 182654.1 | L54: 183194.81 | M54: 182634.65 | N54: 184009.55 | O54: 183674.48 | P54: 182121.65 | Q54: 181988.71 | R54: 182066.97 | S54: 183230.97 | T54: 182570.45 | U54: 180372.45 | V54: 201736.71 | W54: 202654.16 | X54: 200518.76 | Y54: 203205.02 | Z54: 201908.71 | AA54: 201807.33 | AB54: 202270.35 | AC54: 203527.39 | AD54: 202754.86 | AE54: 202518.61 | AF54: 200361.61 | AG54: 198914.76 | AH54: 202796.02 | AI54: 200006.31 | AJ54: 202091.84 | AK54: 200505.31 | AL54: 202180.02 | AM54: 203048.29 | AN54: 202741.45 | AO54: 203179.51 | AP54: 188506.47 | AQ54: 191878.14 | AR54: 190928.76 | AS54: 190646.77 | AT54: 189583.63 | AU54: 192186.35 | AV54: 192687.29 | AW54: 192897.88 | AX54: 189292.31 | AY54: 191949.83 | AZ54: 191268.89 | BA54: 193612.46 | BB54: 192309.48 | BC54: 191636.28 | BD54: 191154.78 | BE54: 191413.5 | BF54: 192336.71 | BG54: 193241.21 | BH54: 194955.09 | BI54: 192482.45
A55: Fuzzy | B55: 178014.45 | C55: 178014.45 | D55: 178014.45 | E55: 178014.45 | F55: 178014.45 | G55: 178014.45 | H55: 178014.45 | I55: 178014.45 | J55: 178014.45 | K55: 178014.45 | L55: 178014.45 | M55: 178014.45 | N55: 178014.45 | O55: 178014.45 | P55: 178014.45 | Q55: 178014.45 | R55: 178014.45 | S55: 178014.45 | T55: 178014.45 | U55: 178014.45 | V55: 193076.96 | W55: 193076.96 | X55: 193076.96 | Y55: 193076.96 | Z55: 193076.96 | AA55: 193076.96 | AB55: 193076.96 | AC55: 193076.96 | AD55: 193076.96 | AE55: 193076.96 | AF55: 193076.96 | AG55: 193076.96 | AH55: 193076.96 | AI55: 193076.96 | AJ55: 193076.96 | AK55: 193076.96 | AL55: 193076.96 | AM55: 193076.96 | AN55: 193076.96 | AO55: 193076.96 | AP55: 186748.07 | AQ55: 186748.33 | AR55: 186748.5 | AS55: 186748.19 | AT55: 186748.67 | AU55: 186748.07 | AV55: 186748.5 | AW55: 186748.05 | AX55: 186748.49 | AY55: 186748.48 | AZ55: 186748.41 | BA55: 186748.32 | BB55: 186748.23 | BC55: 186748.29 | BD55: 186748.46 | BE55: 186748.52 | BF55: 186747.99 | BG55: 186748.44 | BH55: 186748.49 | BI55: 186748.58
A56: NSGA3 | B56: 200494.42 | C56: 213914.74 | D56: 197031.45 | E56: 198263.32 | F56: 188775.16 | G56: 192881.84 | H56: 205086.23 | I56: 191426.13 | J56: 200975.77 | K56: 207929.26 | L56: 194096.97 | M56: 193029.26 | N56: 192915 | O56: 195612.52 | P56: 191255.77 | Q56: 202072.48 | R56: 213293.94 | S56: 197284.29 | T56: 195630.97 | U56: 211637.97 | V56: 207506.53 | W56: 211129.41 | X56: 213501.43 | Y56: 206757.2 | Z56: 214301.31 | AA56: 225472.94 | AB56: 222364.49 | AC56: 215229.37 | AD56: 227833.53 | AE56: 220102.9 | AF56: 225156.65 | AG56: 236645.43 | AH56: 245094.02 | AI56: 213419.31 | AJ56: 213537.84 | AK56: 230359.27 | AL56: 220340.71 | AM56: 221312.49 | AN56: 224943.45 | AO56: 215571.76 | AP56: 210968.77 | AQ56: 240137.63 | AR56: 220188.46 | AS56: 233455.11 | AT56: 212982.72 | AU56: 222713.44 | AV56: 215354.33 | AW56: 210550.25 | AX56: 217271.55 | AY56: 217406.75 | AZ56: 212689.81 | BA56: 207101.22 | BB56: 211721.06 | BC56: 203095.99 | BD56: 221124.63 | BE56: 220883.43 | BF56: 217702.13 | BG56: 195167.28 | BH56: 212697.54 | BI56: 208382.54
A57: MQGA | B57: 193810.42 | C57: 186562.26 | D57: 191970.42 | E57: 188577.35 | F57: 185232.58 | G57: 187589.55 | H57: 191761.16 | I57: 191211.42 | J57: 183774.77 | K57: 194979.35 | L57: 183154.55 | M57: 189073.55 | N57: 188124.45 | O57: 198296.45 | P57: 185558.06 | Q57: 189414.94 | R57: 196763.45 | S57: 184519.77 | T57: 194981.87 | U57: 188044.61 | V57: 208905.69 | W57: 206611.88 | X57: 209418.92 | Y57: 208197.29 | Z57: 223148.75 | AA57: 207748.41 | AB57: 209532.22 | AC57: 216985.69 | AD57: 213417.71 | AE57: 215966.65 | AF57: 210908.92 | AG57: 222673.8 | AH57: 215765.29 | AI57: 220408.22 | AJ57: 209177.08 | AK57: 207524.33 | AL57: 205687.16 | AM57: 215088.51 | AN57: 210508.94 | AO57: 210060.61 | AP57: 198964.31 | AQ57: 206475.78 | AR57: 207044.01 | AS57: 197242.24 | AT57: 212729.18 | AU57: 206049.2 | AV57: 210532.15 | AW57: 208063 | AX57: 202687.72 | AY57: 198757.66 | AZ57: 210926.1 | BA57: 197188.42 | BB57: 212805.42 | BC57: 219010.75 | BD57: 207470.84 | BE57: 215837.28 | BF57: 204710.89 | BG57: 200856.34 | BH57: 214535.75 | BI57: 204209.4
...

Sheet Energy
A1: Algorithm | B1: Load | C1: Average | D1: Min | E1: Max | F1: Std Dev
A2: QUEST | B2: 1 | C2: 1.2227249e+09 | D2: 1.2039012e+09 | E2: 1.301649e+09 | F2: 29193469
A3: QUEST | B3: 2 | C3: 1.3194119e+09 | D3: 1.2834563e+09 | E3: 1.398002e+09 | F3: 34807124
A4: QUEST | B4: 3 | C4: 1.2921245e+09 | D4: 1.2386298e+09 | E4: 1.3516904e+09 | F4: 32364240
A5: QUEST_NDVFS | B5: 1 | C5: 1.2635108e+09 | D5: 1.2481686e+09 | E5: 1.3700148e+09 | F5: 25624392
A6: QUEST_NDVFS | B6: 2 | C6: 1.4702213e+09 | D6: 1.3766132e+09 | E6: 1.6105248e+09 | F6: 51878736
A7: QUEST_NDVFS | B7: 3 | C7: 1.4772561e+09 | D7: 1369195580 | E7: 1680784160 | F7: 78018818
A8: Fuzzy | B8: 1 | C8: 1.2681604e+09 | D8: 1.2681249e+09 | E8: 1.2681852e+09 | F8: 16802.599
A9: Fuzzy | B9: 2 | C9: 1.4213567e+09 | D9: 1.4213127e+09 | E9: 1.4213948e+09 | F9: 23797.827
A10: Fuzzy | B10: 3 | C10: 1.405614e+09 | D10: 1.405585e+09 | E10: 1.4056433e+09 | F10: 17353.593
A11: NSGA3 | B11: 1 | C11: 1.4110384e+09 | D11: 1.3301048e+09 | E11: 1.6267592e+09 | F11: 85913624
A12: NSGA3 | B12: 2 | C12: 1.6672214e+09 | D12: 1.4068548e+09 | E12: 2.3481206e+09 | F12: 2.3964762e+08
A13: NSGA3 | B13: 3 | C13: 1.9959407e+09 | D13: 1463395925 | E13: 2503763970 | F13: 2.6342402e+08
... A25: RL | B25: 3 | C25: 1.8772486e+09 | D25: 1.5612057e+09 | E25: 2.3873318e+09 | F25: 2.31947e+08
A28: Summary by Algorithm
A29: QUEST | C29: 1.2780871e+09 | D29: 1.2039012e+09 | E29: 1.398002e+09 | F29: 51900569
A30: QUEST_NDVFS | C30: 1.4036627e+09 | D30: 1.2481686e+09 | E30: 1680784160 | F30: 1.1390575e+08
A31: Fuzzy | C31: 1.3650437e+09 | D31: 1.2681249e+09 | E31: 1.4213948e+09 | F31: 68807635
A32: NSGA3 | C32: 1.6914002e+09 | D32: 1.3301048e+09 | E32: 2503763970 | F32: 3.1944566e+08
A33: MQGA | C33: 1.5480488e+09 | D33: 1343195000 | E33: 1.8040538e+09 | F33: 1.5888608e+08
A34: Greedy | C34: 1.68939e+09 | D34: 1.248328e+09 | E34: 2.4820364e+09 | F34: 2.5665871e+08
A35: MOPSO | C35: 1.6461377e+09 | D35: 1346083105 | E35: 2.0571327e+09 | F35: 2.1175127e+08
A36: RL | C36: 1.6629761e+09 | D36: 1.2555451e+09 | E36: 2.3873318e+09 | F36: 2.8912968e+08
A39: Average data for chart
A40: Algorithms | B40: 1 | C40: 2 | D40: 3
A41: QUEST | B41: 1.2227249e+09 | C41: 1.3194119e+09 | D41: 1.2921245e+09
A42: QUEST_NDVFS | B42: 1.2635108e+09 | C42: 1.4702213e+09 | D42: 1.4772561e+09
A43: Fuzzy | B43: 1.2681604e+09 | C43: 1.4213567e+09 | D43: 1.405614e+09
A44: NSGA3 | B44: 1.4110384e+09 | C44: 1.6672214e+09 | D44: 1.9959407e+09
A45: MQGA | B45: 1.3527754e+09 | C45: 1.5529082e+09 | D45: 1.7384627e+09
A46: Greedy | B46: 1.4933059e+09 | C46: 1.7563347e+09 | D46: 1818529417
A47: MOPSO | B47: 1.4059674e+09 | C47: 1.632873e+09 | D47: 1.8995726e+09
A48: RL | B48: 1.3801106e+09 | C48: 1.731569e+09 | D48: 1.8772486e+09
A51: All data for chart
A52: Algorithms | B52: 1 | C52: 1 | D52: 1 | E52: 1 | F52: 1 | G52: 1 | H52: 1 | I52: 1 | J52: 1 | K52: 1 | L52: 1 | M52: 1 | N52: 1 | O52: 1 | P52: 1 | Q52: 1 | R52: 1 | S52: 1 | T52: 1 | U52: 1 | V52: 2 | W52: 2 | X52: 2 | Y52: 2 | Z52: 2 | AA52: 2 | AB52: 2 | AC52: 2 | AD52: 2 | AE52: 2 | AF52: 2 | AG52: 2 | AH52: 2 | AI52: 2 | AJ52: 2 | AK52: 2 | AL52: 2 | AM52: 2 | AN52: 2 | AO52: 2 | AP52: 3 | AQ52: 3 | AR52: 3 | AS52: 3 | AT52: 3 | AU52: 3 | AV52: 3 | AW52: 3 | AX52: 3 | AY52: 3 | AZ52: 3 | BA52: 3 | BB52: 3 | BC52: 3 | BD52: 3 | BE52: 3 | BF52: 3 | BG52: 3 | BH52: 3 | BI52: 3
A53: QUEST | B53: 1.208822e+09 | C53: 1.2073749e+09 | D53: 1.2821623e+09 | E53: 1.2060204e+09 | F53: 1.2046495e+09 | G53: 1.2145363e+09 | H53: 1.2070884e+09 | I53: 1.2063547e+09 | J53: 1.2112148e+09 | K53: 1.2088878e+09 | L53: 1.2039012e+09 | M53: 1.2862516e+09 | N53: 1.2086229e+09 | O53: 1.2107965e+09 | P53: 1.207783e+09 | Q53: 1.2101252e+09 | R53: 1.231307e+09 | S53: 1.2106563e+09 | T53: 1.2262935e+09 | U53: 1.301649e+09 | V53: 1.2905973e+09 | W53: 1.3750494e+09 | X53: 1.3396131e+09 | Y53: 1.327035e+09 | Z53: 1.2891499e+09 | AA53: 1.3797152e+09 | AB53: 1.3075513e+09 | AC53: 1.3119209e+09 | AD53: 1.3344787e+09 | AE53: 1.2966e+09 | AF53: 1.2982246e+09 | AG53: 1.2887974e+09 | AH53: 1.2862442e+09 | AI53: 1.398002e+09 | AJ53: 1.3615475e+09 | AK53: 1.28904e+09 | AL53: 1.2978725e+09 | AM53: 1.2834563e+09 | AN53: 1.2920755e+09 | AO53: 1.3412681e+09 | AP53: 1.3017839e+09 | AQ53: 1.2923107e+09 | AR53: 1.2696742e+09 | AS53: 1.2701176e+09 | AT53: 1.3359615e+09 | AU53: 1.2664386e+09 | AV53: 1.2720212e+09 | AW53: 1.2841651e+09 | AX53: 1.2837735e+09 | AY53: 1.2507766e+09 | AZ53: 1.2728423e+09 | BA53: 1.3392943e+09 | BB53: 1.3140969e+09 | BC53: 1.2593232e+09 | BD53: 1.3425448e+09 | BE53: 1.2786348e+09 | BF53: 1.2386298e+09 | BG53: 1.3333499e+09 | BH53: 1.3516904e+09 | BI53: 1.2850615e+09
A54: QUEST_NDVFS | B54: 1.2537954e+09 | C54: 1.2594854e+09 | D54: 1.2526221e+09 | E54: 1.2527214e+09 | F54: 1.2594701e+09 | G54: 1260303270 | H54: 1.3700148e+09 | I54: 1.2587234e+09 | J54: 1.2545801e+09 | K54: 1252865255 | L54: 1258677300 | M54: 1.2481686e+09 | N54: 1252212895 | O54: 1.2873051e+09 | P54: 1.2596788e+09 | Q54: 1.261802e+09 | R54: 1.2626285e+09 | S54: 1.2518618e+09 | T54: 1256888360 | U54: 1.2564105e+09 | V54: 1.4509983e+09 | W54: 1.4377867e+09 | X54: 1.387505e+09 | Y54: 1.4901226e+09 | Z54: 1.4935581e+09 | AA54: 1491324975 | AB54: 1.6105248e+09 | AC54: 1.4991395e+09 | AD54: 1.489839e+09 | AE54: 1.4856262e+09 | AF54: 1459791720 | AG54: 1.3769417e+09 | AH54: 1.4459364e+09 | AI54: 1.3766132e+09 | AJ54: 1.4551733e+09 | AK54: 1510519585 | AL54: 1.4879545e+09 | AM54: 1.4488699e+09 | AN54: 1.5098128e+09 | AO54: 1.496388e+09 | AP54: 1680784160 | AQ54: 1.3806667e+09 | AR54: 1475112625 | AS54: 1.3750515e+09 | AT54: 1.491632e+09 | AU54: 1.4653339e+09 | AV54: 1.457118e+09 | AW54: 1.442159e+09 | AX54: 1.4915431e+09 | AY54: 1.6607859e+09 | AZ54: 1.4577354e+09 | BA54: 1.487768e+09 | BB54: 1.4657791e+09 | BC54: 1476188635 | BD54: 1.396578e+09 | BE54: 1.495313e+09 | BF54: 1369195580 | BG54: 1.4770932e+09 | BH54: 1.5471969e+09 | BI54: 1.4520879e+09
A55: Fuzzy | B55: 1.2681582e+09 | C55: 1.2681426e+09 | D55: 1.26818e+09 | E55: 1.2681551e+09 | F55: 1.2681717e+09 | G55: 1.2681249e+09 | H55: 1.2681447e+09 | I55: 1.2681311e+09 | J55: 1.2681571e+09 | K55: 1.2681644e+09 | L55: 1.2681779e+09 | M55: 1.2681675e+09 | N55: 1.2681852e+09 | O55: 1.2681811e+09 | P55: 1.2681727e+09 | Q55: 1.2681603e+09 | R55: 1.2681727e+09 | S55: 1.2681582e+09 | T55: 1.2681675e+09 | U55: 1.2681353e+09 | V55: 1.4213605e+09 | W55: 1.4213522e+09 | X55: 1.4213761e+09 | Y55: 1.4213657e+09 | Z55: 1.4213148e+09 | AA55: 1.4213408e+09 | AB55: 1.4213189e+09 | AC55: 1.4213366e+09 | AD55: 1.4213761e+09 | AE55: 1.4213616e+09 | AF55: 1.4213616e+09 | AG55: 1.4213626e+09 | AH55: 1.4213127e+09 | AI55: 1.4213272e+09 | AJ55: 1.4213876e+09 | AK55: 1.4213824e+09 | AL55: 1.421374e+09 | AM55: 1.4213751e+09 | AN55: 1.4213948e+09 | AO55: 1.4213522e+09 | AP55: 1.4056318e+09 | AQ55: 1.4056214e+09 | AR55: 1.40561e+09 | AS55: 1.405585e+09 | AT55: 1.4056329e+09 | AU55: 1.4055965e+09 | AV55: 1.4056433e+09 | AW55: 1.4055965e+09 | AX55: 1.4056017e+09 | AY55: 1.405609e+09 | AZ55: 1.4056225e+09 | BA55: 1.4055965e+09 | BB55: 1.4055975e+09 | BC55: 1.405611e+09 | BD55: 1.4056142e+09 | BE55: 1.405637e+09 | BF55: 1.4056277e+09 | BG55: 1.4055892e+09 | BH55: 1.4056142e+09 | BI55: 1.4056422e+09
A56: NSGA3 | B56: 1.4680938e+09 | C56: 1.6267592e+09 | D56: 1.423156e+09 | E56: 1.4292964e+09 | F56: 1.3674515e+09 | G56: 1.345265e+09 | H56: 1.344543e+09 | I56: 1.3529191e+09 | J56: 1.4222516e+09 | K56: 1.3538883e+09 | L56: 1.4389617e+09 | M56: 1.3301048e+09 | N56: 1350422680 | O56: 1.3362705e+09 | P56: 1.3340362e+09 | Q56: 1369567180 | R56: 1530078380 | S56: 1363226080 | T56: 1.4259217e+09 | U56: 1.6085555e+09 | V56: 1.4302497e+09 | W56: 1.5363991e+09 | X56: 1.4068548e+09 | Y56: 1.4851326e+09 | Z56: 1442774580 | AA56: 1.7545601e+09 | AB56: 1837928415 | AC56: 1.4471834e+09 | AD56: 1.7432345e+09 | AE56: 1.5447783e+09 | AF56: 1.8026751e+09 | AG56: 2.1324065e+09 | AH56: 2.3481206e+09 | AI56: 1.5425045e+09 | AJ56: 1.5019787e+09 | AK56: 1.7348912e+09 | AL56: 1.8940144e+09 | AM56: 1609521335 | AN56: 1587741680 | AO56: 1.5614782e+09 | AP56: 1.5813173e+09 | AQ56: 2.4111446e+09 | AR56: 2.1425527e+09 | AS56: 2503763970 | AT56: 2.0252578e+09 | AU56: 2.3376935e+09 | AV56: 1873431310 | AW56: 1.7181322e+09 | AX56: 2.1392806e+09 | AY56: 2.1014583e+09 | AZ56: 1.9554995e+09 | BA56: 2.2015819e+09 | BB56: 1.8112682e+09 | BC56: 1.6621023e+09 | BD56: 2.1531939e+09 | BE56: 2018417900 | BF56: 1.9775741e+09 | BG56: 1463395925 | BH56: 1.8411365e+09 | BI56: 2.0006114e+09
A57: MQGA | B57: 1.3604686e+09 | C57: 1.3507837e+09 | D57: 1.3466914e+09 | E57: 1.3580576e+09 | F57: 1.3590648e+09 | G57: 1354137820 | H57: 1.3471458e+09 | I57: 1.3432213e+09 | J57: 1.359209e+09 | K57: 1343195000 | L57: 1.3662561e+09 | M57: 1.3498898e+09 | N57: 1.3604586e+09 | O57: 1.350805e+09 | P57: 1.3513611e+09 | Q57: 1.3508602e+09 | R57: 1357252100 | S57: 1.3479856e+09 | T57: 1.344777e+09 | U57: 1.3538881e+09 | V57: 1.5546171e+09 | W57: 1568403645 | X57: 1.5457074e+09 | Y57: 1.5457862e+09 | Z57: 1.5624191e+09 | AA57: 1544492345 | AB57: 1.5598659e+09 | AC57: 1.5372712e+09 | AD57: 1.5421272e+09 | AE57: 1.5392582e+09 | AF57: 1.535942e+09 | AG57: 1546145550 | AH57: 1.6056426e+09 | AI57: 1.5455143e+09 | AJ57: 1.5633801e+09 | AK57: 1.5653657e+09 | AL57: 1.5475279e+09 | AM57: 1547663920 | AN57: 1.5464527e+09 | AO57: 1.5545811e+09 | AP57: 1.7256087e+09 | AQ57: 1.7359739e+09 | AR57: 1.7485551e+09 | AS57: 1.7286887e+09 | AT57: 1.713482e+09 | AU57: 1.7190664e+09 | AV57: 1.788342e+09 | AW57: 1.725139e+09 | AX57: 1.7530382e+09 | AY57: 1.7380772e+09 | AZ57: 1.7628503e+09 | BA57: 1.7165253e+09 | BB57: 1.8024708e+09 | BC57: 1.768893e+09 | BD57: 1.733362e+09 | BE57: 1.8040538e+09 | BF57: 1685801760 | BG57: 1.7101767e+09 | BH57: 1.6894379e+09 | BI57: 1719710330
...

Sheet Makespan
A1: Algorithm | B1: Load | C1: Average | D1: Min | E1: Max | F1: Std Dev
A2: QUEST | B2: 1 | C2: 1136360.8 | D2: 1114817 | E2: 1222316 | F2: 32918.676
A3: QUEST | B3: 2 | C3: 1225334.1 | D3: 1177970 | E3: 1336484 | F3: 47215.444
A4: QUEST | B4: 3 | C4: 1242820.5 | D4: 1129720 | E4: 1335124 | F4: 53896.238
A5: QUEST_NDVFS | B5: 1 | C5: 1123188.1 | D5: 1112777 | E5: 1226275 | F5: 24760.876
A6: QUEST_NDVFS | B6: 2 | C6: 1270395.6 | D6: 1176896 | E6: 1409397 | F6: 52822.867
A7: QUEST_NDVFS | B7: 3 | C7: 1218447.7 | D7: 1115715 | E7: 1384500 | F7: 70090.391
A8: Fuzzy | B8: 1 | C8: 1113666.1 | D8: 1113632 | E8: 1113690 | F8: 16.156346
A9: Fuzzy | B9: 2 | C9: 1181680.3 | D9: 1181638 | E9: 1181717 | F9: 22.882526
A10: Fuzzy | B10: 3 | C10: 1111605.9 | D10: 1111578 | E10: 1111634 | F10: 16.686147
A11: NSGA3 | B11: 1 | C11: 1294983.2 | D11: 1218382 | E11: 1507870 | F11: 83207.22
A12: NSGA3 | B12: 2 | C12: 1496014.4 | D12: 1245675 | E12: 2125860 | F12: 224475.15
A13: NSGA3 | B13: 3 | C13: 1719146.1 | D13: 1227399 | E13: 2171707 | F13: 249374.16
... A25: RL | B25: 3 | C25: 1605627.4 | D25: 1329835 | E25: 2088720 | F25: 214250.83
A28: Summary by Algorithm
A29: QUEST | C29: 1201505.1 | D29: 1114817 | E29: 1336484 | F29: 65157.014
A30: QUEST_NDVFS | C30: 1204010.4 | D30: 1112777 | E30: 1409397 | F30: 80547.505
A31: Fuzzy | C31: 1135650.8 | D31: 1111578 | E31: 1181717 | F31: 32558.667
A32: NSGA3 | C32: 1503381.2 | D32: 1218382 | E32: 2171707 | F32: 264284.24
A33: MQGA | C33: 1352250.9 | D33: 1206003 | E33: 1526258 | F33: 102310.18
A34: Greedy | C34: 1498815.2 | D34: 1118717 | E34: 2256046 | F34: 222761.75
A35: MOPSO | C35: 1457971.2 | D35: 1222225 | E35: 1766461 | F35: 150366.14
A36: RL | C36: 1474581.6 | D36: 1145021 | E36: 2088720 | F36: 239059.18
A39: Average data for chart
A40: Algorithms | B40: 1 | C40: 2 | D40: 3
A41: QUEST | B41: 1136360.8 | C41: 1225334.1 | D41: 1242820.5
A42: QUEST_NDVFS | B42: 1123188.1 | C42: 1270395.6 | D42: 1218447.7
A43: Fuzzy | B43: 1113666.1 | C43: 1181680.3 | D43: 1111605.9
A44: NSGA3 | B44: 1294983.2 | C44: 1496014.4 | D44: 1719146.1
A45: MQGA | B45: 1221345.5 | C45: 1369898.8 | D45: 1465508.3
A46: Greedy | B46: 1369452.8 | C46: 1576353.1 | D46: 1550639.7
A47: MOPSO | B47: 1288624.1 | C47: 1464479.9 | D47: 1620809.6
A48: RL | B48: 1268530.8 | C48: 1549586.6 | D48: 1605627.4
A51: All data for chart
A52: Algorithms | B52: 1 | C52: 1 | D52: 1 | E52: 1 | F52: 1 | G52: 1 | H52: 1 | I52: 1 | J52: 1 | K52: 1 | L52: 1 | M52: 1 | N52: 1 | O52: 1 | P52: 1 | Q52: 1 | R52: 1 | S52: 1 | T52: 1 | U52: 1 | V52: 2 | W52: 2 | X52: 2 | Y52: 2 | Z52: 2 | AA52: 2 | AB52: 2 | AC52: 2 | AD52: 2 | AE52: 2 | AF52: 2 | AG52: 2 | AH52: 2 | AI52: 2 | AJ52: 2 | AK52: 2 | AL52: 2 | AM52: 2 | AN52: 2 | AO52: 2 | AP52: 3 | AQ52: 3 | AR52: 3 | AS52: 3 | AT52: 3 | AU52: 3 | AV52: 3 | AW52: 3 | AX52: 3 | AY52: 3 | AZ52: 3 | BA52: 3 | BB52: 3 | BC52: 3 | BD52: 3 | BE52: 3 | BF52: 3 | BG52: 3 | BH52: 3 | BI52: 3
A53: QUEST | B53: 1119644 | C53: 1119887 | D53: 1207316 | E53: 1117563 | F53: 1114817 | G53: 1121948 | H53: 1120936 | I53: 1120326 | J53: 1119258 | K53: 1119550 | L53: 1121255 | M53: 1205385 | N53: 1120978 | O53: 1120288 | P53: 1118173 | Q53: 1118889 | R53: 1149273 | S53: 1122299 | T53: 1147114 | U53: 1222316 | V53: 1185155 | W53: 1296820 | X53: 1247974 | Y53: 1244750 | Z53: 1181388 | AA53: 1296697 | AB53: 1222283 | AC53: 1224133 | AD53: 1251891 | AE53: 1181259 | AF53: 1182647 | AG53: 1177970 | AH53: 1179016 | AI53: 1336484 | AJ53: 1271643 | AK53: 1178932 | AL53: 1228976 | AM53: 1181129 | AN53: 1184323 | AO53: 1253211 | AP53: 1247969 | AQ53: 1222541 | AR53: 1232807 | AS53: 1205841 | AT53: 1318565 | AU53: 1223104 | AV53: 1234810 | AW53: 1221211 | AX53: 1221920 | AY53: 1185691 | AZ53: 1220423 | BA53: 1319944 | BB53: 1254550 | BC53: 1206779 | BD53: 1319588 | BE53: 1197826 | BF53: 1129720 | BG53: 1334223 | BH53: 1335124 | BI53: 1223774
A54: QUEST_NDVFS | B54: 1117783 | C54: 1116878 | D54: 1113616 | E54: 1113662 | F54: 1117826 | G54: 1117760 | H54: 1226275 | I54: 1112777 | J54: 1117797 | K54: 1114680 | L54: 1116871 | M54: 1113799 | N54: 1116915 | O54: 1148787 | P54: 1114710 | Q54: 1116763 | R54: 1117718 | S54: 1117683 | T54: 1113692 | U54: 1117769 | V54: 1244147 | W54: 1241203 | X54: 1179885 | Y54: 1308226 | Z54: 1291382 | AA54: 1292183 | AB54: 1409397 | AC54: 1294764 | AD54: 1291341 | AE54: 1290488 | AF54: 1246551 | AG54: 1176896 | AH54: 1245741 | AI54: 1177920 | AJ54: 1266854 | AK54: 1309028 | AL54: 1295293 | AM54: 1247394 | AN54: 1307876 | AO54: 1291343 | AP54: 1372580 | AQ54: 1128658 | AR54: 1213861 | AS54: 1115715 | AT54: 1203566 | AU54: 1215475 | AV54: 1206515 | AW54: 1206761 | AX54: 1225486 | AY54: 1384500 | AZ54: 1203917 | BA54: 1230894 | BB54: 1224072 | BC54: 1227360 | BD54: 1116479 | BE54: 1227166 | BF54: 1116655 | BG54: 1232178 | BH54: 1297342 | BI54: 1219774
A55: Fuzzy | B55: 1113664 | C55: 1113649 | D55: 1113685 | E55: 1113661 | F55: 1113677 | G55: 1113632 | H55: 1113651 | I55: 1113638 | J55: 1113663 | K55: 1113670 | L55: 1113683 | M55: 1113673 | N55: 1113690 | O55: 1113686 | P55: 1113678 | Q55: 1113666 | R55: 1113678 | S55: 1113664 | T55: 1113673 | U55: 1113642 | V55: 1181684 | W55: 1181676 | X55: 1181699 | Y55: 1181689 | Z55: 1181640 | AA55: 1181665 | AB55: 1181644 | AC55: 1181661 | AD55: 1181699 | AE55: 1181685 | AF55: 1181685 | AG55: 1181686 | AH55: 1181638 | AI55: 1181652 | AJ55: 1181710 | AK55: 1181705 | AL55: 1181697 | AM55: 1181698 | AN55: 1181717 | AO55: 1181676 | AP55: 1111623 | AQ55: 1111613 | AR55: 1111602 | AS55: 1111578 | AT55: 1111624 | AU55: 1111589 | AV55: 1111634 | AW55: 1111589 | AX55: 1111594 | AY55: 1111601 | AZ55: 1111614 | BA55: 1111589 | BB55: 1111590 | BC55: 1111603 | BD55: 1111606 | BE55: 1111628 | BF55: 1111619 | BG55: 1111582 | BH55: 1111606 | BI55: 1111633
A56: NSGA3 | B56: 1343107 | C56: 1507870 | D56: 1316906 | E56: 1316960 | F56: 1239510 | G56: 1222121 | H56: 1250582 | I56: 1227216 | J56: 1316837 | K56: 1266280 | L56: 1315932 | M56: 1221276 | N56: 1228297 | O56: 1219995 | P56: 1218382 | Q56: 1252139 | R56: 1410349 | S56: 1250341 | T56: 1294385 | U56: 1481180 | V56: 1245675 | W56: 1364508 | X56: 1247863 | Y56: 1309020 | Z56: 1294452 | AA56: 1551427 | AB56: 1643423 | AC56: 1293457 | AD56: 1591560 | AE56: 1406380 | AF56: 1631715 | AG56: 1924388 | AH56: 2125860 | AI56: 1375639 | AJ56: 1343442 | AK56: 1586418 | AL56: 1712789 | AM56: 1443273 | AN56: 1417986 | AO56: 1411013 | AP56: 1301315 | AQ56: 2108421 | AR56: 1863313 | AS56: 2171707 | AT56: 1760682 | AU56: 2030650 | AV56: 1597765 | AW56: 1431554 | AX56: 1833407 | AY56: 1842732 | AZ56: 1689903 | BA56: 1928834 | BB56: 1524401 | BC56: 1403537 | BD56: 1883509 | BE56: 1722861 | BF56: 1716595 | BG56: 1227399 | BH56: 1595093 | BI56: 1749244
A57: MQGA | B57: 1240338 | C57: 1217263 | D57: 1222086 | E57: 1225292 | F57: 1218287 | G57: 1219170 | H57: 1222101 | I57: 1217310 | J57: 1222106 | K57: 1226270 | L57: 1220320 | M57: 1218352 | N57: 1226459 | O57: 1221356 | P57: 1220318 | Q57: 1220317 | R57: 1217226 | S57: 1206003 | T57: 1226321 | U57: 1220015 | V57: 1354414 | W57: 1371598 | X57: 1380626 | Y57: 1364504 | Z57: 1409346 | AA57: 1355226 | AB57: 1359739 | AC57: 1382771 | AD57: 1375766 | AE57: 1367980 | AF57: 1367797 | AG57: 1375847 | AH57: 1398387 | AI57: 1347859 | AJ57: 1381444 | AK57: 1381468 | AL57: 1350139 | AM57: 1363697 | AN57: 1344883 | AO57: 1364485 | AP57: 1470132 | AQ57: 1487167 | AR57: 1465072 | AS57: 1470794 | AT57: 1416787 | AU57: 1454959 | AV57: 1488652 | AW57: 1466388 | AX57: 1457142 | AY57: 1464822 | AZ57: 1478202 | BA57: 1422071 | BB57: 1526258 | BC57: 1497234 | BD57: 1483875 | BE57: 1486496 | BF57: 1413989 | BG57: 1422558 | BH57: 1446756 | BI57: 1490812
...

Sheet Success Rate
A1: Algorithm | B1: Load | C1: Average | D1: Min | E1: Max | F1: Std Dev
A2: QUEST | B2: 1 | C2: 1 | D2: TRUE | E2: TRUE | F2: 0
A3: QUEST | B3: 2 | C3: 1 | D3: TRUE | E3: TRUE | F3: 0
A4: QUEST | B4: 3 | C4: 1 | D4: TRUE | E4: TRUE | F4: 0
A5: QUEST_NDVFS | B5: 1 | C5: 1 | D5: TRUE | E5: TRUE | F5: 0
A6: QUEST_NDVFS | B6: 2 | C6: 1 | D6: TRUE | E6: TRUE | F6: 0
A7: QUEST_NDVFS | B7: 3 | C7: 1 | D7: TRUE | E7: TRUE | F7: 0
A8: Fuzzy | B8: 1 | C8: 1 | D8: TRUE | E8: TRUE | F8: 0
A9: Fuzzy | B9: 2 | C9: 1 | D9: TRUE | E9: TRUE | F9: 0
A10: Fuzzy | B10: 3 | C10: 1 | D10: TRUE | E10: TRUE | F10: 0
A11: NSGA3 | B11: 1 | C11: 1 | D11: TRUE | E11: TRUE | F11: 0
A12: NSGA3 | B12: 2 | C12: 0.95 | D12: FALSE | E12: TRUE | F12: 0.21794495
A13: NSGA3 | B13: 3 | C13: 1 | D13: TRUE | E13: TRUE | F13: 0
... A25: RL | B25: 3 | C25: 1 | D25: TRUE | E25: TRUE | F25: 0
A28: Summary by Algorithm
A29: QUEST | C29: 1 | D29: TRUE | E29: TRUE | F29: 0
A30: QUEST_NDVFS | C30: 1 | D30: TRUE | E30: TRUE | F30: 0
A31: Fuzzy | C31: 1 | D31: TRUE | E31: TRUE | F31: 0
A32: NSGA3 | C32: 0.98333333 | D32: FALSE | E32: TRUE | F32: 0.1280191
A33: MQGA | C33: 1 | D33: TRUE | E33: TRUE | F33: 0
A34: Greedy | C34: 0.95 | D34: FALSE | E34: TRUE | F34: 0.21794495
A35: MOPSO | C35: 1 | D35: TRUE | E35: TRUE | F35: 0
A36: RL | C36: 0.98333333 | D36: FALSE | E36: TRUE | F36: 0.1280191
A39: Average data for chart
A40: Algorithms | B40: 1 | C40: 2 | D40: 3
A41: QUEST | B41: 1 | C41: 1 | D41: 1
A42: QUEST_NDVFS | B42: 1 | C42: 1 | D42: 1
A43: Fuzzy | B43: 1 | C43: 1 | D43: 1
A44: NSGA3 | B44: 1 | C44: 0.95 | D44: 1
A45: MQGA | B45: 1 | C45: 1 | D45: 1
A46: Greedy | B46: 0.9 | C46: 0.95 | D46: 1
A47: MOPSO | B47: 1 | C47: 1 | D47: 1
A48: RL | B48: 1 | C48: 0.95 | D48: 1
A51: All data for chart
A52: Algorithms | B52: 1 | C52: 1 | D52: 1 | E52: 1 | F52: 1 | G52: 1 | H52: 1 | I52: 1 | J52: 1 | K52: 1 | L52: 1 | M52: 1 | N52: 1 | O52: 1 | P52: 1 | Q52: 1 | R52: 1 | S52: 1 | T52: 1 | U52: 1 | V52: 2 | W52: 2 | X52: 2 | Y52: 2 | Z52: 2 | AA52: 2 | AB52: 2 | AC52: 2 | AD52: 2 | AE52: 2 | AF52: 2 | AG52: 2 | AH52: 2 | AI52: 2 | AJ52: 2 | AK52: 2 | AL52: 2 | AM52: 2 | AN52: 2 | AO52: 2 | AP52: 3 | AQ52: 3 | AR52: 3 | AS52: 3 | AT52: 3 | AU52: 3 | AV52: 3 | AW52: 3 | AX52: 3 | AY52: 3 | AZ52: 3 | BA52: 3 | BB52: 3 | BC52: 3 | BD52: 3 | BE52: 3 | BF52: 3 | BG52: 3 | BH52: 3 | BI52: 3
A53: QUEST | B53: TRUE | C53: TRUE | D53: TRUE | E53: TRUE | F53: TRUE | G53: TRUE | H53: TRUE | I53: TRUE | J53: TRUE | K53: TRUE | L53: TRUE | M53: TRUE | N53: TRUE | O53: TRUE | P53: TRUE | Q53: TRUE | R53: TRUE | S53: TRUE | T53: TRUE | U53: TRUE | V53: TRUE | W53: TRUE | X53: TRUE | Y53: TRUE | Z53: TRUE | AA53: TRUE | AB53: TRUE | AC53: TRUE | AD53: TRUE | AE53: TRUE | AF53: TRUE | AG53: TRUE | AH53: TRUE | AI53: TRUE | AJ53: TRUE | AK53: TRUE | AL53: TRUE | AM53: TRUE | AN53: TRUE | AO53: TRUE | AP53: TRUE | AQ53: TRUE | AR53: TRUE | AS53: TRUE | AT53: TRUE | AU53: TRUE | AV53: TRUE | AW53: TRUE | AX53: TRUE | AY53: TRUE | AZ53: TRUE | BA53: TRUE | BB53: TRUE | BC53: TRUE | BD53: TRUE | BE53: TRUE | BF53: TRUE | BG53: TRUE | BH53: TRUE | BI53: TRUE
A54: QUEST_NDVFS | B54: TRUE | C54: TRUE | D54: TRUE | E54: TRUE | F54: TRUE | G54: TRUE | H54: TRUE | I54: TRUE | J54: TRUE | K54: TRUE | L54: TRUE | M54: TRUE | N54: TRUE | O54: TRUE | P54: TRUE | Q54: TRUE | R54: TRUE | S54: TRUE | T54: TRUE | U54: TRUE | V54: TRUE | W54: TRUE | X54: TRUE | Y54: TRUE | Z54: TRUE | AA54: TRUE | AB54: TRUE | AC54: TRUE | AD54: TRUE | AE54: TRUE | AF54: TRUE | AG54: TRUE | AH54: TRUE | AI54: TRUE | AJ54: TRUE | AK54: TRUE | AL54: TRUE | AM54: TRUE | AN54: TRUE | AO54: TRUE | AP54: TRUE | AQ54: TRUE | AR54: TRUE | AS54: TRUE | AT54: TRUE | AU54: TRUE | AV54: TRUE | AW54: TRUE | AX54: TRUE | AY54: TRUE | AZ54: TRUE | BA54: TRUE | BB54: TRUE | BC54: TRUE | BD54: TRUE | BE54: TRUE | BF54: TRUE | BG54: TRUE | BH54: TRUE | BI54: TRUE
A55: Fuzzy | B55: TRUE | C55: TRUE | D55: TRUE | E55: TRUE | F55: TRUE | G55: TRUE | H55: TRUE | I55: TRUE | J55: TRUE | K55: TRUE | L55: TRUE | M55: TRUE | N55: TRUE | O55: TRUE | P55: TRUE | Q55: TRUE | R55: TRUE | S55: TRUE | T55: TRUE | U55: TRUE | V55: TRUE | W55: TRUE | X55: TRUE | Y55: TRUE | Z55: TRUE | AA55: TRUE | AB55: TRUE | AC55: TRUE | AD55: TRUE | AE55: TRUE | AF55: TRUE | AG55: TRUE | AH55: TRUE | AI55: TRUE | AJ55: TRUE | AK55: TRUE | AL55: TRUE | AM55: TRUE | AN55: TRUE | AO55: TRUE | AP55: TRUE | AQ55: TRUE | AR55: TRUE | AS55: TRUE | AT55: TRUE | AU55: TRUE | AV55: TRUE | AW55: TRUE | AX55: TRUE | AY55: TRUE | AZ55: TRUE | BA55: TRUE | BB55: TRUE | BC55: TRUE | BD55: TRUE | BE55: TRUE | BF55: TRUE | BG55: TRUE | BH55: TRUE | BI55: TRUE
A56: NSGA3 | B56: TRUE | C56: TRUE | D56: TRUE | E56: TRUE | F56: TRUE | G56: TRUE | H56: TRUE | I56: TRUE | J56: TRUE | K56: TRUE | L56: TRUE | M56: TRUE | N56: TRUE | O56: TRUE | P56: TRUE | Q56: TRUE | R56: TRUE | S56: TRUE | T56: TRUE | U56: TRUE | V56: TRUE | W56: TRUE | X56: TRUE | Y56: TRUE | Z56: TRUE | AA56: TRUE | AB56: TRUE | AC56: TRUE | AD56: TRUE | AE56: TRUE | AF56: TRUE | AG56: TRUE | AH56: FALSE | AI56: TRUE | AJ56: TRUE | AK56: TRUE | AL56: TRUE | AM56: TRUE | AN56: TRUE | AO56: TRUE | AP56: TRUE | AQ56: TRUE | AR56: TRUE | AS56: TRUE | AT56: TRUE | AU56: TRUE | AV56: TRUE | AW56: TRUE | AX56: TRUE | AY56: TRUE | AZ56: TRUE | BA56: TRUE | BB56: TRUE | BC56: TRUE | BD56: TRUE | BE56: TRUE | BF56: TRUE | BG56: TRUE | BH56: TRUE | BI56: TRUE
A57: MQGA | B57: TRUE | C57: TRUE | D57: TRUE | E57: TRUE | F57: TRUE | G57: TRUE | H57: TRUE | I57: TRUE | J57: TRUE | K57: TRUE | L57: TRUE | M57: TRUE | N57: TRUE | O57: TRUE | P57: TRUE | Q57: TRUE | R57: TRUE | S57: TRUE | T57: TRUE | U57: TRUE | V57: TRUE | W57: TRUE | X57: TRUE | Y57: TRUE | Z57: TRUE | AA57: TRUE | AB57: TRUE | AC57: TRUE | AD57: TRUE | AE57: TRUE | AF57: TRUE | AG57: TRUE | AH57: TRUE | AI57: TRUE | AJ57: TRUE | AK57: TRUE | AL57: TRUE | AM57: TRUE | AN57: TRUE | AO57: TRUE | AP57: TRUE | AQ57: TRUE | AR57: TRUE | AS57: TRUE | AT57: TRUE | AU57: TRUE | AV57: TRUE | AW57: TRUE | AX57: TRUE | AY57: TRUE | AZ57: TRUE | BA57: TRUE | BB57: TRUE | BC57: TRUE | BD57: TRUE | BE57: TRUE | BF57: TRUE | BG57: TRUE | BH57: TRUE | BI57: TRUE
...

Sheet Load Edge
A1: Algorithm | B1: Load | C1: Average | D1: Min | E1: Max | F1: Std Dev
A2: QUEST | B2: 1 | C2: 136626.8 | D2: 125456.96 | E2: 145695.08 | F2: 5404.3847
A3: QUEST | B3: 2 | C3: 251654.88 | D3: 230540.82 | E3: 274398.44 | F3: 13543.37
A4: QUEST | B4: 3 | C4: 489395.88 | D4: 461859.52 | E4: 519219.04 | F4: 16014.607
A5: QUEST_NDVFS | B5: 1 | C5: 109914.47 | D5: 100209.4 | E5: 114227.62 | F5: 4152.1455
A6: QUEST_NDVFS | B6: 2 | C6: 195894.44 | D6: 181008.16 | E6: 206942.42 | F6: 8163.2262
A7: QUEST_NDVFS | B7: 3 | C7: 371127.28 | D7: 352780.98 | E7: 386030.88 | F7: 9266.137
A8: Fuzzy | B8: 1 | C8: 110368.96 | D8: 110368.96 | E8: 110368.96 | F8: 0
A9: Fuzzy | B9: 2 | C9: 196938.5 | D9: 196938.5 | E9: 196938.5 | F9: 0
A10: Fuzzy | B10: 3 | C10: 375230.84 | D10: 375230.84 | E10: 375230.84 | F10: 0
A11: NSGA3 | B11: 1 | C11: 117783.55 | D11: 103491.3 | E11: 128616.48 | F11: 7011.422
A12: NSGA3 | B12: 2 | C12: 212262.49 | D12: 186149.72 | E12: 224504.96 | F12: 9329.2113
A13: NSGA3 | B13: 3 | C13: 379475.01 | D13: 363509.08 | E13: 392438.66 | F13: 6953.9459
... A25: RL | B25: 3 | C25: 375332.7 | D25: 360105.94 | E25: 390137.5 | F25: 10026.484
A28: Summary by Algorithm
A29: QUEST | C29: 292559.19 | D29: 125456.96 | E29: 519219.04 | F29: 147424.39
A30: QUEST_NDVFS | C30: 225645.4 | D30: 100209.4 | E30: 386030.88 | F30: 108954.86
A31: Fuzzy | C31: 227512.77 | D31: 110368.96 | E31: 375230.84 | F31: 110269.5
A32: NSGA3 | C32: 236507.02 | D32: 103491.3 | E32: 392438.66 | F32: 108485.73
A33: MQGA | C33: 233403.94 | D33: 104750 | E33: 388233.78 | F33: 108113.59
A34: Greedy | C34: 235800.53 | D34: 105949.58 | E34: 396504.94 | F34: 107666.6
A35: MOPSO | C35: 235251.75 | D35: 107942.12 | E35: 386070.84 | F35: 105011.6
A36: RL | C36: 235196.62 | D36: 108377.32 | E36: 390137.5 | F36: 106177.64
A39: Average data for chart
A40: Algorithms | B40: 1 | C40: 2 | D40: 3
A41: QUEST | B41: 136626.8 | C41: 251654.88 | D41: 489395.88
A42: QUEST_NDVFS | B42: 109914.47 | C42: 195894.44 | D42: 371127.28
A43: Fuzzy | B43: 110368.96 | C43: 196938.5 | D43: 375230.84
A44: NSGA3 | B44: 117783.55 | C44: 212262.49 | D44: 379475.01
A45: MQGA | B45: 115120.25 | C45: 209033 | D45: 376058.58
A46: Greedy | B46: 117914.35 | C46: 211858.2 | D46: 377629.05
A47: MOPSO | B47: 119853.26 | C47: 212470.25 | D47: 373431.75
A48: RL | B48: 119283.92 | C48: 210973.23 | D48: 375332.7
A51: All data for chart
A52: Algorithms | B52: 1 | C52: 1 | D52: 1 | E52: 1 | F52: 1 | G52: 1 | H52: 1 | I52: 1 | J52: 1 | K52: 1 | L52: 1 | M52: 1 | N52: 1 | O52: 1 | P52: 1 | Q52: 1 | R52: 1 | S52: 1 | T52: 1 | U52: 1 | V52: 2 | W52: 2 | X52: 2 | Y52: 2 | Z52: 2 | AA52: 2 | AB52: 2 | AC52: 2 | AD52: 2 | AE52: 2 | AF52: 2 | AG52: 2 | AH52: 2 | AI52: 2 | AJ52: 2 | AK52: 2 | AL52: 2 | AM52: 2 | AN52: 2 | AO52: 2 | AP52: 3 | AQ52: 3 | AR52: 3 | AS52: 3 | AT52: 3 | AU52: 3 | AV52: 3 | AW52: 3 | AX52: 3 | AY52: 3 | AZ52: 3 | BA52: 3 | BB52: 3 | BC52: 3 | BD52: 3 | BE52: 3 | BF52: 3 | BG52: 3 | BH52: 3 | BI52: 3
A53: QUEST | B53: 141523.6 | C53: 142375.16 | D53: 130247.74 | E53: 139833.14 | F53: 139098.14 | G53: 139525.62 | H53: 129979.84 | I53: 128593.58 | J53: 137802.44 | K53: 139224.3 | L53: 133449.86 | M53: 135857.06 | N53: 125456.96 | O53: 140268.04 | P53: 141146.04 | Q53: 138253.66 | R53: 131284.86 | S53: 142036.88 | T53: 130884.06 | U53: 145695.08 | V53: 243202.04 | W53: 274398.44 | X53: 261011.2 | Y53: 254290.9 | Z53: 242191.54 | AA53: 269359.1 | AB53: 230790.12 | AC53: 241999.42 | AD53: 270557.56 | AE53: 253725.6 | AF53: 238084.14 | AG53: 254947.76 | AH53: 230540.82 | AI53: 268628.68 | AJ53: 251676.04 | AK53: 255294.86 | AL53: 231928.94 | AM53: 242727.48 | AN53: 249465.44 | AO53: 268277.52 | AP53: 509719 | AQ53: 481608.82 | AR53: 514869.58 | AS53: 469531.54 | AT53: 488709.6 | AU53: 471829.94 | AV53: 498921.26 | AW53: 490168.26 | AX53: 481068.94 | AY53: 500666.5 | AZ53: 493069.04 | BA53: 507684.6 | BB53: 494164.42 | BC53: 461859.52 | BD53: 519219.04 | BE53: 465269.24 | BF53: 473361.42 | BG53: 496788.04 | BH53: 490145.64 | BI53: 479263.2
A54: QUEST_NDVFS | B54: 102952.14 | C54: 113015.86 | D54: 108030.94 | E54: 114227.62 | F54: 113512.76 | G54: 113039.66 | H54: 113823.12 | I54: 112497.02 | J54: 107723.56 | K54: 107710.7 | L54: 113572.96 | M54: 103322.98 | N54: 108990.92 | O54: 109522.1 | P54: 112660.58 | Q54: 112646.48 | R54: 112695.1 | S54: 104941.88 | T54: 113193.68 | U54: 100209.4 | V54: 205769.58 | W54: 198489.5 | X54: 199144.96 | Y54: 181008.16 | Z54: 199255.54 | AA54: 195137.78 | AB54: 191202.32 | AC54: 206894.64 | AD54: 198164.8 | AE54: 193027.8 | AF54: 204196.18 | AG54: 182803 | AH54: 201552.3 | AI54: 188857.96 | AJ54: 182585.9 | AK54: 189690.9 | AL54: 188769.4 | AM54: 206942.42 | AN54: 197817.98 | AO54: 206577.6 | AP54: 352780.98 | AQ54: 365070.8 | AR54: 384731.58 | AS54: 384322.52 | AT54: 359653.94 | AU54: 381447.92 | AV54: 368731.44 | AW54: 371497.24 | AX54: 364198.24 | AY54: 361134.16 | AZ54: 378473.7 | BA54: 367530 | BB54: 364957.52 | BC54: 377015.9 | BD54: 378659.94 | BE54: 366388.04 | BF54: 386030.88 | BG54: 360869.06 | BH54: 377958.08 | BI54: 371093.72
A55: Fuzzy | B55: 110368.96 | C55: 110368.96 | D55: 110368.96 | E55: 110368.96 | F55: 110368.96 | G55: 110368.96 | H55: 110368.96 | I55: 110368.96 | J55: 110368.96 | K55: 110368.96 | L55: 110368.96 | M55: 110368.96 | N55: 110368.96 | O55: 110368.96 | P55: 110368.96 | Q55: 110368.96 | R55: 110368.96 | S55: 110368.96 | T55: 110368.96 | U55: 110368.96 | V55: 196938.5 | W55: 196938.5 | X55: 196938.5 | Y55: 196938.5 | Z55: 196938.5 | AA55: 196938.5 | AB55: 196938.5 | AC55: 196938.5 | AD55: 196938.5 | AE55: 196938.5 | AF55: 196938.5 | AG55: 196938.5 | AH55: 196938.5 | AI55: 196938.5 | AJ55: 196938.5 | AK55: 196938.5 | AL55: 196938.5 | AM55: 196938.5 | AN55: 196938.5 | AO55: 196938.5 | AP55: 375230.84 | AQ55: 375230.84 | AR55: 375230.84 | AS55: 375230.84 | AT55: 375230.84 | AU55: 375230.84 | AV55: 375230.84 | AW55: 375230.84 | AX55: 375230.84 | AY55: 375230.84 | AZ55: 375230.84 | BA55: 375230.84 | BB55: 375230.84 | BC55: 375230.84 | BD55: 375230.84 | BE55: 375230.84 | BF55: 375230.84 | BG55: 375230.84 | BH55: 375230.84 | BI55: 375230.84
A56: NSGA3 | B56: 120040.16 | C56: 112666.12 | D56: 111632.14 | E56: 122841.08 | F56: 109766.96 | G56: 119291.02 | H56: 126772.82 | I56: 118602.02 | J56: 124305.48 | K56: 128616.48 | L56: 120257.76 | M56: 103491.3 | N56: 119607.3 | O56: 120986.86 | P56: 106932.88 | Q56: 121020.12 | R56: 122026.92 | S56: 122137.94 | T56: 104209.76 | U56: 120465.8 | V56: 211353.9 | W56: 209822.94 | X56: 217771.46 | Y56: 192804.76 | Z56: 207075.08 | AA56: 209771.84 | AB56: 212012.2 | AC56: 219435.7 | AD56: 223037.76 | AE56: 224504.96 | AF56: 218617.88 | AG56: 212177.26 | AH56: 210355.84 | AI56: 216973.3 | AJ56: 186149.72 | AK56: 223678.56 | AL56: 207044.92 | AM56: 217805.56 | AN56: 216781.74 | AO56: 208074.52 | AP56: 366071.88 | AQ56: 383402.88 | AR56: 379884.24 | AS56: 376597.98 | AT56: 389089.44 | AU56: 381545.18 | AV56: 384576 | AW56: 363509.08 | AX56: 379765.92 | AY56: 383181.92 | AZ56: 388080.8 | BA56: 375711.46 | BB56: 381526.78 | BC56: 376551.46 | BD56: 375567.8 | BE56: 380968.46 | BF56: 377327.94 | BG56: 382649.36 | BH56: 371052.98 | BI56: 392438.66
A57: MQGA | B57: 119869.62 | C57: 109533.82 | D57: 118925.28 | E57: 116917.28 | F57: 114844.2 | G57: 116305.52 | H57: 118705.28 | I57: 118551.08 | J57: 105434.18 | K57: 120887.2 | L57: 113468.14 | M57: 117046.2 | N57: 116255.46 | O57: 107054.2 | P57: 104750 | Q57: 117423.2 | R57: 115021.56 | S57: 114320.08 | T57: 120505.04 | U57: 116587.66 | V57: 198345.7 | W57: 208735.64 | X57: 195461.46 | Y57: 203105.24 | Z57: 220865.92 | AA57: 210909.68 | AB57: 208606.5 | AC57: 220243.48 | AD57: 217208.22 | AE57: 210390.06 | AF57: 207086.64 | AG57: 215856.96 | AH57: 206843.12 | AI57: 209105.58 | AJ57: 213270.88 | AK57: 203183.02 | AL57: 209194.98 | AM57: 212686.04 | AN57: 208097.22 | AO57: 201463.66 | AP57: 376999.02 | AQ57: 382698.38 | AR57: 381683.88 | AS57: 388233.78 | AT57: 376767.22 | AU57: 374591.54 | AV57: 368288.4 | AW57: 387975.6 | AX57: 378041.78 | AY57: 364630.48 | AZ57: 381512.94 | BA57: 372476.6 | BB57: 359144.64 | BC57: 367335.72 | BD57: 370710.22 | BE57: 364371.04 | BF57: 384186.2 | BG57: 379865.18 | BH57: 375659.76 | BI57: 385999.12
...

Sheet Load Cloud
A1: Algorithm | B1: Load | C1: Average | D1: Min | E1: Max | F1: Std Dev
A2: QUEST | B2: 1 | C2: 193357.45 | D2: 0 | E2: 575500 | F2: 237450.28
A3: QUEST | B3: 2 | C3: 469023.7 | D3: 0 | E3: 1703052 | F3: 479337.66
A4: QUEST | B4: 3 | C4: 779522.95 | D4: 0 | E4: 1700504 | F4: 590826.53
A5: QUEST_NDVFS | B5: 1 | C5: 167899.85 | D5: 0 | E5: 581076 | F5: 198721.02
A6: QUEST_NDVFS | B6: 2 | C6: 487956.7 | D6: 0 | E6: 1298085 | F6: 390417
A7: QUEST_NDVFS | B7: 3 | C7: 588908 | D7: 0 | E7: 1157885 | F7: 361939.69
A8: Fuzzy | B8: 1 | C8: 0 | D8: 0 | E8: 0 | F8: 0
A9: Fuzzy | B9: 2 | C9: 0 | D9: 0 | E9: 0 | F9: 0
A10: Fuzzy | B10: 3 | C10: 15700 | D10: 15700 | E10: 15700 | F10: 0
A11: NSGA3 | B11: 1 | C11: 164442.1 | D11: 0 | E11: 794668 | F11: 258089.37
A12: NSGA3 | B12: 2 | C12: 202531.25 | D12: 0 | E12: 1341184 | F12: 359919.31
A13: NSGA3 | B13: 3 | C13: 267378.85 | D13: 0 | E13: 877400 | F13: 285610.42
... A25: RL | B25: 3 | C25: 443807.45 | D25: 0 | E25: 1283418 | F25: 403392.74
A28: Summary by Algorithm
A29: QUEST | C29: 480634.7 | D29: 0 | E29: 1703052 | F29: 518722.93
A30: QUEST_NDVFS | C30: 414921.52 | D30: 0 | E30: 1298085 | F30: 373961.21
A31: Fuzzy | C31: 5233.3333 | D31: 0 | E31: 15700 | F31: 7401.051
A32: NSGA3 | C32: 211450.73 | D32: 0 | E32: 1341184 | F32: 307214.73
A33: MQGA | C33: 196970.32 | D33: 0 | E33: 1028276 | F33: 274854.88
A34: Greedy | C34: 212347.5 | D34: 0 | E34: 1311410 | F34: 318228.35
A35: MOPSO | C35: 242805.93 | D35: 0 | E35: 1439401 | F35: 342484.73
A36: RL | C36: 249543.25 | D36: 0 | E36: 1283418 | F36: 318870.08
A39: Average data for chart
A40: Algorithms | B40: 1 | C40: 2 | D40: 3
A41: QUEST | B41: 193357.45 | C41: 469023.7 | D41: 779522.95
A42: QUEST_NDVFS | B42: 167899.85 | C42: 487956.7 | D42: 588908
A43: Fuzzy | B43: 0 | C43: 0 | D43: 15700
A44: NSGA3 | B44: 164442.1 | C44: 202531.25 | D44: 267378.85
A45: MQGA | B45: 85806.05 | C45: 162233.95 | D45: 342870.95
A46: Greedy | B46: 109648.6 | C46: 162081.5 | D46: 365312.4
A47: MOPSO | B47: 63710.2 | C47: 209932 | D47: 454775.6
A48: RL | B48: 137936.65 | C48: 166885.65 | D48: 443807.45
A51: All data for chart
A52: Algorithms | B52: 1 | C52: 1 | D52: 1 | E52: 1 | F52: 1 | G52: 1 | H52: 1 | I52: 1 | J52: 1 | K52: 1 | L52: 1 | M52: 1 | N52: 1 | O52: 1 | P52: 1 | Q52: 1 | R52: 1 | S52: 1 | T52: 1 | U52: 1 | V52: 2 | W52: 2 | X52: 2 | Y52: 2 | Z52: 2 | AA52: 2 | AB52: 2 | AC52: 2 | AD52: 2 | AE52: 2 | AF52: 2 | AG52: 2 | AH52: 2 | AI52: 2 | AJ52: 2 | AK52: 2 | AL52: 2 | AM52: 2 | AN52: 2 | AO52: 2 | AP52: 3 | AQ52: 3 | AR52: 3 | AS52: 3 | AT52: 3 | AU52: 3 | AV52: 3 | AW52: 3 | AX52: 3 | AY52: 3 | AZ52: 3 | BA52: 3 | BB52: 3 | BC52: 3 | BD52: 3 | BE52: 3 | BF52: 3 | BG52: 3 | BH52: 3 | BI52: 3
A53: QUEST | B53: 0 | C53: 22463 | D53: 575500 | E53: 22188 | F53: 0 | G53: 0 | H53: 404150 | I53: 529676 | J53: 0 | K53: 6788 | L53: 456450 | M53: 319513 | N53: 557398 | O53: 0 | P53: 0 | Q53: 0 | R53: 437813 | S53: 0 | T53: 535210 | U53: 0 | V53: 547613 | W53: 4275 | X53: 0 | Y53: 639853 | Z53: 530675 | AA53: 36726 | AB53: 1394521 | AC53: 924264 | AD53: 6600 | AE53: 23000 | AF53: 589136 | AG53: 7100 | AH53: 945736 | AI53: 498463 | AJ53: 593175 | AK53: 0 | AL53: 1703052 | AM53: 574409 | AN53: 361876 | AO53: 0 | AP53: 11457 | AQ53: 432254 | AR53: 5313 | AS53: 1340208 | AT53: 1700504 | AU53: 1407723 | AV53: 561738 | AW53: 320613 | AX53: 842476 | AY53: 22575 | AZ53: 389310 | BA53: 1089226 | BB53: 497075 | BC53: 1574864 | BD53: 389750 | BE53: 952048 | BF53: 0 | BG53: 1667614 | BH53: 1639601 | BI53: 746110
A54: QUEST_NDVFS | B54: 495525 | C54: 14642 | D54: 254750 | E54: 0 | F54: 4525 | G54: 14684 | H54: 14792 | I54: 0 | J54: 291875 | K54: 276742 | L54: 0 | M54: 495525 | N54: 254750 | O54: 213009 | P54: 4109 | Q54: 4809 | R54: 4525 | S54: 432659 | T54: 0 | U54: 581076 | V54: 0 | W54: 402767 | X54: 237525 | Y54: 1298085 | Z54: 334567 | AA54: 534950 | AB54: 724125 | AC54: 0 | AD54: 417025 | AE54: 661884 | AF54: 0 | AG54: 984426 | AH54: 241934 | AI54: 750309 | AJ54: 1150509 | AK54: 741226 | AL54: 863959 | AM54: 8342 | AN54: 402767 | AO54: 4734 | AP54: 898192 | AQ54: 870284 | AR54: 3842 | AS54: 0 | AT54: 753427 | AU54: 256067 | AV54: 766459 | AW54: 809042 | AX54: 801719 | AY54: 887751 | AZ54: 332735 | BA54: 761435 | BB54: 1019735 | BC54: 453334 | BD54: 19684 | BE54: 691135 | BF54: 0 | BG54: 1157885 | BH54: 432867 | BI54: 862567
A55: Fuzzy | B55: 0 | C55: 0 | D55: 0 | E55: 0 | F55: 0 | G55: 0 | H55: 0 | I55: 0 | J55: 0 | K55: 0 | L55: 0 | M55: 0 | N55: 0 | O55: 0 | P55: 0 | Q55: 0 | R55: 0 | S55: 0 | T55: 0 | U55: 0 | V55: 0 | W55: 0 | X55: 0 | Y55: 0 | Z55: 0 | AA55: 0 | AB55: 0 | AC55: 0 | AD55: 0 | AE55: 0 | AF55: 0 | AG55: 0 | AH55: 0 | AI55: 0 | AJ55: 0 | AK55: 0 | AL55: 0 | AM55: 0 | AN55: 0 | AO55: 0 | AP55: 15700 | AQ55: 15700 | AR55: 15700 | AS55: 15700 | AT55: 15700 | AU55: 15700 | AV55: 15700 | AW55: 15700 | AX55: 15700 | AY55: 15700 | AZ55: 15700 | BA55: 15700 | BB55: 15700 | BC55: 15700 | BD55: 15700 | BE55: 15700 | BF55: 15700 | BG55: 15700 | BH55: 15700 | BI55: 15700
A56: NSGA3 | B56: 0 | C56: 432659 | D56: 526368 | E56: 4109 | F56: 348659 | G56: 0 | H56: 4042 | I56: 4109 | J56: 14975 | K56: 0 | L56: 0 | M56: 794668 | N56: 0 | O56: 0 | P56: 582285 | Q56: 0 | R56: 0 | S56: 0 | T56: 562284 | U56: 14684 | V56: 0 | W56: 241650 | X56: 0 | Y56: 873768 | Z56: 567368 | AA56: 0 | AB56: 34318 | AC56: 4434 | AD56: 0 | AE56: 0 | AF56: 0 | AG56: 4217 | AH56: 15525 | AI56: 4409 | AJ56: 1341184 | AK56: 4434 | AL56: 402767 | AM56: 4342 | AN56: 0 | AO56: 552209 | AP56: 612935 | AQ56: 0 | AR56: 284659 | AS56: 4284 | AT56: 15300 | AU56: 0 | AV56: 19884 | AW56: 704060 | AX56: 4075 | AY56: 351317 | AZ56: 17176 | BA56: 549309 | BB56: 0 | BC56: 444809 | BD56: 568026 | BE56: 15200 | BF56: 516625 | BG56: 353842 | BH56: 877400 | BI56: 8676
A57: MQGA | B57: 14642 | C57: 291875 | D57: 0 | E57: 0 | F57: 0 | G57: 0 | H57: 4525 | I57: 0 | J57: 425309 | K57: 0 | L57: 4384 | M57: 4459 | N57: 14975 | O57: 437043 | P57: 514800 | Q57: 0 | R57: 0 | S57: 4109 | T57: 0 | U57: 0 | V57: 417992 | W57: 33634 | X57: 907292 | Y57: 420925 | Z57: 0 | AA57: 15050 | AB57: 0 | AC57: 0 | AD57: 0 | AE57: 226092 | AF57: 393675 | AG57: 15084 | AH57: 15084 | AI57: 0 | AJ57: 4117 | AK57: 397867 | AL57: 0 | AM57: 0 | AN57: 0 | AO57: 397867 | AP57: 485442 | AQ57: 327018 | AR57: 3925 | AS57: 0 | AT57: 50317 | AU57: 489467 | AV57: 396934 | AW57: 0 | AX57: 22776 | AY57: 808351 | AZ57: 4375 | BA57: 251493 | BB57: 1028276 | BC57: 727035 | BD57: 810517 | BE57: 373501 | BF57: 0 | BG57: 18675 | BH57: 662025 | BI57: 397292
...

Sheet Loads
A1: Average data for chart
B2: Edge | C2: Edge | D2: Edge | E2: Edge | F2: Edge | G2: Edge | H2: Edge | I2: Edge | J2: Edge | K2: Edge | L2: Edge | M2: Edge | N2: Edge | O2: Edge | P2: Edge | Q2: Edge | R2: Edge | S2: Edge | T2: Edge | U2: Edge | V2: Edge | W2: Edge | X2: Edge | Y2: Edge | Z2: Edge | AA2: Edge | AB2: Edge | AC2: Edge | AD2: Edge | AE2: Edge | AF2: Edge | AG2: Edge | AH2: Edge | AI2: Edge | AJ2: Edge | AK2: Edge | AL2: Edge | AM2: Edge | AN2: Edge | AO2: Edge | AP2: Edge | AQ2: Edge | AR2: Edge | AS2: Edge | AT2: Edge | AU2: Edge | AV2: Edge | AW2: Edge | AX2: Edge | AY2: Edge | AZ2: Cloud | BA2: Edge | BB2: Edge | BC2: Edge | BD2: Edge | BE2: Edge | BF2: Edge | BG2: Edge | BH2: Edge | BI2: Edge | BJ2: Edge | BK2: Edge | BL2: Edge | BM2: Edge | BN2: Edge | BO2: Edge | BP2: Edge | BQ2: Edge | BR2: Edge | BS2: Edge | BT2: Edge | BU2: Edge | BV2: Edge | BW2: Edge | BX2: Edge | BY2: Edge | BZ2: Edge | CA2: Edge | CB2: Edge | CC2: Edge | CD2: Edge | CE2: Edge | CF2: Edge | CG2: Edge | CH2: Edge | CI2: Edge | CJ2: Edge | CK2: Edge | CL2: Edge | CM2: Edge | CN2: Edge | CO2: Edge | CP2: Edge | CQ2: Edge | CR2: Edge | CS2: Edge | CT2: Edge | CU2: Edge | CV2: Edge | CW2: Edge | CX2: Edge | CY2: Cloud | CZ2: Edge | DA2: Edge | DB2: Edge | DC2: Edge | DD2: Edge | DE2: Edge | DF2: Edge | DG2: Edge | DH2: Edge | DI2: Edge | DJ2: Edge | DK2: Edge | DL2: Edge | DM2: Edge | DN2: Edge | DO2: Edge | DP2: Edge | DQ2: Edge | DR2: Edge | DS2: Edge | DT2: Edge | DU2: Edge | DV2: Edge | DW2: Edge | DX2: Edge | DY2: Edge | DZ2: Edge | EA2: Edge | EB2: Edge | EC2: Edge | ED2: Edge | EE2: Edge | EF2: Edge | EG2: Edge | EH2: Edge | EI2: Edge | EJ2: Edge | EK2: Edge | EL2: Edge | EM2: Edge | EN2: Edge | EO2: Edge | EP2: Edge | EQ2: Edge | ER2: Edge | ES2: Edge | ET2: Edge | EU2: Edge | EV2: Edge | EW2: Edge | EX2: Cloud
B3: 1 | C3: 1 | D3: 1 | E3: 1 | F3: 1 | G3: 1 | H3: 1 | I3: 1 | J3: 1 | K3: 1 | L3: 1 | M3: 1 | N3: 1 | O3: 1 | P3: 1 | Q3: 1 | R3: 1 | S3: 1 | T3: 1 | U3: 1 | V3: 1 | W3: 1 | X3: 1 | Y3: 1 | Z3: 1 | AA3: 1 | AB3: 1 | AC3: 1 | AD3: 1 | AE3: 1 | AF3: 1 | AG3: 1 | AH3: 1 | AI3: 1 | AJ3: 1 | AK3: 1 | AL3: 1 | AM3: 1 | AN3: 1 | AO3: 1 | AP3: 1 | AQ3: 1 | AR3: 1 | AS3: 1 | AT3: 1 | AU3: 1 | AV3: 1 | AW3: 1 | AX3: 1 | AY3: 1 | AZ3: 1 | BA3: 2 | BB3: 2 | BC3: 2 | BD3: 2 | BE3: 2 | BF3: 2 | BG3: 2 | BH3: 2 | BI3: 2 | BJ3: 2 | BK3: 2 | BL3: 2 | BM3: 2 | BN3: 2 | BO3: 2 | BP3: 2 | BQ3: 2 | BR3: 2 | BS3: 2 | BT3: 2 | BU3: 2 | BV3: 2 | BW3: 2 | BX3: 2 | BY3: 2 | BZ3: 2 | CA3: 2 | CB3: 2 | CC3: 2 | CD3: 2 | CE3: 2 | CF3: 2 | CG3: 2 | CH3: 2 | CI3: 2 | CJ3: 2 | CK3: 2 | CL3: 2 | CM3: 2 | CN3: 2 | CO3: 2 | CP3: 2 | CQ3: 2 | CR3: 2 | CS3: 2 | CT3: 2 | CU3: 2 | CV3: 2 | CW3: 2 | CX3: 2 | CY3: 2 | CZ3: 3 | DA3: 3 | DB3: 3 | DC3: 3 | DD3: 3 | DE3: 3 | DF3: 3 | DG3: 3 | DH3: 3 | DI3: 3 | DJ3: 3 | DK3: 3 | DL3: 3 | DM3: 3 | DN3: 3 | DO3: 3 | DP3: 3 | DQ3: 3 | DR3: 3 | DS3: 3 | DT3: 3 | DU3: 3 | DV3: 3 | DW3: 3 | DX3: 3 | DY3: 3 | DZ3: 3 | EA3: 3 | EB3: 3 | EC3: 3 | ED3: 3 | EE3: 3 | EF3: 3 | EG3: 3 | EH3: 3 | EI3: 3 | EJ3: 3 | EK3: 3 | EL3: 3 | EM3: 3 | EN3: 3 | EO3: 3 | EP3: 3 | EQ3: 3 | ER3: 3 | ES3: 3 | ET3: 3 | EU3: 3 | EV3: 3 | EW3: 3 | EX3: 3
A4: Algorithms | B4: 1 | C4: 2 | D4: 3 | E4: 4 | F4: 5 | G4: 6 | H4: 7 | I4: 8 | J4: 9 | K4: 10 | L4: 11 | M4: 12 | N4: 13 | O4: 14 | P4: 15 | Q4: 16 | R4: 17 | S4: 18 | T4: 19 | U4: 20 | V4: 21 | W4: 22 | X4: 23 | Y4: 24 | Z4: 25 | AA4: 26 | AB4: 27 | AC4: 28 | AD4: 29 | AE4: 30 | AF4: 31 | AG4: 32 | AH4: 33 | AI4: 34 | AJ4: 35 | AK4: 36 | AL4: 37 | AM4: 38 | AN4: 39 | AO4: 40 | AP4: 41 | AQ4: 42 | AR4: 43 | AS4: 44 | AT4: 45 | AU4: 46 | AV4: 47 | AW4: 48 | AX4: 49 | AY4: 50 | AZ4: 51 | BA4: 1 | BB4: 2 | BC4: 3 | BD4: 4 | BE4: 5 | BF4: 6 | BG4: 7 | BH4: 8 | BI4: 9 | BJ4: 10 | BK4: 11 | BL4: 12 | BM4: 13 | BN4: 14 | BO4: 15 | BP4: 16 | BQ4: 17 | BR4: 18 | BS4: 19 | BT4: 20 | BU4: 21 | BV4: 22 | BW4: 23 | BX4: 24 | BY4: 25 | BZ4: 26 | CA4: 27 | CB4: 28 | CC4: 29 | CD4: 30 | CE4: 31 | CF4: 32 | CG4: 33 | CH4: 34 | CI4: 35 | CJ4: 36 | CK4: 37 | CL4: 38 | CM4: 39 | CN4: 40 | CO4: 41 | CP4: 42 | CQ4: 43 | CR4: 44 | CS4: 45 | CT4: 46 | CU4: 47 | CV4: 48 | CW4: 49 | CX4: 50 | CY4: 51 | CZ4: 1 | DA4: 2 | DB4: 3 | DC4: 4 | DD4: 5 | DE4: 6 | DF4: 7 | DG4: 8 | DH4: 9 | DI4: 10 | DJ4: 11 | DK4: 12 | DL4: 13 | DM4: 14 | DN4: 15 | DO4: 16 | DP4: 17 | DQ4: 18 | DR4: 19 | DS4: 20 | DT4: 21 | DU4: 22 | DV4: 23 | DW4: 24 | DX4: 25 | DY4: 26 | DZ4: 27 | EA4: 28 | EB4: 29 | EC4: 30 | ED4: 31 | EE4: 32 | EF4: 33 | EG4: 34 | EH4: 35 | EI4: 36 | EJ4: 37 | EK4: 38 | EL4: 39 | EM4: 40 | EN4: 41 | EO4: 42 | EP4: 43 | EQ4: 44 | ER4: 45 | ES4: 46 | ET4: 47 | EU4: 48 | EV4: 49 | EW4: 50 | EX4: 51
A5: QUEST | B5: 73326.373 | C5: 29562.804 | D5: 127836.86 | E5: 78524.843 | F5: 79502.039 | G5: 90840.843 | H5: 126293.29 | I5: 73314.529 | J5: 114830 | K5: 122161.2 | L5: 65488.824 | M5: 69465.667 | N5: 65285.451 | O5: 95995.667 | P5: 95149.059 | Q5: 158536.08 | R5: 100927.61 | S5: 78137.353 | T5: 128321.9 | U5: 56230.255 | V5: 48793.255 | W5: 71737.824 | X5: 93930.98 | Y5: 61583.118 | Z5: 123488.65 | AA5: 23313.824 | AB5: 12769.667 | AC5: 24696.49 | AD5: 31167.235 | AE5: 12916.255 | AF5: 1005.5882 | AG5: 20530.863 | AH5: 10344.412 | AI5: 32996.745 | AJ5: 26333.608 | AK5: 2554.6275 | AL5: 11596.176 | AM5: 12025.314 | AN5: 22081.02 | AO5: 24466.549 | AP5: 3134.7255 | AQ5: 58787.843 | AR5: 1253.6471 | AS5: 19545.078 | AT5: 21483.843 | AU5: 2006.1765 | AV5: 20157.569 | AW5: 29748.098 | AX5: 12088.176 | AY5: 12688.922 | AZ5: 75826.451 | BA5: 153883.59 | BB5: 113433.57 | BC5: 162641.08 | BD5: 163463.43 | BE5: 130374.69 | BF5: 121594.33 | BG5: 91842.588 | BH5: 122097.71 | BI5: 165614.29 | BJ5: 147454.88 | BK5: 177013.35 | BL5: 159736.06 | BM5: 111852.92 | BN5: 130204.8 | BO5: 168771.1 | BP5: 84470.529 | BQ5: 124214.24 | BR5: 124678.88 | BS5: 105634.12 | BT5: 123311.12 | BU5: 165699 | BV5: 161069.71 | BW5: 149959.45 | BX5: 105870.78 | BY5: 135935.69 | BZ5: 34571.137 | CA5: 49729.039 | CB5: 53426.98 | CC5: 33472.745 | CD5: 38384.059 | CE5: 55440.078 | CF5: 36874.608 | CG5: 105440.49 | CH5: 39674 | CI5: 29235.157 | CJ5: 78274.647 | CK5: 74765.294 | CL5: 42057.588 | CM5: 121793.9 | CN5: 85897.784 | CO5: 66351.667 | CP5: 68551.667 | CQ5: 35489.216 | CR5: 51349.569 | CS5: 67887.431 | CT5: 72799.961 | CU5: 63687.804 | CV5: 60757.549 | CW5: 84158.667 | CX5: 83516.471 | CY5: 183930.86 | CZ5: 175220.27 | DA5: 197953.84 | DB5: 207679.49 | DC5: 145836.78 | DD5: 179502.55 | DE5: 164081.82 | DF5: 199647.75 | DG5: 200326.04 | DH5: 215026.9 | DI5: 196137.82 | DJ5: 143801.37 | DK5: 200060.43 | DL5: 214692.51 | DM5: 147005.61 | DN5: 173310.67 | DO5: 169436.71 | DP5: 135492.04 | DQ5: 176507.2 | DR5: 198358.76 | DS5: 178477.24 | DT5: 210603.2 | DU5: 173089.37 | DV5: 217762.8 | DW5: 132995.37 | DX5: 229000.53 | DY5: 205043.49 | DZ5: 151846.45 | EA5: 200168.31 | EB5: 208969.59 | EC5: 193000.49 | ED5: 215114.84 | EE5: 133366.51 | EF5: 158387.18 | EG5: 210303.73 | EH5: 264517.65 | EI5: 228759.33 | EJ5: 95584.294 | EK5: 168990.18 | EL5: 169655.78 | EM5: 202905.76 | EN5: 219623.39 | EO5: 342824.86 | EP5: 213252.76 | EQ5: 161062.51 | ER5: 168110.51 | ES5: 166732.59 | ET5: 352458.33 | EU5: 183096.71 | EV5: 156809.2 | EW5: 243406.12 | EX5: 305695.27
