Workbook

Sheet Charts
R2: AoI | S2: 1000 | T2: 2000
R3: QUEST | S3: ='Data Age'!B33 -> 313823.46 | T3: ='Data Age'!C33 -> 7158576.9
R4: QUEST_NDVFS | S4: ='Data Age'!B34 -> 251767.87 | T4: ='Data Age'!C34 -> 7283348.5
R5: Fuzzy | S5: ='Data Age'!B35 -> 930749.59 | T5: ='Data Age'!C35 -> 13293421
R6: NSGA3 | S6: ='Data Age'!B36 -> 747528.39 | T6: ='Data Age'!C36 -> 10629096
R7: MQGA | S7: ='Data Age'!B37 -> 804867.39 | T7: ='Data Age'!C37 -> 10388180
R8: Greedy | S8: ='Data Age'!B38 -> 986531.36 | T8: ='Data Age'!C38 -> 12103683
R9: MOPSO | S9: ='Data Age'!B39 -> 1187513.5 | T9: ='Data Age'!C39 -> 10948988
R10: RL | S10: ='Data Age'!B40 -> 917953.04 | T10: ='Data Age'!C40 -> 11101314
R17: AoI | S17: 1000 | T17: 2000
R18: QUEST | S18: =S3/S3 -> 1 | T18: =T3/T3 -> 1
R19: QUEST_NDVFS | S19: =S4/S3 -> 0.80225955 | T19: =T4/T3 -> 1.0174297
R20: Fuzzy | S20: =S5/S3 -> 2.9658382 | T20: =T5/T3 -> 1.8569921
R21: NSGA3 | S21: =S6/S3 -> 2.3820029 | T21: =T6/T3 -> 1.4848057
R22: MQGA | S22: =S7/S3 -> 2.5647139 | T22: =T7/T3 -> 1.4511515
R23: Greedy | S23: =S8/S3 -> 3.143587 | T23: =T8/T3 -> 1.6907945
R24: MOPSO | S24: =S9/S3 -> 3.7840177 | T24: =T9/T3 -> 1.5294923
R25: RL | S25: =S10/S3 -> 2.9250619 | T25: =T10/T3 -> 1.550771
R36: Energy | S36: 1000 | T36: 2000
R37: QUEST | S37: =Energy!B33 -> 1.0887791e+09 | T37: =Energy!C33 -> 9.3953063e+09
R38: QUEST_NDVFS | S38: =Energy!B34 -> 1.1941738e+09 | T38: =Energy!C34 -> 8.2509054e+09
R39: Fuzzy | S39: =Energy!B35 -> 2445648885 | T39: =Energy!C35 -> 1.3661621e+10
R40: NSGA3 | S40: =Energy!B36 -> 1.6339716e+09 | T40: =Energy!C36 -> 1.206705e+10
R41: MQGA | S41: =Energy!B37 -> 1554170910 | T41: =Energy!C37 -> 1.0799505e+10
R42: Greedy | S42: =Energy!B38 -> 2.0368112e+09 | T42: =Energy!C38 -> 1.2160651e+10
R43: MOPSO | S43: =Energy!B39 -> 1.7663712e+09 | T43: =Energy!C39 -> 1.175641e+10
R44: RL | S44: =Energy!B40 -> 2.040643e+09 | T44: =Energy!C40 -> 1.1107014e+10
R51: Energy | S51: 1000 | T51: 2000
R52: QUEST | S52: =S37/S37 -> 1 | T52: =T37/T37 -> 1
R53: QUEST_NDVFS | S53: =S38/S37 -> 1.0968008 | T53: =T38/T37 -> 0.87819441
R54: Fuzzy | S54: =S39/S37 -> 2.2462306 | T54: =T39/T37 -> 1.45409
R55: NSGA3 | S55: =S40/S37 -> 1.5007375 | T55: =T40/T37 -> 1.2843701
R56: MQGA | S56: =S41/S37 -> 1.4274438 | T56: =T41/T37 -> 1.1494575
R57: Greedy | S57: =S42/S37 -> 1.8707295 | T57: =T42/T37 -> 1.2943326
R58: MOPSO | S58: =S43/S37 -> 1.6223413 | T58: =T43/T37 -> 1.2513068
R59: RL | S59: =S44/S37 -> 1.8742489 | T59: =T44/T37 -> 1.1821876
R67: Makespan | S67: 1000 | T67: 2000
R68: QUEST | S68: =Makespan!B33 -> 5168349.5 | T68: =Makespan!C33 -> 34719096
R69: QUEST_NDVFS | S69: =Makespan!B34 -> 5054557.5 | T69: =Makespan!C34 -> 29759761
R70: Fuzzy | S70: =Makespan!B35 -> 9993650 | T70: =Makespan!C35 -> 53170016
...

Sheet Data Age
A1: Algorithm | B1: Load | C1: Average | D1: Min | E1: Max | F1: Std Dev
A2: QUEST | B2: 1 | C2: 313823.46 | D2: 280252.44 | E2: 347394.48 | F2: 33571.02
A3: QUEST | B3: 2 | C3: 7158576.9 | D3: 6755972.8 | E3: 7561180.9 | F3: 402604.06
A4: QUEST_NDVFS | B4: 1 | C4: 251767.87 | D4: 216677.1 | E4: 286858.63 | F4: 35090.765
A5: QUEST_NDVFS | B5: 2 | C5: 7283348.5 | D5: 7245273.4 | E5: 7321423.7 | F5: 38075.182
A6: Fuzzy | B6: 1 | C6: 930749.59 | D6: 930749.2 | E6: 930749.98 | F6: 0.3877551
A7: Fuzzy | B7: 2 | C7: 13293421 | D7: 13293420 | E7: 13293421 | F7: 0.96542828
A8: NSGA3 | B8: 1 | C8: 747528.39 | D8: 564284.73 | E8: 930772.05 | F8: 183243.66
A9: NSGA3 | B9: 2 | C9: 10629096 | D9: 9925889.1 | E9: 11332303 | F9: 703206.91
A10: MQGA | B10: 1 | C10: 804867.39 | D10: 775761.97 | E10: 833972.82 | F10: 29105.423
A11: MQGA | B11: 2 | C11: 10388180 | D11: 10307432 | E11: 10468928 | F11: 80748.13
A12: Greedy | B12: 1 | C12: 986531.36 | D12: 952781.48 | E12: 1020281.2 | F12: 33749.883
A13: Greedy | B13: 2 | C13: 12103683 | D13: 10227668 | E13: 13979697 | F13: 1876014.2
... A17: RL | B17: 2 | C17: 11101314 | D17: 9849695.6 | E17: 12352931 | F17: 1251617.9
A20: Summary by Algorithm
A21: QUEST | C21: 3736200.2 | D21: 280252.44 | E21: 7561180.9 | F21: 3434278.8
A22: QUEST_NDVFS | C22: 3767558.2 | D22: 216677.1 | E22: 7321423.7 | F22: 3515981
A23: Fuzzy | C23: 7112085.1 | D23: 930749.2 | E23: 13293421 | F23: 6181335.5
A24: NSGA3 | C24: 5688312.2 | D24: 564284.73 | E24: 11332303 | F24: 4967432.3
A25: MQGA | C25: 5596523.6 | D25: 775761.97 | E25: 10468928 | F25: 4792040.6
A26: Greedy | C26: 6545107 | D26: 952781.48 | E26: 13979697 | F26: 5714721.9
A27: MOPSO | C27: 6068250.9 | D27: 1079711.4 | E27: 11028311 | F27: 4881654.8
A28: RL | C28: 6009633.3 | D28: 681258.45 | E28: 12352931 | F28: 5170734.3
A31: Average data for chart
A32: Algorithms | B32: 1 | C32: 2
A33: QUEST | B33: 313823.46 | C33: 7158576.9
A34: QUEST_NDVFS | B34: 251767.87 | C34: 7283348.5
A35: Fuzzy | B35: 930749.59 | C35: 13293421
A36: NSGA3 | B36: 747528.39 | C36: 10629096
A37: MQGA | B37: 804867.39 | C37: 10388180
A38: Greedy | B38: 986531.36 | C38: 12103683
A39: MOPSO | B39: 1187513.5 | C39: 10948988
A40: RL | B40: 917953.04 | C40: 11101314
A43: All data for chart
A44: Algorithms | B44: 1 | C44: 1 | D44: 2 | E44: 2
A45: QUEST | B45: 347394.48 | C45: 280252.44 | D45: 7561180.9 | E45: 6755972.8
A46: QUEST_NDVFS | B46: 286858.63 | C46: 216677.1 | D46: 7321423.7 | E46: 7245273.4
A47: Fuzzy | B47: 930749.98 | C47: 930749.2 | D47: 13293421 | E47: 13293420
A48: NSGA3 | B48: 930772.05 | C48: 564284.73 | D48: 9925889.1 | E48: 11332303
A49: MQGA | B49: 833972.82 | C49: 775761.97 | D49: 10468928 | E49: 10307432
...

Sheet Energy
A1: Algorithm | B1: Load | C1: Average | D1: Min | E1: Max | F1: Std Dev
A2: QUEST | B2: 1 | C2: 1.0887791e+09 | D2: 1.0486695e+09 | E2: 1.1288886e+09 | F2: 40109539
A3: QUEST | B3: 2 | C3: 9.3953063e+09 | D3: 8.3876304e+09 | E3: 10402982070 | F3: 1.0076758e+09
A4: QUEST_NDVFS | B4: 1 | C4: 1.1941738e+09 | D4: 1.161595e+09 | E4: 1226752595 | F4: 32578778
A5: QUEST_NDVFS | B5: 2 | C5: 8.2509054e+09 | D5: 7.9456094e+09 | E5: 8.5562014e+09 | F5: 3.0529597e+08
A6: Fuzzy | B6: 1 | C6: 2445648885 | D6: 2445646520 | E6: 2445651250 | F6: 2365
A7: Fuzzy | B7: 2 | C7: 1.3661621e+10 | D7: 1.366162e+10 | E7: 1.3661621e+10 | F7: 645
A8: NSGA3 | B8: 1 | C8: 1.6339716e+09 | D8: 1.2759297e+09 | E8: 1.9920135e+09 | F8: 3.580419e+08
A9: NSGA3 | B9: 2 | C9: 1.206705e+10 | D9: 10833967995 | E9: 1.3300132e+10 | F9: 1.233082e+09
A10: MQGA | B10: 1 | C10: 1554170910 | D10: 1.5472505e+09 | E10: 1.5610914e+09 | F10: 6920457.5
A11: MQGA | B11: 2 | C11: 1.0799505e+10 | D11: 10727835340 | E11: 1.0871176e+10 | F11: 71670080
A12: Greedy | B12: 1 | C12: 2.0368112e+09 | D12: 1.8553237e+09 | E12: 2218298675 | F12: 1.8148747e+08
A13: Greedy | B13: 2 | C13: 1.2160651e+10 | D13: 1.0903198e+10 | E13: 1.3418104e+10 | F13: 1.2574526e+09
... A17: RL | B17: 2 | C17: 1.1107014e+10 | D17: 1.071105e+10 | E17: 1.1502979e+10 | F17: 3.9596427e+08
A20: Summary by Algorithm
A21: QUEST | C21: 5.2420427e+09 | D21: 1.0486695e+09 | E21: 10402982070 | F21: 4.214037e+09
A22: QUEST_NDVFS | C22: 4.7225396e+09 | D22: 1.161595e+09 | E22: 8.5562014e+09 | F22: 3.5350387e+09
A23: Fuzzy | C23: 8.0536347e+09 | D23: 2445646520 | E23: 1.3661621e+10 | F23: 5.6079858e+09
A24: NSGA3 | C24: 6.8505108e+09 | D24: 1.2759297e+09 | E24: 1.3300132e+10 | F24: 5.2949621e+09
A25: MQGA | C25: 6.1768382e+09 | D25: 1.5472505e+09 | E25: 1.0871176e+10 | F25: 4.6229476e+09
A26: Greedy | C26: 7.0987311e+09 | D26: 1.8553237e+09 | E26: 1.3418104e+10 | F26: 5.1410208e+09
A27: MOPSO | C27: 6.7613908e+09 | D27: 1.6861744e+09 | E27: 1.1840589e+10 | F27: 4.9956961e+09
A28: RL | C28: 6.5738287e+09 | D28: 1.7728781e+09 | E28: 1.1502979e+10 | F28: 4.5457689e+09
A31: Average data for chart
A32: Algorithms | B32: 1 | C32: 2
A33: QUEST | B33: 1.0887791e+09 | C33: 9.3953063e+09
A34: QUEST_NDVFS | B34: 1.1941738e+09 | C34: 8.2509054e+09
A35: Fuzzy | B35: 2445648885 | C35: 1.3661621e+10
A36: NSGA3 | B36: 1.6339716e+09 | C36: 1.206705e+10
A37: MQGA | B37: 1554170910 | C37: 1.0799505e+10
A38: Greedy | B38: 2.0368112e+09 | C38: 1.2160651e+10
A39: MOPSO | B39: 1.7663712e+09 | C39: 1.175641e+10
A40: RL | B40: 2.040643e+09 | C40: 1.1107014e+10
A43: All data for chart
A44: Algorithms | B44: 1 | C44: 1 | D44: 2 | E44: 2
A45: QUEST | B45: 1.0486695e+09 | C45: 1.1288886e+09 | D45: 10402982070 | E45: 8.3876304e+09
A46: QUEST_NDVFS | B46: 1.161595e+09 | C46: 1226752595 | D46: 7.9456094e+09 | E46: 8.5562014e+09
A47: Fuzzy | B47: 2445651250 | C47: 2445646520 | D47: 1.3661621e+10 | E47: 1.366162e+10
A48: NSGA3 | B48: 1.9920135e+09 | C48: 1.2759297e+09 | D48: 10833967995 | E48: 1.3300132e+10
A49: MQGA | B49: 1.5610914e+09 | C49: 1.5472505e+09 | D49: 10727835340 | E49: 1.0871176e+10
...

Sheet Makespan
A1: Algorithm | B1: Load | C1: Average | D1: Min | E1: Max | F1: Std Dev
A2: QUEST | B2: 1 | C2: 5168349.5 | D2: 5035751 | E2: 5300948 | F2: 132598.5
A3: QUEST | B3: 2 | C3: 34719096 | D3: 30965042 | E3: 38473149 | F3: 3754053.5
A4: QUEST_NDVFS | B4: 1 | C4: 5054557.5 | D4: 4738989 | E4: 5370126 | F4: 315568.5
A5: QUEST_NDVFS | B5: 2 | C5: 29759761 | D5: 28532506 | E5: 30987016 | F5: 1227255
A6: Fuzzy | B6: 1 | C6: 9993650 | D6: 9993639 | E6: 9993661 | F6: 11
A7: Fuzzy | B7: 2 | C7: 53170016 | D7: 53170013 | E7: 53170019 | F7: 3
A8: NSGA3 | B8: 1 | C8: 6800770 | D8: 5299297 | E8: 8302243 | F8: 1501473
A9: NSGA3 | B9: 2 | C9: 45688922 | D9: 40298558 | E9: 51079286 | F9: 5390364
A10: MQGA | B10: 1 | C10: 6021083.5 | D10: 5956840 | E10: 6085327 | F10: 64243.5
A11: MQGA | B11: 2 | C11: 41004353 | D11: 40752058 | E11: 41256648 | F11: 252295
A12: Greedy | B12: 1 | C12: 8295357.5 | D12: 7451141 | E12: 9139574 | F12: 844216.5
A13: Greedy | B13: 2 | C13: 46628882 | D13: 40673531 | E13: 52584232 | F13: 5955350.5
... A17: RL | B17: 2 | C17: 42692492 | D17: 41463091 | E17: 43921894 | F17: 1229401.5
A20: Summary by Algorithm
A21: QUEST | C21: 19943722 | D21: 5035751 | E21: 38473149 | F21: 15012225
A22: QUEST_NDVFS | C22: 17407159 | D22: 4738989 | E22: 30987016 | F22: 12385057
A23: Fuzzy | C23: 31581833 | D23: 9993639 | E23: 53170019 | F23: 21588183
A24: NSGA3 | C24: 26244846 | D24: 5299297 | E24: 51079286 | F24: 19842563
A25: MQGA | C25: 23512718 | D25: 5956840 | E25: 41256648 | F25: 17492603
A26: Greedy | C26: 27462120 | D26: 7451141 | E26: 52584232 | F26: 19632988
A27: MOPSO | C27: 25617440 | D27: 6931381 | E27: 44920474 | F27: 18656540
A28: RL | C28: 25496478 | D28: 7161933 | E28: 43921894 | F28: 17236785
A31: Average data for chart
A32: Algorithms | B32: 1 | C32: 2
A33: QUEST | B33: 5168349.5 | C33: 34719096
A34: QUEST_NDVFS | B34: 5054557.5 | C34: 29759761
A35: Fuzzy | B35: 9993650 | C35: 53170016
A36: NSGA3 | B36: 6800770 | C36: 45688922
A37: MQGA | B37: 6021083.5 | C37: 41004353
A38: Greedy | B38: 8295357.5 | C38: 46628882
A39: MOPSO | B39: 6966618 | C39: 44268262
A40: RL | B40: 8300462.5 | C40: 42692492
A43: All data for chart
A44: Algorithms | B44: 1 | C44: 1 | D44: 2 | E44: 2
A45: QUEST | B45: 5035751 | C45: 5300948 | D45: 38473149 | E45: 30965042
A46: QUEST_NDVFS | B46: 4738989 | C46: 5370126 | D46: 28532506 | E46: 30987016
A47: Fuzzy | B47: 9993661 | C47: 9993639 | D47: 53170019 | E47: 53170013
A48: NSGA3 | B48: 8302243 | C48: 5299297 | D48: 40298558 | E48: 51079286
A49: MQGA | B49: 5956840 | C49: 6085327 | D49: 40752058 | E49: 41256648
...

Sheet Success Rate
A1: Algorithm | B1: Load | C1: Average | D1: Min | E1: Max | F1: Std Dev
A2: QUEST | B2: 1 | C2: 1 | D2: =TRUE() -> TRUE | E2: =TRUE() -> TRUE | F2: 0
A3: QUEST | B3: 2 | C3: 1 | D3: =TRUE() -> TRUE | E3: =TRUE() -> TRUE | F3: 0
A4: QUEST_NDVFS | B4: 1 | C4: 1 | D4: =TRUE() -> TRUE | E4: =TRUE() -> TRUE | F4: 0
A5: QUEST_NDVFS | B5: 2 | C5: 1 | D5: =TRUE() -> TRUE | E5: =TRUE() -> TRUE | F5: 0.5
A6: Fuzzy | B6: 1 | C6: 0.78 | D6: =FALSE() -> FALSE | E6: =TRUE() -> TRUE | F6: 0
A7: Fuzzy | B7: 2 | C7: 0.57 | D7: =FALSE() -> FALSE | E7: =TRUE() -> TRUE | F7: 0
A8: NSGA3 | B8: 1 | C8: 1 | D8: =TRUE() -> TRUE | E8: =TRUE() -> TRUE | F8: 0
A9: NSGA3 | B9: 2 | C9: 0.64 | D9: =FALSE() -> FALSE | E9: =TRUE() -> TRUE | F9: 0
A10: MQGA | B10: 1 | C10: 1 | D10: =TRUE() -> TRUE | E10: =TRUE() -> TRUE | F10: 0
A11: MQGA | B11: 2 | C11: 0.62 | D11: =FALSE() -> FALSE | E11: =TRUE() -> TRUE | F11: 0
A12: Greedy | B12: 1 | C12: 0.77 | D12: =FALSE() -> FALSE | E12: =TRUE() -> TRUE | F12: 0.5
A13: Greedy | B13: 2 | C13: 0.38 | D13: =FALSE() -> FALSE | E13: =TRUE() -> TRUE | F13: 0
A14: MOPSO | B14: 1 | C14: 1 | D14: =TRUE() -> TRUE | E14: =TRUE() -> TRUE | F14: 0
A15: MOPSO | B15: 2 | C15: 0.68 | D15: =FALSE() -> FALSE | E15: =TRUE() -> TRUE | F15: 0
A16: RL | B16: 1 | C16: 0.8 | D16: =FALSE() -> FALSE | E16: =TRUE() -> TRUE | F16: 0.5
A17: RL | B17: 2 | C17: 0.44 | D17: =FALSE() -> FALSE | E17: =TRUE() -> TRUE | F17: 0
A20: Summary by Algorithm
A21: QUEST | C21: 0.5 | D21: =FALSE() -> FALSE | E21: =TRUE() -> TRUE | F21: 0.5
A22: QUEST_NDVFS | C22: 0.75 | D22: =FALSE() -> FALSE | E22: =TRUE() -> TRUE | F22: 0.4330127
A23: Fuzzy | C23: 0.62 | D23: =FALSE() -> FALSE | E23: =TRUE() -> TRUE | F23: 0
A24: NSGA3 | C24: 0.5 | D24: =FALSE() -> FALSE | E24: =TRUE() -> TRUE | F24: 0.5
A25: MQGA | C25: 0.5 | D25: =FALSE() -> FALSE | E25: =TRUE() -> TRUE | F25: 0.5
A26: Greedy | C26: 0.25 | D26: =FALSE() -> FALSE | E26: =TRUE() -> TRUE | F26: 0.4330127
A27: MOPSO | C27: 0.5 | D27: =FALSE() -> FALSE | E27: =TRUE() -> TRUE | F27: 0.5
A28: RL | C28: 0.25 | D28: =FALSE() -> FALSE | E28: =TRUE() -> TRUE | F28: 0.4330127
A31: Average data for chart
A32: Algorithms | B32: 1 | C32: 2
A33: QUEST | B33: 1 | C33: 1
A34: QUEST_NDVFS | B34: 1 | C34: 1
A35: Fuzzy | B35: 0.78 | C35: 0.57
A36: NSGA3 | B36: 1 | C36: 0.64
A37: MQGA | B37: 1 | C37: 0.62
A38: Greedy | B38: 0.5 | C38: 0.38
A39: MOPSO | B39: 1 | C39: 0.68
A40: RL | B40: 0.5 | C40: 0.44
A43: All data for chart
A44: Algorithms | B44: 1 | C44: 1 | D44: 2 | E44: 2
A45: QUEST | B45: =TRUE() -> TRUE | C45: =TRUE() -> TRUE | D45: =FALSE() -> FALSE | E45: =FALSE() -> FALSE
A46: QUEST_NDVFS | B46: =TRUE() -> TRUE | C46: =TRUE() -> TRUE | D46: =TRUE() -> TRUE | E46: =FALSE() -> FALSE
...

Sheet Load Edge
A1: Algorithm | B1: Load | C1: Average | D1: Min | E1: Max | F1: Std Dev
A2: QUEST | B2: 1 | C2: 1918557.1 | D2: 1580319.6 | E2: 2256794.6 | F2: 338237.5
A3: QUEST | B3: 2 | C3: 15791533 | D3: 15298302 | E3: 16284765 | F3: 493231.65
A4: QUEST_NDVFS | B4: 1 | C4: 1716093.6 | D4: 1516230.8 | E4: 1915956.5 | F4: 199862.85
A5: QUEST_NDVFS | B5: 2 | C5: 16333364 | D5: 16086521 | E5: 16580207 | F5: 246843.25
A6: Fuzzy | B6: 1 | C6: 1812059.1 | D6: 1812059.1 | E6: 1812059.1 | F6: 0
A7: Fuzzy | B7: 2 | C7: 16018134 | D7: 16018134 | E7: 16018134 | F7: 0
A8: NSGA3 | B8: 1 | C8: 1692428.5 | D8: 1615254.6 | E8: 1769602.4 | F8: 77173.9
A9: NSGA3 | B9: 2 | C9: 15882583 | D9: 15395168 | E9: 16369998 | F9: 487415.4
A10: MQGA | B10: 1 | C10: 1616243.2 | D10: 1541546.5 | E10: 1690939.9 | F10: 74696.7
A11: MQGA | B11: 2 | C11: 16120449 | D11: 15985591 | E11: 16255307 | F11: 134858.25
A12: Greedy | B12: 1 | C12: 1624148.1 | D12: 1607674.2 | E12: 1640621.9 | F12: 16473.85
A13: Greedy | B13: 2 | C13: 15598618 | D13: 15597319 | E13: 15599918 | F13: 1299.75
... A17: RL | B17: 2 | C17: 15129361 | D17: 14546468 | E17: 15712255 | F17: 582893.8
A20: Summary by Algorithm
A21: QUEST | C21: 8855045.2 | D21: 1580319.6 | E21: 16284765 | F21: 6949367.4
A22: QUEST_NDVFS | C22: 9024728.8 | D22: 1516230.8 | E22: 16580207 | F22: 7312084.9
A23: Fuzzy | C23: 8915096.6 | D23: 1812059.1 | E23: 16018134 | F23: 7103037.5
A24: NSGA3 | C24: 8787505.8 | D24: 1615254.6 | E24: 16369998 | F24: 7103653
A25: MQGA | C25: 8868346 | D25: 1541546.5 | E25: 16255307 | F25: 7252922.1
A26: Greedy | C26: 8611383.2 | D26: 1607674.2 | E26: 15599918 | F26: 6987244.9
A27: MOPSO | C27: 8560474.7 | D27: 1388261.8 | E27: 15758288 | F27: 7053834
A28: RL | C28: 8459142.2 | D28: 1656104.8 | E28: 15712255 | F28: 6683601.3
A31: Average data for chart
A32: Algorithms | B32: 1 | C32: 2
A33: QUEST | B33: 1918557.1 | C33: 15791533
A34: QUEST_NDVFS | B34: 1716093.6 | C34: 16333364
A35: Fuzzy | B35: 1812059.1 | C35: 16018134
A36: NSGA3 | B36: 1692428.5 | C36: 15882583
A37: MQGA | B37: 1616243.2 | C37: 16120449
A38: Greedy | B38: 1624148.1 | C38: 15598618
A39: MOPSO | B39: 1507895.7 | C39: 15613054
A40: RL | B40: 1788923 | C40: 15129361
A43: All data for chart
A44: Algorithms | B44: 1 | C44: 1 | D44: 2 | E44: 2
A45: QUEST | B45: 1580319.6 | C45: 2256794.6 | D45: 16284765 | E45: 15298302
A46: QUEST_NDVFS | B46: 1516230.8 | C46: 1915956.5 | D46: 16580207 | E46: 16086521
A47: Fuzzy | B47: 1812059.1 | C47: 1812059.1 | D47: 16018134 | E47: 16018134
A48: NSGA3 | B48: 1769602.4 | C48: 1615254.6 | D48: 15395168 | E48: 16369998
A49: MQGA | B49: 1541546.5 | C49: 1690939.9 | D49: 16255307 | E49: 15985591
...

Sheet Load Cloud
A1: Algorithm | B1: Load | C1: Average | D1: Min | E1: Max | F1: Std Dev
A2: QUEST | B2: 1 | C2: 4719898 | D2: 1932873 | E2: 7506923 | F2: 2787025
A3: QUEST | B3: 2 | C3: 17137770 | D3: 11502890 | E3: 22772649 | F3: 5634879.5
A4: QUEST_NDVFS | B4: 1 | C4: 2745363 | D4: 1376048 | E4: 4114678 | F4: 1369315
A5: QUEST_NDVFS | B5: 2 | C5: 13287626 | D5: 11579778 | E5: 14995473 | F5: 1707847.5
A6: Fuzzy | B6: 1 | C6: 468238 | D6: 468238 | E6: 468238 | F6: 0
A7: Fuzzy | B7: 2 | C7: 12922772 | D7: 12922772 | E7: 12922772 | F7: 0
A8: NSGA3 | B8: 1 | C8: 2435453.5 | D8: 1523626 | E8: 3347281 | F8: 911827.5
A9: NSGA3 | B9: 2 | C9: 13930336 | D9: 9334727 | E9: 18525944 | F9: 4595608.5
A10: MQGA | B10: 1 | C10: 2373985 | D10: 1921447 | E10: 2826523 | F10: 452538
A11: MQGA | B11: 2 | C11: 14013508 | D11: 13039596 | E11: 14987419 | F11: 973911.5
A12: Greedy | B12: 1 | C12: 2358520 | D12: 2222704 | E12: 2494336 | F12: 135816
A13: Greedy | B13: 2 | C13: 17119772 | D13: 16929086 | E13: 17310458 | F13: 190686
... A17: RL | B17: 2 | C17: 22610234 | D17: 16777439 | E17: 28443028 | F17: 5832794.5
A20: Summary by Algorithm
A21: QUEST | C21: 10928834 | D21: 1932873 | E21: 22772649 | F21: 7636135.9
A22: QUEST_NDVFS | C22: 8016494.2 | D22: 1376048 | E22: 14995473 | F22: 5493697.1
A23: Fuzzy | C23: 6695505 | D23: 468238 | E23: 12922772 | F23: 6227267
A24: NSGA3 | C24: 8182894.5 | D24: 1523626 | E24: 18525944 | F24: 6633897.9
A25: MQGA | C25: 8193746.2 | D25: 1921447 | E25: 14987419 | F25: 5869094.3
A26: Greedy | C26: 9739146 | D26: 2222704 | E26: 17310458 | F26: 7382482.2
A27: MOPSO | C27: 9693566.5 | D27: 2780726 | E27: 17826397 | F27: 6605875.1
A28: RL | C28: 11795171 | D28: 66553 | E28: 28443028 | F28: 11592826
A31: Average data for chart
A32: Algorithms | B32: 1 | C32: 2
A33: QUEST | B33: 4719898 | C33: 17137770
A34: QUEST_NDVFS | B34: 2745363 | C34: 13287626
A35: Fuzzy | B35: 468238 | C35: 12922772
A36: NSGA3 | B36: 2435453.5 | C36: 13930336
A37: MQGA | B37: 2373985 | C37: 14013508
A38: Greedy | B38: 2358520 | C38: 17119772
A39: MOPSO | B39: 3196370.5 | C39: 16190762
A40: RL | B40: 980108 | C40: 22610234
A43: All data for chart
A44: Algorithms | B44: 1 | C44: 1 | D44: 2 | E44: 2
A45: QUEST | B45: 7506923 | C45: 1932873 | D45: 11502890 | E45: 22772649
A46: QUEST_NDVFS | B46: 4114678 | C46: 1376048 | D46: 11579778 | E46: 14995473
A47: Fuzzy | B47: 468238 | C47: 468238 | D47: 12922772 | E47: 12922772
A48: NSGA3 | B48: 1523626 | C48: 3347281 | D48: 18525944 | E48: 9334727
A49: MQGA | B49: 2826523 | C49: 1921447 | D49: 13039596 | E49: 14987419
...

Sheet Loads
A1: Average data for chart
B2: Edge | C2: Edge | D2: Edge | E2: Edge | F2: Edge | G2: Edge | H2: Edge | I2: Edge | J2: Edge | K2: Edge | L2: Cloud | M2: Edge | N2: Edge | O2: Edge | P2: Edge | Q2: Edge | R2: Edge | S2: Edge | T2: Edge | U2: Edge | V2: Edge | W2: Cloud
B3: 1 | C3: 1 | D3: 1 | E3: 1 | F3: 1 | G3: 1 | H3: 1 | I3: 1 | J3: 1 | K3: 1 | L3: 1 | M3: 2 | N3: 2 | O3: 2 | P3: 2 | Q3: 2 | R3: 2 | S3: 2 | T3: 2 | U3: 2 | V3: 2 | W3: 2
A4: Algorithms | B4: 1 | C4: 2 | D4: 3 | E4: 4 | F4: 5 | G4: 6 | H4: 7 | I4: 8 | J4: 9 | K4: 10 | L4: 11 | M4: 1 | N4: 2 | O4: 3 | P4: 4 | Q4: 5 | R4: 6 | S4: 7 | T4: 8 | U4: 9 | V4: 10 | W4: 11
A5: QUEST | B5: 3713.0909 | C5: 202575.64 | D5: 42197.091 | E5: 1940.7273 | F5: 399818.45 | G5: 539817.91 | H5: 85608 | I5: 550055.82 | J5: 877894.91 | K5: 784664 | L5: 858163.27 | M5: 2331558 | N5: 2343200.5 | O5: 2892774.2 | P5: 2328623.5 | Q5: 1528782.5 | R5: 2185735 | S5: 4219908.5 | T5: 2776141.4 | U5: 4874671.8 | V5: 3230483.4 | W5: 3115958.1
A6: QUEST_NDVFS | B6: 5249.2727 | C6: 12166.909 | D6: 181986.82 | E6: 128347.64 | F6: 36255.727 | G6: 825059.09 | H6: 358118.91 | I6: 791803.27 | J6: 570884.55 | K6: 210298.09 | L6: 499156.91 | M6: 2385978.2 | N6: 1322167.1 | O6: 2019153.5 | P6: 2886280.4 | Q6: 2084817.5 | R6: 4003610.3 | S6: 3167469.3 | T6: 3687994.5 | U6: 4305520.3 | V6: 3834034.2 | W6: 2415931.9
A7: Fuzzy | B7: 576215.64 | C7: 410042.36 | D7: 367743.09 | E7: 348384.91 | F7: 273347.45 | G7: 319149.09 | H7: 300012.36 | I7: 296502.91 | J7: 282195.27 | K7: 121059.82 | L7: 85134.182 | M7: 2905194.5 | N7: 2844254.5 | O7: 2776271.1 | P7: 2735221.8 | Q7: 2701204 | R7: 3177064.4 | S7: 3139532.2 | T7: 3057740.5 | U7: 2940141.8 | V7: 2847255.3 | W7: 2349594.9
A8: NSGA3 | B8: 10944.545 | C8: 446620.55 | D8: 129223.73 | E8: 4513.0909 | F8: 325927.45 | G8: 651110.18 | H8: 8207.4545 | I8: 519531.45 | J8: 808451.45 | K8: 172612.82 | L8: 442809.73 | M8: 3079549.5 | N8: 3089271.8 | O8: 2616916.8 | P8: 2486379.5 | Q8: 2823153.7 | R8: 2703099.5 | S8: 4443721.2 | T8: 2233257.5 | U8: 2996011.1 | V8: 2406063.2 | W8: 2532788.3
A9: MQGA | B9: 676447.73 | C9: 492945.73 | D9: 333297.73 | E9: 6969.2727 | F9: 167219.73 | G9: 361534.18 | H9: 210260.09 | I9: 228298.09 | J9: 147535.82 | K9: 314115.64 | L9: 431633.64 | M9: 2195136.3 | N9: 1616838.1 | O9: 2675716.9 | P9: 2421317.2 | Q9: 2933124.1 | R9: 3270551.3 | S9: 2652850 | T9: 3904390 | U9: 2915613.8 | V9: 4724369.4 | W9: 2547910.5
A10: Greedy | B10: 627997.36 | C10: 182064.36 | D10: 1119.3636 | E10: 383226.64 | F10: 427478.45 | G10: 97776 | H10: 56877.455 | I10: 368677.64 | J10: 255313.73 | K10: 552465.45 | L10: 428821.82 | M10: 1692031.5 | N10: 3340435.4 | O10: 2361618.5 | P10: 2182636.9 | Q10: 3620660.2 | R10: 2795120.9 | S10: 3065654.4 | T10: 3372029.7 | U10: 2810935 | V10: 3120001.9 | W10: 3112685.8
A11: MOPSO | B11: 226929.09 | C11: 5698.9091 | D11: 303601.45 | E11: 861769 | F11: 366708.55 | G11: 245794.55 | H11: 13001 | I11: 5998.2727 | J11: 665423 | K11: 46704.727 | L11: 581158.27 | M11: 2536033.4 | N11: 2900074.3 | O11: 3562020.3 | P11: 1854782.5 | Q11: 3226715.3 | R11: 2697735.8 | S11: 3040251.9 | T11: 2626757.7 | U11: 3279134.1 | V11: 2663865.3 | W11: 2943775
A12: RL | B12: 507743.27 | C12: 159085 | D12: 378524.73 | E12: 314233.09 | F12: 268071.82 | G12: 509262.91 | H12: 531147.45 | I12: 239788.45 | J12: 276897 | K12: 67833.545 | L12: 178201.45 | M12: 1704174.7 | N12: 1921715.8 | O12: 2784622.5 | P12: 1653604.1 | Q12: 3409651.6 | R12: 3265925.9 | S12: 3722021.2 | T12: 3179266 | U12: 2893490.1 | V12: 2973457.6 | W12: 4110951.5
