Workbook

Sheet Charts
R2: AoI | S2: 24 | T2: 46 | U2: 100
R3: QUEST | S3: ='Data Age'!B41 -> 639543.17 | T3: ='Data Age'!C41 -> 756496.63 | U3: ='Data Age'!D41 -> 3724298.1
R4: QUEST_NDVFS | S4: ='Data Age'!B42 -> 615599.3 | T4: ='Data Age'!C42 -> 736665.31 | U4: ='Data Age'!D42 -> 3680223.6
R5: Fuzzy | S5: ='Data Age'!B43 -> 645495.67 | T5: ='Data Age'!C43 -> 769467.57 | U5: ='Data Age'!D43 -> 3967037.5
R6: NSGA3 | S6: ='Data Age'!B44 -> 705348.74 | T6: ='Data Age'!C44 -> 834198.14 | U6: ='Data Age'!D44 -> 4184215.7
R7: MQGA | S7: ='Data Age'!B45 -> 656462.89 | T7: ='Data Age'!C45 -> 776951.01 | U7: ='Data Age'!D45 -> 4150785.3
R8: Greedy | S8: ='Data Age'!B46 -> 694590.73 | T8: ='Data Age'!C46 -> 846832.2 | U8: ='Data Age'!D46 -> 4336366.8
R9: MOPSO | S9: ='Data Age'!B47 -> 670193.24 | T9: ='Data Age'!C47 -> 813201.44 | U9: ='Data Age'!D47 -> 4273009.1
R10: RL | S10: ='Data Age'!B48 -> 682618.35 | T10: ='Data Age'!C48 -> 829104.11 | U10: ='Data Age'!D48 -> 4222229.4
R17: AoI | S17: 24 | T17: 46 | U17: 100
R18: QUEST | S18: =S3/S3 -> 1 | T18: =T3/T3 -> 1 | U18: =U3/U3 -> 1
R19: QUEST_NDVFS | S19: =S4/S3 -> 0.96256098 | T19: =T4/T3 -> 0.97378531 | U19: =U4/U3 -> 0.98816571
R20: Fuzzy | S20: =S5/S3 -> 1.0093074 | T20: =T5/T3 -> 1.0171461 | U20: =U5/U3 -> 1.0651772
R21: NSGA3 | S21: =S6/S3 -> 1.1028947 | T21: =T6/T3 -> 1.1027123 | U21: =U6/U3 -> 1.1234911
R22: MQGA | S22: =S7/S3 -> 1.0264559 | T22: =T7/T3 -> 1.0270383 | U22: =U7/U3 -> 1.1145148
R23: Greedy | S23: =S8/S3 -> 1.0860732 | T23: =T8/T3 -> 1.119413 | U23: =U8/U3 -> 1.1643447
R24: MOPSO | S24: =S9/S3 -> 1.0479249 | T24: =T9/T3 -> 1.0749571 | U24: =U9/U3 -> 1.1473327
R25: RL | S25: =S10/S3 -> 1.067353 | T25: =T10/T3 -> 1.0959786 | U25: =U10/U3 -> 1.133698
R36: Energy | S36: 24 | T36: 46 | U36: 100
R37: QUEST | S37: =Energy!B41 -> 3.5993326e+09 | T37: =Energy!C41 -> 5.2522481e+09 | U37: =Energy!D41 -> 23727784862
R38: QUEST_NDVFS | S38: =Energy!B42 -> 3.2491868e+09 | T38: =Energy!C42 -> 4.7857253e+09 | U38: =Energy!D42 -> 2.1470355e+10
R39: Fuzzy | S39: =Energy!B43 -> 3.672274e+09 | T39: =Energy!C43 -> 5.3158162e+09 | U39: =Energy!D43 -> 2.4688133e+10
R40: NSGA3 | S40: =Energy!B44 -> 3.8002602e+09 | T40: =Energy!C44 -> 5.5920446e+09 | U40: =Energy!D44 -> 2.9752374e+10
R41: MQGA | S41: =Energy!B45 -> 3.990736e+09 | T41: =Energy!C45 -> 5.4560437e+09 | U41: =Energy!D45 -> 2.6690191e+10
R42: Greedy | S42: =Energy!B46 -> 3.7644858e+09 | T42: =Energy!C46 -> 5.5302667e+09 | U42: =Energy!D46 -> 3.1585253e+10
R43: MOPSO | S43: =Energy!B47 -> 3.6371668e+09 | T43: =Energy!C47 -> 5.2067453e+09 | U43: =Energy!D47 -> 3.0258767e+10
R44: RL | S44: =Energy!B48 -> 3.8658905e+09 | T44: =Energy!C48 -> 5.5954418e+09 | U44: =Energy!D48 -> 2.991427e+10
R51: Energy | S51: 24 | T51: 46 | U51: 100
R52: QUEST | S52: =S37/S37 -> 1 | T52: =T37/T37 -> 1 | U52: =U37/U37 -> 1
R53: QUEST_NDVFS | S53: =S38/S37 -> 0.90271924 | T53: =T38/T37 -> 0.91117655 | U53: =U38/U37 -> 0.90486135
R54: Fuzzy | S54: =S39/S37 -> 1.0202653 | T54: =T39/T37 -> 1.012103 | U54: =U39/U37 -> 1.0404736
R55: NSGA3 | S55: =S40/S37 -> 1.0558236 | T55: =T40/T37 -> 1.0646954 | U55: =U40/U37 -> 1.2539044
R56: MQGA | S56: =S41/S37 -> 1.1087433 | T56: =T41/T37 -> 1.0388016 | U56: =U41/U37 -> 1.1248497
R57: Greedy | S57: =S42/S37 -> 1.0458844 | T57: =T42/T37 -> 1.0529333 | U57: =U42/U37 -> 1.3311505
R58: MOPSO | S58: =S43/S37 -> 1.0105115 | T58: =T43/T37 -> 0.99133651 | U58: =U43/U37 -> 1.2752462
R59: RL | S59: =S44/S37 -> 1.0740576 | T59: =T44/T37 -> 1.0653422 | U59: =U44/U37 -> 1.2607275
R67: Makespan | S67: 24 | T67: 46 | U67: 100
R68: QUEST | S68: =Makespan!B41 -> 5227377.5 | T68: =Makespan!C41 -> 7339177.4 | U68: =Makespan!D41 -> 31537079
R69: QUEST_NDVFS | S69: =Makespan!B42 -> 4653333 | T69: =Makespan!C42 -> 6571627 | U69: =Makespan!D42 -> 27874131
R70: Fuzzy | S70: =Makespan!B43 -> 5352096.5 | T70: =Makespan!C43 -> 7448946.8 | U70: =Makespan!D43 -> 33947861
...

Sheet Data Age
A1: Algorithm | B1: Load | C1: Average | D1: Min | E1: Max | F1: Std Dev
A2: QUEST | B2: 1 | C2: 639543.17 | D2: 639288.29 | E2: 640389.88 | F2: 235.47167
A3: QUEST | B3: 2 | C3: 756496.63 | D3: 744279.71 | E3: 767970.1 | F3: 6186.953
A4: QUEST | B4: 3 | C4: 3724298.1 | D4: 3673329.2 | E4: 3769581.6 | F4: 25876.699
A5: QUEST_NDVFS | B5: 1 | C5: 615599.3 | D5: 615460.83 | E5: 615724.75 | F5: 77.601373
A6: QUEST_NDVFS | B6: 2 | C6: 736665.31 | D6: 727889.62 | E6: 748614.06 | F6: 4991.2874
A7: QUEST_NDVFS | B7: 3 | C7: 3680223.6 | D7: 3610587.6 | E7: 3745693.6 | F7: 31013.461
A8: Fuzzy | B8: 1 | C8: 615495.67 | D8: 615495.67 | E8: 615495.67 | F8: 0
A9: Fuzzy | B9: 2 | C9: 719467.57 | D9: 719465.58 | E9: 719469.75 | F9: 0.99030182
A10: Fuzzy | B10: 3 | C10: 3567037.5 | D10: 3567035.8 | E10: 3567038.5 | F10: 0.65146201
A11: NSGA3 | B11: 1 | C11: 705348.74 | D11: 642129.46 | E11: 774584.12 | F11: 41746.705
A12: NSGA3 | B12: 2 | C12: 834198.14 | D12: 778316.5 | E12: 924972.4 | F12: 39876.703
A13: NSGA3 | B13: 3 | C13: 4184215.7 | D13: 3742574.7 | E13: 4598828.1 | F13: 196409.11
... A25: RL | B25: 3 | C25: 4222229.4 | D25: 3783624.1 | E25: 5010560.1 | F25: 298796.7
A28: Summary by Algorithm
A29: QUEST | C29: 1706779.3 | D29: 639288.29 | E29: 3769581.6 | F29: 1427482.6
A30: QUEST_NDVFS | C30: 1677496.1 | D30: 615460.83 | E30: 3745693.6 | F30: 1417120.5
A31: Fuzzy | C31: 1634000.2 | D31: 615495.67 | E31: 3567038.5 | F31: 1367522.6
A32: NSGA3 | C32: 1907920.8 | D32: 642129.46 | E32: 4598828.1 | F32: 1614774.3
A33: MQGA | C33: 1854733.1 | D33: 624925.12 | E33: 4410358.9 | F33: 1626345.7
A34: Greedy | C34: 1959263.3 | D34: 632414.71 | E34: 4946655.5 | F34: 1692975.4
A35: MOPSO | C35: 1918801.2 | D35: 642024.42 | E35: 4774469 | F35: 1670601.1
A36: RL | C36: 1911317.3 | D36: 615785.54 | E36: 5010560.1 | F36: 1644579.9
A39: Average data for chart
A40: Algorithms | B40: 1 | C40: 2 | D40: 3
A41: QUEST | B41: 639543.17 | C41: 756496.63 | D41: 3724298.1
A42: QUEST_NDVFS | B42: 615599.3 | C42: 736665.31 | D42: 3680223.6
A43: Fuzzy | B43: 645495.67 | C43: 769467.57 | D43: 3967037.5
A44: NSGA3 | B44: 705348.74 | C44: 834198.14 | D44: 4184215.7
A45: MQGA | B45: 656462.89 | C45: 776951.01 | D45: 4150785.3
A46: Greedy | B46: 694590.73 | C46: 846832.2 | D46: 4336366.8
A47: MOPSO | B47: 670193.24 | C47: 813201.44 | D47: 4273009.1
A48: RL | B48: 682618.35 | C48: 829104.11 | D48: 4222229.4
A51: All data for chart
A52: Algorithms | B52: 1 | C52: 1 | D52: 1 | E52: 1 | F52: 1 | G52: 1 | H52: 1 | I52: 1 | J52: 1 | K52: 1 | L52: 1 | M52: 1 | N52: 1 | O52: 1 | P52: 1 | Q52: 1 | R52: 1 | S52: 1 | T52: 1 | U52: 1 | V52: 2 | W52: 2 | X52: 2 | Y52: 2 | Z52: 2 | AA52: 2 | AB52: 2 | AC52: 2 | AD52: 2 | AE52: 2 | AF52: 2 | AG52: 2 | AH52: 2 | AI52: 2 | AJ52: 2 | AK52: 2 | AL52: 2 | AM52: 2 | AN52: 2 | AO52: 2 | AP52: 3 | AQ52: 3 | AR52: 3 | AS52: 3 | AT52: 3 | AU52: 3 | AV52: 3 | AW52: 3 | AX52: 3 | AY52: 3 | AZ52: 3 | BA52: 3 | BB52: 3 | BC52: 3 | BD52: 3 | BE52: 3 | BF52: 3 | BG52: 3 | BH52: 3 | BI52: 3
A53: QUEST | B53: 639502.54 | C53: 639584.17 | D53: 639516.29 | E53: 639441.92 | F53: 639527.04 | G53: 639429.5 | H53: 639432.88 | I53: 639904.54 | J53: 640389.88 | K53: 639383.54 | L53: 639335.62 | M53: 639628.33 | N53: 639288.29 | O53: 639342.58 | P53: 639438.42 | Q53: 639420.46 | R53: 639560.71 | S53: 639656.83 | T53: 639512.54 | U53: 639567.33 | V53: 767970.1 | W53: 754910.62 | X53: 757775.92 | Y53: 755434.12 | Z53: 765194.88 | AA53: 758723 | AB53: 751309.79 | AC53: 748597.69 | AD53: 758872.29 | AE53: 751763.73 | AF53: 759685.5 | AG53: 747177.69 | AH53: 744279.71 | AI53: 761471.25 | AJ53: 756778.96 | AK53: 756930.15 | AL53: 762467.04 | AM53: 757787.62 | AN53: 764214.08 | AO53: 748588.5 | AP53: 3712602.1 | AQ53: 3673329.2 | AR53: 3738515.4 | AS53: 3759486.6 | AT53: 3759721.8 | AU53: 3703306 | AV53: 3706999.2 | AW53: 3762091.1 | AX53: 3736134.5 | AY53: 3769581.6 | AZ53: 3722942.4 | BA53: 3736460.8 | BB53: 3701052.2 | BC53: 3724326.3 | BD53: 3709751.3 | BE53: 3706408.8 | BF53: 3689828.1 | BG53: 3704290.7 | BH53: 3751628 | BI53: 3717505.2
A54: QUEST_NDVFS | B54: 615637.29 | C54: 615587.38 | D54: 615473.83 | E54: 615684.58 | F54: 615633.62 | G54: 615653.17 | H54: 615659.67 | I54: 615477.25 | J54: 615674.88 | K54: 615571.96 | L54: 615488.46 | M54: 615616.88 | N54: 615607.75 | O54: 615587.58 | P54: 615460.83 | Q54: 615505.62 | R54: 615624.17 | S54: 615621.33 | T54: 615695.04 | U54: 615724.75 | V54: 741167.98 | W54: 734120.5 | X54: 738010.92 | Y54: 748614.06 | Z54: 741864.98 | AA54: 733106.92 | AB54: 738888.46 | AC54: 742554.79 | AD54: 735074.96 | AE54: 735087.12 | AF54: 738976.46 | AG54: 738355.04 | AH54: 740169.62 | AI54: 728543.15 | AJ54: 730488.79 | AK54: 730584.5 | AL54: 737779.98 | AM54: 736989.67 | AN54: 727889.62 | AO54: 735038.58 | AP54: 3666684.2 | AQ54: 3696111.7 | AR54: 3701565.6 | AS54: 3689818.5 | AT54: 3664208.2 | AU54: 3703522.2 | AV54: 3664008.6 | AW54: 3745693.6 | AX54: 3727120 | AY54: 3686656.3 | AZ54: 3622224.8 | BA54: 3676519.8 | BB54: 3648967.4 | BC54: 3700684.5 | BD54: 3673666.2 | BE54: 3610587.6 | BF54: 3686284.4 | BG54: 3656637 | BH54: 3683395.5 | BI54: 3700116.5
A55: Fuzzy | B55: 615495.67 | C55: 615495.67 | D55: 615495.67 | E55: 615495.67 | F55: 615495.67 | G55: 615495.67 | H55: 615495.67 | I55: 615495.67 | J55: 615495.67 | K55: 615495.67 | L55: 615495.67 | M55: 615495.67 | N55: 615495.67 | O55: 615495.67 | P55: 615495.67 | Q55: 615495.67 | R55: 615495.67 | S55: 615495.67 | T55: 615495.67 | U55: 615495.67 | V55: 719469.35 | W55: 719466.6 | X55: 719467.06 | Y55: 719469.75 | Z55: 719467.75 | AA55: 719468.23 | AB55: 719467.08 | AC55: 719468.75 | AD55: 719468.15 | AE55: 719467.67 | AF55: 719465.58 | AG55: 719467.04 | AH55: 719468.06 | AI55: 719467.25 | AJ55: 719467.33 | AK55: 719467.85 | AL55: 719466.69 | AM55: 719467.48 | AN55: 719465.98 | AO55: 719467.73 | AP55: 3567038.1 | AQ55: 3567037.8 | AR55: 3567038.5 | AS55: 3567036.9 | AT55: 3567036.7 | AU55: 3567036.8 | AV55: 3567038.4 | AW55: 3567037.7 | AX55: 3567037.6 | AY55: 3567038 | AZ55: 3567037.2 | BA55: 3567036.8 | BB55: 3567037.5 | BC55: 3567037.7 | BD55: 3567037.6 | BE55: 3567038.3 | BF55: 3567037.5 | BG55: 3567037.2 | BH55: 3567037.7 | BI55: 3567035.8
A56: NSGA3 | B56: 684633.38 | C56: 670300.12 | D56: 759929.96 | E56: 767152.29 | F56: 737590.79 | G56: 680782.75 | H56: 720429.38 | I56: 642129.46 | J56: 651150.92 | K56: 690538.96 | L56: 761163.62 | M56: 710979.25 | N56: 678806.17 | O56: 774584.12 | P56: 677963.04 | Q56: 655359.54 | R56: 739812.38 | S56: 752873.33 | T56: 664417.12 | U56: 686378.25 | V56: 857945.52 | W56: 833240.21 | X56: 924972.4 | Y56: 877518.77 | Z56: 831406.85 | AA56: 854306.27 | AB56: 846474.71 | AC56: 786993.15 | AD56: 809410.35 | AE56: 912693.77 | AF56: 805188.29 | AG56: 800282.19 | AH56: 847681.96 | AI56: 786989.58 | AJ56: 860815.65 | AK56: 790541.17 | AL56: 798172.6 | AM56: 778316.5 | AN56: 844833.4 | AO56: 836179.5 | AP56: 3742574.7 | AQ56: 4397629.1 | AR56: 4133197.2 | AS56: 4023334.9 | AT56: 4191608.6 | AU56: 3944722.1 | AV56: 4414356.3 | AW56: 4048983.4 | AX56: 4094188.2 | AY56: 4253303.6 | AZ56: 4297435.2 | BA56: 4210825.5 | BB56: 4007412.1 | BC56: 4333031.4 | BD56: 4200165.6 | BE56: 3994741.7 | BF56: 4396209.2 | BG56: 4598828.1 | BH56: 4343051 | BI56: 4058715.4
A57: MQGA | B57: 624925.12 | C57: 645622.42 | D57: 625276.42 | E57: 625213.67 | F57: 641970.33 | G57: 625057.58 | H57: 625172.29 | I57: 625175.46 | J57: 625262.67 | K57: 645707.29 | L57: 645888.83 | M57: 641955.92 | N57: 642012.83 | O57: 687555.17 | P57: 642103.67 | Q57: 625431.38 | R57: 625328.79 | S57: 640714.46 | T57: 626224.58 | U57: 642658.83 | V57: 826571.25 | W57: 776836.65 | X57: 728560.31 | Y57: 815764.94 | Z57: 780165.96 | AA57: 771793.44 | AB57: 729044.29 | AC57: 742880.35 | AD57: 854967.96 | AE57: 737604.27 | AF57: 822115.81 | AG57: 767338.4 | AH57: 864509.52 | AI57: 719559.69 | AJ57: 770735.48 | AK57: 776469.38 | AL57: 757822.69 | AM57: 767139 | AN57: 777285.21 | AO57: 751855.62 | AP57: 4195785.7 | AQ57: 4120280.7 | AR57: 4216797.5 | AS57: 4082143.4 | AT57: 4127808.9 | AU57: 4181451.9 | AV57: 4283230.3 | AW57: 3940208.9 | AX57: 4301155.7 | AY57: 4061060.5 | AZ57: 3929380.9 | BA57: 4030274.5 | BB57: 4198124.7 | BC57: 4358910.9 | BD57: 4167457.7 | BE57: 4172147.4 | BF57: 4123174.8 | BG57: 3988029.3 | BH57: 4127923 | BI57: 4410358.9
...

Sheet Energy
A1: Algorithm | B1: Load | C1: Average | D1: Min | E1: Max | F1: Std Dev
A2: QUEST | B2: 1 | C2: 3.5993326e+09 | D2: 3.5095713e+09 | E2: 3.6537545e+09 | F2: 41559082
A3: QUEST | B3: 2 | C3: 5.2522481e+09 | D3: 4.9861015e+09 | E3: 5.6072022e+09 | F3: 1.9056748e+08
A4: QUEST | B4: 3 | C4: 23727784862 | D4: 2.1497787e+10 | E4: 2.5152917e+10 | F4: 9.5765992e+08
A5: QUEST_NDVFS | B5: 1 | C5: 3.2491868e+09 | D5: 3.1845632e+09 | E5: 3.273938e+09 | F5: 29929127
A6: QUEST_NDVFS | B6: 2 | C6: 4.7857253e+09 | D6: 4.5990492e+09 | E6: 5.3065901e+09 | F6: 1.5335991e+08
A7: QUEST_NDVFS | B7: 3 | C7: 2.1470355e+10 | D7: 1.9777715e+10 | E7: 22916706485 | F7: 9.6265616e+08
A8: Fuzzy | B8: 1 | C8: 3.272274e+09 | D8: 3.272243e+09 | E8: 3.2723115e+09 | F8: 16194.024
A9: Fuzzy | B9: 2 | C9: 4.8158162e+09 | D9: 4.8157774e+09 | E9: 4.8158382e+09 | F9: 14836.237
A10: Fuzzy | B10: 3 | C10: 2.1688133e+10 | D10: 2.168811e+10 | E10: 2.1688171e+10 | F10: 12825.375
A11: NSGA3 | B11: 1 | C11: 3.8002602e+09 | D11: 3.2084839e+09 | E11: 4.8735008e+09 | F11: 5.105444e+08
A12: NSGA3 | B12: 2 | C12: 5.3920446e+09 | D12: 4.5788763e+09 | E12: 6862697855 | F12: 5.7456874e+08
A13: NSGA3 | B13: 3 | C13: 2.9752374e+10 | D13: 2.2271421e+10 | E13: 3.7936635e+10 | F13: 4.1937657e+09
... A25: RL | B25: 3 | C25: 2.991427e+10 | D25: 22135062785 | E25: 4.175994e+10 | F25: 6.2017302e+09
A28: Summary by Algorithm
A29: QUEST | C29: 1.0859789e+10 | D29: 3.5095713e+09 | E29: 2.5152917e+10 | F29: 9.1414662e+09
A30: QUEST_NDVFS | C30: 9.8350892e+09 | D30: 3.1845632e+09 | E30: 22916706485 | F30: 8.2704439e+09
A31: Fuzzy | C31: 9.9254079e+09 | D31: 3.272243e+09 | E31: 2.1688171e+10 | F31: 8.3413394e+09
A32: NSGA3 | C32: 1.298156e+10 | D32: 3.2084839e+09 | E32: 3.7936635e+10 | F32: 1.2128969e+10
A33: MQGA | C33: 1.1645657e+10 | D33: 3.3678093e+09 | E33: 2.8542308e+10 | F33: 1.0663031e+10
A34: Greedy | C34: 1.3626668e+10 | D34: 3.2415129e+09 | E34: 4.6422473e+10 | F34: 1.3252757e+10
A35: MOPSO | C35: 1.3000893e+10 | D35: 3.3592378e+09 | E35: 3.5196324e+10 | F35: 1.2304919e+10
A36: RL | C36: 1.3025201e+10 | D36: 3.2307584e+09 | E36: 4.175994e+10 | F36: 1.250555e+10
A39: Average data for chart
A40: Algorithms | B40: 1 | C40: 2 | D40: 3
A41: QUEST | B41: 3.5993326e+09 | C41: 5.2522481e+09 | D41: 23727784862
A42: QUEST_NDVFS | B42: 3.2491868e+09 | C42: 4.7857253e+09 | D42: 2.1470355e+10
A43: Fuzzy | B43: 3.672274e+09 | C43: 5.3158162e+09 | D43: 2.4688133e+10
A44: NSGA3 | B44: 3.8002602e+09 | C44: 5.5920446e+09 | D44: 2.9752374e+10
A45: MQGA | B45: 3.990736e+09 | C45: 5.4560437e+09 | D45: 2.6690191e+10
A46: Greedy | B46: 3.7644858e+09 | C46: 5.5302667e+09 | D46: 3.1585253e+10
A47: MOPSO | B47: 3.6371668e+09 | C47: 5.2067453e+09 | D47: 3.0258767e+10
A48: RL | B48: 3.8658905e+09 | C48: 5.5954418e+09 | D48: 2.991427e+10
A51: All data for chart
A52: Algorithms | B52: 1 | C52: 1 | D52: 1 | E52: 1 | F52: 1 | G52: 1 | H52: 1 | I52: 1 | J52: 1 | K52: 1 | L52: 1 | M52: 1 | N52: 1 | O52: 1 | P52: 1 | Q52: 1 | R52: 1 | S52: 1 | T52: 1 | U52: 1 | V52: 2 | W52: 2 | X52: 2 | Y52: 2 | Z52: 2 | AA52: 2 | AB52: 2 | AC52: 2 | AD52: 2 | AE52: 2 | AF52: 2 | AG52: 2 | AH52: 2 | AI52: 2 | AJ52: 2 | AK52: 2 | AL52: 2 | AM52: 2 | AN52: 2 | AO52: 2 | AP52: 3 | AQ52: 3 | AR52: 3 | AS52: 3 | AT52: 3 | AU52: 3 | AV52: 3 | AW52: 3 | AX52: 3 | AY52: 3 | AZ52: 3 | BA52: 3 | BB52: 3 | BC52: 3 | BD52: 3 | BE52: 3 | BF52: 3 | BG52: 3 | BH52: 3 | BI52: 3
A53: QUEST | B53: 3.5095713e+09 | C53: 3649966020 | D53: 3.610056e+09 | E53: 3.5788004e+09 | F53: 3.605949e+09 | G53: 3649686335 | H53: 3544299440 | I53: 3.6537545e+09 | J53: 3.5601829e+09 | K53: 3650334500 | L53: 3.5953736e+09 | M53: 3.5925815e+09 | N53: 3.6090873e+09 | O53: 3.6505143e+09 | P53: 3.568086e+09 | Q53: 3.6522124e+09 | R53: 3.5926581e+09 | S53: 3.5403412e+09 | T53: 3.5985315e+09 | U53: 3574666320 | V53: 5.5982572e+09 | W53: 5.1428948e+09 | X53: 5.0867916e+09 | Y53: 4.9861015e+09 | Z53: 5.6072022e+09 | AA53: 5.5172659e+09 | AB53: 5.0737084e+09 | AC53: 5.211305e+09 | AD53: 5190279020 | AE53: 5.111918e+09 | AF53: 5.140886e+09 | AG53: 5.2139404e+09 | AH53: 5.2271677e+09 | AI53: 5.4687334e+09 | AJ53: 5.1774933e+09 | AK53: 5.0968563e+09 | AL53: 5.1630383e+09 | AM53: 5.4912549e+09 | AN53: 5.4776712e+09 | AO53: 5.0621965e+09 | AP53: 2.3225313e+10 | AQ53: 2.1497787e+10 | AR53: 23919790585 | AS53: 2.5026044e+10 | AT53: 2.5152917e+10 | AU53: 2.2450334e+10 | AV53: 25028338705 | AW53: 2.3306577e+10 | AX53: 2.3842497e+10 | AY53: 2.3868281e+10 | AZ53: 2.4303756e+10 | BA53: 2.3312293e+10 | BB53: 2.5134012e+10 | BC53: 2.1978962e+10 | BD53: 2.4005642e+10 | BE53: 2.3471083e+10 | BF53: 23503893370 | BG53: 2.3654932e+10 | BH53: 2.3980801e+10 | BI53: 2.3892443e+10
A54: QUEST_NDVFS | B54: 3.2723494e+09 | C54: 3.21935e+09 | D54: 3.2717167e+09 | E54: 3.2021671e+09 | F54: 3.273938e+09 | G54: 3.2209889e+09 | H54: 3.220957e+09 | I54: 3.2301672e+09 | J54: 3273890330 | K54: 3.2721164e+09 | L54: 3.2723862e+09 | M54: 3.273431e+09 | N54: 3.1845632e+09 | O54: 3.2733581e+09 | P54: 3.2708374e+09 | Q54: 3.2721384e+09 | R54: 3219660205 | S54: 3271868580 | T54: 3273453980 | U54: 3214397860 | V54: 4.9159299e+09 | W54: 4.7636798e+09 | X54: 4.6169093e+09 | Y54: 4.7072048e+09 | Z54: 4.9092915e+09 | AA54: 4673846205 | AB54: 4.7532463e+09 | AC54: 4.5990492e+09 | AD54: 4.8732319e+09 | AE54: 4.6429887e+09 | AF54: 4.863642e+09 | AG54: 4.6797501e+09 | AH54: 5.3065901e+09 | AI54: 4.6950514e+09 | AJ54: 4.7817679e+09 | AK54: 4.7905258e+09 | AL54: 4.7540328e+09 | AM54: 4.7077217e+09 | AN54: 4.7486056e+09 | AO54: 4.9314408e+09 | AP54: 22101240015 | AQ54: 2.1923101e+10 | AR54: 2.2431242e+10 | AS54: 20252977035 | AT54: 2.2278509e+10 | AU54: 2.1217299e+10 | AV54: 2.0305886e+10 | AW54: 2.2100018e+10 | AX54: 2.2543938e+10 | AY54: 2.0294396e+10 | AZ54: 2.1015567e+10 | BA54: 1.9777715e+10 | BB54: 22916706485 | BC54: 2.1322292e+10 | BD54: 2.1884953e+10 | BE54: 2.0725575e+10 | BF54: 2.0887854e+10 | BG54: 2.2291945e+10 | BH54: 20230956310 | BI54: 2.2904937e+10
A55: Fuzzy | B55: 3.2722775e+09 | C55: 3.2722564e+09 | D55: 3.2722852e+09 | E55: 3.272243e+09 | F55: 3.2722788e+09 | G55: 3.2722775e+09 | H55: 3.2722884e+09 | I55: 3.2722647e+09 | J55: 3.2722679e+09 | K55: 3.2723108e+09 | L55: 3.2722622e+09 | M55: 3.272259e+09 | N55: 3.2722737e+09 | O55: 3.2722622e+09 | P55: 3.2722635e+09 | Q55: 3.2722763e+09 | R55: 3.2722686e+09 | S55: 3.2723115e+09 | T55: 3.2722814e+09 | U55: 3.2722718e+09 | V55: 4.8158356e+09 | W55: 4.8158074e+09 | X55: 4.8158196e+09 | Y55: 4.8158215e+09 | Z55: 4.8158222e+09 | AA55: 4.8158151e+09 | AB55: 4.8158382e+09 | AC55: 4.8158337e+09 | AD55: 4.815801e+09 | AE55: 4.8158247e+09 | AF55: 4.8157774e+09 | AG55: 4.8158049e+09 | AH55: 4.815826e+09 | AI55: 4.8157946e+09 | AJ55: 4.815817e+09 | AK55: 4.8158324e+09 | AL55: 4.815803e+09 | AM55: 4.8158241e+09 | AN55: 4.8158074e+09 | AO55: 4.815819e+09 | AP55: 2.1688119e+10 | AQ55: 2.1688171e+10 | AR55: 2.1688145e+10 | AS55: 2.168811e+10 | AT55: 2.1688134e+10 | AU55: 2.1688116e+10 | AV55: 2.1688124e+10 | AW55: 2.1688141e+10 | AX55: 2.1688129e+10 | AY55: 2.1688131e+10 | AZ55: 2.1688138e+10 | BA55: 2.1688122e+10 | BB55: 2.1688124e+10 | BC55: 2.1688137e+10 | BD55: 2.1688141e+10 | BE55: 2.1688142e+10 | BF55: 2.1688141e+10 | BG55: 2.1688127e+10 | BH55: 2.168814e+10 | BI55: 2.1688136e+10
A56: NSGA3 | B56: 3298481920 | C56: 3748582140 | D56: 4.3608802e+09 | E56: 3.803575e+09 | F56: 4.4034346e+09 | G56: 3.3131174e+09 | H56: 3.6526543e+09 | I56: 3.3710183e+09 | J56: 3.4659135e+09 | K56: 3.7197054e+09 | L56: 4686766820 | M56: 3522747480 | N56: 3.7341405e+09 | O56: 4649380500 | P56: 3307929215 | Q56: 3.2084839e+09 | R56: 4.8735008e+09 | S56: 4.0632964e+09 | T56: 3.328199e+09 | U56: 3.4933974e+09 | V56: 6862697855 | W56: 5228834985 | X56: 5.2721382e+09 | Y56: 5.8501793e+09 | Z56: 5.2064882e+09 | AA56: 6268734900 | AB56: 5.824786e+09 | AC56: 4733449105 | AD56: 4.5788763e+09 | AE56: 5.9598801e+09 | AF56: 5308210245 | AG56: 5.144132e+09 | AH56: 5.5645798e+09 | AI56: 5.3288529e+09 | AJ56: 5.9033546e+09 | AK56: 4.7177465e+09 | AL56: 4.6978871e+09 | AM56: 4702157905 | AN56: 5330514850 | AO56: 5357391540 | AP56: 2.2271421e+10 | AQ56: 3.1328669e+10 | AR56: 2.7750486e+10 | AS56: 2.4538596e+10 | AT56: 3.1502493e+10 | AU56: 28382910170 | AV56: 2.8315049e+10 | AW56: 2.4982692e+10 | AX56: 2.971721e+10 | AY56: 3.5963792e+10 | AZ56: 3.1084717e+10 | BA56: 2.9462092e+10 | BB56: 26865324115 | BC56: 3.1189052e+10 | BD56: 3.3432934e+10 | BE56: 2.4683146e+10 | BF56: 3.4342896e+10 | BG56: 3.7936635e+10 | BH56: 3.5777627e+10 | BI56: 2.5519743e+10
A57: MQGA | B57: 3.4002536e+09 | C57: 3.3739732e+09 | D57: 3.4007107e+09 | E57: 3.4015576e+09 | F57: 3.3699224e+09 | G57: 3.4005192e+09 | H57: 3.4002316e+09 | I57: 3.4016251e+09 | J57: 3.4008206e+09 | K57: 3.3737719e+09 | L57: 3.3752756e+09 | M57: 3.3681453e+09 | N57: 3.3693621e+09 | O57: 3.4426041e+09 | P57: 3.3678093e+09 | Q57: 3.4022173e+09 | R57: 3.4018421e+09 | S57: 3.3728339e+09 | T57: 3.4123909e+09 | U57: 3.378854e+09 | V57: 5066146610 | W57: 4.7775915e+09 | X57: 4754498275 | Y57: 4.8079544e+09 | Z57: 4.8093893e+09 | AA57: 4.7945463e+09 | AB57: 4.73005e+09 | AC57: 4.9082287e+09 | AD57: 5.1409493e+09 | AE57: 4.7478318e+09 | AF57: 5.0622984e+09 | AG57: 4.8068867e+09 | AH57: 5.0346981e+09 | AI57: 4.818222e+09 | AJ57: 4808100920 | AK57: 4.7687061e+09 | AL57: 4.8442712e+09 | AM57: 4.8053895e+09 | AN57: 4.7684216e+09 | AO57: 4.8666928e+09 | AP57: 26170354680 | AQ57: 2.8542308e+10 | AR57: 2.7573794e+10 | AS57: 2.6488849e+10 | AT57: 2.6265946e+10 | AU57: 25770289345 | AV57: 2.6886315e+10 | AW57: 2.5430989e+10 | AX57: 2.6837945e+10 | AY57: 2.5589971e+10 | AZ57: 26966505295 | BA57: 2.6632927e+10 | BB57: 2.6825821e+10 | BC57: 2.6997238e+10 | BD57: 2.7539183e+10 | BE57: 2.6733086e+10 | BF57: 2.6176788e+10 | BG57: 2.6218338e+10 | BH57: 2.7012691e+10 | BI57: 2.7144476e+10
...

Sheet Makespan
A1: Algorithm | B1: Load | C1: Average | D1: Min | E1: Max | F1: Std Dev
A2: QUEST | B2: 1 | C2: 5227377.5 | D2: 5224084 | E2: 5243411 | F2: 4124.9669
A3: QUEST | B3: 2 | C3: 7339177.4 | D3: 7124957 | E3: 7823117 | F3: 312422.48
A4: QUEST | B4: 3 | C4: 31537079 | D4: 27809290 | E4: 34043534 | F4: 1577926.9
A5: QUEST_NDVFS | B5: 1 | C5: 4653333 | D5: 4651042 | E5: 4657015 | F5: 1609.9026
A6: QUEST_NDVFS | B6: 2 | C6: 6571627 | D6: 6441592 | E6: 7448124 | F6: 233663.61
A7: QUEST_NDVFS | B7: 3 | C7: 27874131 | D7: 25599452 | E7: 29873565 | F7: 1522810
A8: Fuzzy | B8: 1 | C8: 4652096.5 | D8: 4652048 | E8: 4652155 | F8: 25.303162
A9: Fuzzy | B9: 2 | C9: 6448946.8 | D9: 6448886 | E9: 6448981 | F9: 23.18162
A10: Fuzzy | B10: 3 | C10: 25947861 | D10: 25947824 | E10: 25947919 | F10: 20.039648
A11: NSGA3 | B11: 1 | C11: 5654229.2 | D11: 4672293 | E11: 7232909 | F11: 773864.82
A12: NSGA3 | B12: 2 | C12: 7777861.9 | D12: 6717680 | E12: 10024604 | F12: 847346.63
A13: NSGA3 | B13: 3 | C13: 40448134 | D13: 29752247 | E13: 52120072 | F13: 6234605.6
... A25: RL | B25: 3 | C25: 40908631 | D25: 29663623 | E25: 58680654 | F25: 9175337.1
A28: Summary by Algorithm
A29: QUEST | C29: 14701211 | D29: 5224084 | E29: 34043534 | F29: 11972009
A30: QUEST_NDVFS | C30: 13033030 | D30: 4651042 | E30: 29873565 | F30: 10560948
A31: Fuzzy | C31: 12349635 | D31: 4652048 | E31: 25947919 | F31: 9643339.1
A32: NSGA3 | C32: 17960075 | D32: 4672293 | E32: 52120072 | F32: 16340250
A33: MQGA | C33: 15648173 | D33: 4880299 | E33: 37945103 | F33: 13916764
A34: Greedy | C34: 18877419 | D34: 4654859 | E34: 66446854 | F34: 18015535
A35: MOPSO | C35: 17821153 | D35: 4883237 | E35: 48691931 | F35: 16349445
A36: RL | C36: 18101670 | D36: 4655832 | E36: 58680654 | F36: 17031405
A39: Average data for chart
A40: Algorithms | B40: 1 | C40: 2 | D40: 3
A41: QUEST | B41: 5227377.5 | C41: 7339177.4 | D41: 31537079
A42: QUEST_NDVFS | B42: 4653333 | C42: 6571627 | D42: 27874131
A43: Fuzzy | B43: 5352096.5 | C43: 7448946.8 | D43: 33947861
A44: NSGA3 | B44: 5654229.2 | C44: 7777861.9 | D44: 40448134
A45: MQGA | B45: 5400000.5 | C45: 7765231.8 | D45: 35279286
A46: Greedy | B46: 5598206.5 | C46: 7949818.8 | D46: 43084232
A47: MOPSO | B47: 5239288.5 | C47: 7523493.2 | D47: 40700678
A48: RL | B48: 5309396 | C48: 8086983.4 | D48: 40908631
A51: All data for chart
A52: Algorithms | B52: 1 | C52: 1 | D52: 1 | E52: 1 | F52: 1 | G52: 1 | H52: 1 | I52: 1 | J52: 1 | K52: 1 | L52: 1 | M52: 1 | N52: 1 | O52: 1 | P52: 1 | Q52: 1 | R52: 1 | S52: 1 | T52: 1 | U52: 1 | V52: 2 | W52: 2 | X52: 2 | Y52: 2 | Z52: 2 | AA52: 2 | AB52: 2 | AC52: 2 | AD52: 2 | AE52: 2 | AF52: 2 | AG52: 2 | AH52: 2 | AI52: 2 | AJ52: 2 | AK52: 2 | AL52: 2 | AM52: 2 | AN52: 2 | AO52: 2 | AP52: 3 | AQ52: 3 | AR52: 3 | AS52: 3 | AT52: 3 | AU52: 3 | AV52: 3 | AW52: 3 | AX52: 3 | AY52: 3 | AZ52: 3 | BA52: 3 | BB52: 3 | BC52: 3 | BD52: 3 | BE52: 3 | BF52: 3 | BG52: 3 | BH52: 3 | BI52: 3
A53: QUEST | B53: 5226041 | C53: 5224191 | D53: 5227005 | E53: 5225064 | F53: 5228860 | G53: 5224169 | H53: 5225041 | I53: 5231128 | J53: 5243411 | K53: 5224848 | L53: 5224084 | M53: 5228023 | N53: 5225103 | O53: 5225105 | P53: 5226160 | Q53: 5227992 | R53: 5228054 | S53: 5229175 | T53: 5226949 | U53: 5227147 | V53: 7816857 | W53: 7131683 | X53: 7129030 | Y53: 7128837 | Z53: 7809582 | AA53: 7817377 | AB53: 7140340 | AC53: 7135739 | AD53: 7154965 | AE53: 7133320 | AF53: 7146294 | AG53: 7128765 | AH53: 7126856 | AI53: 7815694 | AJ53: 7128990 | AK53: 7138695 | AL53: 7137345 | AM53: 7823117 | AN53: 7815105 | AO53: 7124957 | AP53: 31435827 | AQ53: 27809290 | AR53: 31810233 | AS53: 33928125 | AT53: 34036034 | AU53: 29197438 | AV53: 34043534 | AW53: 31810929 | AX53: 31316254 | AY53: 31805423 | AZ53: 31236666 | BA53: 31436356 | BB53: 33923259 | BC53: 29199343 | BD53: 31431159 | BE53: 30820356 | BF53: 31435438 | BG53: 31316301 | BH53: 31429607 | BI53: 31320009
A54: QUEST_NDVFS | B54: 4652910 | C54: 4652119 | D54: 4651160 | E54: 4657015 | F54: 4655043 | G54: 4654976 | H54: 4654963 | I54: 4651042 | J54: 4655019 | K54: 4652079 | L54: 4652139 | M54: 4654093 | N54: 4652877 | O54: 4654066 | P54: 4652106 | Q54: 4652011 | R54: 4652830 | S54: 4651169 | T54: 4654210 | U54: 4654834 | V54: 6728153 | W54: 6446499 | X54: 6449272 | Y54: 6446268 | Z54: 6721636 | AA54: 6443342 | AB54: 6461069 | AC54: 6467473 | AD54: 6737453 | AE54: 6441592 | AF54: 6739046 | AG54: 6448099 | AH54: 7448124 | AI54: 6444956 | AJ54: 6456509 | AK54: 6467056 | AL54: 6457506 | AM54: 6452649 | AN54: 6455228 | AO54: 6720611 | AP54: 28825195 | AQ54: 28831388 | AR54: 28715595 | AS54: 25607066 | AT54: 28824460 | AU54: 27633846 | AV54: 26647576 | AW54: 28824236 | AX54: 29871702 | AY54: 25599452 | AZ54: 26593084 | BA54: 25605810 | BB54: 29756588 | BC54: 28710715 | BD54: 28708756 | BE54: 26245281 | BF54: 26600197 | BG54: 29756766 | BH54: 26251339 | BI54: 29873565
A55: Fuzzy | B55: 4652102 | C55: 4652069 | D55: 4652114 | E55: 4652048 | F55: 4652104 | G55: 4652102 | H55: 4652119 | I55: 4652082 | J55: 4652087 | K55: 4652154 | L55: 4652078 | M55: 4652073 | N55: 4652096 | O55: 4652078 | P55: 4652080 | Q55: 4652100 | R55: 4652088 | S55: 4652155 | T55: 4652108 | U55: 4652093 | V55: 6448977 | W55: 6448933 | X55: 6448952 | Y55: 6448955 | Z55: 6448956 | AA55: 6448945 | AB55: 6448981 | AC55: 6448974 | AD55: 6448923 | AE55: 6448960 | AF55: 6448886 | AG55: 6448929 | AH55: 6448962 | AI55: 6448913 | AJ55: 6448948 | AK55: 6448972 | AL55: 6448926 | AM55: 6448959 | AN55: 6448933 | AO55: 6448951 | AP55: 25947838 | AQ55: 25947919 | AR55: 25947879 | AS55: 25947824 | AT55: 25947861 | AU55: 25947834 | AV55: 25947846 | AW55: 25947873 | AX55: 25947854 | AY55: 25947857 | AZ55: 25947868 | BA55: 25947843 | BB55: 25947846 | BC55: 25947867 | BD55: 25947873 | BE55: 25947874 | BF55: 25947872 | BG55: 25947851 | BH55: 25947871 | BI55: 25947865
A56: NSGA3 | B56: 4900460 | C56: 5560469 | D56: 6533777 | E56: 5642745 | F56: 6533063 | G56: 4911047 | H56: 5561242 | I56: 4886286 | J56: 5134459 | K56: 5576609 | L56: 7005157 | M56: 5329288 | N56: 5563347 | O56: 6947412 | P56: 4893132 | Q56: 4672293 | R56: 7232909 | S56: 5966118 | T56: 4886244 | U56: 5348526 | V56: 10024604 | W56: 7470599 | X56: 7470441 | Y56: 8518015 | Z56: 7728154 | AA56: 8901266 | AB56: 8392888 | AC56: 6727312 | AD56: 6724398 | AE56: 8375584 | AF56: 7720805 | AG56: 7442318 | AH56: 7989649 | AI56: 7751200 | AJ56: 8713696 | AK56: 6717680 | AL56: 6731087 | AM56: 6730699 | AN56: 7719734 | AO56: 7707109 | AP56: 29752247 | AQ56: 42861029 | AR56: 37894955 | AS56: 32635861 | AT56: 42393406 | AU56: 39051404 | AV56: 38340424 | AW56: 33682494 | AX56: 39946798 | AY56: 50532716 | AZ56: 42162088 | BA56: 39175754 | BB56: 37082504 | BC56: 42402723 | BD56: 46757639 | BE56: 32241420 | BF56: 47241288 | BG56: 52120072 | BH56: 49118242 | BI56: 33569615
A57: MQGA | B57: 4880355 | C57: 4901593 | D57: 4882181 | E57: 4883256 | F57: 4884096 | G57: 4881219 | H57: 4881220 | I57: 4883247 | J57: 4882091 | K57: 4901508 | L57: 4903507 | M57: 4881276 | N57: 4883351 | O57: 5134416 | P57: 4880299 | Q57: 4884146 | R57: 4884206 | S57: 4885041 | T57: 4902491 | U57: 4900510 | V57: 7079969 | W57: 6450662 | X57: 6462860 | Y57: 6730462 | Z57: 6732591 | AA57: 6728774 | AB57: 6458803 | AC57: 6732733 | AD57: 7318133 | AE57: 6448348 | AF57: 7450207 | AG57: 6718023 | AH57: 7216020 | AI57: 6452406 | AJ57: 6736081 | AK57: 6716146 | AL57: 6720594 | AM57: 6715074 | AN57: 6718179 | AO57: 6718570 | AP57: 35405553 | AQ57: 37945103 | AR57: 35737230 | AS57: 34867332 | AT57: 33583749 | AU57: 34440134 | AV57: 35982945 | AW57: 33014697 | AX57: 34330526 | AY57: 34860206 | AZ57: 34827671 | BA57: 35926961 | BB57: 35661158 | BC57: 34592691 | BD57: 36306825 | BE57: 35138146 | BF57: 36373219 | BG57: 34660545 | BH57: 36205318 | BI57: 35725704
...

Sheet Success Rate
A1: Algorithm | B1: Load | C1: Average | D1: Min | E1: Max | F1: Std Dev
A2: QUEST | B2: 1 | C2: 0 | D2: FALSE | E2: FALSE | F2: 0
A3: QUEST | B3: 2 | C3: 0 | D3: FALSE | E3: FALSE | F3: 0
A4: QUEST | B4: 3 | C4: 0 | D4: FALSE | E4: FALSE | F4: 0
A5: QUEST_NDVFS | B5: 1 | C5: 0 | D5: FALSE | E5: FALSE | F5: 0
A6: QUEST_NDVFS | B6: 2 | C6: 0 | D6: FALSE | E6: FALSE | F6: 0
A7: QUEST_NDVFS | B7: 3 | C7: 0 | D7: FALSE | E7: FALSE | F7: 0
A8: Fuzzy | B8: 1 | C8: 0 | D8: FALSE | E8: FALSE | F8: 0
A9: Fuzzy | B9: 2 | C9: 0 | D9: FALSE | E9: FALSE | F9: 0
A10: Fuzzy | B10: 3 | C10: 0 | D10: FALSE | E10: FALSE | F10: 0
A11: NSGA3 | B11: 1 | C11: 0 | D11: FALSE | E11: FALSE | F11: 0
A12: NSGA3 | B12: 2 | C12: 0 | D12: FALSE | E12: FALSE | F12: 0
A13: NSGA3 | B13: 3 | C13: 0 | D13: FALSE | E13: FALSE | F13: 0
... A25: RL | B25: 3 | C25: 0 | D25: FALSE | E25: FALSE | F25: 0
A28: Summary by Algorithm
A29: QUEST | C29: 0 | D29: FALSE | E29: FALSE | F29: 0
A30: QUEST_NDVFS | C30: 0 | D30: FALSE | E30: FALSE | F30: 0
A31: Fuzzy | C31: 0 | D31: FALSE | E31: FALSE | F31: 0
A32: NSGA3 | C32: 0 | D32: FALSE | E32: FALSE | F32: 0
A33: MQGA | C33: 0 | D33: FALSE | E33: FALSE | F33: 0
A34: Greedy | C34: 0 | D34: FALSE | E34: FALSE | F34: 0
A35: MOPSO | C35: 0 | D35: FALSE | E35: FALSE | F35: 0
A36: RL | C36: 0 | D36: FALSE | E36: FALSE | F36: 0
A39: Average data for chart
A40: Algorithms | B40: 1 | C40: 2 | D40: 3
A41: QUEST | B41: 0 | C41: 0 | D41: 0
A42: QUEST_NDVFS | B42: 0 | C42: 0 | D42: 0
A43: Fuzzy | B43: 0 | C43: 0 | D43: 0
A44: NSGA3 | B44: 0 | C44: 0 | D44: 0
A45: MQGA | B45: 0 | C45: 0 | D45: 0
A46: Greedy | B46: 0 | C46: 0 | D46: 0
A47: MOPSO | B47: 0 | C47: 0 | D47: 0
A48: RL | B48: 0 | C48: 0 | D48: 0
A51: All data for chart
A52: Algorithms | B52: 1 | C52: 1 | D52: 1 | E52: 1 | F52: 1 | G52: 1 | H52: 1 | I52: 1 | J52: 1 | K52: 1 | L52: 1 | M52: 1 | N52: 1 | O52: 1 | P52: 1 | Q52: 1 | R52: 1 | S52: 1 | T52: 1 | U52: 1 | V52: 2 | W52: 2 | X52: 2 | Y52: 2 | Z52: 2 | AA52: 2 | AB52: 2 | AC52: 2 | AD52: 2 | AE52: 2 | AF52: 2 | AG52: 2 | AH52: 2 | AI52: 2 | AJ52: 2 | AK52: 2 | AL52: 2 | AM52: 2 | AN52: 2 | AO52: 2 | AP52: 3 | AQ52: 3 | AR52: 3 | AS52: 3 | AT52: 3 | AU52: 3 | AV52: 3 | AW52: 3 | AX52: 3 | AY52: 3 | AZ52: 3 | BA52: 3 | BB52: 3 | BC52: 3 | BD52: 3 | BE52: 3 | BF52: 3 | BG52: 3 | BH52: 3 | BI52: 3
A53: QUEST | B53: FALSE | C53: FALSE | D53: FALSE | E53: FALSE | F53: FALSE | G53: FALSE | H53: FALSE | I53: FALSE | J53: FALSE | K53: FALSE | L53: FALSE | M53: FALSE | N53: FALSE | O53: FALSE | P53: FALSE | Q53: FALSE | R53: FALSE | S53: FALSE | T53: FALSE | U53: FALSE | V53: FALSE | W53: FALSE | X53: FALSE | Y53: FALSE | Z53: FALSE | AA53: FALSE | AB53: FALSE | AC53: FALSE | AD53: FALSE | AE53: FALSE | AF53: FALSE | AG53: FALSE | AH53: FALSE | AI53: FALSE | AJ53: FALSE | AK53: FALSE | AL53: FALSE | AM53: FALSE | AN53: FALSE | AO53: FALSE | AP53: FALSE | AQ53: FALSE | AR53: FALSE | AS53: FALSE | AT53: FALSE | AU53: FALSE | AV53: FALSE | AW53: FALSE | AX53: FALSE | AY53: FALSE | AZ53: FALSE | BA53: FALSE | BB53: FALSE | BC53: FALSE | BD53: FALSE | BE53: FALSE | BF53: FALSE | BG53: FALSE | BH53: FALSE | BI53: FALSE
A54: QUEST_NDVFS | B54: FALSE | C54: FALSE | D54: FALSE | E54: FALSE | F54: FALSE | G54: FALSE | H54: FALSE | I54: FALSE | J54: FALSE | K54: FALSE | L54: FALSE | M54: FALSE | N54: FALSE | O54: FALSE | P54: FALSE | Q54: FALSE | R54: FALSE | S54: FALSE | T54: FALSE | U54: FALSE | V54: FALSE | W54: FALSE | X54: FALSE | Y54: FALSE | Z54: FALSE | AA54: FALSE | AB54: FALSE | AC54: FALSE | AD54: FALSE | AE54: FALSE | AF54: FALSE | AG54: FALSE | AH54: FALSE | AI54: FALSE | AJ54: FALSE | AK54: FALSE | AL54: FALSE | AM54: FALSE | AN54: FALSE | AO54: FALSE | AP54: FALSE | AQ54: FALSE | AR54: FALSE | AS54: FALSE | AT54: FALSE | AU54: FALSE | AV54: FALSE | AW54: FALSE | AX54: FALSE | AY54: FALSE | AZ54: FALSE | BA54: FALSE | BB54: FALSE | BC54: FALSE | BD54: FALSE | BE54: FALSE | BF54: FALSE | BG54: FALSE | BH54: FALSE | BI54: FALSE
A55: Fuzzy | B55: FALSE | C55: FALSE | D55: FALSE | E55: FALSE | F55: FALSE | G55: FALSE | H55: FALSE | I55: FALSE | J55: FALSE | K55: FALSE | L55: FALSE | M55: FALSE | N55: FALSE | O55: FALSE | P55: FALSE | Q55: FALSE | R55: FALSE | S55: FALSE | T55: FALSE | U55: FALSE | V55: FALSE | W55: FALSE | X55: FALSE | Y55: FALSE | Z55: FALSE | AA55: FALSE | AB55: FALSE | AC55: FALSE | AD55: FALSE | AE55: FALSE | AF55: FALSE | AG55: FALSE | AH55: FALSE | AI55: FALSE | AJ55: FALSE | AK55: FALSE | AL55: FALSE | AM55: FALSE | AN55: FALSE | AO55: FALSE | AP55: FALSE | AQ55: FALSE | AR55: FALSE | AS55: FALSE | AT55: FALSE | AU55: FALSE | AV55: FALSE | AW55: FALSE | AX55: FALSE | AY55: FALSE | AZ55: FALSE | BA55: FALSE | BB55: FALSE | BC55: FALSE | BD55: FALSE | BE55: FALSE | BF55: FALSE | BG55: FALSE | BH55: FALSE | BI55: FALSE
A56: NSGA3 | B56: FALSE | C56: FALSE | D56: FALSE | E56: FALSE | F56: FALSE | G56: FALSE | H56: FALSE | I56: FALSE | J56: FALSE | K56: FALSE | L56: FALSE | M56: FALSE | N56: FALSE | O56: FALSE | P56: FALSE | Q56: FALSE | R56: FALSE | S56: FALSE | T56: FALSE | U56: FALSE | V56: FALSE | W56: FALSE | X56: FALSE | Y56: FALSE | Z56: FALSE | AA56: FALSE | AB56: FALSE | AC56: FALSE | AD56: FALSE | AE56: FALSE | AF56: FALSE | AG56: FALSE | AH56: FALSE | AI56: FALSE | AJ56: FALSE | AK56: FALSE | AL56: FALSE | AM56: FALSE | AN56: FALSE | AO56: FALSE | AP56: FALSE | AQ56: FALSE | AR56: FALSE | AS56: FALSE | AT56: FALSE | AU56: FALSE | AV56: FALSE | AW56: FALSE | AX56: FALSE | AY56: FALSE | AZ56: FALSE | BA56: FALSE | BB56: FALSE | BC56: FALSE | BD56: FALSE | BE56: FALSE | BF56: FALSE | BG56: FALSE | BH56: FALSE | BI56: FALSE
A57: MQGA | B57: FALSE | C57: FALSE | D57: FALSE | E57: FALSE | F57: FALSE | G57: FALSE | H57: FALSE | I57: FALSE | J57: FALSE | K57: FALSE | L57: FALSE | M57: FALSE | N57: FALSE | O57: FALSE | P57: FALSE | Q57: FALSE | R57: FALSE | S57: FALSE | T57: FALSE | U57: FALSE | V57: FALSE | W57: FALSE | X57: FALSE | Y57: FALSE | Z57: FALSE | AA57: FALSE | AB57: FALSE | AC57: FALSE | AD57: FALSE | AE57: FALSE | AF57: FALSE | AG57: FALSE | AH57: FALSE | AI57: FALSE | AJ57: FALSE | AK57: FALSE | AL57: FALSE | AM57: FALSE | AN57: FALSE | AO57: FALSE | AP57: FALSE | AQ57: FALSE | AR57: FALSE | AS57: FALSE | AT57: FALSE | AU57: FALSE | AV57: FALSE | AW57: FALSE | AX57: FALSE | AY57: FALSE | AZ57: FALSE | BA57: FALSE | BB57: FALSE | BC57: FALSE | BD57: FALSE | BE57: FALSE | BF57: FALSE | BG57: FALSE | BH57: FALSE | BI57: FALSE
...

Sheet Load Edge
A1: Algorithm | B1: Load | C1: Average | D1: Min | E1: Max | F1: Std Dev
A2: QUEST | B2: 1 | C2: 411912.72 | D2: 242583.4 | E2: 511536.37 | F2: 80033.019
A3: QUEST | B3: 2 | C3: 1078863.1 | D3: 831445.13 | E3: 1226793.4 | F3: 125356.93
A4: QUEST | B4: 3 | C4: 11206630 | D4: 10319681 | E4: 12504729 | F4: 617336.08
A5: QUEST_NDVFS | B5: 1 | C5: 447181.63 | D5: 324876.43 | E5: 492488.93 | F5: 57384.91
A6: QUEST_NDVFS | B6: 2 | C6: 1090505.8 | D6: 914359.03 | E6: 1195191.8 | F6: 89988.306
A7: QUEST_NDVFS | B7: 3 | C7: 11148341 | D7: 10057105 | E7: 12485077 | F7: 631237.27
A8: Fuzzy | B8: 1 | C8: 492396.53 | D8: 492396.53 | E8: 492396.53 | F8: 0
A9: Fuzzy | B9: 2 | C9: 1150585.6 | D9: 1150585.6 | E9: 1150585.6 | F9: 0
A10: Fuzzy | B10: 3 | C10: 11889572 | D10: 11889572 | E10: 11889572 | F10: 0
A11: NSGA3 | B11: 1 | C11: 523871.85 | D11: 380537.23 | E11: 576343.5 | F11: 43131.091
A12: NSGA3 | B12: 2 | C12: 1217949.9 | D12: 1106496.7 | E12: 1328948.9 | F12: 70183.513
A13: NSGA3 | B13: 3 | C13: 11947888 | D13: 11150398 | E13: 12701716 | F13: 505217.96
... A25: RL | B25: 3 | C25: 12058925 | D25: 10755995 | E25: 12734435 | F25: 426596.86
A28: Summary by Algorithm
A29: QUEST | C29: 4232468.5 | D29: 242583.4 | E29: 12504729 | F29: 4952575.8
A30: QUEST_NDVFS | C30: 4228676.3 | D30: 324876.43 | E30: 12485077 | F30: 4913906.6
A31: Fuzzy | C31: 4510851.5 | D31: 492396.53 | E31: 11889572 | F31: 5224458.1
A32: NSGA3 | C32: 4563236.7 | D32: 380537.23 | E32: 12701716 | F32: 5237764.2
A33: MQGA | C33: 4572277.5 | D33: 499416.47 | E33: 12640504 | F33: 5268792
A34: Greedy | C34: 4612429.8 | D34: 422526 | E34: 12975655 | F34: 5325586.1
A35: MOPSO | C35: 4462528.6 | D35: 441896.13 | E35: 12315710 | F35: 5074628.4
A36: RL | C36: 4591217.3 | D36: 316526.5 | E36: 12734435 | F36: 5294455.8
A39: Average data for chart
A40: Algorithms | B40: 1 | C40: 2 | D40: 3
A41: QUEST | B41: 411912.72 | C41: 1078863.1 | D41: 11206630
A42: QUEST_NDVFS | B42: 447181.63 | C42: 1090505.8 | D42: 11148341
A43: Fuzzy | B43: 492396.53 | C43: 1150585.6 | D43: 11889572
A44: NSGA3 | B44: 523871.85 | C44: 1217949.9 | D44: 11947888
A45: MQGA | B45: 508975.66 | C45: 1206881 | D45: 12000976
A46: Greedy | B46: 513117.35 | C46: 1198493.1 | D46: 12125679
A47: MOPSO | B47: 524190.32 | C47: 1246501.9 | D47: 11616894
A48: RL | B48: 505590.1 | C48: 1209136.7 | D48: 12058925
A51: All data for chart
A52: Algorithms | B52: 1 | C52: 1 | D52: 1 | E52: 1 | F52: 1 | G52: 1 | H52: 1 | I52: 1 | J52: 1 | K52: 1 | L52: 1 | M52: 1 | N52: 1 | O52: 1 | P52: 1 | Q52: 1 | R52: 1 | S52: 1 | T52: 1 | U52: 1 | V52: 2 | W52: 2 | X52: 2 | Y52: 2 | Z52: 2 | AA52: 2 | AB52: 2 | AC52: 2 | AD52: 2 | AE52: 2 | AF52: 2 | AG52: 2 | AH52: 2 | AI52: 2 | AJ52: 2 | AK52: 2 | AL52: 2 | AM52: 2 | AN52: 2 | AO52: 2 | AP52: 3 | AQ52: 3 | AR52: 3 | AS52: 3 | AT52: 3 | AU52: 3 | AV52: 3 | AW52: 3 | AX52: 3 | AY52: 3 | AZ52: 3 | BA52: 3 | BB52: 3 | BC52: 3 | BD52: 3 | BE52: 3 | BF52: 3 | BG52: 3 | BH52: 3 | BI52: 3
A53: QUEST | B53: 242583.4 | C53: 511458.8 | D53: 432868.83 | E53: 375369.03 | F53: 422832.73 | G53: 511425.53 | H53: 309640.43 | I53: 511336.97 | J53: 320620.07 | K53: 511480.47 | L53: 407657.6 | M53: 398842.67 | N53: 432325.87 | O53: 511474.07 | P53: 353608.77 | Q53: 511536.37 | R53: 398649.1 | S53: 298060.17 | T53: 410968.9 | U53: 365514.67 | V53: 1226793.4 | W53: 1124995.9 | X53: 1044134.5 | Y53: 831445.13 | Z53: 1221298.9 | AA53: 988639.93 | AB53: 952241.87 | AC53: 1197308.5 | AD53: 1211305.7 | AE53: 1034234.1 | AF53: 1146599.3 | AG53: 1193193.3 | AH53: 1188332.4 | AI53: 925518.93 | AJ53: 1209706.4 | AK53: 1042518.3 | AL53: 1217915.7 | AM53: 925430.97 | AN53: 970326.2 | AO53: 925321.9 | AP53: 10334290 | AQ53: 10734743 | AR53: 11516221 | AS53: 11427512 | AT53: 11546388 | AU53: 11413803 | AV53: 10319681 | AW53: 10785567 | AX53: 12092052 | AY53: 11999240 | AZ53: 10587621 | BA53: 10942126 | BB53: 10559257 | BC53: 10903331 | BD53: 11772388 | BE53: 11271579 | BF53: 10442205 | BG53: 11142933 | BH53: 12504729 | BI53: 11836925
A54: QUEST_NDVFS | B54: 492179.53 | C54: 391560.53 | D54: 492379.07 | E54: 353705.97 | F54: 492488.93 | G54: 391796.9 | H54: 391886.6 | I54: 413395.9 | J54: 492222.4 | K54: 492457.57 | L54: 492085.23 | M54: 492009.5 | N54: 324876.43 | O54: 492470.07 | P54: 489493.1 | Q54: 492286.43 | R54: 391858.2 | S54: 492318.2 | T54: 492468.47 | U54: 379693.5 | V54: 1182218.9 | W54: 1171682.6 | X54: 934283.1 | Y54: 1195191.8 | Z54: 1183940.1 | AA54: 1001757.1 | AB54: 1179993 | AC54: 914359.03 | AD54: 1044367.4 | AE54: 969370.13 | AF54: 1056064.6 | AG54: 1054914.2 | AH54: 1053189.1 | AI54: 996572.6 | AJ54: 1166808.7 | AK54: 1166059.7 | AL54: 1178718.6 | AM54: 1096825.7 | AN54: 1088888.2 | AO54: 1174910.7 | AP54: 11018556 | AQ54: 11216766 | AR54: 10844410 | AS54: 11850526 | AT54: 11311143 | AU54: 11471754 | AV54: 10203964 | AW54: 12485077 | AX54: 11707530 | AY54: 11880901 | AZ54: 10846782 | BA54: 10700581 | BB54: 11106637 | BC54: 10307108 | BD54: 10877452 | BE54: 10500599 | BF54: 11783705 | BG54: 10057105 | BH54: 10903116 | BI54: 11893117
A55: Fuzzy | B55: 492396.53 | C55: 492396.53 | D55: 492396.53 | E55: 492396.53 | F55: 492396.53 | G55: 492396.53 | H55: 492396.53 | I55: 492396.53 | J55: 492396.53 | K55: 492396.53 | L55: 492396.53 | M55: 492396.53 | N55: 492396.53 | O55: 492396.53 | P55: 492396.53 | Q55: 492396.53 | R55: 492396.53 | S55: 492396.53 | T55: 492396.53 | U55: 492396.53 | V55: 1150585.6 | W55: 1150585.6 | X55: 1150585.6 | Y55: 1150585.6 | Z55: 1150585.6 | AA55: 1150585.6 | AB55: 1150585.6 | AC55: 1150585.6 | AD55: 1150585.6 | AE55: 1150585.6 | AF55: 1150585.6 | AG55: 1150585.6 | AH55: 1150585.6 | AI55: 1150585.6 | AJ55: 1150585.6 | AK55: 1150585.6 | AL55: 1150585.6 | AM55: 1150585.6 | AN55: 1150585.6 | AO55: 1150585.6 | AP55: 11889572 | AQ55: 11889572 | AR55: 11889572 | AS55: 11889572 | AT55: 11889572 | AU55: 11889572 | AV55: 11889572 | AW55: 11889572 | AX55: 11889572 | AY55: 11889572 | AZ55: 11889572 | BA55: 11889572 | BB55: 11889572 | BC55: 11889572 | BD55: 11889572 | BE55: 11889572 | BF55: 11889572 | BG55: 11889572 | BH55: 11889572 | BI55: 11889572
A56: NSGA3 | B56: 547706.7 | C56: 536167.47 | D56: 540481.67 | E56: 534755.67 | F56: 522670.73 | G56: 544431.87 | H56: 576343.5 | I56: 513703.57 | J56: 432131.83 | K56: 552100.87 | L56: 530337.3 | M56: 568616.93 | N56: 542952.17 | O56: 530686.37 | P56: 541696.43 | Q56: 523937.97 | R56: 513435.4 | S56: 513209.57 | T56: 531533.7 | U56: 380537.23 | V56: 1251077.5 | W56: 1106496.7 | X56: 1232039.4 | Y56: 1270935.8 | Z56: 1328948.9 | AA56: 1199261.9 | AB56: 1248375.3 | AC56: 1258803.1 | AD56: 1163669.5 | AE56: 1187766.3 | AF56: 1284014.9 | AG56: 1277243.8 | AH56: 1249266.9 | AI56: 1124759.7 | AJ56: 1300832.6 | AK56: 1263217.5 | AL56: 1274123.3 | AM56: 1113599.9 | AN56: 1115971.4 | AO56: 1108593 | AP56: 11622222 | AQ56: 12382543 | AR56: 11230255 | AS56: 12005034 | AT56: 11394585 | AU56: 12594342 | AV56: 11872962 | AW56: 12579467 | AX56: 12277122 | AY56: 12057231 | AZ56: 12298161 | BA56: 12177909 | BB56: 12701716 | BC56: 11524788 | BD56: 12545075 | BE56: 11179285 | BF56: 11150398 | BG56: 11635399 | BH56: 11403659 | BI56: 12325612
A57: MQGA | B57: 499937.3 | C57: 516240.4 | D57: 499416.47 | E57: 500170.93 | F57: 513576.27 | G57: 499980.5 | H57: 499943.1 | I57: 500140.37 | J57: 499888.7 | K57: 516339.43 | L57: 516411.6 | M57: 513564.73 | N57: 513411 | O57: 550044.13 | P57: 513444.27 | Q57: 500133.37 | R57: 500068.3 | S57: 512367.63 | T57: 500786.33 | U57: 513648.43 | V57: 1214657.9 | W57: 1167023.9 | X57: 1088402.6 | Y57: 1228538.1 | Z57: 1227594.4 | AA57: 1233126.1 | AB57: 1060574.1 | AC57: 1187864 | AD57: 1246696 | AE57: 1178461.6 | AF57: 1314699.6 | AG57: 1225990.1 | AH57: 1262478.5 | AI57: 1150613 | AJ57: 1230476.8 | AK57: 1240070.4 | AL57: 1211214.3 | AM57: 1225951.2 | AN57: 1241936.3 | AO57: 1201250.9 | AP57: 12063764 | AQ57: 12232958 | AR57: 12047723 | AS57: 12267878 | AT57: 12018418 | AU57: 12453327 | AV57: 12399677 | AW57: 12213452 | AX57: 11979164 | AY57: 12640504 | AZ57: 12058236 | BA57: 11877054 | BB57: 12339060 | BC57: 11327744 | BD57: 11717559 | BE57: 10907941 | BF57: 12263088 | BG57: 10582015 | BH57: 12406398 | BI57: 12223554
...

Sheet Load Cloud
A1: Algorithm | B1: Load | C1: Average | D1: Min | E1: Max | F1: Std Dev
A2: QUEST | B2: 1 | C2: 2990597.4 | D2: 0 | E2: 8070559 | F2: 2402908.9
A3: QUEST | B3: 2 | C3: 3903562.8 | D3: 0 | E3: 11273036 | F3: 3756682
A4: QUEST | B4: 3 | C4: 35655850 | D4: 1167 | E4: 61216786 | F4: 16926378
A5: QUEST_NDVFS | B5: 1 | C5: 1357891.8 | D5: 0 | E5: 5028293 | F5: 1722675.7
A6: QUEST_NDVFS | B6: 2 | C6: 2595442.4 | D6: 0 | E6: 8162309 | F6: 2696074.3
A7: QUEST_NDVFS | B7: 3 | C7: 33125749 | D7: 0 | E7: 63918194 | F7: 17070028
A8: Fuzzy | B8: 1 | C8: 0 | D8: 0 | E8: 0 | F8: 0
A9: Fuzzy | B9: 2 | C9: 2642 | D9: 2642 | E9: 2642 | F9: 0
A10: Fuzzy | B10: 3 | C10: 2210 | D10: 2210 | E10: 2210 | F10: 0
A11: NSGA3 | B11: 1 | C11: 388080.25 | D11: 0 | E11: 5056961 | F11: 1217707
A12: NSGA3 | B12: 2 | C12: 1157545.1 | D12: 0 | E12: 3928234 | F12: 1752015
A13: NSGA3 | B13: 3 | C13: 11037860 | D13: 342 | E13: 32475527 | F13: 11347692
... A25: RL | B25: 3 | C25: 9666917.7 | D25: 0 | E25: 36902369 | F25: 11022287
A28: Summary by Algorithm
A29: QUEST | C29: 14183337 | D29: 0 | E29: 61216786 | F29: 18242888
A30: QUEST_NDVFS | C30: 12359695 | D30: 0 | E30: 63918194 | F30: 17787932
A31: Fuzzy | C31: 1617.3333 | D31: 0 | E31: 2642 | F31: 1157.1463
A32: NSGA3 | C32: 4194495 | D32: 0 | E32: 32475527 | F32: 8243502.2
A33: MQGA | C33: 2497956.6 | D33: 0 | E33: 42915543 | F33: 7644627.4
A34: Greedy | C34: 2388629.4 | D34: 0 | E34: 28053160 | F34: 5327635.9
A35: MOPSO | C35: 5563276.2 | D35: 0 | E35: 54503043 | F35: 10992417
A36: RL | C36: 3987582.8 | D36: 0 | E36: 36902369 | F36: 7719254.2
A39: Average data for chart
A40: Algorithms | B40: 1 | C40: 2 | D40: 3
A41: QUEST | B41: 2990597.4 | C41: 3903562.8 | D41: 35655850
A42: QUEST_NDVFS | B42: 1357891.8 | C42: 2595442.4 | D42: 33125749
A43: Fuzzy | B43: 0 | C43: 2642 | D43: 2210
A44: NSGA3 | B44: 388080.25 | C44: 1157545.1 | D44: 11037860
A45: MQGA | B45: 4170.3 | C45: 280447.25 | D45: 7209252.2
A46: Greedy | B46: 651985.4 | C46: 1347561 | D46: 5166341.8
A47: MOPSO | B47: 354921.6 | C47: 685530.1 | D47: 15649377
A48: RL | B48: 978364.25 | C48: 1317466.4 | D48: 9666917.7
A51: All data for chart
A52: Algorithms | B52: 1 | C52: 1 | D52: 1 | E52: 1 | F52: 1 | G52: 1 | H52: 1 | I52: 1 | J52: 1 | K52: 1 | L52: 1 | M52: 1 | N52: 1 | O52: 1 | P52: 1 | Q52: 1 | R52: 1 | S52: 1 | T52: 1 | U52: 1 | V52: 2 | W52: 2 | X52: 2 | Y52: 2 | Z52: 2 | AA52: 2 | AB52: 2 | AC52: 2 | AD52: 2 | AE52: 2 | AF52: 2 | AG52: 2 | AH52: 2 | AI52: 2 | AJ52: 2 | AK52: 2 | AL52: 2 | AM52: 2 | AN52: 2 | AO52: 2 | AP52: 3 | AQ52: 3 | AR52: 3 | AS52: 3 | AT52: 3 | AU52: 3 | AV52: 3 | AW52: 3 | AX52: 3 | AY52: 3 | AZ52: 3 | BA52: 3 | BB52: 3 | BC52: 3 | BD52: 3 | BE52: 3 | BF52: 3 | BG52: 3 | BH52: 3 | BI52: 3
A53: QUEST | B53: 8070559 | C53: 0 | D53: 2362326 | E53: 4085535 | F53: 2663667 | G53: 3542 | H53: 6057176 | I53: 9676 | J53: 5744584 | K53: 0 | L53: 3114327 | M53: 3385800 | N53: 2373143 | O53: 0 | P53: 4738259 | Q53: 0 | R53: 3389984 | S53: 6409959 | T53: 3019234 | U53: 4384176 | V53: 11859 | W53: 2457718 | X53: 5006150 | Y53: 11273036 | Z53: 7609 | AA53: 6708192 | AB53: 7476552 | AC53: 2693 | AD53: 0 | AE53: 5020309 | AF53: 2042450 | AG53: 31185 | AH53: 2642 | AI53: 8748659 | AJ53: 0 | AK53: 5006150 | AL53: 1025 | AM53: 8568559 | AN53: 7550176 | AO53: 8156292 | AP53: 61216786 | AQ53: 45272744 | AR53: 28348926 | AS53: 33088402 | AT53: 29569276 | AU53: 27899643 | AV53: 61092110 | AW53: 52628185 | AX53: 10833817 | AY53: 16955959 | AZ53: 43503718 | BA53: 45366043 | BB53: 53321528 | BC53: 45312211 | BD53: 17783434 | BE53: 32475359 | BF53: 55700636 | BG53: 36120801 | BH53: 1167 | BI53: 16626251
A54: QUEST_NDVFS | B54: 9909 | C54: 3025076 | D54: 0 | E54: 4165251 | F54: 0 | G54: 3021201 | H54: 3019234 | I54: 2369577 | J54: 6892 | K54: 0 | L54: 6792 | M54: 10767 | N54: 5028293 | O54: 0 | P54: 86267 | Q54: 3542 | R54: 3019234 | S54: 0 | T54: 0 | U54: 3385800 | V54: 29909 | W54: 2000 | X54: 7369218 | Y54: 1025 | Z54: 12851 | AA54: 5085426 | AB54: 84 | AC54: 8162309 | AD54: 3922150 | AE54: 6187644 | AF54: 3743034 | AG54: 3747617 | AH54: 3925218 | AI54: 5006150 | AJ54: 2159 | AK54: 0 | AL54: 0 | AM54: 2458927 | AN54: 2251917 | AO54: 1209 | AP54: 36092726 | AQ54: 33081443 | AR54: 36275344 | AS54: 13445894 | AT54: 27067627 | AU54: 26183026 | AV54: 60264011 | AW54: 0 | AX54: 21462277 | AY54: 12223417 | AZ54: 36804327 | BA54: 46618453 | BB54: 31674594 | BC54: 60843071 | BD54: 41020086 | BE54: 46017011 | BF54: 15098177 | BG54: 63918194 | BH54: 41221676 | BI54: 13203635
A55: Fuzzy | B55: 0 | C55: 0 | D55: 0 | E55: 0 | F55: 0 | G55: 0 | H55: 0 | I55: 0 | J55: 0 | K55: 0 | L55: 0 | M55: 0 | N55: 0 | O55: 0 | P55: 0 | Q55: 0 | R55: 0 | S55: 0 | T55: 0 | U55: 0 | V55: 2642 | W55: 2642 | X55: 2642 | Y55: 2642 | Z55: 2642 | AA55: 2642 | AB55: 2642 | AC55: 2642 | AD55: 2642 | AE55: 2642 | AF55: 2642 | AG55: 2642 | AH55: 2642 | AI55: 2642 | AJ55: 2642 | AK55: 2642 | AL55: 2642 | AM55: 2642 | AN55: 2642 | AO55: 2642 | AP55: 2210 | AQ55: 2210 | AR55: 2210 | AS55: 2210 | AT55: 2210 | AU55: 2210 | AV55: 2210 | AW55: 2210 | AX55: 2210 | AY55: 2210 | AZ55: 2210 | BA55: 2210 | BB55: 2210 | BC55: 2210 | BD55: 2210 | BE55: 2210 | BF55: 2210 | BG55: 2210 | BH55: 2210 | BI55: 2210
A56: NSGA3 | B56: 0 | C56: 0 | D56: 2717 | E56: 10792 | F56: 0 | G56: 0 | H56: 0 | I56: 0 | J56: 2663667 | K56: 9909 | L56: 4184 | M56: 0 | N56: 0 | O56: 0 | P56: 2950 | Q56: 10425 | R56: 0 | S56: 0 | T56: 0 | U56: 5056961 | V56: 6318 | W56: 3558050 | X56: 22592 | Y56: 12901 | Z56: 2117 | AA56: 0 | AB56: 7334 | AC56: 10834 | AD56: 3918817 | AE56: 84 | AF56: 16642 | AG56: 38151 | AH56: 7267 | AI56: 3924567 | AJ56: 16059 | AK56: 0 | AL56: 23242 | AM56: 3928234 | AN56: 3917300 | AO56: 3740392 | AP56: 25573084 | AQ56: 10034 | AR56: 32475527 | AS56: 11825284 | AT56: 19476660 | AU56: 2668 | AV56: 13788768 | AW56: 759 | AX56: 3493 | AY56: 10835719 | AZ56: 1268 | BA56: 1034 | BB56: 526 | BC56: 19547601 | BD56: 4786 | BE56: 28079701 | BF56: 28177086 | BG56: 11404568 | BH56: 19548285 | BI56: 342
A57: MQGA | B57: 84 | C57: 7726 | D57: 20201 | E57: 0 | F57: 0 | G57: 1967 | H57: 5842 | I57: 0 | J57: 6859 | K57: 6792 | L57: 2717 | M57: 0 | N57: 4925 | O57: 0 | P57: 0 | Q57: 0 | R57: 5842 | S57: 6092 | T57: 0 | U57: 14359 | V57: 84 | W57: 1317 | X57: 2253534 | Y57: 12343 | Z57: 34827 | AA57: 25842 | AB57: 3162659 | AC57: 0 | AD57: 7576 | AE57: 9809 | AF57: 7267 | AG57: 4359 | AH57: 38559 | AI57: 0 | AJ57: 0 | AK57: 37042 | AL57: 1517 | AM57: 1317 | AN57: 7376 | AO57: 3517 | AP57: 11824184 | AQ57: 1544 | AR57: 1951 | AS57: 275 | AT57: 1467 | AU57: 1050 | AV57: 2435 | AW57: 28959 | AX57: 2959 | AY57: 442 | AZ57: 1334 | BA57: 15098352 | BB57: 2751 | BC57: 16125026 | BD57: 12222917 | BE57: 32748310 | BF57: 13203627 | BG57: 42915543 | BH57: 509 | BI57: 1410
...

Sheet Loads
A1: Average data for chart
B2: Edge | C2: Edge | D2: Edge | E2: Edge | F2: Edge | G2: Edge | H2: Edge | I2: Edge | J2: Edge | K2: Edge | L2: Edge | M2: Edge | N2: Edge | O2: Edge | P2: Edge | Q2: Edge | R2: Edge | S2: Edge | T2: Edge | U2: Edge | V2: Edge | W2: Edge | X2: Edge | Y2: Edge | Z2: Edge | AA2: Edge | AB2: Edge | AC2: Edge | AD2: Edge | AE2: Edge | AF2: Cloud | AG2: Edge | AH2: Edge | AI2: Edge | AJ2: Edge | AK2: Edge | AL2: Edge | AM2: Edge | AN2: Edge | AO2: Edge | AP2: Edge | AQ2: Edge | AR2: Edge | AS2: Edge | AT2: Edge | AU2: Edge | AV2: Edge | AW2: Edge | AX2: Edge | AY2: Edge | AZ2: Edge | BA2: Edge | BB2: Edge | BC2: Edge | BD2: Edge | BE2: Edge | BF2: Edge | BG2: Edge | BH2: Edge | BI2: Edge | BJ2: Edge | BK2: Cloud | BL2: Edge | BM2: Edge | BN2: Edge | BO2: Edge | BP2: Edge | BQ2: Edge | BR2: Edge | BS2: Edge | BT2: Edge | BU2: Edge | BV2: Edge | BW2: Edge | BX2: Edge | BY2: Edge | BZ2: Edge | CA2: Edge | CB2: Edge | CC2: Edge | CD2: Edge | CE2: Edge | CF2: Edge | CG2: Edge | CH2: Edge | CI2: Edge | CJ2: Edge | CK2: Edge | CL2: Edge | CM2: Edge | CN2: Edge | CO2: Edge | CP2: Cloud
B3: 1 | C3: 1 | D3: 1 | E3: 1 | F3: 1 | G3: 1 | H3: 1 | I3: 1 | J3: 1 | K3: 1 | L3: 1 | M3: 1 | N3: 1 | O3: 1 | P3: 1 | Q3: 1 | R3: 1 | S3: 1 | T3: 1 | U3: 1 | V3: 1 | W3: 1 | X3: 1 | Y3: 1 | Z3: 1 | AA3: 1 | AB3: 1 | AC3: 1 | AD3: 1 | AE3: 1 | AF3: 1 | AG3: 2 | AH3: 2 | AI3: 2 | AJ3: 2 | AK3: 2 | AL3: 2 | AM3: 2 | AN3: 2 | AO3: 2 | AP3: 2 | AQ3: 2 | AR3: 2 | AS3: 2 | AT3: 2 | AU3: 2 | AV3: 2 | AW3: 2 | AX3: 2 | AY3: 2 | AZ3: 2 | BA3: 2 | BB3: 2 | BC3: 2 | BD3: 2 | BE3: 2 | BF3: 2 | BG3: 2 | BH3: 2 | BI3: 2 | BJ3: 2 | BK3: 2 | BL3: 3 | BM3: 3 | BN3: 3 | BO3: 3 | BP3: 3 | BQ3: 3 | BR3: 3 | BS3: 3 | BT3: 3 | BU3: 3 | BV3: 3 | BW3: 3 | BX3: 3 | BY3: 3 | BZ3: 3 | CA3: 3 | CB3: 3 | CC3: 3 | CD3: 3 | CE3: 3 | CF3: 3 | CG3: 3 | CH3: 3 | CI3: 3 | CJ3: 3 | CK3: 3 | CL3: 3 | CM3: 3 | CN3: 3 | CO3: 3 | CP3: 3
A4: Algorithms | B4: 1 | C4: 2 | D4: 3 | E4: 4 | F4: 5 | G4: 6 | H4: 7 | I4: 8 | J4: 9 | K4: 10 | L4: 11 | M4: 12 | N4: 13 | O4: 14 | P4: 15 | Q4: 16 | R4: 17 | S4: 18 | T4: 19 | U4: 20 | V4: 21 | W4: 22 | X4: 23 | Y4: 24 | Z4: 25 | AA4: 26 | AB4: 27 | AC4: 28 | AD4: 29 | AE4: 30 | AF4: 31 | AG4: 1 | AH4: 2 | AI4: 3 | AJ4: 4 | AK4: 5 | AL4: 6 | AM4: 7 | AN4: 8 | AO4: 9 | AP4: 10 | AQ4: 11 | AR4: 12 | AS4: 13 | AT4: 14 | AU4: 15 | AV4: 16 | AW4: 17 | AX4: 18 | AY4: 19 | AZ4: 20 | BA4: 21 | BB4: 22 | BC4: 23 | BD4: 24 | BE4: 25 | BF4: 26 | BG4: 27 | BH4: 28 | BI4: 29 | BJ4: 30 | BK4: 31 | BL4: 1 | BM4: 2 | BN4: 3 | BO4: 4 | BP4: 5 | BQ4: 6 | BR4: 7 | BS4: 8 | BT4: 9 | BU4: 10 | BV4: 11 | BW4: 12 | BX4: 13 | BY4: 14 | BZ4: 15 | CA4: 16 | CB4: 17 | CC4: 18 | CD4: 19 | CE4: 20 | CF4: 21 | CG4: 22 | CH4: 23 | CI4: 24 | CJ4: 25 | CK4: 26 | CL4: 27 | CM4: 28 | CN4: 29 | CO4: 30 | CP4: 31
A5: QUEST | B5: 524909.29 | C5: 776551.1 | D5: 625312.19 | E5: 733517.19 | F5: 534232.23 | G5: 446490.84 | H5: 87914.452 | I5: 650524.71 | J5: 455242.74 | K5: 457802.84 | L5: 556261.52 | M5: 529955.87 | N5: 533274.42 | O5: 332711.55 | P5: 696328.52 | Q5: 2233.871 | R5: 2142.2581 | S5: 5841.9355 | T5: 2963.2258 | U5: 2436.7742 | V5: 1700.9677 | W5: 2800.9677 | X5: 828.06452 | Y5: 1484.8387 | Z5: 1891.6129 | AA5: 1822.5806 | AB5: 592.58065 | AC5: 1035.8065 | AD5: 2241.6129 | AE5: 1457.7419 | AF5: 1929417.6 | AG5: 1285824.7 | AH5: 1286456.2 | AI5: 1363000.9 | AJ5: 1004341 | AK5: 1192002.7 | AL5: 1103252.5 | AM5: 1220970.5 | AN5: 981578.26 | AO5: 1333973.9 | AP5: 467198.19 | AQ5: 929190.35 | AR5: 1446205 | AS5: 1209830.8 | AT5: 697002.48 | AU5: 1415791.8 | AV5: 97645.806 | AW5: 146974.19 | AX5: 92089.355 | AY5: 352234.1 | AZ5: 182115.39 | BA5: 320422.26 | BB5: 338263.87 | BC5: 182883.03 | BD5: 404168.94 | BE5: 214081.84 | BF5: 559274.19 | BG5: 3613.2258 | BH5: 421002.58 | BI5: 82286.129 | BJ5: 547546.13 | BK5: 2518427.6 | BL5: 4778418.9 | BM5: 5707113.5 | BN5: 4561479.9 | BO5: 6536399.7 | BP5: 5564693.7 | BQ5: 5074163.5 | BR5: 5693612.3 | BS5: 5222802.6 | BT5: 6013993.8 | BU5: 8458467.9 | BV5: 5997824 | BW5: 6408813.1 | BX5: 8495804.3 | BY5: 5871175.5 | BZ5: 5973366.5 | CA5: 6073721.3 | CB5: 7401450.3 | CC5: 11937184 | CD5: 8798533.5 | CE5: 7926051.3 | CF5: 9914187.4 | CG5: 8639044.5 | CH5: 7360302.3 | CI5: 7529843.9 | CJ5: 6906982 | CK5: 8413408.1 | CL5: 10166459 | CM5: 9061564.4 | CN5: 7259018.6 | CO5: 9156630.5 | CP5: 23003774
A6: QUEST_NDVFS | B6: 524695.68 | C6: 703422 | D6: 628147.03 | E6: 579988.16 | F6: 382533.03 | G6: 884590.03 | H6: 467515.58 | I6: 422906.71 | J6: 393607.87 | K6: 705657.94 | L6: 724074.81 | M6: 544985.48 | N6: 467003.97 | O6: 714008.1 | P6: 486828.65 | Q6: 1704.1935 | R6: 1275.8065 | S6: 1600 | T6: 2230 | U6: 1509.3548 | V6: 646.12903 | W6: 1230.6452 | X6: 1427.0968 | Y6: 2672.2581 | Z6: 1594.1935 | AA6: 1386.129 | AB6: 1163.2258 | AC6: 1560.3226 | AD6: 3002.5806 | AE6: 2161.2903 | AF6: 876059.19 | AG6: 888056.81 | AH6: 1002166.7 | AI6: 758424.9 | AJ6: 1084902.9 | AK6: 791716.29 | AL6: 1736084.5 | AM6: 1126888 | AN6: 1915998.2 | AO6: 1547119.1 | AP6: 951811.9 | AQ6: 1279044.8 | AR6: 1076189.5 | AS6: 998350.61 | AT6: 1202034.5 | AU6: 1615848.9 | AV6: 124694.52 | AW6: 272859.03 | AX6: 145929.03 | AY6: 206911.61 | AZ6: 91807.097 | BA6: 97994.839 | BB6: 622044.19 | BC6: 407601.61 | BD6: 79341.613 | BE6: 202490.32 | BF6: 397576.45 | BG6: 147595.16 | BH6: 201456.45 | BI6: 5908.0645 | BJ6: 127715.48 | BK6: 1674478.9 | BL6: 8678361.8 | BM6: 3276075 | BN6: 4969107.7 | BO6: 5514093.3 | BP6: 6534001.7 | BQ6: 6148489.5 | BR6: 7995905.1 | BS6: 6660745.4 | BT6: 7566371.8 | BU6: 5039270.6 | BV6: 8559434.4 | BW6: 4952338.1 | BX6: 5900534.3 | BY6: 6573608 | BZ6: 5822492.7 | CA6: 8762474.8 | CB6: 8764346.8 | CC6: 7202557.1 | CD6: 6532944.2 | CE6: 7955699.4 | CF6: 7474771 | CG6: 8665083.2 | CH6: 7478875.8 | CI6: 8456445.5 | CJ6: 10422838 | CK6: 6848441.9 | CL6: 10489014 | CM6: 9143836.5 | CN6: 7427481.3 | CO6: 5958712.3 | CP6: 21371451
A7: Fuzzy | B7: 2184387.1 | C7: 1947892.9 | D7: 1718494.8 | E7: 1521796.1 | F7: 1303930.3 | G7: 739365.81 | H7: 55656.129 | I7: 9263.871 | J7: 6392.9032 | K7: 4973.5484 | L7: 4425.1613 | M7: 4381.9355 | N7: 3769.0323 | O7: 3177.4194 | P7: 2774.1935 | Q7: 3238.7097 | R7: 3045.1613 | S7: 2741.9355 | T7: 2600 | U7: 2283.871 | V7: 2103.2258 | W7: 1974.1935 | X7: 1522.5806 | Y7: 64.516129 | Z7: 0 | AA7: 0 | AB7: 0 | AC7: 0 | AD7: 0 | AE7: 0 | AF7: 0 | AG7: 3231441.3 | AH7: 2528903.2 | AI7: 2453307.1 | AJ7: 2414521.9 | AK7: 2296833.5 | AL7: 2033640 | AM7: 2007038.1 | AN7: 1585161.9 | AO7: 1453204.5 | AP7: 1249549 | AQ7: 879392.9 | AR7: 24801.29 | AS7: 16065.161 | AT7: 14505.806 | AU7: 8736.7742 | AV7: 8529.0323 | AW7: 7212.9032 | AX7: 7206.4516 | AY7: 7154.8387 | AZ7: 5890.3226 | BA7: 5625.8065 | BB7: 5593.5484 | BC7: 3754.8387 | BD7: 3664.5161 | BE7: 3554.8387 | BF7: 3535.4839 | BG7: 3374.1935 | BH7: 2722.5806 | BI7: 2303.2258 | BJ7: 2174.1935 | BK7: 1704.5161 | BL7: 12674023 | BM7: 12611941 | BN7: 11473909 | BO7: 10940404 | BP7: 10726711 | BQ7: 10675210 | BR7: 10403152 | BS7: 9740431 | BT7: 9709425.2 | BU7: 9408973.5 | BV7: 8894935.5 | BW7: 8675065.2 | BX7: 8517200 | BY7: 8341102.6 | BZ7: 7886479.4 | CA7: 9155058.1 | CB7: 9124877.4 | CC7: 8829071 | CD7: 8716083.9 | CE7: 8621445.2 | CF7: 8473258.1 | CG7: 8387948.4 | CH7: 7454780.6 | CI7: 6606148.4 | CJ7: 4036096.8 | CK7: 22974.194 | CL7: 7580.6452 | CM7: 2632.2581 | CN7: 2045.1613 | CO7: 1793.5484 | CP7: 1425.8065
