Workbook

Sheet Charts
R2: AoI | S2: 25 | T2: 50 | U2: 100
R3: QUEST | S3: ='Data Age'!B41 -> 8093.2096 | T3: ='Data Age'!C41 -> 10255.682 | U3: ='Data Age'!D41 -> 14859.628
R4: QUEST_NDVFS | S4: ='Data Age'!B42 -> 7614.0596 | T4: ='Data Age'!C42 -> 9219.7627 | U4: ='Data Age'!D42 -> 10853.409
R5: Fuzzy | S5: ='Data Age'!B43 -> 8637.2692 | T5: ='Data Age'!C43 -> 10570.476 | U5: ='Data Age'!D43 -> 15764.343
R6: NSGA3 | S6: ='Data Age'!B44 -> 9046.3404 | T6: ='Data Age'!C44 -> 11226.836 | U6: ='Data Age'!D44 -> 17982.884
R7: MQGA | S7: ='Data Age'!B45 -> 8776.3962 | T7: ='Data Age'!C45 -> 10882.539 | U7: ='Data Age'!D45 -> 17683.282
R8: Greedy | S8: ='Data Age'!B46 -> 9034.9769 | T8: ='Data Age'!C46 -> 10935.005 | U8: ='Data Age'!D46 -> 17992.358
R9: MOPSO | S9: ='Data Age'!B47 -> 9166.4577 | T9: ='Data Age'!C47 -> 10367.643 | U9: ='Data Age'!D47 -> 17791.538
R10: RL | S10: ='Data Age'!B48 -> 9074.3192 | T10: ='Data Age'!C48 -> 10883.372 | U10: ='Data Age'!D48 -> 18196.268
R17: AoI | S17: 25 | T17: 50 | U17: 100
R18: QUEST | S18: =S3/S3 -> 1 | T18: =T3/T3 -> 1 | U18: =U3/U3 -> 1
R19: QUEST_NDVFS | S19: =S4/S3 -> 0.94079605 | T19: =T4/T3 -> 0.89899067 | U19: =U4/U3 -> 0.73039578
R20: Fuzzy | S20: =S5/S3 -> 1.0672242 | T20: =T5/T3 -> 1.0306946 | U20: =U5/U3 -> 1.0608841
R21: NSGA3 | S21: =S6/S3 -> 1.1177692 | T21: =T6/T3 -> 1.0946942 | U21: =U6/U3 -> 1.210184
R22: MQGA | S22: =S7/S3 -> 1.0844148 | T22: =T7/T3 -> 1.0611229 | U22: =U7/U3 -> 1.1900219
R23: Greedy | S23: =S8/S3 -> 1.1163651 | T23: =T8/T3 -> 1.0662386 | U23: =U8/U3 -> 1.2108216
R24: MOPSO | S24: =S9/S3 -> 1.1326109 | T24: =T9/T3 -> 1.010917 | U24: =U9/U3 -> 1.1973071
R25: RL | S25: =S10/S3 -> 1.1212263 | T25: =T10/T3 -> 1.061204 | U25: =U10/U3 -> 1.224544
R36: Energy | S36: 25 | T36: 50 | U36: 100
R37: QUEST | S37: =Energy!B41 -> 30024885 | T37: =Energy!C41 -> 38003453 | U37: =Energy!D41 -> 52884091
R38: QUEST_NDVFS | S38: =Energy!B42 -> 30410960 | T38: =Energy!C42 -> 40929850 | U38: =Energy!D42 -> 63729865
R39: Fuzzy | S39: =Energy!B43 -> 31032453 | T39: =Energy!C43 -> 48278536 | U39: =Energy!D43 -> 69934569
R40: NSGA3 | S40: =Energy!B44 -> 36148971 | T40: =Energy!C44 -> 50113689 | U40: =Energy!D44 -> 80452122
R41: MQGA | S41: =Energy!B45 -> 31885094 | T41: =Energy!C45 -> 47756167 | U41: =Energy!D45 -> 75574324
R42: Greedy | S42: =Energy!B46 -> 35808293 | T42: =Energy!C46 -> 49681987 | U42: =Energy!D46 -> 81191819
R43: MOPSO | S43: =Energy!B47 -> 34167956 | T43: =Energy!C47 -> 50503172 | U43: =Energy!D47 -> 80039993
R44: RL | S44: =Energy!B48 -> 36517745 | T44: =Energy!C48 -> 49490369 | U44: =Energy!D48 -> 83468504
R51: Energy | S51: 25 | T51: 50 | U51: 100
R52: QUEST | S52: =S37/S37 -> 1 | T52: =T37/T37 -> 1 | U52: =U37/U37 -> 1
R53: QUEST_NDVFS | S53: =S38/S37 -> 1.0128585 | T53: =T38/T37 -> 1.0770035 | U53: =U38/U37 -> 1.2050858
R54: Fuzzy | S54: =S39/S37 -> 1.0335578 | T54: =T39/T37 -> 1.2703723 | U54: =U39/U37 -> 1.3224122
R55: NSGA3 | S55: =S40/S37 -> 1.203967 | T55: =T40/T37 -> 1.3186614 | U55: =U40/U37 -> 1.5212916
R56: MQGA | S56: =S41/S37 -> 1.0619556 | T56: =T41/T37 -> 1.256627 | U56: =U41/U37 -> 1.4290559
R57: Greedy | S57: =S42/S37 -> 1.1926205 | T57: =T42/T37 -> 1.3073019 | U57: =U42/U37 -> 1.5352787
R58: MOPSO | S58: =S43/S37 -> 1.1379879 | T58: =T43/T37 -> 1.3289101 | U58: =U43/U37 -> 1.5134985
R59: RL | S59: =S44/S37 -> 1.2162493 | T59: =T44/T37 -> 1.3022598 | U59: =U44/U37 -> 1.5783292
R67: Makespan | S67: 25 | T67: 50 | U67: 100
R68: QUEST | S68: =Makespan!B41 -> 43353.6 | T68: =Makespan!C41 -> 55803.1 | U68: =Makespan!D41 -> 87358.75
R69: QUEST_NDVFS | S69: =Makespan!B42 -> 42950.4 | T69: =Makespan!C42 -> 56617 | U69: =Makespan!D42 -> 85796.35
R70: Fuzzy | S70: =Makespan!B43 -> 43653.5 | T70: =Makespan!C43 -> 61972.9 | U70: =Makespan!D43 -> 91590.6
...

Sheet Data Age
A1: Algorithm | B1: Load | C1: Average | D1: Min | E1: Max | F1: Std Dev
A2: QUEST | B2: 1 | C2: 8093.2096 | D2: 7739.7308 | E2: 8520.6923 | F2: 175.29206
A3: QUEST | B3: 2 | C3: 10255.682 | D3: 9602.0784 | E3: 12027.314 | F3: 594.37608
A4: QUEST | B4: 3 | C4: 14859.628 | D4: 12582.168 | E4: 15561.05 | F4: 645.76112
A5: QUEST_NDVFS | B5: 1 | C5: 7614.0596 | D5: 7534.2692 | E5: 7673.3846 | F5: 34.701057
A6: QUEST_NDVFS | B6: 2 | C6: 9219.7627 | D6: 9119 | E6: 9305.4118 | F6: 50.991367
A7: QUEST_NDVFS | B7: 3 | C7: 10853.409 | D7: 10558.119 | E7: 11152.356 | F7: 156.04616
A8: Fuzzy | B8: 1 | C8: 7637.2692 | D8: 7637.2692 | E8: 7637.2692 | F8: 0
A9: Fuzzy | B9: 2 | C9: 9570.4765 | D9: 9569.4902 | E9: 9571.549 | F9: 0.61598282
A10: Fuzzy | B10: 3 | C10: 10764.343 | D10: 10763.178 | E10: 10765.743 | F10: 0.64586242
A11: NSGA3 | B11: 1 | C11: 8446.3404 | D11: 8037.7692 | E11: 9259.4231 | F11: 335.86239
A12: NSGA3 | B12: 2 | C12: 10226.836 | D12: 9519.8235 | E12: 11268.353 | F12: 487.40963
A13: NSGA3 | B13: 3 | C13: 12982.884 | D13: 11796.347 | E13: 14505.04 | F13: 712.45972
... A25: RL | B25: 3 | C25: 13196.268 | D25: 11780.416 | E25: 14220.792 | F25: 667.88275
A28: Summary by Algorithm
A29: QUEST | C29: 11069.507 | D29: 7739.7308 | E29: 15561.05 | F29: 2868.6053
A30: QUEST_NDVFS | C30: 9229.0773 | D30: 7534.2692 | E30: 11152.356 | F30: 1326.0189
A31: Fuzzy | C31: 9324.0296 | D31: 7637.2692 | E31: 10765.743 | F31: 1288.4617
A32: NSGA3 | C32: 10552.02 | D32: 8037.7692 | E32: 14505.04 | F32: 1941.3655
A33: MQGA | C33: 10114.073 | D33: 7621.9615 | E33: 13234.644 | F33: 2027.7828
A34: Greedy | C34: 10487.447 | D34: 7829.3077 | E34: 14245.495 | F34: 1958.5888
A35: MOPSO | C35: 10441.879 | D35: 7824.6154 | E35: 14272.059 | F35: 1944.5555
A36: RL | C36: 10617.986 | D36: 7811.9231 | E36: 14220.792 | F36: 2026.8996
A39: Average data for chart
A40: Algorithms | B40: 1 | C40: 2 | D40: 3
A41: QUEST | B41: 8093.2096 | C41: 10255.682 | D41: 14859.628
A42: QUEST_NDVFS | B42: 7614.0596 | C42: 9219.7627 | D42: 10853.409
A43: Fuzzy | B43: 8637.2692 | C43: 10570.476 | D43: 15764.343
A44: NSGA3 | B44: 9046.3404 | C44: 11226.836 | D44: 17982.884
A45: MQGA | B45: 8776.3962 | C45: 10882.539 | D45: 17683.282
A46: Greedy | B46: 9034.9769 | C46: 10935.005 | D46: 17992.358
A47: MOPSO | B47: 9166.4577 | C47: 10367.643 | D47: 17791.538
A48: RL | B48: 9074.3192 | C48: 10883.372 | D48: 18196.268
A51: All data for chart
A52: Algorithms | B52: 1 | C52: 1 | D52: 1 | E52: 1 | F52: 1 | G52: 1 | H52: 1 | I52: 1 | J52: 1 | K52: 1 | L52: 1 | M52: 1 | N52: 1 | O52: 1 | P52: 1 | Q52: 1 | R52: 1 | S52: 1 | T52: 1 | U52: 1 | V52: 2 | W52: 2 | X52: 2 | Y52: 2 | Z52: 2 | AA52: 2 | AB52: 2 | AC52: 2 | AD52: 2 | AE52: 2 | AF52: 2 | AG52: 2 | AH52: 2 | AI52: 2 | AJ52: 2 | AK52: 2 | AL52: 2 | AM52: 2 | AN52: 2 | AO52: 2 | AP52: 3 | AQ52: 3 | AR52: 3 | AS52: 3 | AT52: 3 | AU52: 3 | AV52: 3 | AW52: 3 | AX52: 3 | AY52: 3 | AZ52: 3 | BA52: 3 | BB52: 3 | BC52: 3 | BD52: 3 | BE52: 3 | BF52: 3 | BG52: 3 | BH52: 3 | BI52: 3
A53: QUEST | B53: 8242.0769 | C53: 8067.9615 | D53: 8159.6154 | E53: 8096.4615 | F53: 8145.3846 | G53: 8171.6923 | H53: 8520.6923 | I53: 8214.3077 | J53: 7865.9615 | K53: 8231.9231 | L53: 7911.6923 | M53: 7949.4615 | N53: 8231.4615 | O53: 8176.5 | P53: 8172.5 | Q53: 7793.7692 | R53: 8015.7308 | S53: 8118.4231 | T53: 8038.8462 | U53: 7739.7308 | V53: 9845.3922 | W53: 11411.118 | X53: 9992.8824 | Y53: 10026.451 | Z53: 10002.373 | AA53: 12027.314 | AB53: 10759 | AC53: 10018.098 | AD53: 10116.471 | AE53: 10115.863 | AF53: 10092.216 | AG53: 9876.9804 | AH53: 9972.902 | AI53: 9934.0588 | AJ53: 9878.4314 | AK53: 9602.0784 | AL53: 9948.6275 | AM53: 10251.353 | AN53: 11170.941 | AO53: 10071.098 | AP53: 14904 | AQ53: 15075.109 | AR53: 15058.554 | AS53: 14776.723 | AT53: 15561.05 | AU53: 15398.465 | AV53: 14928.337 | AW53: 15478.218 | AX53: 14661.198 | AY53: 12582.168 | AZ53: 15186.109 | BA53: 15505.02 | BB53: 14581.802 | BC53: 14860.297 | BD53: 14366.129 | BE53: 15344.723 | BF53: 14660.713 | BG53: 14326.772 | BH53: 14508.703 | BI53: 15428.465
A54: QUEST_NDVFS | B54: 7672.6154 | C54: 7534.2692 | D54: 7590.2308 | E54: 7615.3462 | F54: 7645.0769 | G54: 7599.1538 | H54: 7610.6538 | I54: 7655.7692 | J54: 7589.4615 | K54: 7643.9231 | L54: 7610.3077 | M54: 7637.1538 | N54: 7673.3846 | O54: 7575.6538 | P54: 7621.7308 | Q54: 7613.3846 | R54: 7638.1923 | S54: 7581.2692 | T54: 7603.2692 | U54: 7570.3462 | V54: 9195.0588 | W54: 9254.7451 | X54: 9230.3529 | Y54: 9254.2941 | Z54: 9126.2549 | AA54: 9195.4314 | AB54: 9157.7843 | AC54: 9228.1176 | AD54: 9150.4902 | AE54: 9207.9216 | AF54: 9262.549 | AG54: 9305.4118 | AH54: 9219.2941 | AI54: 9297.1373 | AJ54: 9219.1765 | AK54: 9196.9608 | AL54: 9272.4902 | AM54: 9257.3137 | AN54: 9119 | AO54: 9245.4706 | AP54: 11152.356 | AQ54: 10690.901 | AR54: 10788.545 | AS54: 10949.891 | AT54: 10948.238 | AU54: 10955.634 | AV54: 11052.03 | AW54: 10989.634 | AX54: 10869.644 | AY54: 10874.802 | AZ54: 10763.653 | BA54: 10822.782 | BB54: 10768.505 | BC54: 10849.713 | BD54: 10558.119 | BE54: 10687.238 | BF54: 10703.485 | BG54: 10932.337 | BH54: 10610.594 | BI54: 11100.089
A55: Fuzzy | B55: 7637.2692 | C55: 7637.2692 | D55: 7637.2692 | E55: 7637.2692 | F55: 7637.2692 | G55: 7637.2692 | H55: 7637.2692 | I55: 7637.2692 | J55: 7637.2692 | K55: 7637.2692 | L55: 7637.2692 | M55: 7637.2692 | N55: 7637.2692 | O55: 7637.2692 | P55: 7637.2692 | Q55: 7637.2692 | R55: 7637.2692 | S55: 7637.2692 | T55: 7637.2692 | U55: 7637.2692 | V55: 9571.1569 | W55: 9570.5294 | X55: 9569.4902 | Y55: 9569.6471 | Z55: 9570.3922 | AA55: 9570.9412 | AB55: 9569.9216 | AC55: 9570.8431 | AD55: 9569.5098 | AE55: 9569.9804 | AF55: 9571.5098 | AG55: 9571.0588 | AH55: 9570.7255 | AI55: 9570.4902 | AJ55: 9570.3922 | AK55: 9570.6471 | AL55: 9569.902 | AM55: 9569.8627 | AN55: 9570.9804 | AO55: 9571.549 | AP55: 10764.059 | AQ55: 10765.208 | AR55: 10764.653 | AS55: 10763.178 | AT55: 10765.188 | AU55: 10764.386 | AV55: 10765.743 | AW55: 10764.03 | AX55: 10764.465 | AY55: 10764.891 | AZ55: 10763.782 | BA55: 10763.95 | BB55: 10763.693 | BC55: 10764.941 | BD55: 10764.04 | BE55: 10764.307 | BF55: 10763.782 | BG55: 10765.03 | BH55: 10763.465 | BI55: 10764.069
A56: NSGA3 | B56: 8119.2692 | C56: 8713.8846 | D56: 8323.6538 | E56: 8375.6154 | F56: 9259.4231 | G56: 8362.7692 | H56: 8810.6154 | I56: 8037.7692 | J56: 8309.8846 | K56: 8049.4615 | L56: 8299.0385 | M56: 8383.2692 | N56: 8262.9615 | O56: 8331.5769 | P56: 8044.1923 | Q56: 8362.1538 | R56: 9158.5 | S56: 8805.6923 | T56: 8324.8846 | U56: 8592.1923 | V56: 9719.2549 | W56: 10833.49 | X56: 9787.8627 | Y56: 10191.235 | Z56: 9735.6078 | AA56: 11268.353 | AB56: 11092.588 | AC56: 9519.8235 | AD56: 10098.275 | AE56: 10538.471 | AF56: 10139.843 | AG56: 10431.373 | AH56: 10755.412 | AI56: 10174.549 | AJ56: 9816.5294 | AK56: 9541.0196 | AL56: 10022.941 | AM56: 9916.9608 | AN56: 10547.549 | AO56: 10405.588 | AP56: 12559.208 | AQ56: 14403.287 | AR56: 12903.802 | AS56: 12917.208 | AT56: 12318.673 | AU56: 14505.04 | AV56: 11796.347 | AW56: 14008.327 | AX56: 13366.05 | AY56: 13293.673 | AZ56: 12568.95 | BA56: 12848.782 | BB56: 12210.653 | BC56: 11972.96 | BD56: 12557.139 | BE56: 13576.564 | BF56: 12804.03 | BG56: 13260.05 | BH56: 12991.683 | BI56: 12795.248
A57: MQGA | B57: 7705.0769 | C57: 7621.9615 | D57: 7750 | E57: 7833.8846 | F57: 7904.3462 | G57: 7746.0769 | H57: 8184.4231 | I57: 7681 | J57: 7867.1538 | K57: 7741.2692 | L57: 7763.0385 | M57: 7717.4615 | N57: 7681.3462 | O57: 7815.1923 | P57: 7709.6923 | Q57: 7707.1538 | R57: 7704.4615 | S57: 7762.6154 | T57: 7773.6154 | U57: 7858.1538 | V57: 9415.0784 | W57: 9746.3333 | X57: 9936.8039 | Y57: 9647.3529 | Z57: 10343.922 | AA57: 9684.3333 | AB57: 9888.8627 | AC57: 9681.2745 | AD57: 10126.745 | AE57: 9569.1176 | AF57: 9747.9216 | AG57: 10102.353 | AH57: 10453.804 | AI57: 9812.7843 | AJ57: 10191.176 | AK57: 9676.9608 | AL57: 10103.137 | AM57: 9856.4118 | AN57: 9561.8039 | AO57: 10104.608 | AP57: 12223.594 | AQ57: 12314.168 | AR57: 12294.851 | AS57: 12826.485 | AT57: 13234.644 | AU57: 12345.059 | AV57: 13016.465 | AW57: 13010.446 | AX57: 12832.248 | AY57: 12538.079 | AZ57: 12823.653 | BA57: 12789.515 | BB57: 12937.901 | BC57: 12254.931 | BD57: 12126.129 | BE57: 13194.376 | BF57: 13082.287 | BG57: 12221.802 | BH57: 13052.97 | BI57: 12546.04
...

Sheet Energy
A1: Algorithm | B1: Load | C1: Average | D1: Min | E1: Max | F1: Std Dev
A2: QUEST | B2: 1 | C2: 30024885 | D2: 29305005 | E2: 30741375 | F2: 403673.03
A3: QUEST | B3: 2 | C3: 38003453 | D3: 36656816 | E3: 40693846 | F3: 950536.89
A4: QUEST | B4: 3 | C4: 52884091 | D4: 50390330 | E4: 56129943 | F4: 1700287.5
A5: QUEST_NDVFS | B5: 1 | C5: 30410960 | D5: 29151758 | E5: 31663272 | F5: 681236.52
A6: QUEST_NDVFS | B6: 2 | C6: 40929850 | D6: 38268681 | E6: 45019407 | F6: 2206945.9
A7: QUEST_NDVFS | B7: 3 | C7: 63729865 | D7: 57364618 | E7: 71045200 | F7: 3434262.1
A8: Fuzzy | B8: 1 | C8: 31032453 | D8: 31006533 | E8: 31046853 | F8: 9308.6454
A9: Fuzzy | B9: 2 | C9: 48278536 | D9: 48256840 | E9: 48299720 | F9: 11833.771
A10: Fuzzy | B10: 3 | C10: 56934569 | D10: 56916905 | E10: 56954665 | F10: 11236.33
A11: NSGA3 | B11: 1 | C11: 36148971 | D11: 30755720 | E11: 47485563 | F11: 4254066.6
A12: NSGA3 | B12: 2 | C12: 50113689 | D12: 42896091 | E12: 61973927 | F12: 4811236
A13: NSGA3 | B13: 3 | C13: 80452122 | D13: 73029570 | E13: 92858538 | F13: 5461306
... A25: RL | B25: 3 | C25: 83468504 | D25: 69720509 | E25: 98662728 | F25: 7993525.2
A28: Summary by Algorithm
A29: QUEST | C29: 40304143 | D29: 29305005 | E29: 56129943 | F29: 9542341.7
A30: QUEST_NDVFS | C30: 45023558 | D30: 29151758 | E30: 71045200 | F30: 14110767
A31: Fuzzy | C31: 45415186 | D31: 31006533 | E31: 56954665 | F31: 10766589
A32: NSGA3 | C32: 55571594 | D32: 30755720 | E32: 92858538 | F32: 19123621
A33: MQGA | C33: 51738528 | D33: 31452751 | E33: 79916805 | F33: 18087135
A34: Greedy | C34: 55560700 | D34: 30282174 | E34: 1.0301983e+08 | F34: 19956465
A35: MOPSO | C35: 54903707 | D35: 31555760 | E35: 84898772 | F35: 19116516
A36: RL | C36: 56492206 | D36: 30956038 | E36: 98662728 | F36: 20620653
A39: Average data for chart
A40: Algorithms | B40: 1 | C40: 2 | D40: 3
A41: QUEST | B41: 30024885 | C41: 38003453 | D41: 52884091
A42: QUEST_NDVFS | B42: 30410960 | C42: 40929850 | D42: 63729865
A43: Fuzzy | B43: 31032453 | C43: 48278536 | D43: 69934569
A44: NSGA3 | B44: 36148971 | C44: 50113689 | D44: 80452122
A45: MQGA | B45: 31885094 | C45: 47756167 | D45: 75574324
A46: Greedy | B46: 35808293 | C46: 49681987 | D46: 81191819
A47: MOPSO | B47: 34167956 | C47: 50503172 | D47: 80039993
A48: RL | B48: 36517745 | C48: 49490369 | D48: 83468504
A51: All data for chart
A52: Algorithms | B52: 1 | C52: 1 | D52: 1 | E52: 1 | F52: 1 | G52: 1 | H52: 1 | I52: 1 | J52: 1 | K52: 1 | L52: 1 | M52: 1 | N52: 1 | O52: 1 | P52: 1 | Q52: 1 | R52: 1 | S52: 1 | T52: 1 | U52: 1 | V52: 2 | W52: 2 | X52: 2 | Y52: 2 | Z52: 2 | AA52: 2 | AB52: 2 | AC52: 2 | AD52: 2 | AE52: 2 | AF52: 2 | AG52: 2 | AH52: 2 | AI52: 2 | AJ52: 2 | AK52: 2 | AL52: 2 | AM52: 2 | AN52: 2 | AO52: 2 | AP52: 3 | AQ52: 3 | AR52: 3 | AS52: 3 | AT52: 3 | AU52: 3 | AV52: 3 | AW52: 3 | AX52: 3 | AY52: 3 | AZ52: 3 | BA52: 3 | BB52: 3 | BC52: 3 | BD52: 3 | BE52: 3 | BF52: 3 | BG52: 3 | BH52: 3 | BI52: 3
A53: QUEST | B53: 30093380 | C53: 29949675 | D53: 30224566 | E53: 29646782 | F53: 30055765 | G53: 29638338 | H53: 30517732 | I53: 30741375 | J53: 29305005 | K53: 30066736 | L53: 29373877 | M53: 30375456 | N53: 30178724 | O53: 29885253 | P53: 30500152 | Q53: 29389259 | R53: 30549625 | S53: 30067652 | T53: 30230024 | U53: 29708322 | V53: 38546510 | W53: 38664361 | X53: 37908786 | Y53: 38511803 | Z53: 37811975 | AA53: 39640436 | AB53: 40693846 | AC53: 37561237 | AD53: 37389972 | AE53: 36656816 | AF53: 37990647 | AG53: 37132182 | AH53: 37648661 | AI53: 37454105 | AJ53: 36994183 | AK53: 38066351 | AL53: 37633567 | AM53: 37390302 | AN53: 39172046 | AO53: 37201280 | AP53: 54958010 | AQ53: 55074616 | AR53: 54668064 | AS53: 51196755 | AT53: 55968352 | AU53: 52621513 | AV53: 50390330 | AW53: 51912758 | AX53: 51813851 | AY53: 52004437 | AZ53: 53251357 | BA53: 56129943 | BB53: 50744727 | BC53: 53450132 | BD53: 51492180 | BE53: 53169340 | BF53: 50500591 | BG53: 52621780 | BH53: 52269475 | BI53: 53443608
A54: QUEST_NDVFS | B54: 31386742 | C54: 31037580 | D54: 29914753 | E54: 30916262 | F54: 31238747 | G54: 29328234 | H54: 30657602 | I54: 30028666 | J54: 29151758 | K54: 30020619 | L54: 31663272 | M54: 31159019 | N54: 30688280 | O54: 30158922 | P54: 30727914 | Q54: 29766188 | R54: 29878111 | S54: 29888350 | T54: 30670461 | U54: 29937722 | V54: 43127479 | W54: 43149971 | X54: 41982002 | Y54: 38430699 | Z54: 38440722 | AA54: 38608242 | AB54: 38914723 | AC54: 43826738 | AD54: 39839274 | AE54: 43535054 | AF54: 39075613 | AG54: 38268681 | AH54: 38737117 | AI54: 43281571 | AJ54: 42797441 | AK54: 39011642 | AL54: 45019407 | AM54: 41933759 | AN54: 39371571 | AO54: 41245304 | AP54: 66634195 | AQ54: 61620549 | AR54: 65550672 | AS54: 61445180 | AT54: 71045200 | AU54: 65470499 | AV54: 66599572 | AW54: 61110526 | AX54: 61672469 | AY54: 67320142 | AZ54: 57364618 | BA54: 66871682 | BB54: 62992983 | BC54: 65440332 | BD54: 57547792 | BE54: 60471522 | BF54: 60924910 | BG54: 62714337 | BH54: 67431586 | BI54: 64368528
A55: Fuzzy | B55: 31028293 | C55: 31028933 | D55: 31027013 | E55: 31041733 | F55: 31036613 | G55: 31043013 | H55: 31021893 | I55: 31006533 | J55: 31031493 | K55: 31021253 | L55: 31045573 | M55: 31046853 | N55: 31037893 | O55: 31036613 | P55: 31027013 | Q55: 31027653 | R55: 31030853 | S55: 31033413 | T55: 31037893 | U55: 31038533 | V55: 48277320 | W55: 48280520 | X55: 48270280 | Y55: 48282440 | Z55: 48274760 | AA55: 48285640 | AB55: 48256840 | AC55: 48270280 | AD55: 48297160 | AE55: 48281800 | AF55: 48292680 | AG55: 48299720 | AH55: 48267080 | AI55: 48261960 | AJ55: 48272840 | AK55: 48264520 | AL55: 48283720 | AM55: 48280520 | AN55: 48298440 | AO55: 48272200 | AP55: 56934185 | AQ55: 56943785 | AR55: 56954665 | AS55: 56920745 | AT55: 56941225 | AU55: 56928425 | AV55: 56946985 | AW55: 56918185 | AX55: 56931625 | AY55: 56954025 | AZ55: 56930345 | BA55: 56925225 | BB55: 56929065 | BC55: 56925225 | BD55: 56946985 | BE55: 56935465 | BF55: 56938025 | BG55: 56946345 | BH55: 56923945 | BI55: 56916905
A56: NSGA3 | B56: 35923878 | C56: 36928382 | D56: 35441264 | E56: 35361053 | F56: 47485563 | G56: 35729440 | H56: 40502433 | I56: 31451540 | J56: 36077053 | K56: 30755720 | L56: 30922596 | M56: 35781524 | N56: 34847927 | O56: 35901476 | P56: 31016453 | Q56: 36295173 | R56: 43400144 | S56: 36364367 | T56: 31246967 | U56: 41546473 | V56: 44171001 | W56: 49795100 | X56: 48714526 | Y56: 49913412 | Z56: 43568628 | AA56: 54624485 | AB56: 61973927 | AC56: 44529766 | AD56: 52764933 | AE56: 49456238 | AF56: 53930078 | AG56: 55232491 | AH56: 54921277 | AI56: 48491115 | AJ56: 44387531 | AK56: 42896091 | AL56: 49091662 | AM56: 48425460 | AN56: 55381642 | AO56: 50004411 | AP56: 80206922 | AQ56: 92858538 | AR56: 78998169 | AS56: 80286470 | AT56: 73029570 | AU56: 90857267 | AV56: 82003191 | AW56: 91706858 | AX56: 76725948 | AY56: 80535115 | AZ56: 76666659 | BA56: 75167111 | BB56: 74365180 | BC56: 78654098 | BD56: 81069014 | BE56: 81645270 | BF56: 80618922 | BG56: 73442945 | BH56: 80502228 | BI56: 79702966
A57: MQGA | B57: 31898347 | C57: 31798087 | D57: 31567673 | E57: 31645899 | F57: 31845000 | G57: 31685713 | H57: 34017415 | I57: 31720893 | J57: 31607447 | K57: 31725080 | L57: 31896266 | M57: 31958453 | N57: 32060080 | O57: 31452751 | P57: 31851867 | Q57: 31811607 | R57: 31727014 | S57: 31780700 | T57: 31825180 | U57: 31826400 | V57: 48106797 | W57: 47182626 | X57: 47453304 | Y57: 46448317 | Z57: 48302436 | AA57: 49052173 | AB57: 48165966 | AC57: 45005324 | AD57: 48933247 | AE57: 46319840 | AF57: 48193581 | AG57: 48036707 | AH57: 48320997 | AI57: 48385727 | AJ57: 48909701 | AK57: 46138921 | AL57: 47317325 | AM57: 48589377 | AN57: 47556594 | AO57: 48704376 | AP57: 74794662 | AQ57: 74208801 | AR57: 74890466 | AS57: 78684240 | AT57: 79916805 | AU57: 74554145 | AV57: 75197458 | AW57: 75469428 | AX57: 75663222 | AY57: 76634546 | AZ57: 75502097 | BA57: 74384141 | BB57: 76109691 | BC57: 74666878 | BD57: 75684996 | BE57: 74916818 | BF57: 74794683 | BG57: 74978022 | BH57: 75421668 | BI57: 75013722
...

Sheet Makespan
A1: Algorithm | B1: Load | C1: Average | D1: Min | E1: Max | F1: Std Dev
A2: QUEST | B2: 1 | C2: 43353.6 | D2: 41491 | E2: 44949 | F2: 911.46028
A3: QUEST | B3: 2 | C3: 55803.1 | D3: 53328 | E3: 62082 | F3: 2424.2589
A4: QUEST | B4: 3 | C4: 87358.75 | D4: 79681 | E4: 95071 | F4: 4060.4038
A5: QUEST_NDVFS | B5: 1 | C5: 42950.4 | D5: 41093 | E5: 45161 | F5: 1023.7521
A6: QUEST_NDVFS | B6: 2 | C6: 56617 | D6: 53267 | E6: 62545 | F6: 3075.0288
A7: QUEST_NDVFS | B7: 3 | C7: 85796.35 | D7: 76248 | E7: 97825 | F7: 5104.7915
A8: Fuzzy | B8: 1 | C8: 43653.5 | D8: 43613 | E8: 43676 | F8: 14.544759
A9: Fuzzy | B9: 2 | C9: 65972.9 | D9: 65939 | E9: 66006 | F9: 18.490268
A10: Fuzzy | B10: 3 | C10: 71590.6 | D10: 71563 | E10: 71622 | F10: 17.556765
A11: NSGA3 | B11: 1 | C11: 53043.8 | D11: 44951 | E11: 70275 | F11: 6391.0472
A12: NSGA3 | B12: 2 | C12: 70856.1 | D12: 60180 | E12: 88646 | F12: 7318.6122
A13: NSGA3 | B13: 3 | C13: 109287.6 | D13: 97502 | E13: 127304 | F13: 8054.4684
... A25: RL | B25: 3 | C25: 113728.4 | D25: 93461 | E25: 137170 | F25: 12065.758
A28: Summary by Algorithm
A29: QUEST | C29: 62171.817 | D29: 41491 | E29: 95071 | F29: 18728.429
A30: QUEST_NDVFS | C30: 61787.917 | D30: 41093 | E30: 97825 | F30: 18207.673
A31: Fuzzy | C31: 60405.667 | D31: 43613 | E31: 71622 | F31: 12065.554
A32: NSGA3 | C32: 77729.167 | D32: 44951 | E32: 127304 | F32: 24575.212
A33: MQGA | C33: 71086.25 | D33: 44800 | E33: 107455 | F33: 22954.511
A34: Greedy | C34: 77580.983 | D34: 43685 | E34: 144099 | F34: 25931.026
A35: MOPSO | C35: 76305.933 | D35: 45367 | E35: 115504 | F35: 24674.864
A36: RL | C36: 79009 | D36: 44721 | E36: 137170 | F36: 26893.178
A39: Average data for chart
A40: Algorithms | B40: 1 | C40: 2 | D40: 3
A41: QUEST | B41: 43353.6 | C41: 55803.1 | D41: 87358.75
A42: QUEST_NDVFS | B42: 42950.4 | C42: 56617 | D42: 85796.35
A43: Fuzzy | B43: 43653.5 | C43: 61972.9 | D43: 91590.6
A44: NSGA3 | B44: 53043.8 | C44: 70856.1 | D44: 109287.6
A45: MQGA | B45: 45420.9 | C45: 66817.2 | D45: 101020.65
A46: Greedy | B46: 52482.45 | C46: 70105.05 | D46: 110155.45
A47: MOPSO | B47: 49636.55 | C47: 70599.6 | D47: 108681.65
A48: RL | B48: 53510.6 | C48: 69788 | D48: 113728.4
A51: All data for chart
A52: Algorithms | B52: 1 | C52: 1 | D52: 1 | E52: 1 | F52: 1 | G52: 1 | H52: 1 | I52: 1 | J52: 1 | K52: 1 | L52: 1 | M52: 1 | N52: 1 | O52: 1 | P52: 1 | Q52: 1 | R52: 1 | S52: 1 | T52: 1 | U52: 1 | V52: 2 | W52: 2 | X52: 2 | Y52: 2 | Z52: 2 | AA52: 2 | AB52: 2 | AC52: 2 | AD52: 2 | AE52: 2 | AF52: 2 | AG52: 2 | AH52: 2 | AI52: 2 | AJ52: 2 | AK52: 2 | AL52: 2 | AM52: 2 | AN52: 2 | AO52: 2 | AP52: 3 | AQ52: 3 | AR52: 3 | AS52: 3 | AT52: 3 | AU52: 3 | AV52: 3 | AW52: 3 | AX52: 3 | AY52: 3 | AZ52: 3 | BA52: 3 | BB52: 3 | BC52: 3 | BD52: 3 | BE52: 3 | BF52: 3 | BG52: 3 | BH52: 3 | BI52: 3
A53: QUEST | B53: 43504 | C53: 43067 | D53: 43873 | E53: 42825 | F53: 43525 | G53: 43423 | H53: 44949 | I53: 44700 | J53: 41491 | K53: 44075 | L53: 41806 | M53: 43204 | N53: 43825 | O53: 43471 | P53: 44239 | Q53: 42054 | R53: 44160 | S53: 43410 | T53: 43455 | U53: 42016 | V53: 55312 | W53: 59313 | X53: 55101 | Y53: 56173 | Z53: 55401 | AA53: 62082 | AB53: 60236 | AC53: 54710 | AD53: 54764 | AE53: 54165 | AF53: 55079 | AG53: 53328 | AH53: 54685 | AI53: 54038 | AJ53: 54116 | AK53: 53604 | AL53: 54649 | AM53: 55069 | AN53: 59958 | AO53: 54279 | AP53: 87755 | AQ53: 90967 | AR53: 89704 | AS53: 84483 | AT53: 95071 | AU53: 91238 | AV53: 84019 | AW53: 89745 | AX53: 85517 | AY53: 79681 | AZ53: 89861 | BA53: 93304 | BB53: 84268 | BC53: 86383 | BD53: 84835 | BE53: 90354 | BF53: 82143 | BG53: 83880 | BH53: 82399 | BI53: 91568
A54: QUEST_NDVFS | B54: 44601 | C54: 43325 | D54: 42546 | E54: 43603 | F54: 44001 | G54: 41486 | H54: 43291 | I54: 42766 | J54: 41093 | K54: 42343 | L54: 45161 | M54: 44171 | N54: 43233 | O54: 42808 | P54: 43327 | Q54: 41834 | R54: 42055 | S54: 42178 | T54: 43214 | U54: 41972 | V54: 59147 | W54: 59576 | X54: 57858 | Y54: 53340 | Z54: 53267 | AA54: 53496 | AB54: 53749 | AC54: 60481 | AD54: 54901 | AE54: 61006 | AF54: 54355 | AG54: 53396 | AH54: 53297 | AI54: 60044 | AJ54: 59075 | AK54: 54083 | AL54: 62545 | AM54: 57962 | AN54: 53860 | AO54: 56902 | AP54: 90458 | AQ54: 83564 | AR54: 89691 | AS54: 81692 | AT54: 97825 | AU54: 87594 | AV54: 90016 | AW54: 82361 | AX54: 82916 | AY54: 89913 | AZ54: 77694 | BA54: 89581 | BB54: 84644 | BC54: 89009 | BD54: 76248 | BE54: 81091 | BF54: 81296 | BG54: 83351 | BH54: 91136 | BI54: 85847
A55: Fuzzy | B55: 43647 | C55: 43648 | D55: 43645 | E55: 43668 | F55: 43660 | G55: 43670 | H55: 43637 | I55: 43613 | J55: 43652 | K55: 43636 | L55: 43674 | M55: 43676 | N55: 43662 | O55: 43660 | P55: 43645 | Q55: 43646 | R55: 43651 | S55: 43655 | T55: 43662 | U55: 43663 | V55: 65971 | W55: 65976 | X55: 65960 | Y55: 65979 | Z55: 65967 | AA55: 65984 | AB55: 65939 | AC55: 65960 | AD55: 66002 | AE55: 65978 | AF55: 65995 | AG55: 66006 | AH55: 65955 | AI55: 65947 | AJ55: 65964 | AK55: 65951 | AL55: 65981 | AM55: 65976 | AN55: 66004 | AO55: 65963 | AP55: 71590 | AQ55: 71605 | AR55: 71622 | AS55: 71569 | AT55: 71601 | AU55: 71581 | AV55: 71610 | AW55: 71565 | AX55: 71586 | AY55: 71621 | AZ55: 71584 | BA55: 71576 | BB55: 71582 | BC55: 71576 | BD55: 71610 | BE55: 71592 | BF55: 71596 | BG55: 71609 | BH55: 71574 | BI55: 71563
A56: NSGA3 | B56: 52224 | C56: 55275 | D56: 51682 | E56: 51772 | F56: 70275 | G56: 51908 | H56: 60021 | I56: 45610 | J56: 52647 | K56: 45320 | L56: 45880 | M56: 52643 | N56: 50816 | O56: 52659 | P56: 44951 | Q56: 53124 | R56: 63929 | S56: 53210 | T56: 46224 | U56: 60706 | V56: 62725 | W56: 69115 | X56: 68339 | Y56: 70304 | Z56: 61230 | AA56: 77137 | AB56: 88646 | AC56: 61058 | AD56: 75118 | AE56: 70729 | AF56: 76578 | AG56: 78559 | AH56: 79037 | AI56: 69180 | AJ56: 62551 | AK56: 60180 | AL56: 70364 | AM56: 67473 | AN56: 79455 | AO56: 69344 | AP56: 108325 | AQ56: 125497 | AR56: 107518 | AS56: 110677 | AT56: 97998 | AU56: 124759 | AV56: 112192 | AW56: 127304 | AX56: 103334 | AY56: 109349 | AZ56: 103593 | BA56: 102674 | BB56: 100861 | BC56: 107669 | BD56: 109943 | BE56: 110250 | BF56: 107751 | BG56: 97502 | BH56: 110002 | BI56: 108554
A57: MQGA | B57: 45259 | C57: 44800 | D57: 44856 | E57: 45320 | F57: 45791 | G57: 45028 | H57: 49327 | I57: 44871 | J57: 45299 | K57: 45106 | L57: 45481 | M57: 45361 | N57: 45402 | O57: 44920 | P57: 45169 | Q57: 45098 | R57: 45205 | S57: 45183 | T57: 45335 | U57: 45607 | V57: 67421 | W57: 66052 | X57: 65865 | Y57: 65331 | Z57: 67246 | AA57: 68240 | AB57: 66986 | AC57: 63353 | AD57: 68275 | AE57: 65442 | AF57: 67567 | AG57: 66271 | AH57: 66747 | AI57: 67218 | AJ57: 68625 | AK57: 63931 | AL57: 66885 | AM57: 68510 | AN57: 68080 | AO57: 68299 | AP57: 99915 | AQ57: 99391 | AR57: 99649 | AS57: 105877 | AT57: 107455 | AU57: 100422 | AV57: 100585 | AW57: 100527 | AX57: 101474 | AY57: 103570 | AZ57: 102130 | BA57: 98737 | BB57: 101041 | BC57: 101089 | BD57: 100265 | BE57: 99544 | BF57: 98989 | BG57: 100251 | BH57: 100096 | BI57: 99406
...

Sheet Success Rate
A1: Algorithm | B1: Load | C1: Average | D1: Min | E1: Max | F1: Std Dev
A2: QUEST | B2: 1 | C2: 1 | D2: TRUE | E2: TRUE | F2: 0
A3: QUEST | B3: 2 | C3: 1 | D3: TRUE | E3: TRUE | F3: 0
A4: QUEST | B4: 3 | C4: 1 | D4: TRUE | E4: TRUE | F4: 0
A5: QUEST_NDVFS | B5: 1 | C5: 1 | D5: TRUE | E5: TRUE | F5: 0
A6: QUEST_NDVFS | B6: 2 | C6: 1 | D6: TRUE | E6: TRUE | F6: 0
A7: QUEST_NDVFS | B7: 3 | C7: 1 | D7: TRUE | E7: TRUE | F7: 0
A8: Fuzzy | B8: 1 | C8: 1 | D8: TRUE | E8: TRUE | F8: 0
A9: Fuzzy | B9: 2 | C9: 1 | D9: TRUE | E9: TRUE | F9: 0
A10: Fuzzy | B10: 3 | C10: 1 | D10: TRUE | E10: TRUE | F10: 0
A11: NSGA3 | B11: 1 | C11: 0.75 | D11: FALSE | E11: TRUE | F11: 0.4330127
A12: NSGA3 | B12: 2 | C12: 0.85 | D12: FALSE | E12: TRUE | F12: 0.35707142
A13: NSGA3 | B13: 3 | C13: 0.9 | D13: FALSE | E13: TRUE | F13: 0.3
... A25: RL | B25: 3 | C25: 0.95 | D25: FALSE | E25: TRUE | F25: 0.21794495
A28: Summary by Algorithm
A29: QUEST | C29: 1 | D29: TRUE | E29: TRUE | F29: 0
A30: QUEST_NDVFS | C30: 1 | D30: TRUE | E30: TRUE | F30: 0
A31: Fuzzy | C31: 1 | D31: TRUE | E31: TRUE | F31: 0
A32: NSGA3 | C32: 0.83333333 | D32: FALSE | E32: TRUE | F32: 0.372678
A33: MQGA | C33: 1 | D33: TRUE | E33: TRUE | F33: 0
A34: Greedy | C34: 0.85 | D34: FALSE | E34: TRUE | F34: 0.35707142
A35: MOPSO | C35: 0.93333333 | D35: FALSE | E35: TRUE | F35: 0.24944383
A36: RL | C36: 0.81666667 | D36: FALSE | E36: TRUE | F36: 0.38693956
A39: Average data for chart
A40: Algorithms | B40: 1 | C40: 2 | D40: 3
A41: QUEST | B41: 1 | C41: 1 | D41: 1
A42: QUEST_NDVFS | B42: 1 | C42: 1 | D42: 1
A43: Fuzzy | B43: 1 | C43: 1 | D43: 1
A44: NSGA3 | B44: 0.75 | C44: 0.85 | D44: 0.9
A45: MQGA | B45: 1 | C45: 1 | D45: 1
A46: Greedy | B46: 0.7 | C46: 0.95 | D46: 0.9
A47: MOPSO | B47: 0.85 | C47: 0.95 | D47: 1
A48: RL | B48: 0.65 | C48: 0.85 | D48: 0.95
A51: All data for chart
A52: Algorithms | B52: 1 | C52: 1 | D52: 1 | E52: 1 | F52: 1 | G52: 1 | H52: 1 | I52: 1 | J52: 1 | K52: 1 | L52: 1 | M52: 1 | N52: 1 | O52: 1 | P52: 1 | Q52: 1 | R52: 1 | S52: 1 | T52: 1 | U52: 1 | V52: 2 | W52: 2 | X52: 2 | Y52: 2 | Z52: 2 | AA52: 2 | AB52: 2 | AC52: 2 | AD52: 2 | AE52: 2 | AF52: 2 | AG52: 2 | AH52: 2 | AI52: 2 | AJ52: 2 | AK52: 2 | AL52: 2 | AM52: 2 | AN52: 2 | AO52: 2 | AP52: 3 | AQ52: 3 | AR52: 3 | AS52: 3 | AT52: 3 | AU52: 3 | AV52: 3 | AW52: 3 | AX52: 3 | AY52: 3 | AZ52: 3 | BA52: 3 | BB52: 3 | BC52: 3 | BD52: 3 | BE52: 3 | BF52: 3 | BG52: 3 | BH52: 3 | BI52: 3
A53: QUEST | B53: TRUE | C53: TRUE | D53: TRUE | E53: TRUE | F53: TRUE | G53: TRUE | H53: TRUE | I53: TRUE | J53: TRUE | K53: TRUE | L53: TRUE | M53: TRUE | N53: TRUE | O53: TRUE | P53: TRUE | Q53: TRUE | R53: TRUE | S53: TRUE | T53: TRUE | U53: TRUE | V53: TRUE | W53: TRUE | X53: TRUE | Y53: TRUE | Z53: TRUE | AA53: TRUE | AB53: TRUE | AC53: TRUE | AD53: TRUE | AE53: TRUE | AF53: TRUE | AG53: TRUE | AH53: TRUE | AI53: TRUE | AJ53: TRUE | AK53: TRUE | AL53: TRUE | AM53: TRUE | AN53: TRUE | AO53: TRUE | AP53: TRUE | AQ53: TRUE | AR53: TRUE | AS53: TRUE | AT53: TRUE | AU53: TRUE | AV53: TRUE | AW53: TRUE | AX53: TRUE | AY53: TRUE | AZ53: TRUE | BA53: TRUE | BB53: TRUE | BC53: TRUE | BD53: TRUE | BE53: TRUE | BF53: TRUE | BG53: TRUE | BH53: TRUE | BI53: TRUE
A54: QUEST_NDVFS | B54: TRUE | C54: TRUE | D54: TRUE | E54: TRUE | F54: TRUE | G54: TRUE | H54: TRUE | I54: TRUE | J54: TRUE | K54: TRUE | L54: TRUE | M54: TRUE | N54: TRUE | O54: TRUE | P54: TRUE | Q54: TRUE | R54: TRUE | S54: TRUE | T54: TRUE | U54: TRUE | V54: TRUE | W54: TRUE | X54: TRUE | Y54: TRUE | Z54: TRUE | AA54: TRUE | AB54: TRUE | AC54: TRUE | AD54: TRUE | AE54: TRUE | AF54: TRUE | AG54: TRUE | AH54: TRUE | AI54: TRUE | AJ54: TRUE | AK54: TRUE | AL54: TRUE | AM54: TRUE | AN54: TRUE | AO54: TRUE | AP54: TRUE | AQ54: TRUE | AR54: TRUE | AS54: TRUE | AT54: TRUE | AU54: TRUE | AV54: TRUE | AW54: TRUE | AX54: TRUE | AY54: TRUE | AZ54: TRUE | BA54: TRUE | BB54: TRUE | BC54: TRUE | BD54: TRUE | BE54: TRUE | BF54: TRUE | BG54: TRUE | BH54: TRUE | BI54: TRUE
A55: Fuzzy | B55: TRUE | C55: TRUE | D55: TRUE | E55: TRUE | F55: TRUE | G55: TRUE | H55: TRUE | I55: TRUE | J55: TRUE | K55: TRUE | L55: TRUE | M55: TRUE | N55: TRUE | O55: TRUE | P55: TRUE | Q55: TRUE | R55: TRUE | S55: TRUE | T55: TRUE | U55: TRUE | V55: TRUE | W55: TRUE | X55: TRUE | Y55: TRUE | Z55: TRUE | AA55: TRUE | AB55: TRUE | AC55: TRUE | AD55: TRUE | AE55: TRUE | AF55: TRUE | AG55: TRUE | AH55: TRUE | AI55: TRUE | AJ55: TRUE | AK55: TRUE | AL55: TRUE | AM55: TRUE | AN55: TRUE | AO55: TRUE | AP55: TRUE | AQ55: TRUE | AR55: TRUE | AS55: TRUE | AT55: TRUE | AU55: TRUE | AV55: TRUE | AW55: TRUE | AX55: TRUE | AY55: TRUE | AZ55: TRUE | BA55: TRUE | BB55: TRUE | BC55: TRUE | BD55: TRUE | BE55: TRUE | BF55: TRUE | BG55: TRUE | BH55: TRUE | BI55: TRUE
A56: NSGA3 | B56: TRUE | C56: TRUE | D56: FALSE | E56: TRUE | F56: FALSE | G56: FALSE | H56: TRUE | I56: TRUE | J56: FALSE | K56: TRUE | L56: TRUE | M56: TRUE | N56: TRUE | O56: TRUE | P56: TRUE | Q56: TRUE | R56: FALSE | S56: TRUE | T56: TRUE | U56: TRUE | V56: TRUE | W56: TRUE | X56: TRUE | Y56: TRUE | Z56: TRUE | AA56: TRUE | AB56: FALSE | AC56: TRUE | AD56: TRUE | AE56: TRUE | AF56: TRUE | AG56: TRUE | AH56: FALSE | AI56: TRUE | AJ56: TRUE | AK56: TRUE | AL56: TRUE | AM56: TRUE | AN56: FALSE | AO56: TRUE | AP56: FALSE | AQ56: TRUE | AR56: TRUE | AS56: FALSE | AT56: TRUE | AU56: TRUE | AV56: TRUE | AW56: TRUE | AX56: TRUE | AY56: TRUE | AZ56: TRUE | BA56: TRUE | BB56: TRUE | BC56: TRUE | BD56: TRUE | BE56: TRUE | BF56: TRUE | BG56: TRUE | BH56: TRUE | BI56: TRUE
A57: MQGA | B57: TRUE | C57: TRUE | D57: TRUE | E57: TRUE | F57: TRUE | G57: TRUE | H57: TRUE | I57: TRUE | J57: TRUE | K57: TRUE | L57: TRUE | M57: TRUE | N57: TRUE | O57: TRUE | P57: TRUE | Q57: TRUE | R57: TRUE | S57: TRUE | T57: TRUE | U57: TRUE | V57: TRUE | W57: TRUE | X57: TRUE | Y57: TRUE | Z57: TRUE | AA57: TRUE | AB57: TRUE | AC57: TRUE | AD57: TRUE | AE57: TRUE | AF57: TRUE | AG57: TRUE | AH57: TRUE | AI57: TRUE | AJ57: TRUE | AK57: TRUE | AL57: TRUE | AM57: TRUE | AN57: TRUE | AO57: TRUE | AP57: TRUE | AQ57: TRUE | AR57: TRUE | AS57: TRUE | AT57: TRUE | AU57: TRUE | AV57: TRUE | AW57: TRUE | AX57: TRUE | AY57: TRUE | AZ57: TRUE | BA57: TRUE | BB57: TRUE | BC57: TRUE | BD57: TRUE | BE57: TRUE | BF57: TRUE | BG57: TRUE | BH57: TRUE | BI57: TRUE
...

Sheet Load Edge
A1: Algorithm | B1: Load | C1: Average | D1: Min | E1: Max | F1: Std Dev
A2: QUEST | B2: 1 | C2: 6535.7283 | D2: 5790.2 | E2: 7143.1333 | F2: 319.47471
A3: QUEST | B3: 2 | C3: 16270.443 | D3: 14320.2 | E3: 18139.967 | F3: 785.90882
A4: QUEST | B4: 3 | C4: 45238.795 | D4: 38512.733 | E4: 48758.167 | F4: 2282.5087
A5: QUEST_NDVFS | B5: 1 | C5: 6168.56 | D5: 5612.6 | E5: 6650.2667 | F5: 289.09859
A6: QUEST_NDVFS | B6: 2 | C6: 14669.698 | D6: 13286.633 | E6: 15371.867 | F6: 529.02586
A7: QUEST_NDVFS | B7: 3 | C7: 32316.913 | D7: 31396.467 | E7: 33728.167 | F7: 690.61145
A8: Fuzzy | B8: 1 | C8: 6618.9667 | D8: 6618.9667 | E8: 6618.9667 | F8: 0
A9: Fuzzy | B9: 2 | C9: 14781.533 | D9: 14781.533 | E9: 14781.533 | F9: 0
A10: Fuzzy | B10: 3 | C10: 31772.533 | D10: 31772.533 | E10: 31772.533 | F10: 0
A11: NSGA3 | B11: 1 | C11: 6774.7483 | D11: 6050.8667 | E11: 7214.9 | F11: 291.07977
A12: NSGA3 | B12: 2 | C12: 14987.76 | D12: 13971.767 | E12: 15686.1 | F12: 398.85838
A13: NSGA3 | B13: 3 | C13: 31879.995 | D13: 29760.733 | E13: 32889.733 | F13: 762.10316
... A25: RL | B25: 3 | C25: 31736.303 | D25: 30205.833 | E25: 32899.9 | F25: 741.73584
A28: Summary by Algorithm
A29: QUEST | C29: 22681.656 | D29: 5790.2 | E29: 48758.167 | F29: 16497.967
A30: QUEST_NDVFS | C30: 17718.391 | D30: 5612.6 | E30: 33728.167 | F30: 10903.369
A31: Fuzzy | C31: 17724.344 | D31: 6618.9667 | E31: 31772.533 | F31: 10477.614
A32: NSGA3 | C32: 17880.834 | D32: 6050.8667 | E32: 32889.733 | F32: 10464.482
A33: MQGA | C33: 17739.874 | D33: 6374.9667 | E33: 32602.567 | F33: 10466.731
A34: Greedy | C34: 17845.225 | D34: 6045.6667 | E34: 32756.833 | F34: 10508.161
A35: MOPSO | C35: 17927.429 | D35: 6042.8667 | E35: 33240.267 | F35: 10577.672
A36: RL | C36: 17802.867 | D36: 5702.4667 | E36: 32899.9 | F36: 10423.247
A39: Average data for chart
A40: Algorithms | B40: 1 | C40: 2 | D40: 3
A41: QUEST | B41: 6535.7283 | C41: 16270.443 | D41: 45238.795
A42: QUEST_NDVFS | B42: 6168.56 | C42: 14669.698 | D42: 32316.913
A43: Fuzzy | B43: 6618.9667 | C43: 14781.533 | D43: 31772.533
A44: NSGA3 | B44: 6774.7483 | C44: 14987.76 | D44: 31879.995
A45: MQGA | B45: 6675.77 | C45: 14776.237 | D45: 31767.617
A46: Greedy | B46: 6752.5 | C46: 14847.5 | D46: 31935.675
A47: MOPSO | B47: 6648.7417 | C47: 15075.718 | D47: 32057.827
A48: RL | B48: 6721.6017 | C48: 14950.697 | D48: 31736.303
A51: All data for chart
A52: Algorithms | B52: 1 | C52: 1 | D52: 1 | E52: 1 | F52: 1 | G52: 1 | H52: 1 | I52: 1 | J52: 1 | K52: 1 | L52: 1 | M52: 1 | N52: 1 | O52: 1 | P52: 1 | Q52: 1 | R52: 1 | S52: 1 | T52: 1 | U52: 1 | V52: 2 | W52: 2 | X52: 2 | Y52: 2 | Z52: 2 | AA52: 2 | AB52: 2 | AC52: 2 | AD52: 2 | AE52: 2 | AF52: 2 | AG52: 2 | AH52: 2 | AI52: 2 | AJ52: 2 | AK52: 2 | AL52: 2 | AM52: 2 | AN52: 2 | AO52: 2 | AP52: 3 | AQ52: 3 | AR52: 3 | AS52: 3 | AT52: 3 | AU52: 3 | AV52: 3 | AW52: 3 | AX52: 3 | AY52: 3 | AZ52: 3 | BA52: 3 | BB52: 3 | BC52: 3 | BD52: 3 | BE52: 3 | BF52: 3 | BG52: 3 | BH52: 3 | BI52: 3
A53: QUEST | B53: 7143.1333 | C53: 6664.0333 | D53: 6655.2333 | E53: 6349.6667 | F53: 6470.4 | G53: 5971.1 | H53: 7034.9333 | I53: 6816.8333 | J53: 6461 | K53: 6172 | L53: 6555.9667 | M53: 6784.9 | N53: 6804.2333 | O53: 6392.5 | P53: 6705.0333 | Q53: 5790.2 | R53: 6334.3 | S53: 6685.6333 | T53: 6507.6667 | U53: 6415.8 | V53: 16380.5 | W53: 17607 | X53: 16632.9 | Y53: 15984.3 | Z53: 15807.9 | AA53: 18139.967 | AB53: 17161.267 | AC53: 15834.867 | AD53: 16076.267 | AE53: 15238.667 | AF53: 16640.433 | AG53: 16424.467 | AH53: 15857.567 | AI53: 16181.967 | AJ53: 14320.2 | AK53: 15950.467 | AL53: 16204 | AM53: 15989.767 | AN53: 16737.1 | AO53: 16239.267 | AP53: 44456.967 | AQ53: 46281.733 | AR53: 45903.867 | AS53: 45272.633 | AT53: 46948.1 | AU53: 48128.2 | AV53: 46696.167 | AW53: 48758.167 | AX53: 43984.933 | AY53: 38512.733 | AZ53: 47028.767 | BA53: 46095.633 | BB53: 45985.5 | BC53: 43942.2 | BD53: 44356.967 | BE53: 45837.333 | BF53: 42665.267 | BG53: 44129.833 | BH53: 42243.967 | BI53: 47546.933
A54: QUEST_NDVFS | B54: 6309.3 | C54: 6529.3 | D54: 5612.6 | E54: 6295.4667 | F54: 6625.7333 | G54: 5830.6333 | H54: 6218.1 | I54: 5878.0333 | J54: 5893.1 | K54: 6321.1 | L54: 5852.5 | M54: 6228.5667 | N54: 6650.2667 | O54: 5688.0333 | P54: 6290.5 | Q54: 6309.6333 | R54: 6309.4333 | S54: 5967.9 | T54: 6300.8667 | U54: 6260.1333 | V54: 14752.367 | W54: 15213.5 | X54: 13714.1 | Y54: 15014.367 | Z54: 13944.067 | AA54: 14681.367 | AB54: 14599.833 | AC54: 14710.033 | AD54: 14887.2 | AE54: 13286.633 | AF54: 15160.2 | AG54: 15198.033 | AH54: 15371.867 | AI54: 14925.233 | AJ54: 14873.267 | AK54: 14748.4 | AL54: 14502.5 | AM54: 14934.4 | AN54: 14906.633 | AO54: 13969.967 | AP54: 31410.567 | AQ54: 33728.167 | AR54: 31822.867 | AS54: 32012.333 | AT54: 31479.9 | AU54: 33194.833 | AV54: 32187.7 | AW54: 32171.667 | AX54: 32096.833 | AY54: 31608.867 | AZ54: 33577.567 | BA54: 32592.167 | BB54: 31988.067 | BC54: 31887.233 | BD54: 33108.067 | BE54: 31396.467 | BF54: 33044.6 | BG54: 32035.633 | BH54: 32161.7 | BI54: 32833.033
A55: Fuzzy | B55: 6618.9667 | C55: 6618.9667 | D55: 6618.9667 | E55: 6618.9667 | F55: 6618.9667 | G55: 6618.9667 | H55: 6618.9667 | I55: 6618.9667 | J55: 6618.9667 | K55: 6618.9667 | L55: 6618.9667 | M55: 6618.9667 | N55: 6618.9667 | O55: 6618.9667 | P55: 6618.9667 | Q55: 6618.9667 | R55: 6618.9667 | S55: 6618.9667 | T55: 6618.9667 | U55: 6618.9667 | V55: 14781.533 | W55: 14781.533 | X55: 14781.533 | Y55: 14781.533 | Z55: 14781.533 | AA55: 14781.533 | AB55: 14781.533 | AC55: 14781.533 | AD55: 14781.533 | AE55: 14781.533 | AF55: 14781.533 | AG55: 14781.533 | AH55: 14781.533 | AI55: 14781.533 | AJ55: 14781.533 | AK55: 14781.533 | AL55: 14781.533 | AM55: 14781.533 | AN55: 14781.533 | AO55: 14781.533 | AP55: 31772.533 | AQ55: 31772.533 | AR55: 31772.533 | AS55: 31772.533 | AT55: 31772.533 | AU55: 31772.533 | AV55: 31772.533 | AW55: 31772.533 | AX55: 31772.533 | AY55: 31772.533 | AZ55: 31772.533 | BA55: 31772.533 | BB55: 31772.533 | BC55: 31772.533 | BD55: 31772.533 | BE55: 31772.533 | BF55: 31772.533 | BG55: 31772.533 | BH55: 31772.533 | BI55: 31772.533
A56: NSGA3 | B56: 6141.8333 | C56: 6808.9667 | D56: 6859.5333 | E56: 6980.2333 | F56: 6371.7 | G56: 6863.0333 | H56: 7037.7667 | I56: 6966.0667 | J56: 6915.2333 | K56: 6050.8667 | L56: 6891.6667 | M56: 6681.5667 | N56: 6939.2 | O56: 6625.6 | P56: 6971.6333 | Q56: 6951.6333 | R56: 6516.7 | S56: 6921.3333 | T56: 7214.9 | U56: 6785.5 | V56: 14819.2 | W56: 15344.167 | X56: 14867.367 | Y56: 15009.333 | Z56: 14931.267 | AA56: 14293 | AB56: 15120.533 | AC56: 13971.767 | AD56: 15358.5 | AE56: 15398.033 | AF56: 14741.3 | AG56: 14891.633 | AH56: 15395.333 | AI56: 15086.8 | AJ56: 15686.1 | AK56: 14667.767 | AL56: 15047.033 | AM56: 15477.067 | AN56: 14687.367 | AO56: 14961.633 | AP56: 32229.867 | AQ56: 30808.467 | AR56: 32745.8 | AS56: 32105.833 | AT56: 32008.6 | AU56: 32889.733 | AV56: 31604.3 | AW56: 32493.2 | AX56: 32022.633 | AY56: 32718.2 | AZ56: 32007.8 | BA56: 32824.167 | BB56: 31854.567 | BC56: 30681.867 | BD56: 32121.133 | BE56: 31612.6 | BF56: 31907.967 | BG56: 31275.133 | BH56: 31927.3 | BI56: 29760.733
A57: MQGA | B57: 6638.2667 | C57: 6605.7 | D57: 6716.6667 | E57: 6705.2 | F57: 6850.4333 | G57: 6713.2667 | H57: 6419.6667 | I57: 6656.8667 | J57: 6818.2 | K57: 6669.6333 | L57: 6643.8 | M57: 6688.4667 | N57: 6657.1667 | O57: 6734.5333 | P57: 6681.7333 | Q57: 6679.5333 | R57: 6374.9667 | S57: 6715.1333 | T57: 6737.1333 | U57: 6809.0333 | V57: 14519.967 | W57: 15253.7 | X57: 15096.833 | Y57: 15376.833 | Z57: 14232.767 | AA57: 15420.4 | AB57: 14038.133 | AC57: 14367.267 | AD57: 15479.3 | AE57: 15098.333 | AF57: 14442.9 | AG57: 15318.5 | AH57: 14284.3 | AI57: 14549.367 | AJ57: 14695.467 | AK57: 15409.3 | AL57: 15423.067 | AM57: 14609.333 | AN57: 14113.467 | AO57: 13795.5 | AP57: 31520.2 | AQ57: 31986.8 | AR57: 31518.4 | AS57: 31879.167 | AT57: 31110.033 | AU57: 31761.667 | AV57: 31897.8 | AW57: 30693.467 | AX57: 31934 | AY57: 32454.433 | AZ57: 32519.267 | BA57: 30052.8 | BB57: 31281.167 | BC57: 32602.567 | BD57: 31964.2 | BE57: 32448.733 | BF57: 31984.533 | BG57: 31719.867 | BH57: 32380.867 | BI57: 31642.367
...

Sheet Load Cloud
A1: Algorithm | B1: Load | C1: Average | D1: Min | E1: Max | F1: Std Dev
A2: QUEST | B2: 1 | C2: 14265.4 | D2: 0 | E2: 32596 | F2: 8324.296
A3: QUEST | B3: 2 | C3: 33352.35 | D3: 10590 | E3: 74194 | F3: 18510.892
A4: QUEST | B4: 3 | C4: 61755 | D4: 37505 | E4: 100203 | F4: 17852.319
A5: QUEST_NDVFS | B5: 1 | C5: 12847.25 | D5: 0 | E5: 28968 | F5: 8434.5765
A6: QUEST_NDVFS | B6: 2 | C6: 25490.6 | D6: 8759 | E6: 61627 | F6: 13294.66
A7: QUEST_NDVFS | B7: 3 | C7: 36571.1 | D7: 8809 | E7: 61761 | F7: 16957.395
A8: Fuzzy | B8: 1 | C8: 0 | D8: 0 | E8: 0 | F8: 0
A9: Fuzzy | B9: 2 | C9: 8784 | D9: 8784 | E9: 8784 | F9: 0
A10: Fuzzy | B10: 3 | C10: 26426 | D10: 26426 | E10: 26426 | F10: 0
A11: NSGA3 | B11: 1 | C11: 5326.15 | D11: 0 | E11: 27760 | F11: 7450.3156
A12: NSGA3 | B12: 2 | C12: 16934.75 | D12: 0 | E12: 34901 | F12: 9831.3239
A13: NSGA3 | B13: 3 | C13: 30017.7 | D13: 0 | E13: 85053 | F13: 18852.645
... A25: RL | B25: 3 | C25: 31768.4 | D25: 0 | E25: 64186 | F25: 17251.982
A28: Summary by Algorithm
A29: QUEST | C29: 36457.583 | D29: 0 | E29: 100203 | F29: 24984.976
A30: QUEST_NDVFS | C30: 24969.65 | D30: 0 | E30: 61761 | F30: 16505.16
A31: Fuzzy | C31: 11736.667 | D31: 0 | E31: 26426 | F31: 10988.541
A32: NSGA3 | C32: 17426.2 | D32: 0 | E32: 85053 | F32: 16459.88
A33: MQGA | C33: 16605.867 | D33: 0 | E33: 67979 | F33: 16215.939
A34: Greedy | C34: 17441.933 | D34: 0 | E34: 53043 | F34: 14691.601
A35: MOPSO | C35: 13787.617 | D35: 0 | E35: 48702 | F35: 13893.07
A36: RL | C36: 18304.633 | D36: 0 | E36: 64186 | F36: 16408.757
A39: Average data for chart
A40: Algorithms | B40: 1 | C40: 2 | D40: 3
A41: QUEST | B41: 14265.4 | C41: 33352.35 | D41: 61755
A42: QUEST_NDVFS | B42: 12847.25 | C42: 25490.6 | D42: 36571.1
A43: Fuzzy | B43: 0 | C43: 8784 | D43: 26426
A44: NSGA3 | B44: 5326.15 | C44: 16934.75 | D44: 30017.7
A45: MQGA | B45: 1458.9 | C45: 19810 | D45: 28548.7
A46: Greedy | B46: 5683.2 | C46: 19885.35 | D46: 26757.25
A47: MOPSO | B47: 6381.1 | C47: 9092.1 | D47: 25889.65
A48: RL | B48: 5916.55 | C48: 17228.95 | D48: 31768.4
A51: All data for chart
A52: Algorithms | B52: 1 | C52: 1 | D52: 1 | E52: 1 | F52: 1 | G52: 1 | H52: 1 | I52: 1 | J52: 1 | K52: 1 | L52: 1 | M52: 1 | N52: 1 | O52: 1 | P52: 1 | Q52: 1 | R52: 1 | S52: 1 | T52: 1 | U52: 1 | V52: 2 | W52: 2 | X52: 2 | Y52: 2 | Z52: 2 | AA52: 2 | AB52: 2 | AC52: 2 | AD52: 2 | AE52: 2 | AF52: 2 | AG52: 2 | AH52: 2 | AI52: 2 | AJ52: 2 | AK52: 2 | AL52: 2 | AM52: 2 | AN52: 2 | AO52: 2 | AP52: 3 | AQ52: 3 | AR52: 3 | AS52: 3 | AT52: 3 | AU52: 3 | AV52: 3 | AW52: 3 | AX52: 3 | AY52: 3 | AZ52: 3 | BA52: 3 | BB52: 3 | BC52: 3 | BD52: 3 | BE52: 3 | BF52: 3 | BG52: 3 | BH52: 3 | BI52: 3
A53: QUEST | B53: 0 | C53: 9846 | D53: 12493 | E53: 19818 | F53: 17668 | G53: 32596 | H53: 10490 | I53: 9067 | J53: 10510 | K53: 28870 | L53: 9025 | M53: 2525 | N53: 9891 | O53: 20814 | P53: 11334 | Q53: 28932 | R53: 18380 | S53: 10510 | T53: 13780 | U53: 8759 | V53: 10700 | W53: 49107 | X53: 10650 | Y53: 31820 | Z53: 35884 | AA53: 57285 | AB53: 24916 | AC53: 35877 | AD53: 33652 | AE53: 58749 | AF53: 15490 | AG53: 10590 | AH53: 32784 | AI53: 21130 | AJ53: 74194 | AK53: 11192 | AL53: 21260 | AM53: 42997 | AN53: 62322 | AO53: 26448 | AP53: 37505 | AQ53: 47947 | AR53: 43314 | AS53: 52676 | AT53: 63514 | AU53: 66339 | AV53: 39318 | AW53: 48838 | AX53: 79514 | AY53: 79323 | AZ53: 53077 | BA53: 70152 | BB53: 43550 | BC53: 67228 | BD53: 64737 | BE53: 94712 | BF53: 100203 | BG53: 39339 | BH53: 77625 | BI53: 66189
A54: QUEST_NDVFS | B54: 10209 | C54: 0 | D54: 28968 | E54: 8825 | F54: 0 | G54: 22659 | H54: 11334 | I54: 22709 | J54: 20351 | K54: 9109 | L54: 22293 | M54: 11709 | N54: 0 | O54: 26326 | P54: 9067 | Q54: 8659 | R54: 8967 | S54: 18076 | T54: 8659 | U54: 9025 | V54: 17525 | W54: 8759 | X54: 46369 | Y54: 21125 | Z54: 46894 | AA54: 28526 | AB54: 29052 | AC54: 20151 | AD54: 20059 | AE54: 61627 | AF54: 17584 | AG54: 18635 | AH54: 8900 | AI54: 17575 | AJ54: 17459 | AK54: 26593 | AL54: 26576 | AM54: 17509 | AN54: 17543 | AO54: 41351 | AP54: 59694 | AQ54: 8809 | AR54: 55618 | AS54: 40560 | AT54: 61104 | AU54: 8909 | AV54: 38018 | AW54: 44461 | AX54: 44185 | AY54: 44201 | AZ54: 17634 | BA54: 22417 | BB54: 44660 | BC54: 50693 | BD54: 17826 | BE54: 61761 | BF54: 17884 | BG54: 37860 | BH54: 37477 | BI54: 17651
A55: Fuzzy | B55: 0 | C55: 0 | D55: 0 | E55: 0 | F55: 0 | G55: 0 | H55: 0 | I55: 0 | J55: 0 | K55: 0 | L55: 0 | M55: 0 | N55: 0 | O55: 0 | P55: 0 | Q55: 0 | R55: 0 | S55: 0 | T55: 0 | U55: 0 | V55: 8784 | W55: 8784 | X55: 8784 | Y55: 8784 | Z55: 8784 | AA55: 8784 | AB55: 8784 | AC55: 8784 | AD55: 8784 | AE55: 8784 | AF55: 8784 | AG55: 8784 | AH55: 8784 | AI55: 8784 | AJ55: 8784 | AK55: 8784 | AL55: 8784 | AM55: 8784 | AN55: 8784 | AO55: 8784 | AP55: 26426 | AQ55: 26426 | AR55: 26426 | AS55: 26426 | AT55: 26426 | AU55: 26426 | AV55: 26426 | AW55: 26426 | AX55: 26426 | AY55: 26426 | AZ55: 26426 | BA55: 26426 | BB55: 26426 | BC55: 26426 | BD55: 26426 | BE55: 26426 | BF55: 26426 | BG55: 26426 | BH55: 26426 | BI55: 26426
A56: NSGA3 | B56: 17834 | C56: 11134 | D56: 1559 | E56: 0 | F56: 12084 | G56: 0 | H56: 0 | I56: 0 | J56: 0 | K56: 27760 | L56: 9025 | M56: 8759 | N56: 0 | O56: 9009 | P56: 0 | Q56: 0 | R56: 8759 | S56: 600 | T56: 0 | U56: 0 | V56: 28659 | W56: 0 | X56: 17725 | Y56: 14834 | Z56: 22267 | AA56: 29002 | AB56: 8800 | AC56: 34901 | AD56: 8592 | AE56: 12743 | AF56: 21418 | AG56: 17367 | AH56: 11292 | AI56: 20134 | AJ56: 3959 | AK56: 28759 | AL56: 22726 | AM56: 0 | AN56: 26742 | AO56: 8775 | AP56: 17601 | AQ56: 35551 | AR56: 12001 | AS56: 35276 | AT56: 28876 | AU56: 0 | AV56: 39959 | AW56: 17751 | AX56: 25643 | AY56: 8934 | AZ56: 28317 | BA56: 17567 | BB56: 37760 | BC56: 67327 | BD56: 22059 | BE56: 30684 | BF56: 17534 | BG56: 39434 | BH56: 33027 | BI56: 85053
A57: MQGA | B57: 1184 | C57: 0 | D57: 0 | E57: 2525 | F57: 0 | G57: 0 | H57: 11534 | I57: 0 | J57: 0 | K57: 1184 | L57: 2525 | M57: 0 | N57: 0 | O57: 1159 | P57: 0 | Q57: 0 | R57: 9067 | S57: 0 | T57: 0 | U57: 0 | V57: 26484 | W57: 8917 | X57: 8775 | Y57: 8684 | Z57: 30401 | AA57: 0 | AB57: 34885 | AC57: 35351 | AD57: 0 | AE57: 17584 | AF57: 28451 | AG57: 0 | AH57: 25668 | AI57: 21568 | AJ57: 21835 | AK57: 1867 | AL57: 8834 | AM57: 26484 | AN57: 46459 | AO57: 43953 | AP57: 35377 | AQ57: 26459 | AR57: 32693 | AS57: 25784 | AT57: 42434 | AU57: 35226 | AV57: 26351 | AW57: 52827 | AX57: 26518 | AY57: 17501 | AZ57: 18068 | BA57: 67979 | BB57: 35167 | BC57: 17751 | BD57: 17617 | BE57: 8834 | BF57: 17868 | BG57: 30785 | BH57: 8950 | BI57: 26785
...

Sheet Loads
A1: Average data for chart
B2: Edge | C2: Edge | D2: Edge | E2: Edge | F2: Edge | G2: Edge | H2: Edge | I2: Edge | J2: Edge | K2: Edge | L2: Edge | M2: Edge | N2: Edge | O2: Edge | P2: Edge | Q2: Edge | R2: Edge | S2: Edge | T2: Edge | U2: Edge | V2: Edge | W2: Edge | X2: Edge | Y2: Edge | Z2: Edge | AA2: Edge | AB2: Edge | AC2: Edge | AD2: Edge | AE2: Edge | AF2: Cloud | AG2: Edge | AH2: Edge | AI2: Edge | AJ2: Edge | AK2: Edge | AL2: Edge | AM2: Edge | AN2: Edge | AO2: Edge | AP2: Edge | AQ2: Edge | AR2: Edge | AS2: Edge | AT2: Edge | AU2: Edge | AV2: Edge | AW2: Edge | AX2: Edge | AY2: Edge | AZ2: Edge | BA2: Edge | BB2: Edge | BC2: Edge | BD2: Edge | BE2: Edge | BF2: Edge | BG2: Edge | BH2: Edge | BI2: Edge | BJ2: Edge | BK2: Cloud | BL2: Edge | BM2: Edge | BN2: Edge | BO2: Edge | BP2: Edge | BQ2: Edge | BR2: Edge | BS2: Edge | BT2: Edge | BU2: Edge | BV2: Edge | BW2: Edge | BX2: Edge | BY2: Edge | BZ2: Edge | CA2: Edge | CB2: Edge | CC2: Edge | CD2: Edge | CE2: Edge | CF2: Edge | CG2: Edge | CH2: Edge | CI2: Edge | CJ2: Edge | CK2: Edge | CL2: Edge | CM2: Edge | CN2: Edge | CO2: Edge | CP2: Cloud
B3: 1 | C3: 1 | D3: 1 | E3: 1 | F3: 1 | G3: 1 | H3: 1 | I3: 1 | J3: 1 | K3: 1 | L3: 1 | M3: 1 | N3: 1 | O3: 1 | P3: 1 | Q3: 1 | R3: 1 | S3: 1 | T3: 1 | U3: 1 | V3: 1 | W3: 1 | X3: 1 | Y3: 1 | Z3: 1 | AA3: 1 | AB3: 1 | AC3: 1 | AD3: 1 | AE3: 1 | AF3: 1 | AG3: 2 | AH3: 2 | AI3: 2 | AJ3: 2 | AK3: 2 | AL3: 2 | AM3: 2 | AN3: 2 | AO3: 2 | AP3: 2 | AQ3: 2 | AR3: 2 | AS3: 2 | AT3: 2 | AU3: 2 | AV3: 2 | AW3: 2 | AX3: 2 | AY3: 2 | AZ3: 2 | BA3: 2 | BB3: 2 | BC3: 2 | BD3: 2 | BE3: 2 | BF3: 2 | BG3: 2 | BH3: 2 | BI3: 2 | BJ3: 2 | BK3: 2 | BL3: 3 | BM3: 3 | BN3: 3 | BO3: 3 | BP3: 3 | BQ3: 3 | BR3: 3 | BS3: 3 | BT3: 3 | BU3: 3 | BV3: 3 | BW3: 3 | BX3: 3 | BY3: 3 | BZ3: 3 | CA3: 3 | CB3: 3 | CC3: 3 | CD3: 3 | CE3: 3 | CF3: 3 | CG3: 3 | CH3: 3 | CI3: 3 | CJ3: 3 | CK3: 3 | CL3: 3 | CM3: 3 | CN3: 3 | CO3: 3 | CP3: 3
A4: Algorithms | B4: 1 | C4: 2 | D4: 3 | E4: 4 | F4: 5 | G4: 6 | H4: 7 | I4: 8 | J4: 9 | K4: 10 | L4: 11 | M4: 12 | N4: 13 | O4: 14 | P4: 15 | Q4: 16 | R4: 17 | S4: 18 | T4: 19 | U4: 20 | V4: 21 | W4: 22 | X4: 23 | Y4: 24 | Z4: 25 | AA4: 26 | AB4: 27 | AC4: 28 | AD4: 29 | AE4: 30 | AF4: 31 | AG4: 1 | AH4: 2 | AI4: 3 | AJ4: 4 | AK4: 5 | AL4: 6 | AM4: 7 | AN4: 8 | AO4: 9 | AP4: 10 | AQ4: 11 | AR4: 12 | AS4: 13 | AT4: 14 | AU4: 15 | AV4: 16 | AW4: 17 | AX4: 18 | AY4: 19 | AZ4: 20 | BA4: 21 | BB4: 22 | BC4: 23 | BD4: 24 | BE4: 25 | BF4: 26 | BG4: 27 | BH4: 28 | BI4: 29 | BJ4: 30 | BK4: 31 | BL4: 1 | BM4: 2 | BN4: 3 | BO4: 4 | BP4: 5 | BQ4: 6 | BR4: 7 | BS4: 8 | BT4: 9 | BU4: 10 | BV4: 11 | BW4: 12 | BX4: 13 | BY4: 14 | BZ4: 15 | CA4: 16 | CB4: 17 | CC4: 18 | CD4: 19 | CE4: 20 | CF4: 21 | CG4: 22 | CH4: 23 | CI4: 24 | CJ4: 25 | CK4: 26 | CL4: 27 | CM4: 28 | CN4: 29 | CO4: 30 | CP4: 31
A5: QUEST | B5: 7136.871 | C5: 3645.7097 | D5: 7661.5806 | E5: 8888.2903 | F5: 5106.1613 | G5: 6561.7742 | H5: 6814.4194 | I5: 5909.9032 | J5: 4556.2581 | K5: 5739.1935 | L5: 6717.9677 | M5: 6505.0645 | N5: 4690.7419 | O5: 6705.8065 | P5: 6082.871 | Q5: 1700.9677 | R5: 1380.3226 | S5: 1314.5161 | T5: 1736.129 | U5: 1763.5484 | V5: 1692.2581 | W5: 2658.0645 | X5: 1938.9677 | Y5: 3605.7419 | Z5: 4526.129 | AA5: 3886.129 | AB5: 2843.8065 | AC5: 1978.129 | AD5: 732.58065 | AE5: 2018.0645 | AF5: 9203.4839 | AG5: 11727.71 | AH5: 7693.6129 | AI5: 11288.323 | AJ5: 9907.7742 | AK5: 9720.4516 | AL5: 8322.1935 | AM5: 10213.29 | AN5: 7898.0645 | AO5: 9528.0323 | AP5: 10744.968 | AQ5: 7894.9677 | AR5: 8007.9355 | AS5: 8113.4516 | AT5: 8598.4839 | AU5: 10466.097 | AV5: 10529.806 | AW5: 8588.5806 | AX5: 11466.032 | AY5: 13530.484 | AZ5: 10108.323 | BA5: 14173.548 | BB5: 8256.6452 | BC5: 11061.613 | BD5: 12388.452 | BE5: 9814.7097 | BF5: 14108.29 | BG5: 12463.935 | BH5: 15215.613 | BI5: 12157.71 | BJ5: 10922.71 | BK5: 21517.645 | BL5: 16487.935 | BM5: 14263.032 | BN5: 19655.839 | BO5: 19549.677 | BP5: 21981 | BQ5: 14827.968 | BR5: 18364.226 | BS5: 17098.516 | BT5: 18820.935 | BU5: 18614.29 | BV5: 18136.387 | BW5: 17173.065 | BX5: 18936.71 | BY5: 20719.71 | BZ5: 18576.645 | CA5: 41191.419 | CB5: 42555.452 | CC5: 37307.677 | CD5: 39759.613 | CE5: 40241.968 | CF5: 44249.097 | CG5: 29932.129 | CH5: 40637.935 | CI5: 40819.29 | CJ5: 43399.161 | CK5: 42225.452 | CL5: 46447.032 | CM5: 38833.548 | CN5: 36354.161 | CO5: 38429.71 | CP5: 39841.935
A6: QUEST_NDVFS | B6: 4284.3548 | C6: 5622.5161 | D6: 6401.4194 | E6: 5413.1935 | F6: 5463.9355 | G6: 6132.7742 | H6: 5963.2258 | I6: 6126.3548 | J6: 6055.0323 | K6: 7951.1935 | L6: 4485.1935 | M6: 7003.2581 | N6: 6229.5484 | O6: 5907.2903 | P6: 4976.0645 | Q6: 3029.3548 | R6: 1842.5806 | S6: 1831.2903 | T6: 1277.7419 | U6: 1497.0968 | V6: 2084.1935 | W6: 1320.9677 | X6: 2213.5484 | Y6: 2129.6774 | Z6: 2273.871 | AA6: 1717.4194 | AB6: 2583.2258 | AC6: 4128.3871 | AD6: 1834.8387 | AE6: 1611.9355 | AF6: 8288.5484 | AG6: 9493.7097 | AH6: 6334.3226 | AI6: 9560.9032 | AJ6: 10285.452 | AK6: 6808.3871 | AL6: 6605.6774 | AM6: 7651.7097 | AN6: 10397.968 | AO6: 8925.129 | AP6: 7668.0645 | AQ6: 8602.2581 | AR6: 8085.7419 | AS6: 7626.6129 | AT6: 6395.7097 | AU6: 8046.3871 | AV6: 11888.065 | AW6: 9511.6129 | AX6: 11074.194 | AY6: 15241.935 | AZ6: 11248.065 | BA6: 8747.0968 | BB6: 9563.5484 | BC6: 11200.968 | BD6: 11553.226 | BE6: 11231.935 | BF6: 8076.7742 | BG6: 11358.71 | BH6: 11198.387 | BI6: 10416.774 | BJ6: 9130.3226 | BK6: 16445.548 | BL6: 13776.903 | BM6: 12698.194 | BN6: 15781.516 | BO6: 13251.097 | BP6: 14660.548 | BQ6: 18203.419 | BR6: 14078.258 | BS6: 12735.387 | BT6: 12590.839 | BU6: 13373.71 | BV6: 13660.677 | BW6: 12347.065 | BX6: 16362.677 | BY6: 13942.226 | BZ6: 15327.742 | CA6: 25512.258 | CB6: 31796.774 | CC6: 28679.032 | CD6: 24929.355 | CE6: 22890 | CF6: 24925.161 | CG6: 25884.839 | CH6: 26424.194 | CI6: 28464.194 | CJ6: 31423.226 | CK6: 29531.935 | CL6: 32800.968 | CM6: 27745.484 | CN6: 28688.387 | CO6: 23002.581 | CP6: 23594.258
A7: Fuzzy | B7: 7435.4839 | C7: 7409.0323 | D7: 7312.2581 | E7: 7199.3548 | F7: 7183.2258 | G7: 5876.7742 | H7: 5849.6774 | I7: 5822.5806 | J7: 5812.2581 | K7: 5785.1613 | L7: 5720.6452 | M7: 5709.6774 | N7: 5693.5484 | O7: 5693.5484 | P7: 5650.9677 | Q7: 6780.6452 | R7: 6767.7419 | S7: 6703.2258 | T7: 6690.3226 | U7: 2490.3226 | V7: 1954.8387 | W7: 916.12903 | X7: 896.77419 | Y7: 464.51613 | Z7: 290.32258 | AA7: 0 | AB7: 0 | AC7: 0 | AD7: 0 | AE7: 0 | AF7: 0 | AG7: 12979.355 | AH7: 12979.355 | AI7: 12946.452 | AJ7: 12898.71 | AK7: 12871.613 | AL7: 12796.129 | AM7: 12715.484 | AN7: 12661.29 | AO7: 11511.613 | AP7: 11392.903 | AQ7: 11344.516 | AR7: 11301.29 | AS7: 11280 | AT7: 8371.6129 | AU7: 8301.9355 | AV7: 9600 | AW7: 8954.8387 | AX7: 8322.5806 | AY7: 7658.0645 | AZ7: 6870.9677 | BA7: 6864.5161 | BB7: 6858.0645 | BC7: 6851.6129 | BD7: 6838.7097 | BE7: 6838.7097 | BF7: 6832.2581 | BG7: 6812.9032 | BH7: 6812.9032 | BI7: 6812.9032 | BJ7: 6812.9032 | BK7: 5667.0968 | BL7: 24468.387 | BM7: 24038.71 | BN7: 22920.645 | BO7: 22501.29 | BP7: 21630.323 | BQ7: 21420.645 | BR7: 19172.903 | BS7: 18710.323 | BT7: 18694.194 | BU7: 18624.516 | BV7: 18587.097 | BW7: 18549.677 | BX7: 18522.581 | BY7: 18467.742 | BZ7: 18462.581 | CA7: 22109.677 | CB7: 20716.129 | CC7: 20670.968 | CD7: 20664.516 | CE7: 20651.613 | CF7: 20625.806 | CG7: 20567.742 | CH7: 20561.29 | CI7: 20548.387 | CJ7: 20548.387 | CK7: 20529.032 | CL7: 20516.129 | CM7: 20503.226 | CN7: 20490.323 | CO7: 20477.419 | CP7: 17049.032
A8: NSGA3 | B8: 3228.129 | C8: 4432.1935 | D8: 3159.0323 | E8: 4546.3548 | F8: 6363.5161 | G8: 3941.0323 | H8: 3384.0645 | I8: 4340.0323 | J8: 3073.5806 | K8: 5638.9355 | L8: 2458.7097 | M8: 3979.4516 | N8: 4963.9355 | O8: 2313.5806 | P8: 2634.8387 | Q8: 3742.9032 | R8: 2521.6129 | S8: 4896.129 | T8: 5229.3548 | U8: 4515.8065 | V8: 4832.2581 | W8: 4508.0645 | X8: 4943.5484 | Y8: 4458.7097 | Z8: 6256.129 | AA8: 5977.7419 | AB8: 6069.6774 | AC8: 5240.6452 | AD8: 5713.5484 | AE8: 3760.6452 | AF8: 3436.2258 | AG8: 10191.065 | AH8: 8551.4194 | AI8: 4183.5161 | AJ8: 9909.5484 | AK8: 9284.2258 | AL8: 8264 | AM8: 8092.5484 | AN8: 9289.6129 | AO8: 9070.0645 | AP8: 7519.9677 | AQ8: 7557.9032 | AR8: 7673.0968 | AS8: 8632.3871 | AT8: 8256.3226 | AU8: 8350.3226 | AV8: 9027.0968 | AW8: 6011.2903 | AX8: 11964.194 | AY8: 7106.7742 | AZ8: 10901.935 | BA8: 9270.9677 | BB8: 10619.355 | BC8: 14298.71 | BD8: 12932.903 | BE8: 13744.839 | BF8: 13703.226 | BG8: 12800.968 | BH8: 11992.903 | BI8: 12473.226 | BJ8: 8411.2903 | BK8: 10925.645 | BL8: 17575.484 | BM8: 20373.097 | BN8: 14259.806 | BO8: 15397.129 | BP8: 21730.258 | BQ8: 24064.645 | BR8: 17584.419 | BS8: 16156.226 | BT8: 19050.968 | BU8: 15718.032 | BV8: 21575.581 | BW8: 20018.452 | BX8: 18877.548 | BY8: 19233.226 | BZ8: 18837.29 | CA8: 18052.903 | CB8: 23529.355 | CC8: 23808.065 | CD8: 23546.774 | CE8: 22956.774 | CF8: 20812.581 | CG8: 17982.258 | CH8: 27041.29 | CI8: 22139.677 | CJ8: 22660.323 | CK8: 20480 | CL8: 22039.355 | CM8: 23999.032 | CN8: 21541.935 | CO8: 25989.677 | CP8: 19366.258
A9: MQGA | B9: 5919.6452 | C9: 3624.3871 | D9: 5035.4194 | E9: 4990.2258 | F9: 5029.2903 | G9: 4384.4516 | H9: 7877.5161 | I9: 7352.7742 | J9: 6174.7419 | K9: 5450.9032 | L9: 7612.9032 | M9: 3590.8065 | N9: 5713.7097 | O9: 4152.0645 | P9: 6103.8065 | Q9: 3293.2258 | R9: 3401.2903 | S9: 1932.2581 | T9: 2775.8065 | U9: 2769.0323 | V9: 2508.7097 | W9: 2872.5806 | X9: 3354.8387 | Y9: 3701.6129 | Z9: 3959.6774 | AA9: 3381.2903 | AB9: 3232.5806 | AC9: 2869.6774 | AD9: 4536.4516 | AE9: 1606.7742 | AF9: 941.22581 | AG9: 10864.645 | AH9: 7447.9032 | AI9: 9091.4839 | AJ9: 8603.8387 | AK9: 11721.871 | AL9: 8995.6129 | AM9: 9151.7097 | AN9: 7895.7419 | AO9: 8771.8387 | AP9: 8909.8065 | AQ9: 9899.0645 | AR9: 8199.5484 | AS9: 8660.871 | AT9: 5645.129 | AU9: 10309.065 | AV9: 12024.516 | AW9: 9247.4194 | AX9: 9303.5484 | AY9: 8280 | AZ9: 8485.8065 | BA9: 10418.71 | BB9: 11779.355 | BC9: 6787.4194 | BD9: 12245.161 | BE9: 11240.645 | BF9: 9629.3548 | BG9: 12284.194 | BH9: 10184.839 | BI9: 9022.5806 | BJ9: 10890 | BK9: 12780.645 | BL9: 21356.161 | BM9: 15801.935 | BN9: 23380.226 | BO9: 19269.387 | BP9: 17652.129 | BQ9: 20147.032 | BR9: 19987.161 | BS9: 21736.097 | BT9: 19748.613 | BU9: 21300.226 | BV9: 18810.968 | BW9: 17218.452 | BX9: 21087.581 | BY9: 19045.871 | BZ9: 20476.548 | CA9: 20650.968 | CB9: 19747.419 | CC9: 21692.581 | CD9: 18872.258 | CE9: 16812.903 | CF9: 21753.548 | CG9: 23613.226 | CH9: 20697.742 | CI9: 19288.387 | CJ9: 19718.065 | CK9: 23077.097 | CL9: 24355.806 | CM9: 25870 | CN9: 20507.097 | CO9: 21181.613 | CP9: 18418.516
