Workbook

Sheet Charts
R2: AoI | S2: Montage | T2: Cybershake | U2: Inspiral | V2: Epigenomics
R3: QUEST | S3: ='Data Age'!B49 -> 128146.35 | T3: ='Data Age'!C49 -> 166003.62 | U3: ='Data Age'!D49 -> 1854410.5 | V3: ='Data Age'!E49 -> 27903495
R4: QUEST_NDVFS | S4: ='Data Age'!B50 -> 128909.79 | T4: ='Data Age'!C50 -> 143001.04 | U4: ='Data Age'!D50 -> 1638629.6 | V4: ='Data Age'!E50 -> 19852293
R5: Fuzzy | S5: ='Data Age'!B51 -> 148043.08 | T5: ='Data Age'!C51 -> 197269.43 | U5: ='Data Age'!D51 -> 2164271.6 | V5: ='Data Age'!E51 -> 27247156
R6: NSGA3 | S6: ='Data Age'!B52 -> 154204.45 | T6: ='Data Age'!C52 -> 192312.63 | U6: ='Data Age'!D52 -> 2307336.8 | V6: ='Data Age'!E52 -> 26546129
R7: MQGA | S7: ='Data Age'!B53 -> 152824.7 | T7: ='Data Age'!C53 -> 247170.1 | U7: ='Data Age'!D53 -> 2284755.6 | V7: ='Data Age'!E53 -> 27445827
R8: Greedy | S8: ='Data Age'!B54 -> 154978.32 | T8: ='Data Age'!C54 -> 220854.8 | U8: ='Data Age'!D54 -> 2537610.9 | V8: ='Data Age'!E54 -> 24901849
R9: MOPSO | S9: ='Data Age'!B55 -> 151170.34 | T9: ='Data Age'!C55 -> 259181.12 | U9: ='Data Age'!D55 -> 2399980.1 | V9: ='Data Age'!E55 -> 26720007
R10: RL | S10: ='Data Age'!B56 -> 153879.62 | T10: ='Data Age'!C56 -> 232892.06 | U10: ='Data Age'!D56 -> 2349624.4 | V10: ='Data Age'!E56 -> 27725689
R17: AoI | S17: Montage | T17: Cybershake | U17: Inspiral | V17: Epigenomics
R18: QUEST | S18: =S3/S3 -> 1 | T18: =T3/T3 -> 1 | U18: =U3/U3 -> 1 | V18: =V3/V3 -> 1
R19: QUEST_NDVFS | S19: =S4/S3 -> 1.0059576 | T19: =T4/T3 -> 0.86143324 | U19: =U4/U3 -> 0.88363905 | V19: =V4/V3 -> 0.71146257
R20: Fuzzy | S20: =S5/S3 -> 1.1552657 | T20: =T5/T3 -> 1.1883442 | U20: =U5/U3 -> 1.1670941 | V20: =V5/V3 -> 0.97647824
R21: NSGA3 | S21: =S6/S3 -> 1.2033464 | T21: =T6/T3 -> 1.1584846 | U21: =U6/U3 -> 1.2442427 | V21: =V6/V3 -> 0.95135497
R22: MQGA | S22: =S7/S3 -> 1.1925794 | T22: =T7/T3 -> 1.488944 | U22: =U7/U3 -> 1.2320657 | V22: =V7/V3 -> 0.98359818
R23: Greedy | S23: =S8/S3 -> 1.2093854 | T23: =T8/T3 -> 1.3304216 | U23: =U8/U3 -> 1.3684192 | V23: =V8/V3 -> 0.89242758
R24: MOPSO | S24: =S9/S3 -> 1.1796695 | T24: =T9/T3 -> 1.561298 | U24: =U9/U3 -> 1.2942011 | V24: =V9/V3 -> 0.95758639
R25: RL | S25: =S10/S3 -> 1.2008116 | T25: =T10/T3 -> 1.4029336 | U25: =U10/U3 -> 1.2670465 | V25: =V10/V3 -> 0.9936278
R36: Energy | S36: Montage | T36: Cybershake | U36: Inspiral | V36: Epigenomics
R37: QUEST | S37: =Energy!B49 -> 3.8126062e+08 | T37: =Energy!C49 -> 7.0813508e+08 | U37: =Energy!D49 -> 6.1213365e+09 | V37: =Energy!E49 -> 6.3633494e+10
R38: QUEST_NDVFS | S38: =Energy!B50 -> 3.7941214e+08 | T38: =Energy!C50 -> 9.7578695e+08 | U38: =Energy!D50 -> 7.7506134e+09 | V38: =Energy!E50 -> 118430608925
R39: Fuzzy | S39: =Energy!B51 -> 3.8494462e+08 | T39: =Energy!C51 -> 1169581360 | U39: =Energy!D51 -> 8047340825 | V39: =Energy!E51 -> 132961529865
R40: NSGA3 | S40: =Energy!B52 -> 4.222971e+08 | T40: =Energy!C52 -> 1.0572235e+09 | U40: =Energy!D52 -> 9022916250 | V40: =Energy!E52 -> 1.4664133e+11
R41: MQGA | S41: =Energy!B53 -> 4.032419e+08 | T41: =Energy!C53 -> 1.0297878e+09 | U41: =Energy!D53 -> 8380478285 | V41: =Energy!E53 -> 1.4198943e+11
R42: Greedy | S42: =Energy!B54 -> 4.1951832e+08 | T42: =Energy!C54 -> 1.0824837e+09 | U42: =Energy!D54 -> 8895985775 | V42: =Energy!E54 -> 141054513705
R43: MOPSO | S43: =Energy!B55 -> 4.1143859e+08 | T43: =Energy!C55 -> 1.076096e+09 | U43: =Energy!D55 -> 8.6867904e+09 | V43: =Energy!E55 -> 1.4433427e+11
R44: RL | S44: =Energy!B56 -> 4.0700842e+08 | T44: =Energy!C56 -> 9.8975058e+08 | U44: =Energy!D56 -> 8.6135867e+09 | V44: =Energy!E56 -> 1.4293626e+11
R51: Energy | S51: Montage | T51: Cybershake | U51: Inspiral | V51: Epigenomics
R52: QUEST | S52: =S37/S37 -> 1 | T52: =T37/T37 -> 1 | U52: =U37/U37 -> 1 | V52: =V37/V37 -> 1
R53: QUEST_NDVFS | S53: =S38/S37 -> 0.99515166 | T53: =T38/T37 -> 1.3779672 | U53: =U38/U37 -> 1.2661636 | V53: =V38/V37 -> 1.8611363
R54: Fuzzy | S54: =S39/S37 -> 1.0096627 | T54: =T39/T37 -> 1.6516359 | U54: =U39/U37 -> 1.3146379 | V54: =V39/V37 -> 2.0894897
R55: NSGA3 | S55: =S40/S37 -> 1.1076337 | T55: =T40/T37 -> 1.4929687 | U55: =U40/U37 -> 1.4740108 | V55: =V40/V37 -> 2.3044677
R56: MQGA | S56: =S41/S37 -> 1.0576542 | T56: =T41/T37 -> 1.4542251 | U56: =U41/U37 -> 1.3690602 | V56: =V41/V37 -> 2.231363
R57: Greedy | S57: =S42/S37 -> 1.1003453 | T57: =T42/T37 -> 1.5286401 | U57: =U42/U37 -> 1.4532751 | V57: =V42/V37 -> 2.2166709
R58: MOPSO | S58: =S43/S37 -> 1.0791531 | T58: =T43/T37 -> 1.5196197 | U58: =U43/U37 -> 1.4191003 | V58: =V43/V37 -> 2.2682123
R59: RL | S59: =S44/S37 -> 1.0675333 | T59: =T44/T37 -> 1.3976861 | U59: =U44/U37 -> 1.4071415 | V59: =V44/V37 -> 2.2462425
R67: Makespan | S67: Montage | T67: Cybershake | U67: Inspiral | V67: Epigenomics
R68: QUEST | S68: =Makespan!B49 -> 1176224 | T68: =Makespan!C49 -> 3281593 | U68: =Makespan!D49 -> 21830704 | V68: =Makespan!E49 -> 3.5110001e+08
R69: QUEST_NDVFS | S69: =Makespan!B50 -> 1167295 | T69: =Makespan!C50 -> 3143636.5 | U69: =Makespan!D50 -> 22406924 | V69: =Makespan!E50 -> 3.4647783e+08
R70: Fuzzy | S70: =Makespan!B51 -> 1155068.5 | T70: =Makespan!C51 -> 3890833 | U70: =Makespan!D51 -> 22891684 | V70: =Makespan!E51 -> 3.7210876e+08
...

Sheet Data Age
A1: Algorithm | B1: Load | C1: Average | D1: Min | E1: Max | F1: Std Dev
A2: QUEST | B2: 1 | C2: 128146.35 | D2: 125121.12 | E2: 131171.58 | F2: 3025.2268
A3: QUEST | B3: 2 | C3: 166003.62 | D3: 164513.63 | E3: 167493.61 | F3: 1489.989
A4: QUEST | B4: 3 | C4: 1854410.5 | D4: 1686347.1 | E4: 2022474 | F4: 168063.42
A5: QUEST | B5: 4 | C5: 27903495 | D5: 27597259 | E5: 28209732 | F5: 306236.45
A6: QUEST_NDVFS | B6: 1 | C6: 128909.79 | D6: 127479.34 | E6: 130340.24 | F6: 1430.4505
A7: QUEST_NDVFS | B7: 2 | C7: 143001.04 | D7: 141695.23 | E7: 144306.84 | F7: 1305.8042
A8: QUEST_NDVFS | B8: 3 | C8: 1638629.6 | D8: 1599893.3 | E8: 1677365.9 | F8: 38736.296
A9: QUEST_NDVFS | B9: 4 | C9: 19852293 | D9: 18684488 | E9: 21020097 | F9: 1167804.8
A10: Fuzzy | B10: 1 | C10: 148043.08 | D10: 148041.9 | E10: 148044.27 | F10: 1.1863137
A11: Fuzzy | B11: 2 | C11: 197269.43 | D11: 197267.89 | E11: 197270.98 | F11: 1.5424575
A12: Fuzzy | B12: 3 | C12: 2164271.6 | D12: 2164271.3 | E12: 2164271.8 | F12: 0.24975025
A13: Fuzzy | B13: 4 | C13: 27247156 | D13: 27247155 | E13: 27247157 | F13: 0.61573146
... A33: RL | B33: 4 | C33: 27725689 | D33: 26321965 | E33: 29129412 | F33: 1403723.8
A36: Summary by Algorithm
A37: QUEST | C37: 7513014 | D37: 125121.12 | E37: 28209732 | F37: 11794367
A38: QUEST_NDVFS | C38: 5440708.2 | D38: 127479.34 | E38: 21020097 | F38: 8363548
A39: Fuzzy | C39: 7439185 | D39: 148041.9 | E39: 27247157 | F39: 11465018
A40: NSGA3 | C40: 7299995.7 | D40: 146223.58 | E40: 26563901 | F40: 11146509
A41: MQGA | C41: 7532644.4 | D41: 149438.46 | E41: 28541141 | F41: 11541563
A42: Greedy | C42: 6953823.2 | D42: 151998.17 | E42: 25932638 | F42: 10419617
A43: MOPSO | C43: 7382584.7 | D43: 147131.79 | E43: 27401477 | F43: 11206358
A44: RL | C44: 7615521.2 | D44: 150473.41 | E44: 29129412 | F44: 11665227
A47: Average data for chart
A48: Algorithms | B48: 1 | C48: 2 | D48: 3 | E48: 4
A49: QUEST | B49: 128146.35 | C49: 166003.62 | D49: 1854410.5 | E49: 27903495
A50: QUEST_NDVFS | B50: 128909.79 | C50: 143001.04 | D50: 1638629.6 | E50: 19852293
A51: Fuzzy | B51: 148043.08 | C51: 197269.43 | D51: 2164271.6 | E51: 27247156
A52: NSGA3 | B52: 154204.45 | C52: 192312.63 | D52: 2307336.8 | E52: 26546129
A53: MQGA | B53: 152824.7 | C53: 247170.1 | D53: 2284755.6 | E53: 27445827
A54: Greedy | B54: 154978.32 | C54: 220854.8 | D54: 2537610.9 | E54: 24901849
A55: MOPSO | B55: 151170.34 | C55: 259181.12 | D55: 2399980.1 | E55: 26720007
A56: RL | B56: 153879.62 | C56: 232892.06 | D56: 2349624.4 | E56: 27725689
A59: All data for chart
A60: Algorithms | B60: 1 | C60: 1 | D60: 2 | E60: 2 | F60: 3 | G60: 3 | H60: 4 | I60: 4
A61: QUEST | B61: 131171.58 | C61: 125121.12 | D61: 167493.61 | E61: 164513.63 | F61: 1686347.1 | G61: 2022474 | H61: 28209732 | I61: 27597259
A62: QUEST_NDVFS | B62: 127479.34 | C62: 130340.24 | D62: 141695.23 | E62: 144306.84 | F62: 1677365.9 | G62: 1599893.3 | H62: 18684488 | I62: 21020097
A63: Fuzzy | B63: 148044.27 | C63: 148041.9 | D63: 197267.89 | E63: 197270.98 | F63: 2164271.8 | G63: 2164271.3 | H63: 27247157 | I63: 27247155
A64: NSGA3 | B64: 146223.58 | C64: 162185.31 | D64: 208866.58 | E64: 175758.68 | F64: 2544418.5 | G64: 2070255.1 | H64: 26563901 | I64: 26528356
A65: MQGA | B65: 149438.46 | C65: 156210.94 | D65: 185176.06 | E65: 309164.14 | F65: 2174651.3 | G65: 2394859.9 | H65: 26350513 | I65: 28541141
...

Sheet Energy
A1: Algorithm | B1: Load | C1: Average | D1: Min | E1: Max | F1: Std Dev
A2: QUEST | B2: 1 | C2: 3.8126062e+08 | D2: 3.7399042e+08 | E2: 3.8853083e+08 | F2: 7270207.5
A3: QUEST | B3: 2 | C3: 7.0813508e+08 | D3: 6.7575553e+08 | E3: 7.4051464e+08 | F3: 32379557
A4: QUEST | B4: 3 | C4: 6.1213365e+09 | D4: 4.3362301e+09 | E4: 7906442990 | F4: 1.7851065e+09
A5: QUEST | B5: 4 | C5: 6.3633494e+10 | D5: 6.0099602e+10 | E5: 6.7167386e+10 | F5: 3.5338921e+09
A6: QUEST_NDVFS | B6: 1 | C6: 3.7941214e+08 | D6: 3.7467952e+08 | E6: 3.8414476e+08 | F6: 4732620
A7: QUEST_NDVFS | B7: 2 | C7: 9.7578695e+08 | D7: 9.5978825e+08 | E7: 9.9178564e+08 | F7: 15998699
A8: QUEST_NDVFS | B8: 3 | C8: 7.7506134e+09 | D8: 7690273235 | E8: 7810953650 | F8: 60340208
A9: QUEST_NDVFS | B9: 4 | C9: 118430608925 | D9: 107751720720 | E9: 129109497130 | F9: 10678888205
A10: Fuzzy | B10: 1 | C10: 3.8494462e+08 | D10: 3.8494234e+08 | E10: 3.849469e+08 | F10: 2280
A11: Fuzzy | B11: 2 | C11: 1169581360 | D11: 1169580880 | E11: 1169581840 | F11: 480
A12: Fuzzy | B12: 3 | C12: 8047340825 | D12: 8047339505 | E12: 8047342145 | F12: 1320
A13: Fuzzy | B13: 4 | C13: 132961529865 | D13: 132961526625 | E13: 132961533105 | F13: 3240
... A33: RL | B33: 4 | C33: 1.4293626e+11 | D33: 139799845660 | E33: 146072668145 | F33: 3.1364112e+09
A36: Summary by Algorithm
A37: QUEST | C37: 1.7711057e+10 | D37: 3.7399042e+08 | E37: 6.7167386e+10 | F37: 2.6684683e+10
A38: QUEST_NDVFS | C38: 3.1884105e+10 | D38: 3.7467952e+08 | E38: 129109497130 | F38: 5.0335462e+10
A39: Fuzzy | C39: 3.5640849e+10 | D39: 3.8494234e+08 | E39: 132961533105 | F39: 5.6267139e+10
A40: NSGA3 | C40: 3.9285941e+10 | D40: 4.0221232e+08 | E40: 147008669680 | F40: 6.2074702e+10
A41: MQGA | C41: 3.7950734e+10 | D41: 4.0237627e+08 | E41: 145580503060 | F41: 6.0175412e+10
A42: Greedy | C42: 3.7863125e+10 | D42: 4.1092796e+08 | E42: 157370455880 | F42: 6.022601e+10
A43: MOPSO | C43: 3.862715e+10 | D43: 4.1001236e+08 | E43: 144676775505 | F43: 6.1116817e+10
A44: RL | C44: 3.8236651e+10 | D44: 4.012071e+08 | E44: 146072668145 | F44: 6.0555488e+10
A47: Average data for chart
A48: Algorithms | B48: 1 | C48: 2 | D48: 3 | E48: 4
A49: QUEST | B49: 3.8126062e+08 | C49: 7.0813508e+08 | D49: 6.1213365e+09 | E49: 6.3633494e+10
A50: QUEST_NDVFS | B50: 3.7941214e+08 | C50: 9.7578695e+08 | D50: 7.7506134e+09 | E50: 118430608925
A51: Fuzzy | B51: 3.8494462e+08 | C51: 1169581360 | D51: 8047340825 | E51: 132961529865
A52: NSGA3 | B52: 4.222971e+08 | C52: 1.0572235e+09 | D52: 9022916250 | E52: 1.4664133e+11
A53: MQGA | B53: 4.032419e+08 | C53: 1.0297878e+09 | D53: 8380478285 | E53: 1.4198943e+11
A54: Greedy | B54: 4.1951832e+08 | C54: 1.0824837e+09 | D54: 8895985775 | E54: 141054513705
A55: MOPSO | B55: 4.1143859e+08 | C55: 1.076096e+09 | D55: 8.6867904e+09 | E55: 1.4433427e+11
A56: RL | B56: 4.0700842e+08 | C56: 9.8975058e+08 | D56: 8.6135867e+09 | E56: 1.4293626e+11
A59: All data for chart
A60: Algorithms | B60: 1 | C60: 1 | D60: 2 | E60: 2 | F60: 3 | G60: 3 | H60: 4 | I60: 4
A61: QUEST | B61: 3.7399042e+08 | C61: 3.8853083e+08 | D61: 6.7575553e+08 | E61: 7.4051464e+08 | F61: 7906442990 | G61: 4.3362301e+09 | H61: 6.7167386e+10 | I61: 6.0099602e+10
A62: QUEST_NDVFS | B62: 3.7467952e+08 | C62: 3.8414476e+08 | D62: 9.9178564e+08 | E62: 9.5978825e+08 | F62: 7690273235 | G62: 7810953650 | H62: 107751720720 | I62: 129109497130
A63: Fuzzy | B63: 3.8494234e+08 | C63: 3.849469e+08 | D63: 1169580880 | E63: 1169581840 | F63: 8047339505 | G63: 8047342145 | H63: 132961533105 | I63: 132961526625
A64: NSGA3 | B64: 4.0221232e+08 | C64: 4.4238189e+08 | D64: 1.0228597e+09 | E64: 1.0915874e+09 | F64: 9323292825 | G64: 8722539675 | H64: 146273988365 | I64: 147008669680
A65: MQGA | B65: 4.0410752e+08 | C65: 4.0237627e+08 | D65: 1.0120514e+09 | E65: 1.0475242e+09 | F65: 8312267215 | G65: 8448689355 | H65: 138398349665 | I65: 145580503060
...

Sheet Makespan
A1: Algorithm | B1: Load | C1: Average | D1: Min | E1: Max | F1: Std Dev
A2: QUEST | B2: 1 | C2: 1176224 | D2: 1142402 | E2: 1210046 | F2: 33822
A3: QUEST | B3: 2 | C3: 3281593 | D3: 3146404 | E3: 3416782 | F3: 135189
A4: QUEST | B4: 3 | C4: 21830704 | D4: 21063159 | E4: 22598250 | F4: 767545.5
A5: QUEST | B5: 4 | C5: 3.5110001e+08 | D5: 325104862 | E5: 377095149 | F5: 25995144
A6: QUEST_NDVFS | B6: 1 | C6: 1167295 | D6: 1145526 | E6: 1189064 | F6: 21769
A7: QUEST_NDVFS | B7: 2 | C7: 3143636.5 | D7: 3083898 | E7: 3203375 | F7: 59738.5
A8: QUEST_NDVFS | B8: 3 | C8: 22406924 | D8: 21856836 | E8: 22957012 | F8: 550088
A9: QUEST_NDVFS | B9: 4 | C9: 3.4647783e+08 | D9: 310044240 | E9: 382911417 | F9: 36433588
A10: Fuzzy | B10: 1 | C10: 1155068.5 | D10: 1155059 | E10: 1155078 | F10: 9.5
A11: Fuzzy | B11: 2 | C11: 3890833 | D11: 3890831 | E11: 3890835 | F11: 2
A12: Fuzzy | B12: 3 | C12: 22891684 | D12: 22891678 | E12: 22891689 | F12: 5.5
A13: Fuzzy | B13: 4 | C13: 3.7210876e+08 | D13: 372108750 | E13: 372108777 | F13: 13.5
... A33: RL | B33: 4 | C33: 413789189 | D33: 396620696 | E33: 430957682 | F33: 17168493
A36: Summary by Algorithm
A37: QUEST | C37: 94347132 | D37: 1142402 | E37: 377095149 | F37: 1.4902246e+08
A38: QUEST_NDVFS | C38: 93298921 | D38: 1145526 | E38: 382911417 | F38: 1.4753742e+08
A39: Fuzzy | C39: 1.0001159e+08 | D39: 1155059 | E39: 372108777 | F39: 1.5731828e+08
A40: NSGA3 | C40: 1.1594841e+08 | D40: 1241852 | E40: 433519352 | F40: 1.8259843e+08
A41: MQGA | C41: 1.0965966e+08 | D41: 1228356 | E41: 421512791 | F41: 1.7350108e+08
A42: Greedy | C42: 1.1286857e+08 | D42: 1273761 | E42: 486602025 | F42: 1.8079392e+08
A43: MOPSO | C43: 1.1377709e+08 | D43: 1260253 | E43: 427399410 | F43: 1.7975991e+08
A44: RL | C44: 1.1094609e+08 | D44: 1226500 | E44: 430957682 | F44: 1.7531762e+08
A47: Average data for chart
A48: Algorithms | B48: 1 | C48: 2 | D48: 3 | E48: 4
A49: QUEST | B49: 1176224 | C49: 3281593 | D49: 21830704 | E49: 3.5110001e+08
A50: QUEST_NDVFS | B50: 1167295 | C50: 3143636.5 | D50: 22406924 | E50: 3.4647783e+08
A51: Fuzzy | B51: 1155068.5 | C51: 3890833 | D51: 22891684 | E51: 3.7210876e+08
A52: NSGA3 | B52: 1318100 | C52: 3445090 | D52: 27311372 | E52: 431719083
A53: MQGA | B53: 1238744.5 | C53: 3286134.5 | D53: 24535266 | E53: 4.0957849e+08
A54: Greedy | B54: 1303244.5 | C54: 3540714.5 | D54: 26412586 | E54: 420217738
A55: MOPSO | B55: 1268083 | C55: 3495996.5 | D55: 25661360 | E55: 4.2468292e+08
A56: RL | B56: 1254359 | C56: 3195723 | D56: 25545074 | E56: 413789189
A59: All data for chart
A60: Algorithms | B60: 1 | C60: 1 | D60: 2 | E60: 2 | F60: 3 | G60: 3 | H60: 4 | I60: 4
A61: QUEST | B61: 1142402 | C61: 1210046 | D61: 3146404 | E61: 3416782 | F61: 22598250 | G61: 21063159 | H61: 377095149 | I61: 325104862
A62: QUEST_NDVFS | B62: 1145526 | C62: 1189064 | D62: 3203375 | E62: 3083898 | F62: 21856836 | G62: 22957012 | H62: 310044240 | I62: 382911417
A63: Fuzzy | B63: 1155059 | C63: 1155078 | D63: 3890831 | E63: 3890835 | F63: 22891678 | G63: 22891689 | H63: 372108777 | I63: 372108750
A64: NSGA3 | B64: 1241852 | C64: 1394348 | D64: 3311620 | E64: 3578560 | F64: 28168491 | G64: 26454254 | H64: 429918814 | I64: 433519352
A65: MQGA | B65: 1249133 | C65: 1228356 | D65: 3230262 | E65: 3342007 | F65: 24103658 | G65: 24966874 | H65: 397644186 | I65: 421512791
...

Sheet Success Rate
A1: Algorithm | B1: Load | C1: Average | D1: Min | E1: Max | F1: Std Dev
A2: QUEST | B2: 1 | C2: 0 | D2: FALSE | E2: FALSE | F2: 0
A3: QUEST | B3: 2 | C3: 1 | D3: TRUE | E3: TRUE | F3: 0
A4: QUEST | B4: 3 | C4: 0.5 | D4: FALSE | E4: TRUE | F4: 0.5
A5: QUEST | B5: 4 | C5: 1 | D5: TRUE | E5: TRUE | F5: 0
A6: QUEST_NDVFS | B6: 1 | C6: 0 | D6: FALSE | E6: FALSE | F6: 0
A7: QUEST_NDVFS | B7: 2 | C7: 1 | D7: TRUE | E7: TRUE | F7: 0
A8: QUEST_NDVFS | B8: 3 | C8: 0.5 | D8: FALSE | E8: TRUE | F8: 0.5
A9: QUEST_NDVFS | B9: 4 | C9: 0.5 | D9: FALSE | E9: TRUE | F9: 0.5
A10: Fuzzy | B10: 1 | C10: 0 | D10: FALSE | E10: FALSE | F10: 0
A11: Fuzzy | B11: 2 | C11: 0 | D11: FALSE | E11: FALSE | F11: 0
A12: Fuzzy | B12: 3 | C12: 0 | D12: FALSE | E12: FALSE | F12: 0
A13: Fuzzy | B13: 4 | C13: 0.5 | D13: FALSE | E13: TRUE | F13: 0.5
... A33: RL | B33: 4 | C33: 0.5 | D33: FALSE | E33: TRUE | F33: 0.5
A36: Summary by Algorithm
A37: QUEST | C37: 0.625 | D37: FALSE | E37: TRUE | F37: 0.48412292
A38: QUEST_NDVFS | C38: 0.5 | D38: FALSE | E38: TRUE | F38: 0.5
A39: Fuzzy | C39: 0.125 | D39: FALSE | E39: TRUE | F39: 0.33071891
A40: NSGA3 | C40: 0.375 | D40: FALSE | E40: TRUE | F40: 0.48412292
A41: MQGA | C41: 0.375 | D41: FALSE | E41: TRUE | F41: 0.48412292
A42: Greedy | C42: 0.25 | D42: FALSE | E42: TRUE | F42: 0.4330127
A43: MOPSO | C43: 0.375 | D43: FALSE | E43: TRUE | F43: 0.48412292
A44: RL | C44: 0.375 | D44: FALSE | E44: TRUE | F44: 0.48412292
A47: Average data for chart
A48: Algorithms | B48: 1 | C48: 2 | D48: 3 | E48: 4
A49: QUEST | B49: 0 | C49: 1 | D49: 0.5 | E49: 1
A50: QUEST_NDVFS | B50: 0 | C50: 1 | D50: 0.5 | E50: 0.5
A51: Fuzzy | B51: 0 | C51: 0 | D51: 0 | E51: 0.5
A52: NSGA3 | B52: 0 | C52: 1 | D52: 0 | E52: 0.5
A53: MQGA | B53: 0 | C53: 1 | D53: 0 | E53: 0.5
A54: Greedy | B54: 0 | C54: 0.5 | D54: 0 | E54: 0.5
A55: MOPSO | B55: 0 | C55: 1 | D55: 0 | E55: 0.5
A56: RL | B56: 0 | C56: 1 | D56: 0 | E56: 0.5
A59: All data for chart
A60: Algorithms | B60: 1 | C60: 1 | D60: 2 | E60: 2 | F60: 3 | G60: 3 | H60: 4 | I60: 4
A61: QUEST | B61: FALSE | C61: FALSE | D61: TRUE | E61: TRUE | F61: FALSE | G61: TRUE | H61: TRUE | I61: TRUE
A62: QUEST_NDVFS | B62: FALSE | C62: FALSE | D62: TRUE | E62: TRUE | F62: TRUE | G62: FALSE | H62: TRUE | I62: FALSE
A63: Fuzzy | B63: FALSE | C63: FALSE | D63: FALSE | E63: FALSE | F63: FALSE | G63: FALSE | H63: TRUE | I63: FALSE
A64: NSGA3 | B64: FALSE | C64: FALSE | D64: TRUE | E64: TRUE | F64: FALSE | G64: FALSE | H64: TRUE | I64: FALSE
A65: MQGA | B65: FALSE | C65: FALSE | D65: TRUE | E65: TRUE | F65: FALSE | G65: FALSE | H65: TRUE | I65: FALSE
...

Sheet Load Edge
A1: Algorithm | B1: Load | C1: Average | D1: Min | E1: Max | F1: Std Dev
A2: QUEST | B2: 1 | C2: 958195.2 | D2: 952293.9 | E2: 964096.5 | F2: 5901.3
A3: QUEST | B3: 2 | C3: 3041008.1 | D3: 3021567.5 | E3: 3060448.7 | F3: 19440.6
A4: QUEST | B4: 3 | C4: 27440759 | D4: 22687712 | E4: 32193806 | F4: 4753046.9
A5: QUEST | B5: 4 | C5: 5.7270784e+08 | D5: 5.723783e+08 | E5: 573037378 | F5: 329537.1
A6: QUEST_NDVFS | B6: 1 | C6: 940968.1 | D6: 930305.4 | E6: 951630.8 | F6: 10662.7
A7: QUEST_NDVFS | B7: 2 | C7: 2064781.4 | D7: 2031694 | E7: 2097868.8 | F7: 33087.4
A8: QUEST_NDVFS | B8: 3 | C8: 22631267 | D8: 22381834 | E8: 22880701 | F8: 249433.5
A9: QUEST_NDVFS | B9: 4 | C9: 3.7894981e+08 | D9: 3.737872e+08 | E9: 384112423 | F9: 5162611.7
A10: Fuzzy | B10: 1 | C10: 949050.3 | D10: 949050.3 | E10: 949050.3 | F10: 0
A11: Fuzzy | B11: 2 | C11: 2087238.6 | D11: 2087238.6 | E11: 2087238.6 | F11: 0
A12: Fuzzy | B12: 3 | C12: 22792190 | D12: 22792190 | E12: 22792190 | F12: 0
A13: Fuzzy | B13: 4 | C13: 385928862 | D13: 385928862 | E13: 385928862 | F13: 0
... A33: RL | B33: 4 | C33: 3.8578879e+08 | D33: 3.8423489e+08 | E33: 3.873427e+08 | F33: 1553906.2
A36: Summary by Algorithm
A37: QUEST | C37: 1.5103695e+08 | D37: 952293.9 | E37: 573037378 | F37: 2.4368601e+08
A38: QUEST_NDVFS | C38: 1.0114671e+08 | D38: 930305.4 | E38: 384112423 | F38: 1.6064275e+08
A39: Fuzzy | C39: 1.0293934e+08 | D39: 949050.3 | E39: 385928862 | F39: 1.6361525e+08
A40: NSGA3 | C40: 1.0002095e+08 | D40: 942687.4 | E40: 377836570 | F40: 1.5857071e+08
A41: MQGA | C41: 1.0157743e+08 | D41: 945531.6 | E41: 3.9029761e+08 | F41: 1.6137275e+08
A42: Greedy | C42: 1.040571e+08 | D42: 944822.4 | E42: 3.9324759e+08 | F42: 1.6575932e+08
A43: MOPSO | C43: 1.024425e+08 | D43: 941016.5 | E43: 3.8777401e+08 | F43: 1.6285567e+08
A44: RL | C44: 1.0291988e+08 | D44: 950839.6 | E44: 3.873427e+08 | F44: 1.6354913e+08
A47: Average data for chart
A48: Algorithms | B48: 1 | C48: 2 | D48: 3 | E48: 4
A49: QUEST | B49: 958195.2 | C49: 3041008.1 | D49: 27440759 | E49: 5.7270784e+08
A50: QUEST_NDVFS | B50: 940968.1 | C50: 2064781.4 | D50: 22631267 | E50: 3.7894981e+08
A51: Fuzzy | B51: 949050.3 | C51: 2087238.6 | D51: 22792190 | E51: 385928862
A52: NSGA3 | B52: 947712.2 | C52: 2085287.1 | D52: 22809062 | E52: 3.7424176e+08
A53: MQGA | B53: 949885.8 | C53: 2080730.1 | D53: 22727102 | E53: 3.80552e+08
A54: Greedy | B54: 946574 | C54: 2066802.6 | D54: 22445286 | E54: 3.9076975e+08
A55: MOPSO | B55: 943210.25 | C55: 2116194.8 | D55: 22606910 | E55: 3.8410367e+08
A56: RL | B56: 951886.05 | C56: 2078454.2 | D56: 22860380 | E56: 3.8578879e+08
A59: All data for chart
A60: Algorithms | B60: 1 | C60: 1 | D60: 2 | E60: 2 | F60: 3 | G60: 3 | H60: 4 | I60: 4
A61: QUEST | B61: 952293.9 | C61: 964096.5 | D61: 3060448.7 | E61: 3021567.5 | F61: 22687712 | G61: 32193806 | H61: 5.723783e+08 | I61: 573037378
A62: QUEST_NDVFS | B62: 951630.8 | C62: 930305.4 | D62: 2097868.8 | E62: 2031694 | F62: 22381834 | G62: 22880701 | H62: 3.737872e+08 | I62: 384112423
A63: Fuzzy | B63: 949050.3 | C63: 949050.3 | D63: 2087238.6 | E63: 2087238.6 | F63: 22792190 | G63: 22792190 | H63: 385928862 | I63: 385928862
A64: NSGA3 | B64: 952737 | C64: 942687.4 | D64: 2075353.5 | E64: 2095220.7 | F64: 22443849 | G64: 23174276 | H64: 3.7064694e+08 | I64: 377836570
A65: MQGA | B65: 945531.6 | C65: 954240 | D65: 2094604.1 | E65: 2066856.1 | F65: 22659579 | G65: 22794626 | H65: 370806389 | I65: 3.9029761e+08
...

Sheet Load Cloud
A1: Algorithm | B1: Load | C1: Average | D1: Min | E1: Max | F1: Std Dev
A2: QUEST | B2: 1 | C2: 849463 | D2: 809730 | E2: 889196 | F2: 39733
A3: QUEST | B3: 2 | C3: 2933547 | D3: 2795555 | E3: 3071539 | F3: 137992
A4: QUEST | B4: 3 | C4: 30007136 | D4: 21923100 | E4: 38091171 | F4: 8084035.5
A5: QUEST | B5: 4 | C5: 616753029 | D5: 566847241 | E5: 666658817 | F5: 49905788
A6: QUEST_NDVFS | B6: 1 | C6: 986723 | D6: 894183 | E6: 1079263 | F6: 92540
A7: QUEST_NDVFS | B7: 2 | C7: 2179245.5 | D7: 1890727 | E7: 2467764 | F7: 288518.5
A8: QUEST_NDVFS | B8: 3 | C8: 23510745 | D8: 22199300 | E8: 24822190 | F8: 1311445
A9: QUEST_NDVFS | B9: 4 | C9: 482503250 | D9: 420298980 | E9: 544707520 | F9: 62204270
A10: Fuzzy | B10: 1 | C10: 833580 | D10: 833580 | E10: 833580 | F10: 0
A11: Fuzzy | B11: 2 | C11: 1846608 | D11: 1846608 | E11: 1846608 | F11: 0
A12: Fuzzy | B12: 3 | C12: 20340250 | D12: 20340250 | E12: 20340250 | F12: 0
A13: Fuzzy | B13: 4 | C13: 339295690 | D13: 339295690 | E13: 339295690 | F13: 0
... A33: RL | B33: 4 | C33: 340738065 | D33: 317895480 | E33: 363580650 | F33: 22842585
A36: Summary by Algorithm
A37: QUEST | C37: 1.6263579e+08 | D37: 809730 | E37: 666658817 | F37: 2.6365148e+08
A38: QUEST_NDVFS | C38: 1.2729499e+08 | D38: 894183 | E38: 544707520 | F38: 2.0761924e+08
A39: Fuzzy | C39: 90579032 | D39: 833580 | E39: 339295690 | F39: 1.4380643e+08
A40: NSGA3 | C40: 1.1636826e+08 | D40: 839841 | E40: 470449410 | F40: 1.8850967e+08
A41: MQGA | C41: 1.0181162e+08 | D41: 792598 | E41: 470471690 | F41: 1.6835654e+08
A42: Greedy | C42: 90262992 | D42: 834136 | E42: 359259300 | F42: 1.4209422e+08
A43: MOPSO | C43: 97911247 | D43: 836054 | E43: 386957450 | F43: 1.5594815e+08
A44: RL | C44: 91030764 | D44: 827937 | E44: 363580650 | F44: 1.4483075e+08
A47: Average data for chart
A48: Algorithms | B48: 1 | C48: 2 | D48: 3 | E48: 4
A49: QUEST | B49: 849463 | C49: 2933547 | D49: 30007136 | E49: 616753029
A50: QUEST_NDVFS | B50: 986723 | C50: 2179245.5 | D50: 23510745 | E50: 482503250
A51: Fuzzy | B51: 833580 | C51: 1846608 | D51: 20340250 | E51: 339295690
A52: NSGA3 | B52: 862764.5 | C52: 1917790 | D52: 21075140 | E52: 441617345
A53: MQGA | B53: 845022.5 | C53: 1845308.5 | D53: 21503250 | E53: 383052905
A54: Greedy | B54: 864036.5 | C54: 2045773.5 | D54: 23149430 | E54: 334992730
A55: MOPSO | B55: 887948.5 | C55: 1595939 | D55: 22119705 | E55: 367041395
A56: RL | B56: 828421.5 | C56: 2052052.5 | D56: 20504515 | E56: 340738065
A59: All data for chart
A60: Algorithms | B60: 1 | C60: 1 | D60: 2 | E60: 2 | F60: 3 | G60: 3 | H60: 4 | I60: 4
A61: QUEST | B61: 889196 | C61: 809730 | D61: 2795555 | E61: 3071539 | F61: 21923100 | G61: 38091171 | H61: 666658817 | I61: 566847241
A62: QUEST_NDVFS | B62: 894183 | C62: 1079263 | D62: 1890727 | E62: 2467764 | F62: 24822190 | G62: 22199300 | H62: 544707520 | I62: 420298980
A63: Fuzzy | B63: 833580 | C63: 833580 | D63: 1846608 | E63: 1846608 | F63: 20340250 | G63: 20340250 | H63: 339295690 | I63: 339295690
A64: NSGA3 | B64: 839841 | C64: 885688 | D64: 2023205 | E64: 1812375 | F64: 23100810 | G64: 19049470 | H64: 470449410 | I64: 412785280
A65: MQGA | B65: 897447 | C65: 792598 | D65: 1775847 | E65: 1914770 | F65: 21694470 | G65: 21312030 | H65: 470471690 | I65: 295634120
...

Sheet Loads
A1: Average data for chart
B2: Edge | C2: Edge | D2: Edge | E2: Edge | F2: Edge | G2: Edge | H2: Edge | I2: Edge | J2: Edge | K2: Edge | L2: Cloud | M2: Edge | N2: Edge | O2: Edge | P2: Edge | Q2: Edge | R2: Edge | S2: Edge | T2: Edge | U2: Edge | V2: Edge | W2: Cloud | X2: Edge | Y2: Edge | Z2: Edge | AA2: Edge | AB2: Edge | AC2: Edge | AD2: Edge | AE2: Edge | AF2: Edge | AG2: Edge | AH2: Cloud | AI2: Edge | AJ2: Edge | AK2: Edge | AL2: Edge | AM2: Edge | AN2: Edge | AO2: Edge | AP2: Edge | AQ2: Edge | AR2: Edge | AS2: Cloud
B3: 1 | C3: 1 | D3: 1 | E3: 1 | F3: 1 | G3: 1 | H3: 1 | I3: 1 | J3: 1 | K3: 1 | L3: 1 | M3: 2 | N3: 2 | O3: 2 | P3: 2 | Q3: 2 | R3: 2 | S3: 2 | T3: 2 | U3: 2 | V3: 2 | W3: 2 | X3: 3 | Y3: 3 | Z3: 3 | AA3: 3 | AB3: 3 | AC3: 3 | AD3: 3 | AE3: 3 | AF3: 3 | AG3: 3 | AH3: 3 | AI3: 4 | AJ3: 4 | AK3: 4 | AL3: 4 | AM3: 4 | AN3: 4 | AO3: 4 | AP3: 4 | AQ3: 4 | AR3: 4 | AS3: 4
A4: Algorithms | B4: 1 | C4: 2 | D4: 3 | E4: 4 | F4: 5 | G4: 6 | H4: 7 | I4: 8 | J4: 9 | K4: 10 | L4: 11 | M4: 1 | N4: 2 | O4: 3 | P4: 4 | Q4: 5 | R4: 6 | S4: 7 | T4: 8 | U4: 9 | V4: 10 | W4: 11 | X4: 1 | Y4: 2 | Z4: 3 | AA4: 4 | AB4: 5 | AC4: 6 | AD4: 7 | AE4: 8 | AF4: 9 | AG4: 10 | AH4: 11 | AI4: 1 | AJ4: 2 | AK4: 3 | AL4: 4 | AM4: 5 | AN4: 6 | AO4: 7 | AP4: 8 | AQ4: 9 | AR4: 10 | AS4: 11
A5: QUEST | B5: 156872 | C5: 129125.27 | D5: 137515.91 | E5: 132951 | F5: 151572.55 | G5: 201162.73 | H5: 229133.64 | I5: 193782.73 | J5: 204274.55 | K5: 205782.73 | L5: 154447.82 | M5: 415365.64 | N5: 370082.91 | O5: 438191.55 | P5: 354043.09 | Q5: 440743.91 | R5: 645404.27 | S5: 582720 | T5: 712073.36 | U5: 829458.64 | V5: 741022.27 | W5: 533372.18 | X5: 3920584.7 | Y5: 3551376.3 | Z5: 3616273.7 | AA5: 3794838.8 | AB5: 3742727.4 | AC5: 7177439.6 | AD5: 5146364.7 | AE5: 6019078.9 | AF5: 5996538.5 | AG5: 6927066.5 | AH5: 5455842.8 | AI5: 61869760 | AJ5: 61852820 | AK5: 61709909 | AL5: 61811062 | AM5: 49669640 | AN5: 1.3233021e+08 | AO5: 156893824 | AP5: 1.5143075e+08 | AQ5: 1.7684505e+08 | AR5: 1.2687397e+08 | AS5: 1.1213691e+08
A6: QUEST_NDVFS | B6: 141816.73 | C6: 152100.55 | D6: 145910.09 | E6: 145654.73 | F6: 128288.09 | G6: 199839.09 | H6: 208103.64 | I6: 188530 | J6: 195875.45 | K6: 204732.73 | L6: 179404.18 | M6: 309543.73 | N6: 309984.91 | O6: 336033.73 | P6: 322683 | Q6: 325827.64 | R6: 429966 | S6: 492121 | T6: 450293 | U6: 461739 | V6: 315956 | W6: 396226.45 | X6: 3983987.3 | Y6: 3406271.8 | Z6: 3461728.2 | AA6: 3018760.9 | AB6: 3145243.6 | AC6: 5350538.2 | AD6: 5044026.5 | AE6: 4239579.3 | AF6: 4720778.2 | AG6: 4776844.4 | AH6: 4274680.9 | AI6: 36308807 | AJ6: 53852872 | AK6: 40089210 | AL6: 57796717 | AM6: 45821611 | AN6: 76450488 | AO6: 80487884 | AP6: 1.0690105e+08 | AQ6: 95027096 | AR6: 96263925 | AS6: 87727864
A7: Fuzzy | B7: 166612.91 | C7: 165011.64 | D7: 161470.55 | E7: 159478.91 | F7: 154799.27 | G7: 184270.91 | H7: 183898.18 | I7: 183840 | J7: 183796.36 | K7: 182367.27 | L7: 151560 | M7: 364955.27 | N7: 353764.73 | O7: 351464.36 | P7: 349486.91 | Q7: 343132 | R7: 410802 | S7: 407520 | T7: 405596 | U7: 404438 | V7: 403820 | W7: 335746.91 | X7: 3817176.4 | Y7: 3809432.7 | Z7: 3801783.6 | AA7: 3795232.7 | AB7: 3788154.5 | AC7: 4533953.5 | AD7: 4523430.5 | AE7: 4465944 | AF7: 4456664.7 | AG7: 4448572.4 | AH7: 3698227.3 | AI7: 66516173 | AJ7: 66121127 | AK7: 65774049 | AL7: 64832542 | AM7: 63405840 | AN7: 75743817 | AO7: 75406652 | AP7: 75039788 | AQ7: 74539004 | AR7: 74309849 | AS7: 61690125
A8: NSGA3 | B8: 170991.18 | C8: 143069.82 | D8: 155451.27 | E8: 156441.91 | F8: 161745.27 | G8: 169217.27 | H8: 196985.45 | I8: 192785.45 | J8: 196452.73 | K8: 179972.73 | L8: 156866.27 | M8: 365347.73 | N8: 368190.64 | O8: 309009.45 | P8: 350971.27 | Q8: 309367 | R8: 440371 | S8: 455113 | T8: 322319 | U8: 439500 | V8: 431242 | W8: 348689.09 | X8: 3394148.2 | Y8: 3510704.5 | Z8: 3129921.8 | AA8: 3883532.7 | AB8: 4138386.4 | AC8: 4836269.5 | AD8: 4344368.7 | AE8: 4783556.7 | AF8: 4215144 | AG8: 5234990.2 | AH8: 3831843.6 | AI8: 62608025 | AJ8: 68024143 | AK8: 58766351 | AL8: 60922835 | AM8: 70951161 | AN8: 53541163 | AO8: 66752102 | AP8: 83961363 | AQ8: 91831174 | AR8: 63081242 | AS8: 80294063
A9: MQGA | B9: 177807.91 | C9: 164829.55 | D9: 156461.45 | E9: 144937.91 | F9: 143248.27 | G9: 167056.36 | H9: 192357.27 | I9: 191907.27 | J9: 205542.73 | K9: 182916.36 | L9: 153640.45 | M9: 323164.45 | N9: 364763.73 | O9: 385813.27 | P9: 397760.82 | Q9: 351893.36 | R9: 352656 | S9: 402920 | T9: 407410 | U9: 387555 | V9: 409209 | W9: 335510.64 | X9: 3110959.1 | Y9: 3330006.4 | Z9: 3923938.2 | AA9: 3713644.5 | AB9: 4256210.9 | AC9: 5404972.4 | AD9: 4898569.1 | AE9: 4686437.5 | AF9: 4075939.6 | AG9: 3921326.2 | AH9: 3909681.8 | AI9: 63560925 | AJ9: 67349059 | AK9: 69886235 | AL9: 65820574 | AM9: 61178374 | AN9: 72045188 | AO9: 72905968 | AP9: 79163183 | AQ9: 72271137 | AR9: 67732082 | AS9: 69645983
A10: Greedy | B10: 169295.73 | C10: 147847.55 | D10: 156866.18 | E10: 170005.55 | F10: 152644.09 | G10: 167230.91 | H10: 173906.36 | I10: 205784.55 | J10: 203320 | K10: 174142.73 | L10: 157097.55 | M10: 350023.73 | N10: 321356.91 | O10: 373536.36 | P10: 342948.91 | Q10: 343454.09 | R10: 504045 | S10: 359618 | T10: 397661 | U10: 382215 | V10: 382964 | W10: 371958.82 | X10: 3575252.7 | Y10: 4112478.2 | Z10: 3739392.7 | AA10: 3897393.6 | AB10: 3776376.4 | AC10: 4688200.4 | AD10: 4304895.3 | AE10: 4146490.9 | AF10: 4210314.5 | AG10: 4358815.6 | AH10: 4208987.3 | AI10: 50898745 | AJ10: 52204155 | AK10: 51149883 | AL10: 57837737 | AM10: 75245296 | AN10: 92766668 | AO10: 85675251 | AP10: 78810854 | AQ10: 94403983 | AR10: 71497879 | AS10: 60907769
A11: MOPSO | B11: 156378.55 | C11: 159185.09 | D11: 169227.91 | E11: 152460.64 | F11: 163894.64 | G11: 169457.27 | H11: 182894.55 | I11: 179810 | J11: 188357.27 | K11: 193261.82 | L11: 161445.18 | M11: 415914 | N11: 343820.55 | O11: 346412.09 | P11: 373873 | Q11: 293004.18 | R11: 432289 | S11: 429904 | T11: 427346 | U11: 396132 | V11: 388932 | W11: 290170.73 | X11: 4212681.8 | Y11: 3599506.4 | Z11: 3274336.4 | AA11: 4138226.4 | AB11: 3530171.8 | AC11: 5045262.5 | AD11: 4350740.7 | AE11: 4182547.6 | AF11: 4329339.3 | AG11: 4440658.9 | AH11: 4021764.5 | AI11: 70642445 | AJ11: 55417118 | AK11: 70769510 | AL11: 65524733 | AM11: 50620514 | AN11: 85696905 | AO11: 65884983 | AP11: 74475861 | AQ11: 83342951 | AR11: 75995294 | AS11: 66734799
A12: RL | B12: 154173.91 | C12: 155216.82 | D12: 158709.55 | E12: 156964 | F12: 162154 | G12: 169910.91 | H12: 167977.27 | I12: 218521.82 | J12: 189592.73 | K12: 197480.91 | L12: 150622.09 | M12: 310877.55 | N12: 335446.45 | O12: 356809.09 | P12: 301762 | Q12: 313633.55 | R12: 440100 | S12: 426086 | T12: 432685 | U12: 392673 | V12: 468935 | W12: 373100.45 | X12: 2893181.8 | Y12: 3876932.7 | Z12: 4225408.2 | AA12: 3392945.5 | AB12: 3824204.5 | AC12: 4483080 | AD12: 4168939.6 | AE12: 4446842.2 | AF12: 5056096.4 | AG12: 5196696 | AH12: 3728093.6 | AI12: 63726165 | AJ12: 62550474 | AK12: 67059716 | AL12: 62390146 | AM12: 70623099 | AN12: 69424729 | AO12: 75952492 | AP12: 53919627 | AQ12: 98907353 | AR12: 76880364 | AS12: 61952375

Sheet ANOVA - AoI
A1: Anova: Two-Factor With Replication
A3: SUMMARY | B3: Load 1 | C3: Load 2 | D3: Load 3 | E3: Load 4 | F3: Total
A4: QUEST
A5: Count | B5: 2 | C5: 2 | D5: 2 | E5: 2 | F5: 8
A6: Sum | B6: 256292.7 | C6: 332007.24 | D6: 3708821.1 | E6: 55806991 | F6: 60104112
A7: Average | B7: 128146.35 | C7: 166003.62 | D7: 1854410.5 | E7: 27903495 | F7: 7513014
A8: Variance | B8: 18303994 | C8: 4440134.5 | D8: 5.6490628e+10 | E8: 1.8756152e+11 | F8: 1.5897954e+14
A10: QUEST_NDVFS
A11: Count | B11: 2 | C11: 2 | D11: 2 | E11: 2 | F11: 8
A12: Sum | B12: 257819.58 | C12: 286002.08 | D12: 3277259.1 | E12: 39704585 | F12: 43525666
A13: Average | B13: 128909.79 | C13: 143001.04 | D13: 1638629.6 | E13: 19852293 | F13: 5440708.2
A14: Variance | B14: 4092377.5 | C14: 3410249.2 | D14: 3.0010013e+09 | E14: 2.7275361e+12 | F14: 7.994164e+13
A16: Fuzzy
A17: Count | B17: 2 | C17: 2 | D17: 2 | E17: 2 | F17: 8
A18: Sum | B18: 296086.16 | C18: 394538.87 | D18: 4328543.1 | E18: 54494312 | F18: 59513480
A19: Average | B19: 148043.08 | C19: 197269.43 | D19: 2164271.6 | E19: 27247156 | F19: 7439185
A20: Variance | B20: 2.8146803 | C20: 4.7583505 | D20: 0.12475037 | E20: 0.75825047 | F20: 1.5022472e+14
A22: NSGA3
A23: Count | B23: 2 | C23: 2 | D23: 2 | E23: 2 | F23: 8
A24: Sum | B24: 308408.89 | C24: 384625.27 | D24: 4614673.6 | E24: 53092258 | F24: 58399966
A25: Average | B25: 154204.45 | C25: 192312.63 | D25: 2307336.8 | E25: 26546129 | F25: 7299995.7
A26: Variance | B26: 1.2738846e+08 | C26: 5.4806656e+08 | D26: 1.1241543e+11 | E26: 6.317176e+08 | F26: 1.419939e+14
A28: MQGA
A29: Count | B29: 2 | C29: 2 | D29: 2 | E29: 2 | F29: 8
A30: Sum | B30: 305649.4 | C30: 494340.2 | D30: 4569511.3 | E30: 54891654 | F30: 60261155
A31: Average | B31: 152824.7 | C31: 247170.1 | D31: 2284755.6 | E31: 27445827 | F31: 7532644.4
A32: Variance | B32: 22933206 | C32: 7.6865225e+09 | D32: 2.4245913e+10 | E32: 2.3994251e+12 | F32: 1.5223736e+14
A34: Greedy
A35: Count | B35: 2 | C35: 2 | D35: 2 | E35: 2 | F35: 8
A36: Sum | B36: 309956.65 | C36: 441709.6 | D36: 5075221.9 | E36: 49803698 | F36: 55630586
A37: Average | B37: 154978.32 | C37: 220854.8 | D37: 2537610.9 | E37: 24901849 | F37: 6953823.2
A38: Variance | B38: 17762652 | C38: 3.4349108e+08 | D38: 3.8554514e+10 | E38: 2.1250523e+12 | F38: 1.240782e+14
A40: MOPSO
A41: Count | B41: 2 | C41: 2 | D41: 2 | E41: 2 | F41: 8
A42: Sum | B42: 302340.68 | C42: 518362.23 | D42: 4799960.2 | E42: 53440015 | F42: 59060678
A43: Average | B43: 151170.34 | C43: 259181.12 | D43: 2399980.1 | E43: 26720007 | F43: 7382584.7
A44: Variance | B44: 32619755 | C44: 1.7401325e+09 | D44: 1.3219295e+11 | E44: 9.2880315e+11 | F44: 1.4352282e+14
A46: RL
A47: Count | B47: 2 | C47: 2 | D47: 2 | E47: 2 | F47: 8
A48: Sum | B48: 307759.24 | C48: 465784.12 | D48: 4699248.7 | E48: 55451377 | F48: 60924169
...

Sheet ANOVA - Energy
A1: Anova: Two-Factor With Replication
A3: SUMMARY | B3: Load 1 | C3: Load 2 | D3: Load 3 | E3: Load 4 | F3: Total
A4: QUEST
A5: Count | B5: 2 | C5: 2 | D5: 2 | E5: 2 | F5: 8
A6: Sum | B6: 7.6252125e+08 | C6: 1.4162702e+09 | D6: 1.2242673e+10 | E6: 1.2726699e+11 | F6: 1.4168845e+11
A7: Average | B7: 3.8126062e+08 | C7: 7.0813508e+08 | D7: 6.1213365e+09 | E7: 6.3633494e+10 | F7: 1.7711057e+10
A8: Variance | B8: 1.0571183e+14 | C8: 2.0968714e+15 | D8: 6.3732102e+18 | E8: 2.4976787e+19 | F8: 8.137969e+20
A10: QUEST_NDVFS
A11: Count | B11: 2 | C11: 2 | D11: 2 | E11: 2 | F11: 8
A12: Sum | B12: 7.5882429e+08 | C12: 1.9515739e+09 | D12: 15501226885 | E12: 236861217850 | F12: 2.5507284e+11
A13: Average | B13: 3.7941214e+08 | C13: 9.7578695e+08 | D13: 7.7506134e+09 | E13: 118430608925 | F13: 3.1884105e+10
A14: Variance | B14: 44795384128800 | C14: 5.1191672e+14 | D14: 7.2818813e+15 | E14: 2.2807731e+20 | F14: 2.89561e+21
A16: Fuzzy
A17: Count | B17: 2 | C17: 2 | D17: 2 | E17: 2 | F17: 8
A18: Sum | B18: 7.6988923e+08 | C18: 2339162720 | D18: 16094681650 | E18: 265923059730 | F18: 2.8512679e+11
A19: Average | B19: 3.8494462e+08 | C19: 1169581360 | D19: 8047340825 | E19: 132961529865 | F19: 3.5640849e+10
A20: Variance | B20: 10396800 | C20: 460800 | D20: 3484800 | E20: 20995200 | F20: 3.6182753e+21
A22: NSGA3
A23: Count | B23: 2 | C23: 2 | D23: 2 | E23: 2 | F23: 8
A24: Sum | B24: 8.445942e+08 | C24: 2.1144471e+09 | D24: 18045832500 | E24: 293282658045 | F24: 3.1428753e+11
A25: Average | B25: 4.222971e+08 | C25: 1.0572235e+09 | D25: 9022916250 | E25: 1.4664133e+11 | F25: 3.9285941e+10
A26: Variance | B26: 8.0679721e+14 | C26: 2.3617448e+15 | D26: 1.8045217e+17 | E26: 2.6987832e+17 | F26: 4.4037355e+21
A28: MQGA
A29: Count | B29: 2 | C29: 2 | D29: 2 | E29: 2 | F29: 8
A30: Sum | B30: 8.0648379e+08 | C30: 2.0595756e+09 | D30: 16760956570 | E30: 283978852725 | F30: 303605868730
A31: Average | B31: 4.032419e+08 | C31: 1.0297878e+09 | D31: 8380478285 | E31: 1.4198943e+11 | F31: 3.7950734e+10
A32: Variance | B32: 1.4986234e+12 | C32: 6.2916122e+14 | D32: 9.3055001e+15 | E32: 2.5791664e+19 | F32: 4.1383774e+21
A34: Greedy
A35: Count | B35: 2 | C35: 2 | D35: 2 | E35: 2 | F35: 8
A36: Sum | B36: 8.3903664e+08 | C36: 2.1649673e+09 | D36: 17791971550 | E36: 282109027410 | F36: 302905002940
A37: Average | B37: 4.1951832e+08 | C37: 1.0824837e+09 | D37: 8895985775 | E37: 141054513705 | F37: 3.7863125e+10
A38: Variance | B38: 1.4758853e+14 | C38: 3.8752824e+15 | D38: 1.5976699e+17 | E38: 5.3241994e+20 | F38: 4.1453397e+21
A40: MOPSO
A41: Count | B41: 2 | C41: 2 | D41: 2 | E41: 2 | F41: 8
A42: Sum | B42: 8.2287718e+08 | C42: 2.152192e+09 | D42: 17373580885 | E42: 288668547575 | F42: 3.090172e+11
A43: Average | B43: 4.1143859e+08 | C43: 1.076096e+09 | D43: 8.6867904e+09 | E43: 1.4433427e+11 | F43: 3.862715e+10
A44: Variance | B44: 4.0682664e+12 | C44: 4.3642446e+12 | D44: 1.4531141e+15 | E44: 2.3461485e+17 | F44: 4.2688747e+21
A46: RL
A47: Count | B47: 2 | C47: 2 | D47: 2 | E47: 2 | F47: 8
A48: Sum | B48: 8.1401685e+08 | C48: 1.9795012e+09 | D48: 17227173415 | E48: 285872513805 | F48: 3.0589321e+11
...

Sheet ANOVA - Makespan
A1: Anova: Two-Factor With Replication
A3: SUMMARY | B3: Load 1 | C3: Load 2 | D3: Load 3 | E3: Load 4 | F3: Total
A4: QUEST
A5: Count | B5: 2 | C5: 2 | D5: 2 | E5: 2 | F5: 8
A6: Sum | B6: 2352448 | C6: 6563186 | D6: 43661409 | E6: 702200011 | F6: 754777054
A7: Average | B7: 1176224 | C7: 3281593 | D7: 21830704 | E7: 3.5110001e+08 | F7: 94347132
A8: Variance | B8: 2287855368 | C8: 36552131442 | D8: 1.1782522e+12 | E8: 1.351495e+15 | F8: 2.5380222e+16
A10: QUEST_NDVFS
A11: Count | B11: 2 | C11: 2 | D11: 2 | E11: 2 | F11: 8
A12: Sum | B12: 2334590 | C12: 6287273 | D12: 44813848 | E12: 692955657 | F12: 746391368
A13: Average | B13: 1167295 | C13: 3143636.5 | D13: 22406924 | E13: 3.4647783e+08 | F13: 93298921
A14: Variance | B14: 947778722 | C14: 7.1373768e+09 | D14: 605193615488 | E14: 2.6548127e+15 | F14: 2.4876903e+16
A16: Fuzzy
A17: Count | B17: 2 | C17: 2 | D17: 2 | E17: 2 | F17: 8
A18: Sum | B18: 2310137 | C18: 7781666 | D18: 45783367 | E18: 744217527 | F18: 800092697
A19: Average | B19: 1155068.5 | C19: 3890833 | D19: 22891684 | E19: 3.7210876e+08 | F19: 1.0001159e+08
A20: Variance | B20: 180.5 | C20: 8 | D20: 60.5 | E20: 364.5 | F20: 2.8284618e+16
A22: NSGA3
A23: Count | B23: 2 | C23: 2 | D23: 2 | E23: 2 | F23: 8
A24: Sum | B24: 2636200 | C24: 6890180 | D24: 54622745 | E24: 863438166 | F24: 927587291
A25: Average | B25: 1318100 | C25: 3445090 | D25: 27311372 | E25: 431719083 | F25: 1.1594841e+08
A26: Variance | B26: 11627515008 | C26: 35628481800 | D26: 1.4693042e+12 | E26: 6481936944722 | F26: 3.8105356e+16
A28: MQGA
A29: Count | B29: 2 | C29: 2 | D29: 2 | E29: 2 | F29: 8
A30: Sum | B30: 2477489 | C30: 6572269 | D30: 49070532 | E30: 819156977 | F30: 877277267
A31: Average | B31: 1238744.5 | C31: 3286134.5 | D31: 24535266 | E31: 4.0957849e+08 | F31: 1.0965966e+08
A32: Variance | B32: 2.1584186e+08 | C32: 6.2434725e+09 | D32: 372570931328 | E32: 2.8485515e+14 | F32: 3.4403001e+16
A34: Greedy
A35: Count | B35: 2 | C35: 2 | D35: 2 | E35: 2 | F35: 8
A36: Sum | B36: 2606489 | C36: 7081429 | D36: 52825173 | E36: 840435476 | F36: 902948567
A37: Average | B37: 1303244.5 | C37: 3540714.5 | D37: 26412586 | E37: 420217738 | F37: 1.1286857e+08
A38: Variance | B38: 1.7385535e+09 | C38: 1.0202141e+11 | D38: 2.588561e+12 | E38: 8.8137471e+15 | F38: 3.7355934e+16
A40: MOPSO
A41: Count | B41: 2 | C41: 2 | D41: 2 | E41: 2 | F41: 8
A42: Sum | B42: 2536166 | C42: 6991993 | D42: 51322719 | E42: 849365849 | F42: 910216727
A43: Average | B43: 1268083 | C43: 3495996.5 | D43: 25661360 | E43: 4.2468292e+08 | F43: 1.1377709e+08
A44: Variance | B44: 122617800 | C44: 2.2740094e+09 | D44: 1.9652876e+11 | E44: 1.4758587e+13 | F44: 3.6929856e+16
A46: RL
A47: Count | B47: 2 | C47: 2 | D47: 2 | E47: 2 | F47: 8
A48: Sum | B48: 2508718 | C48: 6391446 | D48: 51090148 | E48: 827578378 | F48: 887568690
...
