Workbook

Sheet Charts
R2: AoI | S2: Montage | T2: Cybershake | U2: Inspiral | V2: Epigenomics
R3: QUEST | S3: ='Data Age'!B49 -> 65375.266 | T3: ='Data Age'!C49 -> 89472.426 | U3: ='Data Age'!D49 -> 932218.07 | V3: ='Data Age'!E49 -> 13520966
R4: QUEST_NDVFS | S4: ='Data Age'!B50 -> 49800.036 | T4: ='Data Age'!C50 -> 67176.996 | U4: ='Data Age'!D50 -> 794046.79 | V4: ='Data Age'!E50 -> 9776850.3
R5: Fuzzy | S5: ='Data Age'!B51 -> 54823.944 | T5: ='Data Age'!C51 -> 73249.958 | U5: ='Data Age'!D51 -> 970411.22 | V5: ='Data Age'!E51 -> 11673941
R6: NSGA3 | S6: ='Data Age'!B52 -> 59931.091 | T6: ='Data Age'!C52 -> 131771.21 | U6: ='Data Age'!D52 -> 1080662 | V6: ='Data Age'!E52 -> 13231220
R7: MQGA | S7: ='Data Age'!B53 -> 60762.517 | T7: ='Data Age'!C53 -> 105789.92 | U7: ='Data Age'!D53 -> 971201.93 | V7: ='Data Age'!E53 -> 12182372
R8: Greedy | S8: ='Data Age'!B54 -> 63824.052 | T8: ='Data Age'!C54 -> 116320.43 | U8: ='Data Age'!D54 -> 1068806.4 | V8: ='Data Age'!E54 -> 11155057
R9: MOPSO | S9: ='Data Age'!B55 -> 58931.569 | T9: ='Data Age'!C55 -> 167763.44 | U9: ='Data Age'!D55 -> 957764.4 | V9: ='Data Age'!E55 -> 12601391
R10: RL | S10: ='Data Age'!B56 -> 61381.839 | T10: ='Data Age'!C56 -> 89533.392 | U10: ='Data Age'!D56 -> 974847.72 | V10: ='Data Age'!E56 -> 12508267
R17: AoI | S17: Montage | T17: Cybershake | U17: Inspiral | V17: Epigenomics
R18: QUEST | S18: =S3/S3 -> 1 | T18: =T3/T3 -> 1 | U18: =U3/U3 -> 1 | V18: =V3/V3 -> 1
R19: QUEST_NDVFS | S19: =S4/S3 -> 0.76175653 | T19: =T4/T3 -> 0.75081228 | U19: =U4/U3 -> 0.85178223 | V19: =V4/V3 -> 0.72308814
R20: Fuzzy | S20: =S5/S3 -> 0.83860376 | T20: =T5/T3 -> 0.81868751 | U20: =U5/U3 -> 1.0409702 | V20: =V5/V3 -> 0.86339546
R21: NSGA3 | S21: =S6/S3 -> 0.91672423 | T21: =T6/T3 -> 1.4727577 | U21: =U6/U3 -> 1.1592374 | V21: =V6/V3 -> 0.97857062
R22: MQGA | S22: =S7/S3 -> 0.92944198 | T22: =T7/T3 -> 1.1823746 | U22: =U7/U3 -> 1.0418184 | V22: =V7/V3 -> 0.90099866
R23: Greedy | S23: =S8/S3 -> 0.97627215 | T23: =T8/T3 -> 1.3000701 | U23: =U8/U3 -> 1.1465198 | V23: =V8/V3 -> 0.82501926
R24: MOPSO | S24: =S9/S3 -> 0.90143525 | T24: =T9/T3 -> 1.8750295 | U24: =U9/U3 -> 1.0274038 | V24: =V9/V3 -> 0.93198895
R25: RL | S25: =S10/S3 -> 0.93891531 | T25: =T10/T3 -> 1.0006814 | U25: =U10/U3 -> 1.0457293 | V25: =V10/V3 -> 0.92510159
R36: Energy | S36: Montage | T36: Cybershake | U36: Inspiral | V36: Epigenomics
R37: QUEST | S37: =Energy!B49 -> 3.9633171e+08 | T37: =Energy!C49 -> 8.4217643e+08 | U37: =Energy!D49 -> 5.3166244e+09 | V37: =Energy!E49 -> 7.6315705e+10
R38: QUEST_NDVFS | S38: =Energy!B50 -> 5.394598e+08 | T38: =Energy!C50 -> 1.2359016e+09 | U38: =Energy!D50 -> 8.7899447e+09 | V38: =Energy!E50 -> 150001327115
R39: Fuzzy | S39: =Energy!B51 -> 5.041572e+08 | T39: =Energy!C51 -> 1.4166506e+09 | U39: =Energy!D51 -> 9298549255 | V39: =Energy!E51 -> 137573600310
R40: NSGA3 | S40: =Energy!B52 -> 6.0548776e+08 | T40: =Energy!C52 -> 1.3894586e+09 | U40: =Energy!D52 -> 12082251500 | V40: =Energy!E52 -> 197858077970
R41: MQGA | S41: =Energy!B53 -> 5.660321e+08 | T41: =Energy!C53 -> 1.2390432e+09 | U41: =Energy!D53 -> 9.7929595e+09 | V41: =Energy!E53 -> 1.7307923e+11
R42: Greedy | S42: =Energy!B54 -> 6.0234251e+08 | T42: =Energy!C54 -> 1.3409222e+09 | U42: =Energy!D54 -> 10329583090 | V42: =Energy!E54 -> 1.6552562e+11
R43: MOPSO | S43: =Energy!B55 -> 576947460 | T43: =Energy!C55 -> 1.3353445e+09 | U43: =Energy!D55 -> 10294011245 | V43: =Energy!E55 -> 1.8250356e+11
R44: RL | S44: =Energy!B56 -> 5.9021183e+08 | T44: =Energy!C56 -> 1.2783681e+09 | U44: =Energy!D56 -> 1.0471703e+10 | V44: =Energy!E56 -> 1.8513377e+11
R51: Energy | S51: Montage | T51: Cybershake | U51: Inspiral | V51: Epigenomics
R52: QUEST | S52: =S37/S37 -> 1 | T52: =T37/T37 -> 1 | U52: =U37/U37 -> 1 | V52: =V37/V37 -> 1
R53: QUEST_NDVFS | S53: =S38/S37 -> 1.3611321 | T53: =T38/T37 -> 1.4675091 | U53: =U38/U37 -> 1.6532943 | V53: =V38/V37 -> 1.9655368
R54: Fuzzy | S54: =S39/S37 -> 1.2720587 | T54: =T39/T37 -> 1.6821305 | U54: =U39/U37 -> 1.7489573 | V54: =V39/V37 -> 1.8026905
R55: NSGA3 | S55: =S40/S37 -> 1.5277298 | T55: =T40/T37 -> 1.6498426 | U55: =U40/U37 -> 2.2725419 | V55: =V40/V37 -> 2.5926259
R56: MQGA | S56: =S41/S37 -> 1.4281777 | T56: =T41/T37 -> 1.4712394 | U56: =U41/U37 -> 1.8419506 | V56: =V41/V37 -> 2.2679372
R57: Greedy | S57: =S42/S37 -> 1.5197939 | T57: =T42/T37 -> 1.5922105 | U57: =U42/U37 -> 1.9428837 | V57: =V42/V37 -> 2.1689588
R58: MOPSO | S58: =S43/S37 -> 1.4557186 | T58: =T43/T37 -> 1.5855876 | U58: =U43/U37 -> 1.9361931 | V58: =V43/V37 -> 2.3914287
R59: RL | S59: =S44/S37 -> 1.4891865 | T59: =T44/T37 -> 1.5179338 | U59: =U44/U37 -> 1.969615 | V59: =V44/V37 -> 2.4258934
R67: Makespan | S67: Montage | T67: Cybershake | U67: Inspiral | V67: Epigenomics
R68: QUEST | S68: =Makespan!B49 -> 689652 | T68: =Makespan!C49 -> 1492468.5 | U68: =Makespan!D49 -> 9783642 | V68: =Makespan!E49 -> 1.5592486e+08
R69: QUEST_NDVFS | S69: =Makespan!B50 -> 681691.5 | T69: =Makespan!C50 -> 1571988.5 | U69: =Makespan!D50 -> 9899651 | V69: =Makespan!E50 -> 1.735997e+08
R70: Fuzzy | S70: =Makespan!B51 -> 610420 | T70: =Makespan!C51 -> 1824271 | U70: =Makespan!D51 -> 10282758 | V70: =Makespan!E51 -> 1.4247688e+08
...

Sheet Data Age
A1: Algorithm | B1: Load | C1: Average | D1: Min | E1: Max | F1: Std Dev
A2: QUEST | B2: 1 | C2: 65375.266 | D2: 64654.591 | E2: 66095.941 | F2: 720.67483
A3: QUEST | B3: 2 | C3: 89472.426 | D3: 87876.788 | E3: 91068.063 | F3: 1595.6374
A4: QUEST | B4: 3 | C4: 932218.07 | D4: 931884.34 | E4: 932551.8 | F4: 333.73127
A5: QUEST | B5: 4 | C5: 13520966 | D5: 13492389 | E5: 13549543 | F5: 28576.934
A6: QUEST_NDVFS | B6: 1 | C6: 49800.036 | D6: 49717.191 | E6: 49882.881 | F6: 82.845155
A7: QUEST_NDVFS | B7: 2 | C7: 67176.996 | D7: 67083.433 | E7: 67270.558 | F7: 93.562937
A8: QUEST_NDVFS | B8: 3 | C8: 794046.79 | D8: 784041.94 | E8: 804051.63 | F8: 10004.846
A9: QUEST_NDVFS | B9: 4 | C9: 9776850.3 | D9: 9579675.8 | E9: 9974024.7 | F9: 197174.43
A10: Fuzzy | B10: 1 | C10: 54823.944 | D10: 54823.724 | E10: 54824.164 | F10: 0.21978022
A11: Fuzzy | B11: 2 | C11: 73249.958 | D11: 73249.036 | E11: 73250.879 | F11: 0.92157842
A12: Fuzzy | B12: 3 | C12: 970411.22 | D12: 970410.95 | E12: 970411.48 | F12: 0.26523477
A13: Fuzzy | B13: 4 | C13: 11673941 | D13: 11673940 | E13: 11673942 | F13: 1.249499
... A33: RL | B33: 4 | C33: 12508267 | D33: 12182168 | E33: 12834366 | F33: 326098.82
A36: Summary by Algorithm
A37: QUEST | C37: 3652008 | D37: 64654.591 | E37: 13549543 | F37: 5708546.3
A38: QUEST_NDVFS | C38: 2671968.5 | D38: 49717.191 | E38: 9974024.7 | F38: 4114171.2
A39: Fuzzy | C39: 3193106.5 | D39: 54823.724 | E39: 11673942 | F39: 4910378
A40: NSGA3 | C40: 3625896.1 | D40: 59791.357 | E40: 14696344 | F40: 5608361.6
A41: MQGA | C41: 3330031.7 | D41: 60552.624 | E41: 12364893 | F41: 5124581.9
A42: Greedy | C42: 3101002.1 | D42: 56062.994 | E42: 11816985 | F42: 4679331.5
A43: MOPSO | C43: 3446462.6 | D43: 57632.264 | E43: 13017221 | F43: 5301109.8
A44: RL | C44: 3408507.6 | D44: 59076.673 | E44: 12834366 | F44: 5269099
A47: Average data for chart
A48: Algorithms | B48: 1 | C48: 2 | D48: 3 | E48: 4
A49: QUEST | B49: 65375.266 | C49: 89472.426 | D49: 932218.07 | E49: 13520966
A50: QUEST_NDVFS | B50: 49800.036 | C50: 67176.996 | D50: 794046.79 | E50: 9776850.3
A51: Fuzzy | B51: 54823.944 | C51: 73249.958 | D51: 970411.22 | E51: 11673941
A52: NSGA3 | B52: 59931.091 | C52: 131771.21 | D52: 1080662 | E52: 13231220
A53: MQGA | B53: 60762.517 | C53: 105789.92 | D53: 971201.93 | E53: 12182372
A54: Greedy | B54: 63824.052 | C54: 116320.43 | D54: 1068806.4 | E54: 11155057
A55: MOPSO | B55: 58931.569 | C55: 167763.44 | D55: 957764.4 | E55: 12601391
A56: RL | B56: 61381.839 | C56: 89533.392 | D56: 974847.72 | E56: 12508267
A59: All data for chart
A60: Algorithms | B60: 1 | C60: 1 | D60: 2 | E60: 2 | F60: 3 | G60: 3 | H60: 4 | I60: 4
A61: QUEST | B61: 66095.941 | C61: 64654.591 | D61: 87876.788 | E61: 91068.063 | F61: 932551.8 | G61: 931884.34 | H61: 13549543 | I61: 13492389
A62: QUEST_NDVFS | B62: 49882.881 | C62: 49717.191 | D62: 67270.558 | E62: 67083.433 | F62: 804051.63 | G62: 784041.94 | H62: 9974024.7 | I62: 9579675.8
A63: Fuzzy | B63: 54823.724 | C63: 54824.164 | D63: 73249.036 | E63: 73250.879 | F63: 970411.48 | G63: 970410.95 | H63: 11673940 | I63: 11673942
A64: NSGA3 | B64: 60070.825 | C64: 59791.357 | D64: 115690.84 | E64: 147851.58 | F64: 1030163.6 | G64: 1131160.5 | H64: 11766096 | I64: 14696344
A65: MQGA | B65: 60552.624 | C65: 60972.41 | D65: 106836.09 | E65: 104743.75 | F65: 958064.12 | G65: 984339.74 | H65: 11999852 | I65: 12364893
...

Sheet Energy
A1: Algorithm | B1: Load | C1: Average | D1: Min | E1: Max | F1: Std Dev
A2: QUEST | B2: 1 | C2: 3.9633171e+08 | D2: 3.8948219e+08 | E2: 4.0318123e+08 | F2: 6849523.1
A3: QUEST | B3: 2 | C3: 8.4217643e+08 | D3: 8.3404567e+08 | E3: 8.503072e+08 | F3: 8130766.4
A4: QUEST | B4: 3 | C4: 5.3166244e+09 | D4: 5.250753e+09 | E4: 5.3824958e+09 | F4: 65871398
A5: QUEST | B5: 4 | C5: 7.6315705e+10 | D5: 7.455023e+10 | E5: 7.808118e+10 | F5: 1.765475e+09
A6: QUEST_NDVFS | B6: 1 | C6: 5.394598e+08 | D6: 5.1748611e+08 | E6: 5.6143348e+08 | F6: 21973685
A7: QUEST_NDVFS | B7: 2 | C7: 1.2359016e+09 | D7: 1.2118841e+09 | E7: 1.2599191e+09 | F7: 24017473
A8: QUEST_NDVFS | B8: 3 | C8: 8.7899447e+09 | D8: 8231996005 | E8: 9347893400 | F8: 5.579487e+08
A9: QUEST_NDVFS | B9: 4 | C9: 150001327115 | D9: 142103790500 | E9: 157898863730 | F9: 7897536615
A10: Fuzzy | B10: 1 | C10: 5.041572e+08 | D10: 5.0415592e+08 | E10: 5.0415848e+08 | F10: 1280
A11: Fuzzy | B11: 2 | C11: 1.4166506e+09 | D11: 1.416643e+09 | E11: 1.4166583e+09 | F11: 7680
A12: Fuzzy | B12: 3 | C12: 9298549255 | D12: 9298539655 | E12: 9298558855 | F12: 9600
A13: Fuzzy | B13: 4 | C13: 137573600310 | D13: 137573599990 | E13: 137573600630 | F13: 320
... A33: RL | B33: 4 | C33: 1.8513377e+11 | D33: 184987471165 | E33: 185280064890 | F33: 1.4629686e+08
A36: Summary by Algorithm
A37: QUEST | C37: 2.0717709e+10 | D37: 3.8948219e+08 | E37: 7.808118e+10 | F37: 3.2169268e+10
A38: QUEST_NDVFS | C38: 4.0141658e+10 | D38: 5.1748611e+08 | E38: 157898863730 | F38: 6.3633231e+10
A39: Fuzzy | C39: 3.7198239e+10 | D39: 5.0415592e+08 | E39: 137573600630 | F39: 5.8052527e+10
A40: NSGA3 | C40: 5.2983819e+10 | D40: 577012780 | E40: 207978329810 | F40: 8.3919491e+10
A41: MQGA | C41: 4.6169316e+10 | D41: 564815675 | E41: 173885034235 | F41: 7.3362806e+10
A42: Greedy | C42: 4.4449617e+10 | D42: 5.7533032e+08 | E42: 178708007495 | F42: 7.0319245e+10
A43: MOPSO | C43: 4.8677467e+10 | D43: 5.7400624e+08 | E43: 185031995525 | F43: 7.7369316e+10
A44: RL | C44: 4.9368513e+10 | D44: 5.6648782e+08 | E44: 185280064890 | F44: 7.8481374e+10
A47: Average data for chart
A48: Algorithms | B48: 1 | C48: 2 | D48: 3 | E48: 4
A49: QUEST | B49: 3.9633171e+08 | C49: 8.4217643e+08 | D49: 5.3166244e+09 | E49: 7.6315705e+10
A50: QUEST_NDVFS | B50: 5.394598e+08 | C50: 1.2359016e+09 | D50: 8.7899447e+09 | E50: 150001327115
A51: Fuzzy | B51: 5.041572e+08 | C51: 1.4166506e+09 | D51: 9298549255 | E51: 137573600310
A52: NSGA3 | B52: 6.0548776e+08 | C52: 1.3894586e+09 | D52: 12082251500 | E52: 197858077970
A53: MQGA | B53: 5.660321e+08 | C53: 1.2390432e+09 | D53: 9.7929595e+09 | E53: 1.7307923e+11
A54: Greedy | B54: 6.0234251e+08 | C54: 1.3409222e+09 | D54: 10329583090 | E54: 1.6552562e+11
A55: MOPSO | B55: 576947460 | C55: 1.3353445e+09 | D55: 10294011245 | E55: 1.8250356e+11
A56: RL | B56: 5.9021183e+08 | C56: 1.2783681e+09 | D56: 1.0471703e+10 | E56: 1.8513377e+11
A59: All data for chart
A60: Algorithms | B60: 1 | C60: 1 | D60: 2 | E60: 2 | F60: 3 | G60: 3 | H60: 4 | I60: 4
A61: QUEST | B61: 4.0318123e+08 | C61: 3.8948219e+08 | D61: 8.3404567e+08 | E61: 8.503072e+08 | F61: 5.250753e+09 | G61: 5.3824958e+09 | H61: 7.808118e+10 | I61: 7.455023e+10
A62: QUEST_NDVFS | B62: 5.6143348e+08 | C62: 5.1748611e+08 | D62: 1.2118841e+09 | E62: 1.2599191e+09 | F62: 8231996005 | G62: 9347893400 | H62: 142103790500 | I62: 157898863730
A63: Fuzzy | B63: 5.0415848e+08 | C63: 5.0415592e+08 | D63: 1.4166583e+09 | E63: 1.416643e+09 | F63: 9298539655 | G63: 9298558855 | H63: 137573600630 | I63: 137573599990
A64: NSGA3 | B64: 6.3396274e+08 | C64: 577012780 | D64: 1.3337814e+09 | E64: 1.4451357e+09 | F64: 11344847505 | G64: 12819655495 | H64: 187737826130 | I64: 207978329810
A65: MQGA | B65: 5.6724853e+08 | C65: 564815675 | D65: 1.2535789e+09 | E65: 1.2245074e+09 | F65: 9823000805 | G65: 9762918190 | H65: 173885034235 | I65: 172273428000
...

Sheet Makespan
A1: Algorithm | B1: Load | C1: Average | D1: Min | E1: Max | F1: Std Dev
A2: QUEST | B2: 1 | C2: 689652 | D2: 684619 | E2: 694685 | F2: 5033
A3: QUEST | B3: 2 | C3: 1492468.5 | D3: 1473739 | E3: 1511198 | F3: 18729.5
A4: QUEST | B4: 3 | C4: 9783642 | D4: 9666372 | E4: 9900912 | F4: 117270
A5: QUEST | B5: 4 | C5: 1.5592486e+08 | D5: 148587369 | E5: 163262348 | F5: 7337489.5
A6: QUEST_NDVFS | B6: 1 | C6: 681691.5 | D6: 645316 | E6: 718067 | F6: 36375.5
A7: QUEST_NDVFS | B7: 2 | C7: 1571988.5 | D7: 1524249 | E7: 1619728 | F7: 47739.5
A8: QUEST_NDVFS | B8: 3 | C8: 9899651 | D8: 9001812 | E8: 10797490 | F8: 897839
A9: QUEST_NDVFS | B9: 4 | C9: 1.735997e+08 | D9: 161213607 | E9: 185985786 | F9: 12386090
A10: Fuzzy | B10: 1 | C10: 610420 | D10: 610418 | E10: 610422 | F10: 2
A11: Fuzzy | B11: 2 | C11: 1824271 | D11: 1824259 | E11: 1824283 | F11: 12
A12: Fuzzy | B12: 3 | C12: 10282758 | D12: 10282743 | E12: 10282773 | F12: 15
A13: Fuzzy | B13: 4 | C13: 1.4247688e+08 | D13: 142476879 | E13: 142476880 | F13: 0.5
... A33: RL | B33: 4 | C33: 219023506 | D33: 216678160 | E33: 221368852 | F33: 2345346
A36: Summary by Algorithm
A37: QUEST | C37: 41972655 | D37: 684619 | E37: 163262348 | F37: 65988677
A38: QUEST_NDVFS | C38: 46438257 | D38: 645316 | E38: 185985786 | F38: 73766476
A39: Fuzzy | C39: 38798582 | D39: 610418 | E39: 142476880 | F39: 59974530
A40: NSGA3 | C40: 63104756 | D40: 726473 | E40: 248010392 | F40: 99760978
A41: MQGA | C41: 53200280 | D41: 710114 | E41: 201226679 | F41: 84518903
A42: Greedy | C42: 51702528 | D42: 728259 | E42: 211623298 | F42: 81910045
A43: MOPSO | C43: 57163526 | D43: 716908 | E43: 218815227 | F43: 90861412
A44: RL | C44: 58400882 | D44: 710726 | E44: 221368852 | F44: 92852894
A47: Average data for chart
A48: Algorithms | B48: 1 | C48: 2 | D48: 3 | E48: 4
A49: QUEST | B49: 689652 | C49: 1492468.5 | D49: 9783642 | E49: 1.5592486e+08
A50: QUEST_NDVFS | B50: 681691.5 | C50: 1571988.5 | D50: 9899651 | E50: 1.735997e+08
A51: Fuzzy | B51: 610420 | C51: 1824271 | D51: 10282758 | E51: 1.4247688e+08
A52: NSGA3 | B52: 771607 | C52: 1796553 | D52: 14566156 | E52: 2.3528471e+08
A53: MQGA | B53: 710447.5 | C53: 1551975 | D53: 11127516 | E53: 199411181
A54: Greedy | B54: 764003.5 | C54: 1713791 | D54: 11950338 | E54: 192381979
A55: MOPSO | B55: 724873 | C55: 1694718 | D55: 11926550 | E55: 2.1430796e+08
A56: RL | B56: 745045.5 | C56: 1621505.5 | D56: 12213473 | E56: 219023506
A59: All data for chart
A60: Algorithms | B60: 1 | C60: 1 | D60: 2 | E60: 2 | F60: 3 | G60: 3 | H60: 4 | I60: 4
A61: QUEST | B61: 694685 | C61: 684619 | D61: 1473739 | E61: 1511198 | F61: 9900912 | G61: 9666372 | H61: 148587369 | I61: 163262348
A62: QUEST_NDVFS | B62: 718067 | C62: 645316 | D62: 1524249 | E62: 1619728 | F62: 9001812 | G62: 10797490 | H62: 161213607 | I62: 185985786
A63: Fuzzy | B63: 610422 | C63: 610418 | D63: 1824283 | E63: 1824259 | F63: 10282743 | G63: 10282773 | H63: 142476880 | I63: 142476879
A64: NSGA3 | B64: 816741 | C64: 726473 | D64: 1728612 | E64: 1864494 | F64: 13559755 | G64: 15572557 | H64: 222559023 | I64: 248010392
A65: MQGA | B65: 710781 | C65: 710114 | D65: 1564396 | E65: 1539554 | F65: 11222422 | G65: 11032610 | H65: 201226679 | I65: 197595683
...

Sheet Success Rate
A1: Algorithm | B1: Load | C1: Average | D1: Min | E1: Max | F1: Std Dev
A2: QUEST | B2: 1 | C2: 1 | D2: TRUE | E2: TRUE | F2: 0
A3: QUEST | B3: 2 | C3: 1 | D3: TRUE | E3: TRUE | F3: 0
A4: QUEST | B4: 3 | C4: 1 | D4: TRUE | E4: TRUE | F4: 0
A5: QUEST | B5: 4 | C5: 1 | D5: TRUE | E5: TRUE | F5: 0
A6: QUEST_NDVFS | B6: 1 | C6: 1 | D6: TRUE | E6: TRUE | F6: 0
A7: QUEST_NDVFS | B7: 2 | C7: 1 | D7: TRUE | E7: TRUE | F7: 0
A8: QUEST_NDVFS | B8: 3 | C8: 1 | D8: TRUE | E8: TRUE | F8: 0
A9: QUEST_NDVFS | B9: 4 | C9: 1 | D9: TRUE | E9: TRUE | F9: 0
A10: Fuzzy | B10: 1 | C10: 1 | D10: TRUE | E10: TRUE | F10: 0
A11: Fuzzy | B11: 2 | C11: 1 | D11: TRUE | E11: TRUE | F11: 0
A12: Fuzzy | B12: 3 | C12: 1 | D12: TRUE | E12: TRUE | F12: 0
A13: Fuzzy | B13: 4 | C13: 1 | D13: TRUE | E13: TRUE | F13: 0
... A33: RL | B33: 4 | C33: 1 | D33: TRUE | E33: TRUE | F33: 0
A36: Summary by Algorithm
A37: QUEST | C37: 1 | D37: TRUE | E37: TRUE | F37: 0
A38: QUEST_NDVFS | C38: 1 | D38: TRUE | E38: TRUE | F38: 0
A39: Fuzzy | C39: 1 | D39: TRUE | E39: TRUE | F39: 0
A40: NSGA3 | C40: 0.875 | D40: FALSE | E40: TRUE | F40: 0.33071891
A41: MQGA | C41: 1 | D41: TRUE | E41: TRUE | F41: 0
A42: Greedy | C42: 1 | D42: TRUE | E42: TRUE | F42: 0
A43: MOPSO | C43: 1 | D43: TRUE | E43: TRUE | F43: 0
A44: RL | C44: 1 | D44: TRUE | E44: TRUE | F44: 0
A47: Average data for chart
A48: Algorithms | B48: 1 | C48: 2 | D48: 3 | E48: 4
A49: QUEST | B49: 1 | C49: 1 | D49: 1 | E49: 1
A50: QUEST_NDVFS | B50: 1 | C50: 1 | D50: 1 | E50: 1
A51: Fuzzy | B51: 1 | C51: 1 | D51: 1 | E51: 1
A52: NSGA3 | B52: 0.5 | C52: 1 | D52: 1 | E52: 1
A53: MQGA | B53: 1 | C53: 1 | D53: 1 | E53: 1
A54: Greedy | B54: 1 | C54: 1 | D54: 1 | E54: 1
A55: MOPSO | B55: 1 | C55: 1 | D55: 1 | E55: 1
A56: RL | B56: 1 | C56: 1 | D56: 1 | E56: 1
A59: All data for chart
A60: Algorithms | B60: 1 | C60: 1 | D60: 2 | E60: 2 | F60: 3 | G60: 3 | H60: 4 | I60: 4
A61: QUEST | B61: TRUE | C61: TRUE | D61: TRUE | E61: TRUE | F61: TRUE | G61: TRUE | H61: TRUE | I61: TRUE
A62: QUEST_NDVFS | B62: TRUE | C62: TRUE | D62: TRUE | E62: TRUE | F62: TRUE | G62: TRUE | H62: TRUE | I62: TRUE
A63: Fuzzy | B63: TRUE | C63: TRUE | D63: TRUE | E63: TRUE | F63: TRUE | G63: TRUE | H63: TRUE | I63: TRUE
A64: NSGA3 | B64: FALSE | C64: TRUE | D64: TRUE | E64: TRUE | F64: TRUE | G64: TRUE | H64: TRUE | I64: TRUE
A65: MQGA | B65: TRUE | C65: TRUE | D65: TRUE | E65: TRUE | F65: TRUE | G65: TRUE | H65: TRUE | I65: TRUE
...

Sheet Load Edge
A1: Algorithm | B1: Load | C1: Average | D1: Min | E1: Max | F1: Std Dev
A2: QUEST | B2: 1 | C2: 504009.28 | D2: 499489.77 | E2: 508528.8 | F2: 4519.5167
A3: QUEST | B3: 2 | C3: 1120269.8 | D3: 1104886.6 | E3: 1135652.9 | F3: 15383.167
A4: QUEST | B4: 3 | C4: 12055898 | D4: 11981085 | E4: 12130711 | F4: 74812.8
A5: QUEST | B5: 4 | C5: 2.0722478e+08 | D5: 2.0598017e+08 | E5: 2.0846938e+08 | F5: 1244606.5
A6: QUEST_NDVFS | B6: 1 | C6: 340068.98 | D6: 338219.37 | E6: 341918.6 | F6: 1849.6167
A7: QUEST_NDVFS | B7: 2 | C7: 741918.13 | D7: 738341.07 | E7: 745495.2 | F7: 3577.0667
A8: QUEST_NDVFS | B8: 3 | C8: 8070633.2 | D8: 7971302.7 | E8: 8169963.7 | F8: 99330.5
A9: QUEST_NDVFS | B9: 4 | C9: 1.3753788e+08 | D9: 1.3688432e+08 | E9: 1.3819144e+08 | F9: 653558.9
A10: Fuzzy | B10: 1 | C10: 335816.53 | D10: 335816.53 | E10: 335816.53 | F10: 0
A11: Fuzzy | B11: 2 | C11: 739067.33 | D11: 739067.33 | E11: 739067.33 | F11: 0
A12: Fuzzy | B12: 3 | C12: 8070557.3 | D12: 8070557.3 | E12: 8070557.3 | F12: 0
A13: Fuzzy | B13: 4 | C13: 1.3691178e+08 | D13: 1.3691178e+08 | E13: 1.3691178e+08 | F13: 0
... A33: RL | B33: 4 | C33: 1.3577271e+08 | D33: 1.3557327e+08 | E33: 1.3597214e+08 | F33: 199434.73
A36: Summary by Algorithm
A37: QUEST | C37: 55226239 | D37: 499489.77 | E37: 2.0846938e+08 | F37: 87878847
A38: QUEST_NDVFS | C38: 36672625 | D38: 338219.37 | E38: 1.3819144e+08 | F38: 58316767
A39: Fuzzy | C39: 36514306 | D39: 335816.53 | E39: 1.3691178e+08 | F39: 58046211
A40: NSGA3 | C40: 36433308 | D40: 337250.23 | E40: 1.3755519e+08 | F40: 57907570
A41: MQGA | C41: 36659064 | D41: 334275.9 | E41: 1.3853603e+08 | F41: 58308033
A42: Greedy | C42: 36588343 | D42: 335908.87 | E42: 1.3882816e+08 | F42: 58166748
A43: MOPSO | C43: 36832825 | D43: 336675 | E43: 1.386887e+08 | F43: 58561599
A44: RL | C44: 36240807 | D44: 333640.7 | E44: 1.3597214e+08 | F44: 57548298
A47: Average data for chart
A48: Algorithms | B48: 1 | C48: 2 | D48: 3 | E48: 4
A49: QUEST | B49: 504009.28 | C49: 1120269.8 | D49: 12055898 | E49: 2.0722478e+08
A50: QUEST_NDVFS | B50: 340068.98 | C50: 741918.13 | D50: 8070633.2 | E50: 1.3753788e+08
A51: Fuzzy | B51: 335816.53 | C51: 739067.33 | D51: 8070557.3 | E51: 1.3691178e+08
A52: NSGA3 | B52: 338926.82 | C52: 739659.97 | D52: 8067686.8 | E52: 1.3658696e+08
A53: MQGA | B53: 336386.95 | C53: 743059.58 | D53: 8049212 | E53: 1.375076e+08
A54: Greedy | B54: 336047.65 | C54: 742679.4 | D54: 8090518.5 | E54: 1.3718413e+08
A55: MOPSO | B55: 336889.97 | C55: 746286.25 | D55: 8127059.2 | E55: 1.3812107e+08
A56: RL | B56: 334293.1 | C56: 739417.8 | D56: 8116811.5 | E56: 1.3577271e+08
A59: All data for chart
A60: Algorithms | B60: 1 | C60: 1 | D60: 2 | E60: 2 | F60: 3 | G60: 3 | H60: 4 | I60: 4
A61: QUEST | B61: 499489.77 | C61: 508528.8 | D61: 1104886.6 | E61: 1135652.9 | F61: 12130711 | G61: 11981085 | H61: 2.0598017e+08 | I61: 2.0846938e+08
A62: QUEST_NDVFS | B62: 341918.6 | C62: 338219.37 | D62: 738341.07 | E62: 745495.2 | F62: 8169963.7 | G62: 7971302.7 | H62: 1.3819144e+08 | I62: 1.3688432e+08
A63: Fuzzy | B63: 335816.53 | C63: 335816.53 | D63: 739067.33 | E63: 739067.33 | F63: 8070557.3 | G63: 8070557.3 | H63: 1.3691178e+08 | I63: 1.3691178e+08
A64: NSGA3 | B64: 340603.4 | C64: 337250.23 | D64: 739962.67 | E64: 739357.27 | F64: 8144873.8 | G64: 7990499.7 | H64: 1.3755519e+08 | I64: 1.3561873e+08
A65: MQGA | B65: 334275.9 | C65: 338498 | D65: 746984.47 | E65: 739134.7 | F65: 8003748.7 | G65: 8094675.4 | H65: 1.3853603e+08 | I65: 1.3647917e+08
...

Sheet Load Cloud
A1: Algorithm | B1: Load | C1: Average | D1: Min | E1: Max | F1: Std Dev
A2: QUEST | B2: 1 | C2: 548126 | D2: 525285 | E2: 570967 | F2: 22841
A3: QUEST | B3: 2 | C3: 1116089.5 | D3: 931510 | E3: 1300669 | F3: 184579.5
A4: QUEST | B4: 3 | C4: 12360382 | D4: 11280765 | E4: 13440000 | F4: 1079617.5
A5: QUEST | B5: 4 | C5: 3.0671026e+08 | D5: 209309004 | E5: 404111507 | F5: 97401252
A6: QUEST_NDVFS | B6: 1 | C6: 296372.5 | D6: 264244 | E6: 328501 | F6: 32128.5
A7: QUEST_NDVFS | B7: 2 | C7: 771092 | D7: 750073 | E7: 792111 | F7: 21019
A8: QUEST_NDVFS | B8: 3 | C8: 9708465 | D8: 7092450 | E8: 12324480 | F8: 2616015
A9: QUEST_NDVFS | B9: 4 | C9: 169142670 | D9: 152751880 | E9: 185533460 | F9: 16390790
A10: Fuzzy | B10: 1 | C10: 295327 | D10: 295327 | E10: 295327 | F10: 0
A11: Fuzzy | B11: 2 | C11: 643450 | D11: 643450 | E11: 643450 | F11: 0
A12: Fuzzy | B12: 3 | C12: 7008630 | D12: 7008630 | E12: 7008630 | F12: 0
A13: Fuzzy | B13: 4 | C13: 107724860 | D13: 107724860 | E13: 107724860 | F13: 0
... A33: RL | B33: 4 | C33: 150426915 | D33: 128622180 | E33: 172231650 | F33: 21804735
A36: Summary by Algorithm
A37: QUEST | C37: 80183713 | D37: 525285 | E37: 404111507 | F37: 1.3963882e+08
A38: QUEST_NDVFS | C38: 44979650 | D38: 264244 | E38: 185533460 | F38: 72261689
A39: Fuzzy | C39: 28918067 | D39: 295327 | E39: 107724860 | F39: 45577542
A40: NSGA3 | C40: 28556685 | D40: 200450 | E40: 110186900 | F40: 45177144
A41: MQGA | C41: 27877944 | D41: 261566 | E41: 124283680 | F41: 44604494
A42: Greedy | C42: 37425320 | D42: 244915 | E42: 173482310 | F42: 62414539
A43: MOPSO | C43: 23891290 | D43: 256783 | E43: 98963480 | F43: 37816805
A44: RL | C44: 39498521 | D44: 331930 | E44: 172231650 | F44: 65012102
A47: Average data for chart
A48: Algorithms | B48: 1 | C48: 2 | D48: 3 | E48: 4
A49: QUEST | B49: 548126 | C49: 1116089.5 | D49: 12360382 | E49: 3.0671026e+08
A50: QUEST_NDVFS | B50: 296372.5 | C50: 771092 | D50: 9708465 | E50: 169142670
A51: Fuzzy | B51: 295327 | C51: 643450 | D51: 7008630 | E51: 107724860
A52: NSGA3 | B52: 237509 | C52: 725812.5 | D52: 6645160 | E52: 106618260
A53: MQGA | B53: 303247 | C53: 579420.5 | D53: 8008255 | E53: 102620855
A54: Greedy | B54: 290738 | C54: 606036.5 | D54: 6888740 | E54: 141915765
A55: MOPSO | B55: 273604 | C55: 449261 | D55: 6197970 | E55: 88644325
A56: RL | B56: 333908 | C56: 722136.5 | D56: 6511125 | E56: 150426915
A59: All data for chart
A60: Algorithms | B60: 1 | C60: 1 | D60: 2 | E60: 2 | F60: 3 | G60: 3 | H60: 4 | I60: 4
A61: QUEST | B61: 570967 | C61: 525285 | D61: 1300669 | E61: 931510 | F61: 13440000 | G61: 11280765 | H61: 209309004 | I61: 404111507
A62: QUEST_NDVFS | B62: 264244 | C62: 328501 | D62: 792111 | E62: 750073 | F62: 7092450 | G62: 12324480 | H62: 152751880 | I62: 185533460
A63: Fuzzy | B63: 295327 | C63: 295327 | D63: 643450 | E63: 643450 | F63: 7008630 | G63: 7008630 | H63: 107724860 | I63: 107724860
A64: NSGA3 | B64: 200450 | C64: 274568 | D64: 843420 | E64: 608205 | F64: 5702170 | G64: 7588150 | H64: 103049620 | I64: 110186900
A65: MQGA | B65: 344928 | C65: 261566 | D65: 415261 | E65: 743580 | F65: 9442210 | G65: 6574300 | H65: 80958030 | I65: 124283680
...

Sheet Loads
A1: Average data for chart
B2: Edge | C2: Edge | D2: Edge | E2: Edge | F2: Edge | G2: Edge | H2: Edge | I2: Edge | J2: Edge | K2: Edge | L2: Edge | M2: Edge | N2: Edge | O2: Edge | P2: Edge | Q2: Edge | R2: Edge | S2: Edge | T2: Edge | U2: Edge | V2: Edge | W2: Edge | X2: Edge | Y2: Edge | Z2: Edge | AA2: Edge | AB2: Edge | AC2: Edge | AD2: Edge | AE2: Edge | AF2: Cloud | AG2: Edge | AH2: Edge | AI2: Edge | AJ2: Edge | AK2: Edge | AL2: Edge | AM2: Edge | AN2: Edge | AO2: Edge | AP2: Edge | AQ2: Edge | AR2: Edge | AS2: Edge | AT2: Edge | AU2: Edge | AV2: Edge | AW2: Edge | AX2: Edge | AY2: Edge | AZ2: Edge | BA2: Edge | BB2: Edge | BC2: Edge | BD2: Edge | BE2: Edge | BF2: Edge | BG2: Edge | BH2: Edge | BI2: Edge | BJ2: Edge | BK2: Cloud | BL2: Edge | BM2: Edge | BN2: Edge | BO2: Edge | BP2: Edge | BQ2: Edge | BR2: Edge | BS2: Edge | BT2: Edge | BU2: Edge | BV2: Edge | BW2: Edge | BX2: Edge | BY2: Edge | BZ2: Edge | CA2: Edge | CB2: Edge | CC2: Edge | CD2: Edge | CE2: Edge | CF2: Edge | CG2: Edge | CH2: Edge | CI2: Edge | CJ2: Edge | CK2: Edge | CL2: Edge | CM2: Edge | CN2: Edge | CO2: Edge | CP2: Cloud | CQ2: Edge | CR2: Edge | CS2: Edge | CT2: Edge | CU2: Edge | CV2: Edge | CW2: Edge | CX2: Edge | CY2: Edge | CZ2: Edge | DA2: Edge | DB2: Edge | DC2: Edge | DD2: Edge | DE2: Edge | DF2: Edge | DG2: Edge | DH2: Edge | DI2: Edge | DJ2: Edge | DK2: Edge | DL2: Edge | DM2: Edge | DN2: Edge | DO2: Edge | DP2: Edge | DQ2: Edge | DR2: Edge | DS2: Edge | DT2: Edge | DU2: Cloud
B3: 1 | C3: 1 | D3: 1 | E3: 1 | F3: 1 | G3: 1 | H3: 1 | I3: 1 | J3: 1 | K3: 1 | L3: 1 | M3: 1 | N3: 1 | O3: 1 | P3: 1 | Q3: 1 | R3: 1 | S3: 1 | T3: 1 | U3: 1 | V3: 1 | W3: 1 | X3: 1 | Y3: 1 | Z3: 1 | AA3: 1 | AB3: 1 | AC3: 1 | AD3: 1 | AE3: 1 | AF3: 1 | AG3: 2 | AH3: 2 | AI3: 2 | AJ3: 2 | AK3: 2 | AL3: 2 | AM3: 2 | AN3: 2 | AO3: 2 | AP3: 2 | AQ3: 2 | AR3: 2 | AS3: 2 | AT3: 2 | AU3: 2 | AV3: 2 | AW3: 2 | AX3: 2 | AY3: 2 | AZ3: 2 | BA3: 2 | BB3: 2 | BC3: 2 | BD3: 2 | BE3: 2 | BF3: 2 | BG3: 2 | BH3: 2 | BI3: 2 | BJ3: 2 | BK3: 2 | BL3: 3 | BM3: 3 | BN3: 3 | BO3: 3 | BP3: 3 | BQ3: 3 | BR3: 3 | BS3: 3 | BT3: 3 | BU3: 3 | BV3: 3 | BW3: 3 | BX3: 3 | BY3: 3 | BZ3: 3 | CA3: 3 | CB3: 3 | CC3: 3 | CD3: 3 | CE3: 3 | CF3: 3 | CG3: 3 | CH3: 3 | CI3: 3 | CJ3: 3 | CK3: 3 | CL3: 3 | CM3: 3 | CN3: 3 | CO3: 3 | CP3: 3 | CQ3: 4 | CR3: 4 | CS3: 4 | CT3: 4 | CU3: 4 | CV3: 4 | CW3: 4 | CX3: 4 | CY3: 4 | CZ3: 4 | DA3: 4 | DB3: 4 | DC3: 4 | DD3: 4 | DE3: 4 | DF3: 4 | DG3: 4 | DH3: 4 | DI3: 4 | DJ3: 4 | DK3: 4 | DL3: 4 | DM3: 4 | DN3: 4 | DO3: 4 | DP3: 4 | DQ3: 4 | DR3: 4 | DS3: 4 | DT3: 4 | DU3: 4
A4: Algorithms | B4: 1 | C4: 2 | D4: 3 | E4: 4 | F4: 5 | G4: 6 | H4: 7 | I4: 8 | J4: 9 | K4: 10 | L4: 11 | M4: 12 | N4: 13 | O4: 14 | P4: 15 | Q4: 16 | R4: 17 | S4: 18 | T4: 19 | U4: 20 | V4: 21 | W4: 22 | X4: 23 | Y4: 24 | Z4: 25 | AA4: 26 | AB4: 27 | AC4: 28 | AD4: 29 | AE4: 30 | AF4: 31 | AG4: 1 | AH4: 2 | AI4: 3 | AJ4: 4 | AK4: 5 | AL4: 6 | AM4: 7 | AN4: 8 | AO4: 9 | AP4: 10 | AQ4: 11 | AR4: 12 | AS4: 13 | AT4: 14 | AU4: 15 | AV4: 16 | AW4: 17 | AX4: 18 | AY4: 19 | AZ4: 20 | BA4: 21 | BB4: 22 | BC4: 23 | BD4: 24 | BE4: 25 | BF4: 26 | BG4: 27 | BH4: 28 | BI4: 29 | BJ4: 30 | BK4: 31 | BL4: 1 | BM4: 2 | BN4: 3 | BO4: 4 | BP4: 5 | BQ4: 6 | BR4: 7 | BS4: 8 | BT4: 9 | BU4: 10 | BV4: 11 | BW4: 12 | BX4: 13 | BY4: 14 | BZ4: 15 | CA4: 16 | CB4: 17 | CC4: 18 | CD4: 19 | CE4: 20 | CF4: 21 | CG4: 22 | CH4: 23 | CI4: 24 | CJ4: 25 | CK4: 26 | CL4: 27 | CM4: 28 | CN4: 29 | CO4: 30 | CP4: 31 | CQ4: 1 | CR4: 2 | CS4: 3 | CT4: 4 | CU4: 5 | CV4: 6 | CW4: 7 | CX4: 8 | CY4: 9 | CZ4: 10 | DA4: 11 | DB4: 12 | DC4: 13 | DD4: 14 | DE4: 15 | DF4: 16 | DG4: 17 | DH4: 18 | DI4: 19 | DJ4: 20 | DK4: 21 | DL4: 22 | DM4: 23 | DN4: 24 | DO4: 25 | DP4: 26 | DQ4: 27 | DR4: 28 | DS4: 29 | DT4: 30 | DU4: 31
A5: QUEST | B5: 16585.129 | C5: 22932.323 | D5: 22292.968 | E5: 21387.032 | F5: 22684.097 | G5: 21821.806 | H5: 23215.71 | I5: 22531.516 | J5: 24409.839 | K5: 22657.645 | L5: 24442.516 | M5: 23865.903 | N5: 24638.677 | O5: 23090.097 | P5: 22399.065 | Q5: 36333.387 | R5: 44437.032 | S5: 45255.452 | T5: 37205.774 | U5: 40466.935 | V5: 46654.677 | W5: 47129.645 | X5: 39304 | Y5: 44211.032 | Z5: 39561.226 | AA5: 48248.742 | AB5: 43900.194 | AC5: 44467.226 | AD5: 35414 | AE5: 43958.194 | AF5: 35362.968 | AG5: 53452.839 | AH5: 37839.387 | AI5: 66193.871 | AJ5: 59729.452 | AK5: 54287.419 | AL5: 60178.355 | AM5: 37701.161 | AN5: 50926.161 | AO5: 55539.968 | AP5: 56262.839 | AQ5: 60364.903 | AR5: 51373.968 | AS5: 41387.419 | AT5: 57883.968 | AU5: 49898.677 | AV5: 91116.226 | AW5: 87677.71 | AX5: 106266.97 | AY5: 77392.387 | AZ5: 107227.68 | BA5: 75098.452 | BB5: 88787.097 | BC5: 89525.935 | BD5: 87203.806 | BE5: 89419.097 | BF5: 74233.742 | BG5: 80978.806 | BH5: 118039.45 | BI5: 105097.23 | BJ5: 97179.097 | BK5: 72005.774 | BL5: 584341.48 | BM5: 627079.97 | BN5: 599160.48 | BO5: 626542 | BP5: 531688.39 | BQ5: 488066.71 | BR5: 541729.1 | BS5: 541779.68 | BT5: 619584.68 | BU5: 582145.19 | BV5: 471938.71 | BW5: 591823.84 | BX5: 582099.52 | BY5: 499869.94 | BZ5: 474712.55 | CA5: 1178134.8 | CB5: 837966.45 | CC5: 934972.26 | CD5: 881381.94 | CE5: 1040401.3 | CF5: 1186334.2 | CG5: 757894.19 | CH5: 1095938.1 | CI5: 834888.58 | CJ5: 943956.52 | CK5: 986176.13 | CL5: 918763.68 | CM5: 941755.32 | CN5: 1306213.2 | CO5: 1126657.4 | CP5: 797444.03 | CQ5: 6329410.5 | CR5: 9261385.3 | CS5: 8714346 | CT5: 8381139.3 | CU5: 9252577.6 | CV5: 9241371.2 | CW5: 8709682.3 | CX5: 9237380.3 | CY5: 6307852.7 | CZ5: 9244696.6 | DA5: 9218770.8 | DB5: 5774703.1 | DC5: 6120035.5 | DD5: 6398902.1 | DE5: 8587679.5 | DF5: 21338001 | DG5: 16589328 | DH5: 23779532 | DI5: 21446611 | DJ5: 12826432 | DK5: 11605426 | DL5: 22225021 | DM5: 14769453 | DN5: 21667036 | DO5: 20559873 | DP5: 19280194 | DQ5: 17017289 | DR5: 12860530 | DS5: 23359521 | DT5: 20976035 | DU5: 19787758
A6: QUEST_NDVFS | B6: 18322.161 | C6: 11673.548 | D6: 19338.032 | E6: 19918.194 | F6: 14405.935 | G6: 18594.968 | H6: 18497.516 | I6: 18259.452 | J6: 14240.161 | K6: 17729.613 | L6: 17978.935 | M6: 17002.161 | N6: 19611.935 | O6: 18791.839 | P6: 20523.581 | Q6: 24570.323 | R6: 23953.226 | S6: 22661.29 | T6: 24559.677 | U6: 27227.419 | V6: 27033.871 | W6: 27920.323 | X6: 24728.065 | Y6: 26237.419 | Z6: 31832.903 | AA6: 29179.677 | AB6: 23277.419 | AC6: 26739.355 | AD6: 28876.774 | AE6: 24512.258 | AF6: 19120.806 | AG6: 25566.516 | AH6: 37064.935 | AI6: 44474.323 | AJ6: 32644.032 | AK6: 27100 | AL6: 36460.29 | AM6: 48715.935 | AN6: 44617.548 | AO6: 39964 | AP6: 39636.355 | AQ6: 34201.129 | AR6: 47689.871 | AS6: 44636.677 | AT6: 48833.323 | AU6: 43399.323 | AV6: 62333.097 | AW6: 77457.387 | AX6: 50827.452 | AY6: 68997.677 | AZ6: 51185.484 | BA6: 50731.645 | BB6: 57180.839 | BC6: 47582.806 | BD6: 54089.839 | BE6: 54494 | BF6: 61785.935 | BG6: 54174.645 | BH6: 45580.452 | BI6: 66150.097 | BJ6: 38394.968 | BK6: 49747.871 | BL6: 317095.48 | BM6: 428959.35 | BN6: 294771.61 | BO6: 517303.55 | BP6: 263873.23 | BQ6: 479150.97 | BR6: 488829.03 | BS6: 397631.94 | BT6: 438777.74 | BU6: 480446.77 | BV6: 362148.39 | BW6: 483247.74 | BX6: 368390.65 | BY6: 470765.16 | BZ6: 490544.84 | CA6: 574475.23 | CB6: 652019.61 | CC6: 680626.06 | CD6: 573891.1 | CE6: 665117.81 | CF6: 658356.39 | CG6: 618710.32 | CH6: 874681.94 | CI6: 352374.97 | CJ6: 665713.94 | CK6: 477196.65 | CL6: 567864.39 | CM6: 853177.55 | CN6: 638734.84 | CO6: 485703.1 | CP6: 626352.58 | CQ6: 4575153.2 | CR6: 9697939.4 | CS6: 6137493.9 | CT6: 9829031 | CU6: 5547970.6 | CV6: 7875113.5 | CW6: 3944277.7 | CX6: 6923981.3 | CY6: 6648879.7 | CZ6: 4718362.3 | DA6: 7709567.1 | DB6: 5776537.7 | DC6: 4022285.8 | DD6: 5633161 | DE6: 6653961.6 | DF6: 15110826 | DG6: 8528832 | DH6: 10732533 | DI6: 11528248 | DJ6: 14494134 | DK6: 13957190 | DL6: 8030380.3 | DM6: 8521267 | DN6: 11306353 | DO6: 14128709 | DP6: 10105356 | DQ6: 13234994 | DR6: 8134645.2 | DS6: 11802710 | DT6: 10892457 | DU6: 10912430
A7: Fuzzy | B7: 24403.419 | C7: 23839.419 | D7: 22589.935 | E7: 21890 | F7: 20232.065 | G7: 19798.71 | H7: 19793.871 | I7: 19372.839 | J7: 19232.968 | K7: 19228.258 | L7: 19223.29 | M7: 19219.484 | N7: 19216.258 | O7: 19210.903 | P7: 19207.032 | Q7: 23042.581 | R7: 22921.935 | S7: 22912.258 | T7: 22907.742 | U7: 22905.161 | V7: 22899.355 | W7: 22896.129 | X7: 22891.613 | Y7: 22887.742 | Z7: 22882.581 | AA7: 22880 | AB7: 22874.194 | AC7: 22871.613 | AD7: 22870.323 | AE7: 22865.806 | AF7: 19053.355 | AG7: 52108.452 | AH7: 48253.677 | AI7: 47545.161 | AJ7: 46994 | AK7: 44864.968 | AL7: 44040.645 | AM7: 43610.516 | AN7: 43374.968 | AO7: 43268.581 | AP7: 43197.613 | AQ7: 43123.742 | AR7: 43001.806 | AS7: 42937.548 | AT7: 42869.935 | AU7: 42815.548 | AV7: 51274.194 | AW7: 51194.71 | AX7: 51125.161 | AY7: 51000.968 | AZ7: 50878.903 | BA7: 50766.065 | BB7: 50638.323 | BC7: 50516.968 | BD7: 50433.226 | BE7: 50331.032 | BF7: 50218.903 | BG7: 50120.968 | BH7: 50056.387 | BI7: 49983.29 | BJ7: 49906.645 | BK7: 41512.903 | BL7: 495726.45 | BM7: 494731.61 | BN7: 493861.29 | BO7: 492993.55 | BP7: 491712.26 | BQ7: 490381.29 | BR7: 489332.26 | BS7: 488157.42 | BT7: 486923.23 | BU7: 486016.13 | BV7: 485354.84 | BW7: 484870.32 | BX7: 483476.77 | BY7: 482648.39 | BZ7: 481582.58 | CA7: 560922.58 | CB7: 560204.9 | CC7: 558761.03 | CD7: 557686.45 | CE7: 556870.45 | CF7: 555592.26 | CG7: 554464.26 | CH7: 552692.13 | CI7: 551513.81 | CJ7: 550423.74 | CK7: 549419.61 | CL7: 548367.48 | CM7: 546397.94 | CN7: 545232.77 | CO7: 544115.61 | CP7: 452169.68 | CQ7: 8711200 | CR7: 8657970.3 | CS7: 8608596.1 | CT7: 8567962.6 | CU7: 8504243.9 | CV7: 8462838.7 | CW7: 8423398.1 | CX7: 8359714.8 | CY7: 8311305.8 | CZ7: 8259491 | DA7: 8230048.4 | DB7: 8196609 | DC7: 8102597.4 | DD7: 8085795.5 | DE7: 8045611 | DF7: 9620900.1 | DG7: 9601259.6 | DH7: 9556374.2 | DI7: 9495160.3 | DJ7: 9470540.1 | DK7: 9444340.6 | DL7: 9396958.5 | DM7: 9348005.4 | DN7: 9324329 | DO7: 9283169.8 | DP7: 9246535.7 | DQ7: 9227467.4 | DR7: 9172505 | DS7: 8888460.4 | DT7: 8387155.4 | DU7: 6949991
A8: NSGA3 | B8: 20445.645 | C8: 21283.29 | D8: 21965.71 | E8: 18058.968 | F8: 21372.806 | G8: 22982.839 | H8: 20333.968 | I8: 17340.032 | J8: 18840.968 | K8: 18355 | L8: 18255.935 | M8: 21352.903 | N8: 23104.613 | O8: 19486.226 | P8: 15554.613 | Q8: 25818.387 | R8: 21744.839 | S8: 27275.484 | T8: 24320.645 | U8: 26138.065 | V8: 21381.613 | W8: 23180.968 | X8: 22114.839 | Y8: 22635.806 | Z8: 27892.258 | AA8: 26123.548 | AB8: 19107.742 | AC8: 22352.258 | AD8: 24930.323 | AE8: 22237.097 | AF8: 15323.161 | AG8: 52597.742 | AH8: 33050.613 | AI8: 34469.387 | AJ8: 43164 | AK8: 35705.968 | AL8: 47701.548 | AM8: 62327.452 | AN8: 36199 | AO8: 43470.161 | AP8: 38865.355 | AQ8: 50004.903 | AR8: 45139.129 | AS8: 34317.355 | AT8: 33367.29 | AU8: 44010.29 | AV8: 40844.065 | AW8: 56215.677 | AX8: 50729.871 | AY8: 55139.097 | AZ8: 47104.484 | BA8: 36941.194 | BB8: 53012.194 | BC8: 30594.194 | BD8: 72727.032 | BE8: 67936 | BF8: 61644.355 | BG8: 50554.935 | BH8: 53564.677 | BI8: 58329.097 | BJ8: 61872.871 | BK8: 46826.613 | BL8: 549619.35 | BM8: 357793.23 | BN8: 452663.55 | BO8: 325303.87 | BP8: 369794.52 | BQ8: 667269.35 | BR8: 650413.87 | BS8: 540870.65 | BT8: 372745.16 | BU8: 582058.39 | BV8: 475541.29 | BW8: 530331.94 | BX8: 586448.06 | BY8: 507789.03 | BZ8: 527603.23 | CA8: 586911.48 | CB8: 654162.19 | CC8: 480496.65 | CD8: 592225.94 | CE8: 617906.32 | CF8: 527835.48 | CG8: 528430.06 | CH8: 524448 | CI8: 346431.48 | CJ8: 610380.39 | CK8: 519544.26 | CL8: 500253.29 | CM8: 661556.9 | CN8: 482554.84 | CO8: 485494.84 | CP8: 428720 | CQ8: 6511617.7 | CR8: 9748106.8 | CS8: 7507596.1 | CT8: 6729834.5 | CU8: 13313176 | CV8: 11312274 | CW8: 9893413.9 | CX8: 5634191.3 | CY8: 9059117.7 | CZ8: 10194993 | DA8: 9100550 | DB8: 7216242.6 | DC8: 6131671.6 | DD8: 6125196.8 | DE8: 10621206 | DF8: 6452237.4 | DG8: 7175218.5 | DH8: 9751076.5 | DI8: 9326557.2 | DJ8: 8279534.3 | DK8: 9057972.4 | DL8: 8807972.5 | DM8: 10836472 | DN8: 8847989.4 | DO8: 12519583 | DP8: 7678800 | DQ8: 6822328.6 | DR8: 10407860 | DS8: 8343181.2 | DT8: 10955883 | DU8: 6878597.4
A9: MQGA | B9: 22028.806 | C9: 18467.258 | D9: 19552.871 | E9: 18526.097 | F9: 18398.258 | G9: 21414.452 | H9: 20400.194 | I9: 18087.452 | J9: 22406.097 | K9: 19595.452 | L9: 18255.419 | M9: 20985.742 | N9: 18049.226 | O9: 18608.484 | P9: 23090.871 | Q9: 20988.71 | R9: 28328.71 | S9: 26757.742 | T9: 18829.677 | U9: 23553.871 | V9: 20984.516 | W9: 22087.097 | X9: 19270.645 | Y9: 19952.258 | Z9: 23494.516 | AA9: 27078.065 | AB9: 26681.935 | AC9: 26863.226 | AD9: 24935.161 | AE9: 23398.71 | AF9: 19564.323 | AG9: 44763.742 | AH9: 55127.161 | AI9: 49335.194 | AJ9: 33304.71 | AK9: 40835.935 | AL9: 53859.581 | AM9: 49998.097 | AN9: 50794.677 | AO9: 36003 | AP9: 31538.419 | AQ9: 36490.839 | AR9: 31059.871 | AS9: 45511.452 | AT9: 53630.516 | AU9: 45906.71 | AV9: 45760.355 | AW9: 69302.839 | AX9: 50306.194 | AY9: 70538.387 | AZ9: 59161.903 | BA9: 49892.097 | BB9: 41740.742 | BC9: 51647.839 | BD9: 58788.613 | BE9: 34968.29 | BF9: 40325.29 | BG9: 56660.29 | BH9: 50954.484 | BI9: 59325.129 | BJ9: 40647.484 | BK9: 37381.968 | BL9: 481493.23 | BM9: 527645.16 | BN9: 507130.32 | BO9: 393619.68 | BP9: 471726.77 | BQ9: 514836.77 | BR9: 529361.61 | BS9: 398610.97 | BT9: 481482.26 | BU9: 413566.45 | BV9: 421533.23 | BW9: 460984.52 | BX9: 585688.39 | BY9: 509502.26 | BZ9: 450201.94 | CA9: 650531.23 | CB9: 440106.19 | CC9: 497828.52 | CD9: 723065.81 | CE9: 691218.58 | CF9: 433940.52 | CG9: 490175.61 | CH9: 691414.84 | CI9: 473409.68 | CJ9: 494668.65 | CK9: 719928.39 | CL9: 476946.58 | CM9: 537930.58 | CN9: 586690.84 | CO9: 523880.52 | CP9: 516661.61 | CQ9: 6716043.5 | CR9: 7328229 | CS9: 11709380 | CT9: 6864774.5 | CU9: 8106898.1 | CV9: 7446944.2 | CW9: 8246794.5 | CX9: 4651592.3 | CY9: 9484670 | CZ9: 6419989.4 | DA9: 7670821.9 | DB9: 8469014.2 | DC9: 11063296 | DD9: 8248113.2 | DE9: 9310587.4 | DF9: 9358072.3 | DG9: 8256299.2 | DH9: 13876361 | DI9: 11207080 | DJ9: 12644389 | DK9: 8581701.3 | DL9: 4822957.2 | DM9: 9056190.2 | DN9: 8042363.2 | DO9: 6519209.8 | DP9: 14669561 | DQ9: 8641065.7 | DR9: 10234754 | DS9: 11062486 | DT9: 7434102.6 | DU9: 6620700.3
A10: Greedy | B10: 19774.226 | C10: 16195.71 | D10: 19267.581 | E10: 23238.387 | F10: 20200.419 | G10: 22775.645 | H10: 21055.774 | I10: 15386.935 | J10: 25578.516 | K10: 23803.677 | L10: 15238.968 | M10: 17886.161 | N10: 22748.032 | O10: 26608.161 | P10: 16236.613 | Q10: 20587.742 | R10: 22218.387 | S10: 28983.548 | T10: 21027.097 | U10: 19177.097 | V10: 22908.065 | W10: 23893.548 | X10: 22193.548 | Y10: 22386.129 | Z10: 20678.065 | AA10: 25685.806 | AB10: 22813.871 | AC10: 20870.645 | AD10: 28810.323 | AE10: 22186.129 | AF10: 18757.29 | AG10: 44503.516 | AH10: 52829.806 | AI10: 34330.548 | AJ10: 41447.871 | AK10: 24057.161 | AL10: 46018.645 | AM10: 46586.548 | AN10: 47264.226 | AO10: 52870.129 | AP10: 39485.258 | AQ10: 45509.355 | AR10: 40607.613 | AS10: 43788.613 | AT10: 50242.968 | AU10: 41991.484 | AV10: 52148.871 | AW10: 48472.742 | AX10: 57355.774 | AY10: 59428.387 | AZ10: 58742.129 | BA10: 44826.774 | BB10: 40929.226 | BC10: 64985.871 | BD10: 48449.677 | BE10: 58998.677 | BF10: 47903.226 | BG10: 65432.258 | BH10: 50766.065 | BI10: 43049.387 | BJ10: 44421.194 | BK10: 39099.129 | BL10: 384881.29 | BM10: 530471.61 | BN10: 430451.29 | BO10: 440565.16 | BP10: 425827.74 | BQ10: 414977.74 | BR10: 659573.87 | BS10: 412070.65 | BT10: 357982.9 | BU10: 503109.03 | BV10: 555857.74 | BW10: 524985.48 | BX10: 532420.32 | BY10: 569030 | BZ10: 438799.35 | CA10: 464766.58 | CB10: 578706.97 | CC10: 833500.65 | CD10: 667938.19 | CE10: 677502.19 | CF10: 462708.39 | CG10: 536644.26 | CH10: 517292.13 | CI10: 636912.77 | CJ10: 580693.94 | CK10: 523412.9 | CL10: 401359.35 | CM10: 570545.81 | CN10: 354949.55 | CO10: 671130.19 | CP10: 444434.84 | CQ10: 6481701 | CR10: 8122591.6 | CS10: 7574899.4 | CT10: 5032622.3 | CU10: 6654484.5 | CV10: 6798752.6 | CW10: 6262662.3 | CX10: 10348585 | CY10: 6899954.5 | CZ10: 6632589 | DA10: 6257685.2 | DB10: 7338434.5 | DC10: 7834804.5 | DD10: 9718957.4 | DE10: 7697855.8 | DF10: 16206364 | DG10: 7262264.9 | DH10: 11494962 | DI10: 11426841 | DJ10: 11811504 | DK10: 7266735.1 | DL10: 5689857.3 | DM10: 9246949.5 | DN10: 8955243.1 | DO10: 9137223.1 | DP10: 8138290.8 | DQ10: 16727893 | DR10: 10086795 | DS10: 9577091.6 | DT10: 12833072 | DU10: 9155855.8
A11: MOPSO | B11: 18205.161 | C11: 21644.935 | D11: 21077.903 | E11: 20946.258 | F11: 18030.839 | G11: 18104.935 | H11: 21459.129 | I11: 20439.71 | J11: 21988.129 | K11: 19346.903 | L11: 23144.645 | M11: 18577.806 | N11: 20174.645 | O11: 17139.355 | P11: 24193.452 | Q11: 28258.71 | R11: 22336.774 | S11: 18914.839 | T11: 26218.387 | U11: 18161.29 | V11: 25637.097 | W11: 24126.452 | X11: 24807.419 | Y11: 18636.129 | Z11: 25450.968 | AA11: 27368.71 | AB11: 22116.129 | AC11: 18849.032 | AD11: 23050 | AE11: 23639.355 | AF11: 17651.871 | AG11: 62244.419 | AH11: 48183 | AI11: 40728.258 | AJ11: 43806.903 | AK11: 41797.935 | AL11: 36068.258 | AM11: 33539.387 | AN11: 43962.323 | AO11: 47511.968 | AP11: 55987.581 | AQ11: 35070.516 | AR11: 41805.161 | AS11: 47154.032 | AT11: 42267.548 | AU11: 57188.226 | AV11: 64337.581 | AW11: 60566 | AX11: 57148.903 | AY11: 38109.677 | AZ11: 63736.129 | BA11: 66446.387 | BB11: 55339.226 | BC11: 49555 | BD11: 34490.323 | BE11: 49976.194 | BF11: 41588.161 | BG11: 50681.968 | BH11: 41033.903 | BI11: 41590.645 | BJ11: 52509.387 | BK11: 28984.581 | BL11: 402565.48 | BM11: 485492.26 | BN11: 431295.81 | BO11: 457807.1 | BP11: 545275.48 | BQ11: 384583.23 | BR11: 469865.81 | BS11: 429634.19 | BT11: 535801.94 | BU11: 404440.97 | BV11: 456830.65 | BW11: 599411.61 | BX11: 691635.16 | BY11: 376507.1 | BZ11: 423632.9 | CA11: 636203.61 | CB11: 408337.94 | CC11: 814006.06 | CD11: 494891.61 | CE11: 659563.35 | CF11: 522192.77 | CG11: 553352.52 | CH11: 484554.58 | CI11: 570533.81 | CJ11: 658493.42 | CK11: 635045.42 | CL11: 551075.23 | CM11: 564039.1 | CN11: 597105.29 | CO11: 485617.55 | CP11: 399869.03 | CQ11: 8475943.2 | CR11: 8500676.8 | CS11: 8725319.4 | CT11: 7768351.3 | CU11: 5919310 | CV11: 6738408.1 | CW11: 10675431 | CX11: 11006849 | CY11: 7935735.8 | CZ11: 6124689 | DA11: 6919004.2 | DB11: 6691357.7 | DC11: 6445088.1 | DD11: 8986681.9 | DE11: 10297804 | DF11: 11937015 | DG11: 9208390.5 | DH11: 9523515.5 | DI11: 9438997.5 | DJ11: 11065427 | DK11: 8734177.9 | DL11: 10655967 | DM11: 6671957.4 | DN11: 11361748 | DO11: 10020316 | DP11: 10841568 | DQ11: 5744609.8 | DR11: 15780298 | DS11: 6050405 | DT11: 9086052.8 | DU11: 5718988.7
A12: RL | B12: 20310.871 | C12: 16656.065 | D12: 19862.645 | E12: 25406.742 | F12: 23035.419 | G12: 23293.903 | H12: 17550.387 | I12: 18800.29 | J12: 20561.484 | K12: 21330.387 | L12: 18654.935 | M12: 19632.29 | N12: 20579.71 | O12: 20224.323 | P12: 20366.226 | Q12: 22336.452 | R12: 29545.161 | S12: 18685.806 | T12: 23451.29 | U12: 16823.548 | V12: 26028.065 | W12: 21902.581 | X12: 24502.258 | Y12: 19786.129 | Z12: 20497.742 | AA12: 21811.935 | AB12: 23427.419 | AC12: 22320.968 | AD12: 23347.419 | AE12: 26286.452 | AF12: 21542.452 | AG12: 34831.419 | AH12: 42271.581 | AI12: 40526.516 | AJ12: 54972.161 | AK12: 39416.839 | AL12: 42721.645 | AM12: 31388.677 | AN12: 46959.935 | AO12: 43534.032 | AP12: 47677.29 | AQ12: 44222.871 | AR12: 35120.71 | AS12: 50500.387 | AT12: 37280.097 | AU12: 46733.742 | AV12: 57632.903 | AW12: 50215 | AX12: 50512 | AY12: 41772.677 | AZ12: 44760.065 | BA12: 82121.742 | BB12: 47815.581 | BC12: 60726.387 | BD12: 46093.903 | BE12: 45654.968 | BF12: 54062.871 | BG12: 54449.645 | BH12: 46583.226 | BI12: 56472.226 | BJ12: 54100.129 | BK12: 46589.452 | BL12: 478326.77 | BM12: 462399.68 | BN12: 532752.26 | BO12: 402073.55 | BP12: 329413.23 | BQ12: 493514.19 | BR12: 425578.39 | BS12: 568998.39 | BT12: 534740.32 | BU12: 393524.84 | BV12: 502398.71 | BW12: 429228.06 | BX12: 642941.29 | BY12: 391705.48 | BZ12: 485133.87 | CA12: 462855.87 | CB12: 584665.94 | CC12: 396621.29 | CD12: 604859.61 | CE12: 587805.68 | CF12: 334151.61 | CG12: 676843.35 | CH12: 893083.74 | CI12: 622189.94 | CJ12: 611639.23 | CK12: 556049.42 | CL12: 684834.19 | CM12: 572052 | CN12: 540850.06 | CO12: 508726.84 | CP12: 420072.58 | CQ12: 8380474.8 | CR12: 7643805.5 | CS12: 8917779 | CT12: 6746068.4 | CU12: 7707376.1 | CV12: 8862939.4 | CW12: 5937133.2 | CX12: 8720910 | CY12: 8691313.2 | CZ12: 6221800.3 | DA12: 12418759 | DB12: 6476664.5 | DC12: 5523963.5 | DD12: 10325488 | DE12: 7446374.8 | DF12: 11771503 | DG12: 9627807.9 | DH12: 5820027.9 | DI12: 13718404 | DJ12: 8776750.8 | DK12: 7921895.2 | DL12: 9938029.2 | DM12: 13283880 | DN12: 12211012 | DO12: 7991092.6 | DP12: 7758786.2 | DQ12: 7801642.8 | DR12: 8241973.2 | DS12: 7930340.1 | DT12: 9971890.8 | DU12: 9704962.3
