Workbook

Sheet Charts
R2: AoI | S2: 30 | T2: 50 | U2: 100
R3: QUEST | S3: ='Data Age'!B41 -> 228384.12 | T3: ='Data Age'!C41 -> 262787.7 | U3: ='Data Age'!D41 -> 259098.12
R4: QUEST_NDVFS | S4: ='Data Age'!B42 -> 183637.36 | T4: ='Data Age'!C42 -> 205044.01 | U4: ='Data Age'!D42 -> 197145.45
R5: Fuzzy | S5: ='Data Age'!B43 -> 178707.61 | T5: ='Data Age'!C43 -> 202644.72 | U5: ='Data Age'!D43 -> 224775.43
R6: NSGA3 | S6: ='Data Age'!B44 -> 204612.72 | T6: ='Data Age'!C44 -> 225469.25 | U6: ='Data Age'!D44 -> 235244.7
R7: MQGA | S7: ='Data Age'!B45 -> 190131.1 | T7: ='Data Age'!C45 -> 217674.57 | U7: ='Data Age'!D45 -> 220894.32
R8: Greedy | S8: ='Data Age'!B46 -> 206897.43 | T8: ='Data Age'!C46 -> 227346.36 | U8: ='Data Age'!D46 -> 232771.1
R9: MOPSO | S9: ='Data Age'!B47 -> 200047 | T9: ='Data Age'!C47 -> 225637.13 | U9: ='Data Age'!D47 -> 230965.34
R10: RL | S10: ='Data Age'!B48 -> 207479.46 | T10: ='Data Age'!C48 -> 236773.49 | U10: ='Data Age'!D48 -> 230319.83
R17: AoI | S17: 30 | T17: 50 | U17: 100
R18: QUEST | S18: =S3/S3 -> 1 | T18: =T3/T3 -> 1 | U18: =U3/U3 -> 1
R19: QUEST_NDVFS | S19: =S4/S3 -> 0.80407234 | T19: =T4/T3 -> 0.78026488 | U19: =U4/U3 -> 0.76089109
R20: Fuzzy | S20: =S5/S3 -> 0.78248702 | T20: =T5/T3 -> 0.77113472 | U20: =U5/U3 -> 0.86753012
R21: NSGA3 | S21: =S6/S3 -> 0.89591482 | T21: =T6/T3 -> 0.85799013 | U21: =U6/U3 -> 0.90793672
R22: MQGA | S22: =S7/S3 -> 0.83250577 | T22: =T7/T3 -> 0.82832861 | U22: =U7/U3 -> 0.85255082
R23: Greedy | S23: =S8/S3 -> 0.90591863 | T23: =T8/T3 -> 0.8651332 | U23: =U8/U3 -> 0.89838974
R24: MOPSO | S24: =S9/S3 -> 0.87592341 | T24: =T9/T3 -> 0.85862897 | U24: =U9/U3 -> 0.89142033
R25: RL | S25: =S10/S3 -> 0.90846708 | T25: =T10/T3 -> 0.90100676 | U25: =U10/U3 -> 0.88892897
R36: Energy | S36: 30 | T36: 50 | U36: 100
R37: QUEST | S37: =Energy!B41 -> 7.6064548e+08 | T37: =Energy!C41 -> 8.3802643e+08 | U37: =Energy!D41 -> 8.0093201e+08
R38: QUEST_NDVFS | S38: =Energy!B42 -> 8.1726622e+08 | T38: =Energy!C42 -> 9.3676855e+08 | U38: =Energy!D42 -> 1.0017913e+09
R39: Fuzzy | S39: =Energy!B43 -> 824200412 | T39: =Energy!C43 -> 9.0570167e+08 | U39: =Energy!D43 -> 1310159343
R40: NSGA3 | S40: =Energy!B44 -> 9.6593664e+08 | T40: =Energy!C44 -> 1.1324514e+09 | U40: =Energy!D44 -> 1.4235712e+09
R41: MQGA | S41: =Energy!B45 -> 8.6619767e+08 | T41: =Energy!C45 -> 1.030689e+09 | U41: =Energy!D45 -> 1.255741e+09
R42: Greedy | S42: =Energy!B46 -> 9.6862965e+08 | T42: =Energy!C46 -> 1.1797493e+09 | U42: =Energy!D46 -> 1.435004e+09
R43: MOPSO | S43: =Energy!B47 -> 9.2275145e+08 | T43: =Energy!C47 -> 1.1155081e+09 | U43: =Energy!D47 -> 1.3862769e+09
R44: RL | S44: =Energy!B48 -> 9.8274917e+08 | T44: =Energy!C48 -> 1.320469e+09 | U44: =Energy!D48 -> 1.404942e+09
R51: Energy | S51: 30 | T51: 50 | U51: 100
R52: QUEST | S52: =S37/S37 -> 1 | T52: =T37/T37 -> 1 | U52: =U37/U37 -> 1
R53: QUEST_NDVFS | S53: =S38/S37 -> 1.0744378 | T53: =T38/T37 -> 1.117827 | U53: =U38/U37 -> 1.2507819
R54: Fuzzy | S54: =S39/S37 -> 1.083554 | T54: =T39/T37 -> 1.0807555 | U54: =U39/U37 -> 1.6357935
R55: NSGA3 | S55: =S40/S37 -> 1.2698907 | T55: =T40/T37 -> 1.3513314 | U55: =U40/U37 -> 1.7773933
R56: MQGA | S56: =S41/S37 -> 1.1387666 | T56: =T41/T37 -> 1.2299004 | U56: =U41/U37 -> 1.5678496
R57: Greedy | S57: =S42/S37 -> 1.2734312 | T57: =T42/T37 -> 1.407771 | U57: =U42/U37 -> 1.7916677
R58: MOPSO | S58: =S43/S37 -> 1.2131163 | T58: =T43/T37 -> 1.3311132 | U58: =U43/U37 -> 1.7308296
R59: RL | S59: =S44/S37 -> 1.2919937 | T59: =T44/T37 -> 1.5756889 | U59: =U44/U37 -> 1.754134
R67: Makespan | S67: 30 | T67: 50 | U67: 100
R68: QUEST | S68: =Makespan!B41 -> 1133674.5 | T68: =Makespan!C41 -> 1275412.1 | U68: =Makespan!D41 -> 1281938.4
R69: QUEST_NDVFS | S69: =Makespan!B42 -> 1134788.9 | T69: =Makespan!C42 -> 1259039.2 | U69: =Makespan!D42 -> 1290864.9
R70: Fuzzy | S70: =Makespan!B43 -> 1118706.6 | T70: =Makespan!C43 -> 1175850.9 | U70: =Makespan!D43 -> 1662054.7
...

Sheet Data Age
A1: Algorithm | B1: Load | C1: Average | D1: Min | E1: Max | F1: Std Dev
A2: QUEST | B2: 1 | C2: 228384.12 | D2: 222842.48 | E2: 234457.94 | F2: 3153.0906
A3: QUEST | B3: 2 | C3: 262787.7 | D3: 248789.75 | E3: 283868.61 | F3: 9385.7299
A4: QUEST | B4: 3 | C4: 259098.12 | D4: 249486.7 | E4: 274700.16 | F4: 7859.0454
A5: QUEST_NDVFS | B5: 1 | C5: 183637.36 | D5: 181512.42 | E5: 186130.87 | F5: 1283.9962
A6: QUEST_NDVFS | B6: 2 | C6: 205044.01 | D6: 201265.69 | E6: 207785.43 | F6: 1470.4134
A7: QUEST_NDVFS | B7: 3 | C7: 197145.45 | D7: 192849.27 | E7: 200760.26 | F7: 2032.0294
A8: Fuzzy | B8: 1 | C8: 178707.61 | D8: 178707.61 | E8: 178707.61 | F8: 0
A9: Fuzzy | B9: 2 | C9: 202644.72 | D9: 202644.14 | E9: 202645.2 | F9: 0.28760602
A10: Fuzzy | B10: 3 | C10: 224775.43 | D10: 224773.84 | E10: 224777.36 | F10: 0.94171312
A11: NSGA3 | B11: 1 | C11: 204612.72 | D11: 189554.03 | E11: 235548.71 | F11: 13229.103
A12: NSGA3 | B12: 2 | C12: 225469.25 | D12: 213000.82 | E12: 236704.65 | F12: 6317.767
A13: NSGA3 | B13: 3 | C13: 235244.7 | D13: 205788.3 | E13: 303924.39 | F13: 25088.285
... A25: RL | B25: 3 | C25: 230319.83 | D25: 209244.98 | E25: 257355.4 | F25: 13564.759
A28: Summary by Algorithm
A29: QUEST | C29: 250089.98 | D29: 222842.48 | E29: 283868.61 | F29: 17061.862
A30: QUEST_NDVFS | C30: 195275.61 | D30: 181512.42 | E30: 207785.43 | F30: 8987.1539
A31: Fuzzy | C31: 202042.59 | D31: 178707.61 | E31: 224777.36 | F31: 18811.926
A32: NSGA3 | C32: 221775.56 | D32: 189554.03 | E32: 303924.39 | F32: 21086.88
A33: MQGA | C33: 209566.66 | D33: 181549.39 | E33: 233071.47 | F33: 15242.264
A34: Greedy | C34: 222338.3 | D34: 191325.29 | E34: 274381.6 | F34: 17910.882
A35: MOPSO | C35: 218883.16 | D35: 190083.71 | E35: 254439.23 | F35: 16015.279
A36: RL | C36: 224857.59 | D36: 190676.35 | E36: 279247.18 | F36: 21836.095
A39: Average data for chart
A40: Algorithms | B40: 1 | C40: 2 | D40: 3
A41: QUEST | B41: 228384.12 | C41: 262787.7 | D41: 259098.12
A42: QUEST_NDVFS | B42: 183637.36 | C42: 205044.01 | D42: 197145.45
A43: Fuzzy | B43: 178707.61 | C43: 202644.72 | D43: 224775.43
A44: NSGA3 | B44: 204612.72 | C44: 225469.25 | D44: 235244.7
A45: MQGA | B45: 190131.1 | C45: 217674.57 | D45: 220894.32
A46: Greedy | B46: 206897.43 | C46: 227346.36 | D46: 232771.1
A47: MOPSO | B47: 200047 | C47: 225637.13 | D47: 230965.34
A48: RL | B48: 207479.46 | C48: 236773.49 | D48: 230319.83
A51: All data for chart
A52: Algorithms | B52: 1 | C52: 1 | D52: 1 | E52: 1 | F52: 1 | G52: 1 | H52: 1 | I52: 1 | J52: 1 | K52: 1 | L52: 1 | M52: 1 | N52: 1 | O52: 1 | P52: 1 | Q52: 1 | R52: 1 | S52: 1 | T52: 1 | U52: 1 | V52: 2 | W52: 2 | X52: 2 | Y52: 2 | Z52: 2 | AA52: 2 | AB52: 2 | AC52: 2 | AD52: 2 | AE52: 2 | AF52: 2 | AG52: 2 | AH52: 2 | AI52: 2 | AJ52: 2 | AK52: 2 | AL52: 2 | AM52: 2 | AN52: 2 | AO52: 2 | AP52: 3 | AQ52: 3 | AR52: 3 | AS52: 3 | AT52: 3 | AU52: 3 | AV52: 3 | AW52: 3 | AX52: 3 | AY52: 3 | AZ52: 3 | BA52: 3 | BB52: 3 | BC52: 3 | BD52: 3 | BE52: 3 | BF52: 3 | BG52: 3 | BH52: 3 | BI52: 3
A53: QUEST | B53: 226892.48 | C53: 224024.42 | D53: 230660.32 | E53: 229586.9 | F53: 229450.9 | G53: 224092.1 | H53: 232295.52 | I53: 225102.23 | J53: 224433.16 | K53: 228937.1 | L53: 222842.48 | M53: 230083.77 | N53: 227215.84 | O53: 227539.81 | P53: 229022.35 | Q53: 234457.94 | R53: 228806.81 | S53: 233350.71 | T53: 227279.55 | U53: 231608.1 | V53: 265990.43 | W53: 273058.61 | X53: 283868.61 | Y53: 266971.22 | Z53: 274546.47 | AA53: 260009.75 | AB53: 274892.88 | AC53: 268849.12 | AD53: 262226.61 | AE53: 259416.08 | AF53: 259953.14 | AG53: 258532.14 | AH53: 251179.98 | AI53: 256398.22 | AJ53: 248789.75 | AK53: 273535.1 | AL53: 258071.96 | AM53: 257124.31 | AN53: 252875.12 | AO53: 249464.47 | AP53: 254737.82 | AQ53: 265460.14 | AR53: 253984.81 | AS53: 259393.86 | AT53: 268083.28 | AU53: 252991.94 | AV53: 269313.73 | AW53: 267743.45 | AX53: 256735.99 | AY53: 256888.92 | AZ53: 252829.66 | BA53: 251800.44 | BB53: 273681.14 | BC53: 253387 | BD53: 256842.86 | BE53: 250494.72 | BF53: 249486.7 | BG53: 274700.16 | BH53: 262939.1 | BI53: 250466.77
A54: QUEST_NDVFS | B54: 185299.45 | C54: 186130.87 | D54: 182129.81 | E54: 185644.48 | F54: 183025.87 | G54: 184806.65 | H54: 184216.13 | I54: 182272 | J54: 182427.23 | K54: 182467.03 | L54: 184039.16 | M54: 183322.74 | N54: 183894.84 | O54: 183948.68 | P54: 184371.29 | Q54: 181596.23 | R54: 183047.13 | S54: 181512.42 | T54: 184460.48 | U54: 184134.65 | V54: 205185.94 | W54: 205653.14 | X54: 206341.12 | Y54: 206359.63 | Z54: 202535.02 | AA54: 203574.73 | AB54: 205053.2 | AC54: 206071.47 | AD54: 207785.43 | AE54: 206838.78 | AF54: 205360.98 | AG54: 205318.73 | AH54: 203092.1 | AI54: 205494.51 | AJ54: 205601.14 | AK54: 204774.02 | AL54: 204838.65 | AM54: 204521.86 | AN54: 205214.08 | AO54: 201265.69 | AP54: 197237.5 | AQ54: 192849.27 | AR54: 196147.17 | AS54: 196014.49 | AT54: 198393.24 | AU54: 197378.86 | AV54: 198333.26 | AW54: 193416.36 | AX54: 200760.26 | AY54: 193780.47 | AZ54: 196906.91 | BA54: 199522.82 | BB54: 199555.77 | BC54: 196920.09 | BD54: 198264.93 | BE54: 198109.93 | BF54: 197767.75 | BG54: 195967.64 | BH54: 199233.75 | BI54: 196348.62
A55: Fuzzy | B55: 178707.61 | C55: 178707.61 | D55: 178707.61 | E55: 178707.61 | F55: 178707.61 | G55: 178707.61 | H55: 178707.61 | I55: 178707.61 | J55: 178707.61 | K55: 178707.61 | L55: 178707.61 | M55: 178707.61 | N55: 178707.61 | O55: 178707.61 | P55: 178707.61 | Q55: 178707.61 | R55: 178707.61 | S55: 178707.61 | T55: 178707.61 | U55: 178707.61 | V55: 202644.73 | W55: 202645.14 | X55: 202644.86 | Y55: 202644.45 | Z55: 202644.73 | AA55: 202644.61 | AB55: 202644.59 | AC55: 202644.31 | AD55: 202645 | AE55: 202644.67 | AF55: 202644.67 | AG55: 202644.55 | AH55: 202644.53 | AI55: 202644.14 | AJ55: 202644.73 | AK55: 202645.2 | AL55: 202644.92 | AM55: 202645.12 | AN55: 202645.08 | AO55: 202644.33 | AP55: 224775.44 | AQ55: 224776.27 | AR55: 224777.36 | AS55: 224774.47 | AT55: 224776.65 | AU55: 224776.6 | AV55: 224775.5 | AW55: 224775.21 | AX55: 224775.18 | AY55: 224775.74 | AZ55: 224774.94 | BA55: 224774.69 | BB55: 224773.84 | BC55: 224774.88 | BD55: 224774.73 | BE55: 224774.14 | BF55: 224774.82 | BG55: 224776.06 | BH55: 224775 | BI55: 224777.04
A56: NSGA3 | B56: 200477.58 | C56: 200387.48 | D56: 191362.42 | E56: 193400.81 | F56: 235548.71 | G56: 195596.16 | H56: 205907.94 | I56: 200147.65 | J56: 195461.87 | K56: 213677.71 | L56: 189554.03 | M56: 208535.32 | N56: 201306.61 | O56: 193176.74 | P56: 229410.39 | Q56: 197830.61 | R56: 191298.13 | S56: 229709.13 | T56: 213842.03 | U56: 205623.13 | V56: 230410.37 | W56: 220636.37 | X56: 217093 | Y56: 228900.84 | Z56: 223499.84 | AA56: 229165.98 | AB56: 232531.94 | AC56: 232870.31 | AD56: 218869.92 | AE56: 225679.25 | AF56: 230799.33 | AG56: 213000.82 | AH56: 231084.31 | AI56: 229067.9 | AJ56: 223446.47 | AK56: 213841.55 | AL56: 222843.29 | AM56: 224507.71 | AN56: 236704.65 | AO56: 224431.12 | AP56: 217701.12 | AQ56: 278555.42 | AR56: 210014.88 | AS56: 241320.74 | AT56: 206604.93 | AU56: 238628.84 | AV56: 264284.87 | AW56: 233521.91 | AX56: 220551.76 | AY56: 217710.17 | AZ56: 205788.3 | BA56: 256998.53 | BB56: 231395.66 | BC56: 217025.64 | BD56: 224574.77 | BE56: 303924.39 | BF56: 255647.89 | BG56: 223959.21 | BH56: 214691.22 | BI56: 241993.78
A57: MQGA | B57: 191236.06 | C57: 197796.58 | D57: 189268.9 | E57: 189960.48 | F57: 190124.29 | G57: 188723.45 | H57: 188689.68 | I57: 187658.74 | J57: 197006.61 | K57: 188294 | L57: 185477.48 | M57: 189181.84 | N57: 188406.26 | O57: 185832.71 | P57: 185046.26 | Q57: 200973.45 | R57: 189538.48 | S57: 190190.71 | T57: 197666.65 | U57: 181549.39 | V57: 216201.71 | W57: 211577.67 | X57: 207479.37 | Y57: 210257.31 | Z57: 230436.65 | AA57: 216918.86 | AB57: 221582.06 | AC57: 214989.53 | AD57: 211773.12 | AE57: 214982.45 | AF57: 214538.96 | AG57: 226720.08 | AH57: 216223.24 | AI57: 229933.82 | AJ57: 215896.67 | AK57: 207919.1 | AL57: 231156.57 | AM57: 225840.59 | AN57: 216969.14 | AO57: 212094.49 | AP57: 223616.48 | AQ57: 210956.56 | AR57: 223158.39 | AS57: 219517.29 | AT57: 222325.62 | AU57: 212355.09 | AV57: 214640.87 | AW57: 232343.24 | AX57: 225333.2 | AY57: 217755.95 | AZ57: 227495.37 | BA57: 233071.47 | BB57: 210251.42 | BC57: 219590.36 | BD57: 231286.01 | BE57: 215742.7 | BF57: 228643.75 | BG57: 212957.61 | BH57: 223454.85 | BI57: 213390.15
...

Sheet TTest - Energy
A1: t-Test: Two-Sample Assuming Unequal Variances
B3: Variable 1 | C3: Variable 2
A4: Mean | B4: 8.3802643e+08 | C4: 1.030689e+09
A5: Variance | B5: 1.0361431e+15 | C5: 3.965391e+14
A6: Observations | B6: 20 | C6: 20
A7: Hypothesized Mean Difference | B7: 0
A8: df | B8: 32
A9: t Stat | B9: -22.763419
A10: P(T<=t) one-tail | B10: 1.2347462e-21
A11: t Critical one-tail | B11: 1.6938887
A12: P(T<=t) two-tail | B12: 2.4694923e-21
A13: t Critical two-tail | B13: 2.0369333

Sheet Energy
A1: Algorithm | B1: Load | C1: Average | D1: Min | E1: Max | F1: Std Dev
A2: QUEST | B2: 1 | C2: 7.6064548e+08 | D2: 7.3911062e+08 | E2: 8.078312e+08 | F2: 18690049
A3: QUEST | B3: 2 | C3: 8.3802643e+08 | D3: 7.8262559e+08 | E3: 9.0377757e+08 | F3: 31374129
A4: QUEST | B4: 3 | C4: 8.0093201e+08 | D4: 7.6291151e+08 | E4: 9.5547443e+08 | F4: 40413178
A5: QUEST_NDVFS | B5: 1 | C5: 8.1726622e+08 | D5: 7.8764771e+08 | E5: 8.7461329e+08 | F5: 23954468
A6: QUEST_NDVFS | B6: 2 | C6: 9.3676855e+08 | D6: 8.4890391e+08 | E6: 9.9234975e+08 | F6: 33391736
A7: QUEST_NDVFS | B7: 3 | C7: 1.0017913e+09 | D7: 9.1758278e+08 | E7: 1.1432367e+09 | F7: 60380269
A8: Fuzzy | B8: 1 | C8: 824200412 | D8: 824182780 | E8: 824221820 | F8: 10000.141
A9: Fuzzy | B9: 2 | C9: 9.0570167e+08 | D9: 9.0568442e+08 | E9: 9.057209e+08 | F9: 9103.9297
A10: Fuzzy | B10: 3 | C10: 1310159343 | D10: 1310139055 | E10: 1310181295 | F10: 10182.036
A11: NSGA3 | B11: 1 | C11: 9.6593664e+08 | D11: 7.8709026e+08 | E11: 1.5129843e+09 | F11: 1.878449e+08
A12: NSGA3 | B12: 2 | C12: 1.1324514e+09 | D12: 9.4812779e+08 | E12: 1338272415 | F12: 1.1068398e+08
A13: NSGA3 | B13: 3 | C13: 1.4235712e+09 | D13: 9.6400103e+08 | E13: 2.0737145e+09 | F13: 2.6730948e+08
... A25: RL | B25: 3 | C25: 1.404942e+09 | D25: 1.0108399e+09 | E25: 1.7474173e+09 | F25: 1.8015947e+08
A28: Summary by Algorithm
A29: QUEST | C29: 7.9986797e+08 | D29: 7.3911062e+08 | E29: 9.5547443e+08 | F29: 44581324
A30: QUEST_NDVFS | C30: 9.1860868e+08 | D30: 7.8764771e+08 | E30: 1.1432367e+09 | F30: 87281195
A31: Fuzzy | C31: 1.0133538e+09 | D31: 824182780 | E31: 1310181295 | F31: 2.1249433e+08
A32: NSGA3 | C32: 1.1739864e+09 | D32: 7.8709026e+08 | E32: 2.0737145e+09 | F32: 2.7464731e+08
A33: MQGA | C33: 1.0508759e+09 | D33: 8.5633107e+08 | E33: 1.29669e+09 | F33: 1.6056073e+08
A34: Greedy | C34: 1.194461e+09 | D34: 8.0547801e+08 | E34: 1.8745671e+09 | F34: 2.5437492e+08
A35: MOPSO | C35: 1.1415121e+09 | D35: 8.6272112e+08 | E35: 1.4993381e+09 | F35: 1.9984046e+08
A36: RL | C36: 1.2360534e+09 | D36: 8.4520025e+08 | E36: 2.0807061e+09 | F36: 2.8137827e+08
A39: Average data for chart
A40: Algorithms | B40: 1 | C40: 2 | D40: 3
A41: QUEST | B41: 7.6064548e+08 | C41: 8.3802643e+08 | D41: 8.0093201e+08
A42: QUEST_NDVFS | B42: 8.1726622e+08 | C42: 9.3676855e+08 | D42: 1.0017913e+09
A43: Fuzzy | B43: 824200412 | C43: 9.0570167e+08 | D43: 1310159343
A44: NSGA3 | B44: 9.6593664e+08 | C44: 1.1324514e+09 | D44: 1.4235712e+09
A45: MQGA | B45: 8.6619767e+08 | C45: 1.030689e+09 | D45: 1.255741e+09
A46: Greedy | B46: 9.6862965e+08 | C46: 1.1797493e+09 | D46: 1.435004e+09
A47: MOPSO | B47: 9.2275145e+08 | C47: 1.1155081e+09 | D47: 1.3862769e+09
A48: RL | B48: 9.8274917e+08 | C48: 1.320469e+09 | D48: 1.404942e+09
A51: All data for chart
A52: Algorithms | B52: 1 | C52: 1 | D52: 1 | E52: 1 | F52: 1 | G52: 1 | H52: 1 | I52: 1 | J52: 1 | K52: 1 | L52: 1 | M52: 1 | N52: 1 | O52: 1 | P52: 1 | Q52: 1 | R52: 1 | S52: 1 | T52: 1 | U52: 1 | V52: 2 | W52: 2 | X52: 2 | Y52: 2 | Z52: 2 | AA52: 2 | AB52: 2 | AC52: 2 | AD52: 2 | AE52: 2 | AF52: 2 | AG52: 2 | AH52: 2 | AI52: 2 | AJ52: 2 | AK52: 2 | AL52: 2 | AM52: 2 | AN52: 2 | AO52: 2 | AP52: 3 | AQ52: 3 | AR52: 3 | AS52: 3 | AT52: 3 | AU52: 3 | AV52: 3 | AW52: 3 | AX52: 3 | AY52: 3 | AZ52: 3 | BA52: 3 | BB52: 3 | BC52: 3 | BD52: 3 | BE52: 3 | BF52: 3 | BG52: 3 | BH52: 3 | BI52: 3
A53: QUEST | B53: 7.4423079e+08 | C53: 7.5219579e+08 | D53: 7.5825347e+08 | E53: 7.5092495e+08 | F53: 7.6152256e+08 | G53: 7.6358169e+08 | H53: 8.078312e+08 | I53: 7.6434632e+08 | J53: 7.601229e+08 | K53: 7.3911062e+08 | L53: 7.5343882e+08 | M53: 7.4849923e+08 | N53: 7.4555918e+08 | O53: 7.4837091e+08 | P53: 7.5283813e+08 | Q53: 8.0121231e+08 | R53: 7.5204289e+08 | S53: 7.5745927e+08 | T53: 7.5320236e+08 | U53: 7.9816612e+08 | V53: 8.6078747e+08 | W53: 8.258314e+08 | X53: 8.9030783e+08 | Y53: 8.3272104e+08 | Z53: 8.7341004e+08 | AA53: 8.4222134e+08 | AB53: 9.0377757e+08 | AC53: 8.6446941e+08 | AD53: 8.0455012e+08 | AE53: 8.3019315e+08 | AF53: 8.3207479e+08 | AG53: 8.5624193e+08 | AH53: 8.1785468e+08 | AI53: 8.3454259e+08 | AJ53: 7.9989346e+08 | AK53: 8.7322104e+08 | AL53: 8.1622666e+08 | AM53: 8.1890443e+08 | AN53: 7.8262559e+08 | AO53: 8.0067408e+08 | AP53: 7.9533124e+08 | AQ53: 8.3936283e+08 | AR53: 7.6291151e+08 | AS53: 7.7398285e+08 | AT53: 7.9937849e+08 | AU53: 7.7280164e+08 | AV53: 8.0013741e+08 | AW53: 8.2398989e+08 | AX53: 7.7532426e+08 | AY53: 7.979652e+08 | AZ53: 8.0848809e+08 | BA53: 7.9317912e+08 | BB53: 8.0673295e+08 | BC53: 7.7079652e+08 | BD53: 7.7315138e+08 | BE53: 7.9601124e+08 | BF53: 7.7286616e+08 | BG53: 9.5547443e+08 | BH53: 8.156607e+08 | BI53: 7.8509419e+08
A54: QUEST_NDVFS | B54: 8.7461329e+08 | C54: 7.9886934e+08 | D54: 8.0669732e+08 | E54: 8.6787516e+08 | F54: 8.3087894e+08 | G54: 8.7011545e+08 | H54: 8.1509889e+08 | I54: 812625980 | J54: 8.0689015e+08 | K54: 8.0803692e+08 | L54: 8.1000602e+08 | M54: 8.0257276e+08 | N54: 8.0878059e+08 | O54: 8.1239179e+08 | P54: 8.0087644e+08 | Q54: 8.1084376e+08 | R54: 8.1291953e+08 | S54: 7.8764771e+08 | T54: 7.9903217e+08 | U54: 8.0855216e+08 | V54: 9.358562e+08 | W54: 9.0789417e+08 | X54: 9.5042079e+08 | Y54: 9.5210339e+08 | Z54: 8.9630453e+08 | AA54: 949820935 | AB54: 965282020 | AC54: 9.2163532e+08 | AD54: 8.4890391e+08 | AE54: 9.9234975e+08 | AF54: 9.4435766e+08 | AG54: 9.2413961e+08 | AH54: 9.6141467e+08 | AI54: 9.3473098e+08 | AJ54: 9.7156513e+08 | AK54: 8.9705225e+08 | AL54: 9.4589493e+08 | AM54: 9.4418067e+08 | AN54: 987379860 | AO54: 9.0408416e+08 | AP54: 1.0582366e+09 | AQ54: 9.7563684e+08 | AR54: 9.7072377e+08 | AS54: 1.0189417e+09 | AT54: 1.0033375e+09 | AU54: 9.3855134e+08 | AV54: 1.0346348e+09 | AW54: 9.5413815e+08 | AX54: 9.9329789e+08 | AY54: 9.7324897e+08 | AZ54: 9.4692354e+08 | BA54: 1.0053802e+09 | BB54: 1.0561955e+09 | BC54: 1122665410 | BD54: 1.1432367e+09 | BE54: 1004678995 | BF54: 1050708660 | BG54: 9.1758278e+08 | BH54: 944436930 | BI54: 9.232693e+08
A55: Fuzzy | B55: 824201980 | C55: 824207740 | D55: 824190460 | E55: 824210300 | F55: 824221820 | G55: 824200060 | H55: 824205180 | I55: 824195580 | J55: 824188540 | K55: 824201340 | L55: 824216060 | M55: 824196220 | N55: 824205180 | O55: 824196220 | P55: 824200700 | Q55: 824214780 | R55: 824182780 | S55: 824187900 | T55: 824194300 | U55: 824191100 | V55: 9.0570362e+08 | W55: 9.057017e+08 | X55: 9.0568762e+08 | Y55: 9.057049e+08 | Z55: 9.0569914e+08 | AA55: 9.0570362e+08 | AB55: 9.0570426e+08 | AC55: 9.0570682e+08 | AD55: 9.057017e+08 | AE55: 9.0568954e+08 | AF55: 9.0571322e+08 | AG55: 9.0571706e+08 | AH55: 9.0570426e+08 | AI55: 9.0568442e+08 | AJ55: 9.057017e+08 | AK55: 9.0568826e+08 | AL55: 9.0569658e+08 | AM55: 9.0570042e+08 | AN55: 9.057209e+08 | AO55: 9.0570362e+08 | AP55: 1310153135 | AQ55: 1310164015 | AR55: 1310175535 | AS55: 1310153135 | AT55: 1310165295 | AU55: 1310172335 | AV55: 1310162735 | AW55: 1310160815 | AX55: 1310164655 | AY55: 1310161455 | AZ55: 1310160175 | BA55: 1310153135 | BB55: 1310149295 | BC55: 1310148655 | BD55: 1310150575 | BE55: 1310139055 | BF55: 1310145455 | BG55: 1310165935 | BH55: 1310160175 | BI55: 1310181295
A56: NSGA3 | B56: 9.52345e+08 | C56: 9.1172416e+08 | D56: 9.305387e+08 | E56: 8.4582722e+08 | F56: 1.5129843e+09 | G56: 9.1683601e+08 | H56: 8.6879933e+08 | I56: 8.5748355e+08 | J56: 8.316516e+08 | K56: 9.5587255e+08 | L56: 807011755 | M56: 1.1276245e+09 | N56: 865815220 | O56: 8.4564401e+08 | P56: 1.0525066e+09 | Q56: 8.3866739e+08 | R56: 7.8709026e+08 | S56: 1425136380 | T56: 1024604320 | U56: 960570100 | V56: 1.1429777e+09 | W56: 1.104522e+09 | X56: 9.5207118e+08 | Y56: 1147258655 | Z56: 1139144685 | AA56: 1.2010931e+09 | AB56: 1.1816653e+09 | AC56: 1.2744788e+09 | AD56: 1.1360762e+09 | AE56: 1.0030074e+09 | AF56: 1.3345842e+09 | AG56: 9.6969517e+08 | AH56: 1.1508224e+09 | AI56: 1052752035 | AJ56: 1125445060 | AK56: 9.4812779e+08 | AL56: 1.118902e+09 | AM56: 1249642595 | AN56: 1338272415 | AO56: 1.0784893e+09 | AP56: 1.1694504e+09 | AQ56: 1.7070379e+09 | AR56: 1.0986728e+09 | AS56: 1765939985 | AT56: 1206300515 | AU56: 1442777020 | AV56: 1.8735523e+09 | AW56: 1.3711829e+09 | AX56: 1.3886376e+09 | AY56: 1.2613468e+09 | AZ56: 9.6400103e+08 | BA56: 1.6242931e+09 | BB56: 1.407852e+09 | BC56: 1.2243952e+09 | BD56: 1.3998894e+09 | BE56: 2.0737145e+09 | BF56: 1572562790 | BG56: 1.3400452e+09 | BH56: 1.2628371e+09 | BI56: 1.3169356e+09
A57: MQGA | B57: 8.6167123e+08 | C57: 864085120 | D57: 8.6629253e+08 | E57: 8.5633107e+08 | F57: 8.6008564e+08 | G57: 8.6795899e+08 | H57: 8.6837709e+08 | I57: 872645840 | J57: 8.6949731e+08 | K57: 8.6934545e+08 | L57: 871131200 | M57: 8.6756013e+08 | N57: 8.5917165e+08 | O57: 8.6253549e+08 | P57: 8.7197405e+08 | Q57: 864384640 | R57: 8.593112e+08 | S57: 8.6154019e+08 | T57: 8.6980617e+08 | U57: 8.8024847e+08 | V57: 1.0351405e+09 | W57: 1.022968e+09 | X57: 1.0176542e+09 | Y57: 1.0266866e+09 | Z57: 1009669625 | AA57: 1.0093543e+09 | AB57: 1.0303867e+09 | AC57: 1.0270084e+09 | AD57: 1.0052193e+09 | AE57: 1029853300 | AF57: 1034495540 | AG57: 1.0618336e+09 | AH57: 1.04862e+09 | AI57: 1.0153092e+09 | AJ57: 1.0730977e+09 | AK57: 1.0159075e+09 | AL57: 1.0539492e+09 | AM57: 1063871040 | AN57: 1009390775 | AO57: 1.0233654e+09 | AP57: 1.2579275e+09 | AQ57: 1.2327899e+09 | AR57: 1.2584148e+09 | AS57: 1.2353491e+09 | AT57: 1.2546114e+09 | AU57: 1.2560814e+09 | AV57: 1.2516625e+09 | AW57: 1234199245 | AX57: 1.2778681e+09 | AY57: 1.2436599e+09 | AZ57: 1.2325615e+09 | BA57: 1.2564807e+09 | BB57: 1.2836381e+09 | BC57: 1.2264328e+09 | BD57: 1.289297e+09 | BE57: 1.2737078e+09 | BF57: 1.2212672e+09 | BG57: 1.2567346e+09 | BH57: 1.29669e+09 | BI57: 1.2754457e+09
...

Sheet Makespan
A1: Algorithm | B1: Load | C1: Average | D1: Min | E1: Max | F1: Std Dev
A2: QUEST | B2: 1 | C2: 1133674.5 | D2: 1115598 | E2: 1209369 | F2: 31629.058
A3: QUEST | B3: 2 | C3: 1275412.1 | D3: 1179867 | E3: 1414012 | F3: 72915.484
A4: QUEST | B4: 3 | C4: 1281938.4 | D4: 1205279 | E4: 1552125 | F4: 81355.439
A5: QUEST_NDVFS | B5: 1 | C5: 1134788.9 | D5: 1112799 | E5: 1223020 | F5: 37782.266
A6: QUEST_NDVFS | B6: 2 | C6: 1259039.2 | D6: 1176958 | E6: 1335739 | F6: 49836.23
A7: QUEST_NDVFS | B7: 3 | C7: 1290864.9 | D7: 1156688 | E7: 1471679 | F7: 88779.14
A8: Fuzzy | B8: 1 | C8: 1118706.6 | D8: 1118679 | E8: 1118740 | F8: 15.62522
A9: Fuzzy | B9: 2 | C9: 1175850.9 | D9: 1175824 | E9: 1175881 | F9: 14.22489
A10: Fuzzy | B10: 3 | C10: 1662054.7 | D10: 1662023 | E10: 1662089 | F10: 15.909431
A11: NSGA3 | B11: 1 | C11: 1402952.9 | D11: 1117831 | E11: 2214069 | F11: 285990.25
A12: NSGA3 | B12: 2 | C12: 1593532.5 | D12: 1337893 | E12: 1945402 | F12: 168814.23
A13: NSGA3 | B13: 3 | C13: 1911092.4 | D13: 1221960 | E13: 2918730 | F13: 404413.18
... A25: RL | B25: 3 | C25: 1866664.5 | D25: 1332340 | E25: 2368270 | F25: 264387.2
A28: Summary by Algorithm
A29: QUEST | C29: 1230341.7 | D29: 1115598 | E29: 1552125 | F29: 94822.433
A30: QUEST_NDVFS | C30: 1228231 | D30: 1112799 | E30: 1471679 | F30: 92008.066
A31: Fuzzy | C31: 1318870.7 | D31: 1118679 | E31: 1662089 | F31: 243786.51
A32: NSGA3 | C32: 1635859.3 | D32: 1117831 | E32: 2918730 | F32: 367708.63
A33: MQGA | C33: 1422290 | D33: 1205084 | E33: 1767744 | F33: 171275.15
A34: Greedy | C34: 1664634.6 | D34: 1148945 | E34: 2569217 | F34: 326069.48
A35: MOPSO | C35: 1575429.9 | D35: 1230068 | E35: 1984398 | F35: 224081.24
A36: RL | C36: 1726435.5 | D36: 1223034 | E36: 3046730 | F36: 382553.48
A39: Average data for chart
A40: Algorithms | B40: 1 | C40: 2 | D40: 3
A41: QUEST | B41: 1133674.5 | C41: 1275412.1 | D41: 1281938.4
A42: QUEST_NDVFS | B42: 1134788.9 | C42: 1259039.2 | D42: 1290864.9
A43: Fuzzy | B43: 1118706.6 | C43: 1175850.9 | D43: 1662054.7
A44: NSGA3 | B44: 1402952.9 | C44: 1593532.5 | D44: 1911092.4
A45: MQGA | B45: 1220253.4 | C45: 1414769.1 | D45: 1631847.6
A46: Greedy | B46: 1411160.3 | C46: 1669363.7 | D46: 1913379.6
A47: MOPSO | B47: 1334668.7 | C47: 1554588.1 | D47: 1837032.9
A48: RL | B48: 1435266.3 | C48: 1877375.6 | D48: 1866664.5
A51: All data for chart
A52: Algorithms | B52: 1 | C52: 1 | D52: 1 | E52: 1 | F52: 1 | G52: 1 | H52: 1 | I52: 1 | J52: 1 | K52: 1 | L52: 1 | M52: 1 | N52: 1 | O52: 1 | P52: 1 | Q52: 1 | R52: 1 | S52: 1 | T52: 1 | U52: 1 | V52: 2 | W52: 2 | X52: 2 | Y52: 2 | Z52: 2 | AA52: 2 | AB52: 2 | AC52: 2 | AD52: 2 | AE52: 2 | AF52: 2 | AG52: 2 | AH52: 2 | AI52: 2 | AJ52: 2 | AK52: 2 | AL52: 2 | AM52: 2 | AN52: 2 | AO52: 2 | AP52: 3 | AQ52: 3 | AR52: 3 | AS52: 3 | AT52: 3 | AU52: 3 | AV52: 3 | AW52: 3 | AX52: 3 | AY52: 3 | AZ52: 3 | BA52: 3 | BB52: 3 | BC52: 3 | BD52: 3 | BE52: 3 | BF52: 3 | BG52: 3 | BH52: 3 | BI52: 3
A53: QUEST | B53: 1122426 | C53: 1115598 | D53: 1119237 | E53: 1120953 | F53: 1122344 | G53: 1131873 | H53: 1209369 | I53: 1119913 | J53: 1117573 | K53: 1120233 | L53: 1116038 | M53: 1120607 | N53: 1121334 | O53: 1119364 | P53: 1117722 | Q53: 1208634 | R53: 1119908 | S53: 1127097 | T53: 1115888 | U53: 1207379 | V53: 1297932 | W53: 1295872 | X53: 1414012 | Y53: 1269521 | Z53: 1384157 | AA53: 1269488 | AB53: 1413712 | AC53: 1340075 | AD53: 1248095 | AE53: 1258149 | AF53: 1247702 | AG53: 1292981 | AH53: 1182190 | AI53: 1227359 | AJ53: 1179867 | AK53: 1361659 | AL53: 1230545 | AM53: 1229367 | AN53: 1185194 | AO53: 1180364 | AP53: 1242816 | AQ53: 1348923 | AR53: 1217360 | AS53: 1253684 | AT53: 1315606 | AU53: 1220364 | AV53: 1364388 | AW53: 1352572 | AX53: 1244862 | AY53: 1270315 | AZ53: 1250001 | BA53: 1228635 | BB53: 1359002 | BC53: 1221294 | BD53: 1238482 | BE53: 1219859 | BF53: 1205279 | BG53: 1552125 | BH53: 1314550 | BI53: 1218652
A54: QUEST_NDVFS | B54: 1223020 | C54: 1115720 | D54: 1114961 | E54: 1219045 | F54: 1145990 | G54: 1222991 | H54: 1149879 | I54: 1114679 | J54: 1112843 | K54: 1113843 | L54: 1115709 | M54: 1114850 | N54: 1112799 | O54: 1118692 | P54: 1117759 | Q54: 1116946 | R54: 1117751 | S54: 1116981 | T54: 1115629 | U54: 1115692 | V54: 1246636 | W54: 1220799 | X54: 1293091 | Y54: 1296494 | Z54: 1178948 | AA54: 1269862 | AB54: 1290849 | AC54: 1246649 | AD54: 1176958 | AE54: 1335739 | AF54: 1268104 | AG54: 1244996 | AH54: 1293549 | AI54: 1247967 | AJ54: 1335648 | AK54: 1192907 | AL54: 1292700 | AM54: 1234886 | AN54: 1333215 | AO54: 1180787 | AP54: 1391064 | AQ54: 1244252 | AR54: 1232285 | AS54: 1328965 | AT54: 1331246 | AU54: 1215872 | AV54: 1334034 | AW54: 1210802 | AX54: 1253472 | AY54: 1226475 | AZ54: 1220378 | BA54: 1330542 | BB54: 1381202 | BC54: 1471679 | BD54: 1464944 | BE54: 1262780 | BF54: 1364177 | BG54: 1156688 | BH54: 1212931 | BI54: 1183510
A55: Fuzzy | B55: 1118709 | C55: 1118718 | D55: 1118691 | E55: 1118722 | F55: 1118740 | G55: 1118706 | H55: 1118714 | I55: 1118699 | J55: 1118688 | K55: 1118708 | L55: 1118731 | M55: 1118700 | N55: 1118714 | O55: 1118700 | P55: 1118707 | Q55: 1118729 | R55: 1118679 | S55: 1118687 | T55: 1118697 | U55: 1118692 | V55: 1175854 | W55: 1175851 | X55: 1175829 | Y55: 1175856 | Z55: 1175847 | AA55: 1175854 | AB55: 1175855 | AC55: 1175859 | AD55: 1175851 | AE55: 1175832 | AF55: 1175869 | AG55: 1175875 | AH55: 1175855 | AI55: 1175824 | AJ55: 1175851 | AK55: 1175830 | AL55: 1175843 | AM55: 1175849 | AN55: 1175881 | AO55: 1175854 | AP55: 1662045 | AQ55: 1662062 | AR55: 1662080 | AS55: 1662045 | AT55: 1662064 | AU55: 1662075 | AV55: 1662060 | AW55: 1662057 | AX55: 1662063 | AY55: 1662058 | AZ55: 1662056 | BA55: 1662045 | BB55: 1662039 | BC55: 1662038 | BD55: 1662041 | BE55: 1662023 | BF55: 1662033 | BG55: 1662065 | BH55: 1662056 | BI55: 1662089
A56: NSGA3 | B56: 1366671 | C56: 1306346 | D56: 1332815 | E56: 1221064 | F56: 2214069 | G56: 1319794 | H56: 1250334 | I56: 1253225 | J56: 1207306 | K56: 1402583 | L56: 1145904 | M56: 1650335 | N56: 1265149 | O56: 1229209 | P56: 1562408 | Q56: 1227264 | R56: 1117831 | S56: 2120124 | T56: 1497067 | U56: 1369561 | V56: 1631698 | W56: 1528906 | X56: 1339024 | Y56: 1617121 | Z56: 1605445 | AA56: 1687809 | AB56: 1681921 | AC56: 1801780 | AD56: 1582326 | AE56: 1406393 | AF56: 1878890 | AG56: 1338577 | AH56: 1605636 | AI56: 1463125 | AJ56: 1587101 | AK56: 1337893 | AL56: 1570051 | AM56: 1784935 | AN56: 1945402 | AO56: 1476617 | AP56: 1555707 | AQ56: 2328834 | AR56: 1450145 | AS56: 2450545 | AT56: 1573339 | AU56: 1929024 | AV56: 2610751 | AW56: 1872532 | AX56: 1836043 | AY56: 1691265 | AZ56: 1221960 | BA56: 2219986 | BB56: 1832294 | BC56: 1606238 | BD56: 1862498 | BE56: 2918730 | BF56: 2060578 | BG56: 1781217 | BH56: 1701025 | BI56: 1719138
A57: MQGA | B57: 1225332 | C57: 1219827 | D57: 1225330 | E57: 1205084 | F57: 1219095 | G57: 1225372 | H57: 1226413 | I57: 1227230 | J57: 1221075 | K57: 1226374 | L57: 1218269 | M57: 1225295 | N57: 1210059 | O57: 1206453 | P57: 1218027 | Q57: 1229235 | R57: 1218294 | S57: 1221065 | T57: 1219945 | U57: 1217293 | V57: 1415755 | W57: 1407990 | X57: 1381476 | Y57: 1409287 | Z57: 1402926 | AA57: 1366874 | AB57: 1439337 | AC57: 1418599 | AD57: 1358734 | AE57: 1402816 | AF57: 1399417 | AG57: 1489185 | AH57: 1453748 | AI57: 1432329 | AJ57: 1448034 | AK57: 1379812 | AL57: 1451915 | AM57: 1493795 | AN57: 1349098 | AO57: 1394254 | AP57: 1600041 | AQ57: 1635733 | AR57: 1620519 | AS57: 1588819 | AT57: 1620320 | AU57: 1600555 | AV57: 1605272 | AW57: 1641530 | AX57: 1767744 | AY57: 1600634 | AZ57: 1580613 | BA57: 1653383 | BB57: 1662822 | BC57: 1596306 | BD57: 1628441 | BE57: 1660846 | BF57: 1620204 | BG57: 1621030 | BH57: 1649781 | BI57: 1682358
...

Sheet Success Rate
A1: Algorithm | B1: Load | C1: Average | D1: Min | E1: Max | F1: Std Dev
A2: QUEST | B2: 1 | C2: 1 | D2: TRUE | E2: TRUE | F2: 0
A3: QUEST | B3: 2 | C3: 1 | D3: TRUE | E3: TRUE | F3: 0
A4: QUEST | B4: 3 | C4: 1 | D4: TRUE | E4: TRUE | F4: 0
A5: QUEST_NDVFS | B5: 1 | C5: 1 | D5: TRUE | E5: TRUE | F5: 0
A6: QUEST_NDVFS | B6: 2 | C6: 1 | D6: TRUE | E6: TRUE | F6: 0
A7: QUEST_NDVFS | B7: 3 | C7: 1 | D7: TRUE | E7: TRUE | F7: 0
A8: Fuzzy | B8: 1 | C8: 1 | D8: TRUE | E8: TRUE | F8: 0
A9: Fuzzy | B9: 2 | C9: 1 | D9: TRUE | E9: TRUE | F9: 0
A10: Fuzzy | B10: 3 | C10: 1 | D10: TRUE | E10: TRUE | F10: 0
A11: NSGA3 | B11: 1 | C11: 0.9 | D11: FALSE | E11: TRUE | F11: 0.3
A12: NSGA3 | B12: 2 | C12: 1 | D12: TRUE | E12: TRUE | F12: 0
A13: NSGA3 | B13: 3 | C13: 0.95 | D13: FALSE | E13: TRUE | F13: 0.21794495
... A25: RL | B25: 3 | C25: 1 | D25: TRUE | E25: TRUE | F25: 0
A28: Summary by Algorithm
A29: QUEST | C29: 1 | D29: TRUE | E29: TRUE | F29: 0
A30: QUEST_NDVFS | C30: 1 | D30: TRUE | E30: TRUE | F30: 0
A31: Fuzzy | C31: 1 | D31: TRUE | E31: TRUE | F31: 0
A32: NSGA3 | C32: 0.95 | D32: FALSE | E32: TRUE | F32: 0.21794495
A33: MQGA | C33: 1 | D33: TRUE | E33: TRUE | F33: 0
A34: Greedy | C34: 0.95 | D34: FALSE | E34: TRUE | F34: 0.21794495
A35: MOPSO | C35: 1 | D35: TRUE | E35: TRUE | F35: 0
A36: RL | C36: 0.85 | D36: FALSE | E36: TRUE | F36: 0.35707142
A39: Average data for chart
A40: Algorithms | B40: 1 | C40: 2 | D40: 3
A41: QUEST | B41: 1 | C41: 1 | D41: 1
A42: QUEST_NDVFS | B42: 1 | C42: 1 | D42: 1
A43: Fuzzy | B43: 1 | C43: 1 | D43: 1
A44: NSGA3 | B44: 0.9 | C44: 1 | D44: 0.95
A45: MQGA | B45: 1 | C45: 1 | D45: 1
A46: Greedy | B46: 1 | C46: 0.85 | D46: 1
A47: MOPSO | B47: 1 | C47: 1 | D47: 1
A48: RL | B48: 0.9 | C48: 0.65 | D48: 1
A51: All data for chart
A52: Algorithms | B52: 1 | C52: 1 | D52: 1 | E52: 1 | F52: 1 | G52: 1 | H52: 1 | I52: 1 | J52: 1 | K52: 1 | L52: 1 | M52: 1 | N52: 1 | O52: 1 | P52: 1 | Q52: 1 | R52: 1 | S52: 1 | T52: 1 | U52: 1 | V52: 2 | W52: 2 | X52: 2 | Y52: 2 | Z52: 2 | AA52: 2 | AB52: 2 | AC52: 2 | AD52: 2 | AE52: 2 | AF52: 2 | AG52: 2 | AH52: 2 | AI52: 2 | AJ52: 2 | AK52: 2 | AL52: 2 | AM52: 2 | AN52: 2 | AO52: 2 | AP52: 3 | AQ52: 3 | AR52: 3 | AS52: 3 | AT52: 3 | AU52: 3 | AV52: 3 | AW52: 3 | AX52: 3 | AY52: 3 | AZ52: 3 | BA52: 3 | BB52: 3 | BC52: 3 | BD52: 3 | BE52: 3 | BF52: 3 | BG52: 3 | BH52: 3 | BI52: 3
A53: QUEST | B53: TRUE | C53: TRUE | D53: TRUE | E53: TRUE | F53: TRUE | G53: TRUE | H53: TRUE | I53: TRUE | J53: TRUE | K53: TRUE | L53: TRUE | M53: TRUE | N53: TRUE | O53: TRUE | P53: TRUE | Q53: TRUE | R53: TRUE | S53: TRUE | T53: TRUE | U53: TRUE | V53: TRUE | W53: TRUE | X53: TRUE | Y53: TRUE | Z53: TRUE | AA53: TRUE | AB53: TRUE | AC53: TRUE | AD53: TRUE | AE53: TRUE | AF53: TRUE | AG53: TRUE | AH53: TRUE | AI53: TRUE | AJ53: TRUE | AK53: TRUE | AL53: TRUE | AM53: TRUE | AN53: TRUE | AO53: TRUE | AP53: TRUE | AQ53: TRUE | AR53: TRUE | AS53: TRUE | AT53: TRUE | AU53: TRUE | AV53: TRUE | AW53: TRUE | AX53: TRUE | AY53: TRUE | AZ53: TRUE | BA53: TRUE | BB53: TRUE | BC53: TRUE | BD53: TRUE | BE53: TRUE | BF53: TRUE | BG53: TRUE | BH53: TRUE | BI53: TRUE
A54: QUEST_NDVFS | B54: TRUE | C54: TRUE | D54: TRUE | E54: TRUE | F54: TRUE | G54: TRUE | H54: TRUE | I54: TRUE | J54: TRUE | K54: TRUE | L54: TRUE | M54: TRUE | N54: TRUE | O54: TRUE | P54: TRUE | Q54: TRUE | R54: TRUE | S54: TRUE | T54: TRUE | U54: TRUE | V54: TRUE | W54: TRUE | X54: TRUE | Y54: TRUE | Z54: TRUE | AA54: TRUE | AB54: TRUE | AC54: TRUE | AD54: TRUE | AE54: TRUE | AF54: TRUE | AG54: TRUE | AH54: TRUE | AI54: TRUE | AJ54: TRUE | AK54: TRUE | AL54: TRUE | AM54: TRUE | AN54: TRUE | AO54: TRUE | AP54: TRUE | AQ54: TRUE | AR54: TRUE | AS54: TRUE | AT54: TRUE | AU54: TRUE | AV54: TRUE | AW54: TRUE | AX54: TRUE | AY54: TRUE | AZ54: TRUE | BA54: TRUE | BB54: TRUE | BC54: TRUE | BD54: TRUE | BE54: TRUE | BF54: TRUE | BG54: TRUE | BH54: TRUE | BI54: TRUE
A55: Fuzzy | B55: TRUE | C55: TRUE | D55: TRUE | E55: TRUE | F55: TRUE | G55: TRUE | H55: TRUE | I55: TRUE | J55: TRUE | K55: TRUE | L55: TRUE | M55: TRUE | N55: TRUE | O55: TRUE | P55: TRUE | Q55: TRUE | R55: TRUE | S55: TRUE | T55: TRUE | U55: TRUE | V55: TRUE | W55: TRUE | X55: TRUE | Y55: TRUE | Z55: TRUE | AA55: TRUE | AB55: TRUE | AC55: TRUE | AD55: TRUE | AE55: TRUE | AF55: TRUE | AG55: TRUE | AH55: TRUE | AI55: TRUE | AJ55: TRUE | AK55: TRUE | AL55: TRUE | AM55: TRUE | AN55: TRUE | AO55: TRUE | AP55: TRUE | AQ55: TRUE | AR55: TRUE | AS55: TRUE | AT55: TRUE | AU55: TRUE | AV55: TRUE | AW55: TRUE | AX55: TRUE | AY55: TRUE | AZ55: TRUE | BA55: TRUE | BB55: TRUE | BC55: TRUE | BD55: TRUE | BE55: TRUE | BF55: TRUE | BG55: TRUE | BH55: TRUE | BI55: TRUE
A56: NSGA3 | B56: TRUE | C56: TRUE | D56: TRUE | E56: TRUE | F56: FALSE | G56: TRUE | H56: TRUE | I56: TRUE | J56: TRUE | K56: TRUE | L56: TRUE | M56: TRUE | N56: TRUE | O56: TRUE | P56: TRUE | Q56: TRUE | R56: TRUE | S56: FALSE | T56: TRUE | U56: TRUE | V56: TRUE | W56: TRUE | X56: TRUE | Y56: TRUE | Z56: TRUE | AA56: TRUE | AB56: TRUE | AC56: TRUE | AD56: TRUE | AE56: TRUE | AF56: TRUE | AG56: TRUE | AH56: TRUE | AI56: TRUE | AJ56: TRUE | AK56: TRUE | AL56: TRUE | AM56: TRUE | AN56: TRUE | AO56: TRUE | AP56: TRUE | AQ56: TRUE | AR56: TRUE | AS56: TRUE | AT56: TRUE | AU56: TRUE | AV56: FALSE | AW56: TRUE | AX56: TRUE | AY56: TRUE | AZ56: TRUE | BA56: TRUE | BB56: TRUE | BC56: TRUE | BD56: TRUE | BE56: TRUE | BF56: TRUE | BG56: TRUE | BH56: TRUE | BI56: TRUE
A57: MQGA | B57: TRUE | C57: TRUE | D57: TRUE | E57: TRUE | F57: TRUE | G57: TRUE | H57: TRUE | I57: TRUE | J57: TRUE | K57: TRUE | L57: TRUE | M57: TRUE | N57: TRUE | O57: TRUE | P57: TRUE | Q57: TRUE | R57: TRUE | S57: TRUE | T57: TRUE | U57: TRUE | V57: TRUE | W57: TRUE | X57: TRUE | Y57: TRUE | Z57: TRUE | AA57: TRUE | AB57: TRUE | AC57: TRUE | AD57: TRUE | AE57: TRUE | AF57: TRUE | AG57: TRUE | AH57: TRUE | AI57: TRUE | AJ57: TRUE | AK57: TRUE | AL57: TRUE | AM57: TRUE | AN57: TRUE | AO57: TRUE | AP57: TRUE | AQ57: TRUE | AR57: TRUE | AS57: TRUE | AT57: TRUE | AU57: TRUE | AV57: TRUE | AW57: TRUE | AX57: TRUE | AY57: TRUE | AZ57: TRUE | BA57: TRUE | BB57: TRUE | BC57: TRUE | BD57: TRUE | BE57: TRUE | BF57: TRUE | BG57: TRUE | BH57: TRUE | BI57: TRUE
...

Sheet Load Edge
A1: Algorithm | B1: Load | C1: Average | D1: Min | E1: Max | F1: Std Dev
A2: QUEST | B2: 1 | C2: 218307.95 | D2: 198111.2 | E2: 240038.7 | F2: 13205.361
A3: QUEST | B3: 2 | C3: 406720.07 | D3: 340044.4 | E3: 459557.23 | F3: 29002.268
A4: QUEST | B4: 3 | C4: 811105.27 | D4: 749456.6 | E4: 883394.9 | F4: 38047.96
A5: QUEST_NDVFS | B5: 1 | C5: 179364.56 | D5: 133291.1 | E5: 191476.1 | F5: 13047.261
A6: QUEST_NDVFS | B6: 2 | C6: 320732.42 | D6: 283239.33 | E6: 351119.37 | F6: 15926.973
A7: QUEST_NDVFS | B7: 3 | C7: 612670.4 | D7: 561046.6 | E7: 649761.03 | F7: 23999.162
A8: Fuzzy | B8: 1 | C8: 184664.53 | D8: 184664.53 | E8: 184664.53 | F8: 0
A9: Fuzzy | B9: 2 | C9: 343970.9 | D9: 343970.9 | E9: 343970.9 | F9: 0
A10: Fuzzy | B10: 3 | C10: 614032.5 | D10: 614032.5 | E10: 614032.5 | F10: 0
A11: NSGA3 | B11: 1 | C11: 193251.51 | D11: 174102.63 | E11: 206668.13 | F11: 8597.2096
A12: NSGA3 | B12: 2 | C12: 350990.89 | D12: 320436.33 | E12: 364387.5 | F12: 12737.258
A13: NSGA3 | B13: 3 | C13: 626154.42 | D13: 597936.67 | E13: 648391.4 | F13: 15030.354
... A25: RL | B25: 3 | C25: 623626.68 | D25: 579358.67 | E25: 647538.73 | F25: 15650.077
A28: Summary by Algorithm
A29: QUEST | C29: 478711.09 | D29: 198111.2 | E29: 883394.9 | F29: 248958.86
A30: QUEST_NDVFS | C30: 370922.46 | D30: 133291.1 | E30: 649761.03 | F30: 181342.58
A31: Fuzzy | C31: 380889.31 | D31: 184664.53 | E31: 614032.5 | F31: 177221.97
A32: NSGA3 | C32: 390132.27 | D32: 174102.63 | E32: 648391.4 | F32: 179315.92
A33: MQGA | C33: 386679.4 | D33: 186242.5 | E33: 638955.4 | F33: 175628.88
A34: Greedy | C34: 386615.61 | D34: 164910.8 | E34: 654864.17 | F34: 177180.73
A35: MOPSO | C35: 388023.63 | D35: 160758.27 | E35: 660068.8 | F35: 179176.63
A36: RL | C36: 387670.22 | D36: 155071.07 | E36: 647538.73 | F36: 177961.81
A39: Average data for chart
A40: Algorithms | B40: 1 | C40: 2 | D40: 3
A41: QUEST | B41: 218307.95 | C41: 406720.07 | D41: 811105.27
A42: QUEST_NDVFS | B42: 179364.56 | C42: 320732.42 | D42: 612670.4
A43: Fuzzy | B43: 184664.53 | C43: 343970.9 | D43: 614032.5
A44: NSGA3 | B44: 193251.51 | C44: 350990.89 | D44: 626154.42
A45: MQGA | B45: 193626.81 | C45: 348799.14 | D45: 617612.25
A46: Greedy | B46: 193936.13 | C46: 345550.26 | D46: 620360.43
A47: MOPSO | B47: 192831.43 | C47: 346691.31 | D47: 624548.13
A48: RL | B48: 195753.04 | C48: 343630.93 | D48: 623626.68
A51: All data for chart
A52: Algorithms | B52: 1 | C52: 1 | D52: 1 | E52: 1 | F52: 1 | G52: 1 | H52: 1 | I52: 1 | J52: 1 | K52: 1 | L52: 1 | M52: 1 | N52: 1 | O52: 1 | P52: 1 | Q52: 1 | R52: 1 | S52: 1 | T52: 1 | U52: 1 | V52: 2 | W52: 2 | X52: 2 | Y52: 2 | Z52: 2 | AA52: 2 | AB52: 2 | AC52: 2 | AD52: 2 | AE52: 2 | AF52: 2 | AG52: 2 | AH52: 2 | AI52: 2 | AJ52: 2 | AK52: 2 | AL52: 2 | AM52: 2 | AN52: 2 | AO52: 2 | AP52: 3 | AQ52: 3 | AR52: 3 | AS52: 3 | AT52: 3 | AU52: 3 | AV52: 3 | AW52: 3 | AX52: 3 | AY52: 3 | AZ52: 3 | BA52: 3 | BB52: 3 | BC52: 3 | BD52: 3 | BE52: 3 | BF52: 3 | BG52: 3 | BH52: 3 | BI52: 3
A53: QUEST | B53: 198111.2 | C53: 214251.07 | D53: 237391.9 | E53: 207307.33 | F53: 237087.63 | G53: 213515.77 | H53: 240038.7 | I53: 232160.2 | J53: 231159.3 | K53: 200054.73 | L53: 212526.07 | M53: 206264.67 | N53: 198815.4 | O53: 201879.6 | P53: 225985.8 | Q53: 226921.07 | R53: 219421.37 | S53: 226619.47 | T53: 216300.67 | U53: 220347.13 | V53: 451164.03 | W53: 408506.93 | X53: 459557.23 | Y53: 410859.4 | Z53: 418287.7 | AA53: 406714.57 | AB53: 435996.13 | AC53: 426569.57 | AD53: 368011.17 | AE53: 387386.37 | AF53: 409169.97 | AG53: 408470.43 | AH53: 409908.73 | AI53: 434633.6 | AJ53: 373041.43 | AK53: 430680.63 | AL53: 386694.83 | AM53: 398914.6 | AN53: 340044.4 | AO53: 369789.57 | AP53: 822251.57 | AQ53: 797677.47 | AR53: 805071.8 | AS53: 813214.43 | AT53: 850216.63 | AU53: 749456.6 | AV53: 827815.17 | AW53: 764355.1 | AX53: 838596.13 | AY53: 828969.2 | AZ53: 789471.77 | BA53: 813854.9 | BB53: 883394.9 | BC53: 777819.3 | BD53: 783453.37 | BE53: 780360.37 | BF53: 795117.43 | BG53: 879783.33 | BH53: 866495.2 | BI53: 754730.63
A54: QUEST_NDVFS | B54: 191476.1 | C54: 181954.3 | D54: 172839.6 | E54: 182696.43 | F54: 188976.43 | G54: 180094.97 | H54: 161040.47 | I54: 188048.27 | J54: 179360.73 | K54: 181448.97 | L54: 189183.13 | M54: 174739.83 | N54: 188741.7 | O54: 189580.97 | P54: 173999.5 | Q54: 177946.63 | R54: 188509.3 | S54: 133291.1 | T54: 173585.53 | U54: 189777.17 | V54: 334136.77 | W54: 321960.4 | X54: 321298.03 | Y54: 314124.17 | Z54: 312893.43 | AA54: 320913.33 | AB54: 333526.93 | AC54: 318399.87 | AD54: 283239.33 | AE54: 351119.37 | AF54: 330117.83 | AG54: 320240.7 | AH54: 309385.97 | AI54: 338457.87 | AJ54: 299912.7 | AK54: 307895.97 | AL54: 298910.33 | AM54: 344295.77 | AN54: 331970.6 | AO54: 321849.13 | AP54: 561046.6 | AQ54: 563955.23 | AR54: 593563.73 | AS54: 642392.17 | AT54: 606291.6 | AU54: 642233.83 | AV54: 601556.3 | AW54: 606696.1 | AX54: 649761.03 | AY54: 624090.27 | AZ54: 633258.1 | BA54: 629132.27 | BB54: 586819.47 | BC54: 619924.47 | BD54: 613747.7 | BE54: 606340.83 | BF54: 621023.2 | BG54: 633490.9 | BH54: 590794.07 | BI54: 627290.07
A55: Fuzzy | B55: 184664.53 | C55: 184664.53 | D55: 184664.53 | E55: 184664.53 | F55: 184664.53 | G55: 184664.53 | H55: 184664.53 | I55: 184664.53 | J55: 184664.53 | K55: 184664.53 | L55: 184664.53 | M55: 184664.53 | N55: 184664.53 | O55: 184664.53 | P55: 184664.53 | Q55: 184664.53 | R55: 184664.53 | S55: 184664.53 | T55: 184664.53 | U55: 184664.53 | V55: 343970.9 | W55: 343970.9 | X55: 343970.9 | Y55: 343970.9 | Z55: 343970.9 | AA55: 343970.9 | AB55: 343970.9 | AC55: 343970.9 | AD55: 343970.9 | AE55: 343970.9 | AF55: 343970.9 | AG55: 343970.9 | AH55: 343970.9 | AI55: 343970.9 | AJ55: 343970.9 | AK55: 343970.9 | AL55: 343970.9 | AM55: 343970.9 | AN55: 343970.9 | AO55: 343970.9 | AP55: 614032.5 | AQ55: 614032.5 | AR55: 614032.5 | AS55: 614032.5 | AT55: 614032.5 | AU55: 614032.5 | AV55: 614032.5 | AW55: 614032.5 | AX55: 614032.5 | AY55: 614032.5 | AZ55: 614032.5 | BA55: 614032.5 | BB55: 614032.5 | BC55: 614032.5 | BD55: 614032.5 | BE55: 614032.5 | BF55: 614032.5 | BG55: 614032.5 | BH55: 614032.5 | BI55: 614032.5
A56: NSGA3 | B56: 196798.37 | C56: 197448.77 | D56: 197262.63 | E56: 185670.53 | F56: 189767.97 | G56: 199494.43 | H56: 201182.33 | I56: 206668.13 | J56: 187307.23 | K56: 190736.33 | L56: 181143.23 | M56: 182428.77 | N56: 206376.43 | O56: 174102.63 | P56: 196614.63 | Q56: 186379.67 | R56: 187531.4 | S56: 201319.2 | T56: 202059.07 | U56: 194738.43 | V56: 347679.77 | W56: 355892.13 | X56: 355365.43 | Y56: 361018.07 | Z56: 361541.27 | AA56: 320436.33 | AB56: 364387.5 | AC56: 356609.5 | AD56: 356989.9 | AE56: 348806.23 | AF56: 330928.5 | AG56: 360063.63 | AH56: 356882.53 | AI56: 359566.13 | AJ56: 351911.6 | AK56: 328536.03 | AL56: 359643.8 | AM56: 363507.27 | AN56: 350592.13 | AO56: 329460.03 | AP56: 639601.67 | AQ56: 622223.1 | AR56: 612457.87 | AS56: 647513.47 | AT56: 646746.13 | AU56: 642923.6 | AV56: 599005.97 | AW56: 648391.4 | AX56: 622137 | AY56: 625955.77 | AZ56: 597936.67 | BA56: 621201.7 | BB56: 614256.23 | BC56: 626035.63 | BD56: 631558.37 | BE56: 643922.77 | BF56: 606861.07 | BG56: 619701.17 | BH56: 626520.23 | BI56: 628138.57
A57: MQGA | B57: 197318.3 | C57: 195011.4 | D57: 195559.17 | E57: 194310.8 | F57: 196315.67 | G57: 194875.97 | H57: 194979.33 | I57: 193418.57 | J57: 193089.13 | K57: 194565.43 | L57: 191660.07 | M57: 194837.8 | N57: 193836.8 | O57: 191736.57 | P57: 191077.5 | Q57: 197395.4 | R57: 186242.5 | S57: 196223.83 | T57: 192480.97 | U57: 187601.03 | V57: 314099.27 | W57: 357628.73 | X57: 350757.37 | Y57: 356425.17 | Z57: 361208.13 | AA57: 352169.63 | AB57: 346534.3 | AC57: 319128.3 | AD57: 351529.5 | AE57: 353380.1 | AF57: 350539.43 | AG57: 363086.7 | AH57: 358523.27 | AI57: 345398.43 | AJ57: 347246.03 | AK57: 352437.93 | AL57: 356433.2 | AM57: 363467.07 | AN57: 346990.3 | AO57: 328999.93 | AP57: 615140.17 | AQ57: 634470.27 | AR57: 584300.6 | AS57: 638955.4 | AT57: 624055.47 | AU57: 610589.67 | AV57: 635573.73 | AW57: 614206.77 | AX57: 632090.63 | AY57: 564628.17 | AZ57: 622003.07 | BA57: 634968.67 | BB57: 612463.57 | BC57: 628124.33 | BD57: 626071.57 | BE57: 619962.37 | BF57: 623174.5 | BG57: 604044.3 | BH57: 599790.1 | BI57: 627631.73
...

Sheet Load Cloud
A1: Algorithm | B1: Load | C1: Average | D1: Min | E1: Max | F1: Std Dev
A2: QUEST | B2: 1 | C2: 522634.7 | D2: 0 | E2: 1090331 | F2: 375885.78
A3: QUEST | B3: 2 | C3: 1168546.8 | D3: 0 | E3: 2675083 | F3: 643152.77
A4: QUEST | B4: 3 | C4: 1272526.2 | D4: 96722 | E4: 3031419 | F4: 740141.26
A5: QUEST_NDVFS | B5: 1 | C5: 307149.5 | D5: 0 | E5: 1628152 | F5: 381348.52
A6: QUEST_NDVFS | B6: 2 | C6: 814585.15 | D6: 0 | E6: 2099877 | F6: 492937.26
A7: QUEST_NDVFS | B7: 3 | C7: 1086681.5 | D7: 15342 | E7: 2436210 | F7: 601240.84
A8: Fuzzy | B8: 1 | C8: 0 | D8: 0 | E8: 0 | F8: 0
A9: Fuzzy | B9: 2 | C9: 15142 | D9: 15142 | E9: 15142 | F9: 0
A10: Fuzzy | B10: 3 | C10: 326934 | D10: 326934 | E10: 326934 | F10: 0
A11: NSGA3 | B11: 1 | C11: 200746.65 | D11: 0 | E11: 765400 | F11: 235683
A12: NSGA3 | B12: 2 | C12: 258405.05 | D12: 0 | E12: 1023593 | F12: 316711.14
A13: NSGA3 | B13: 3 | C13: 500056.85 | D13: 3842 | E13: 1384651 | F13: 382260.71
... A25: RL | B25: 3 | C25: 461718.4 | D25: 0 | E25: 1464210 | F25: 338515.91
A28: Summary by Algorithm
A29: QUEST | C29: 987902.58 | D29: 0 | E29: 3031419 | F29: 691101.02
A30: QUEST_NDVFS | C30: 736138.72 | D30: 0 | E30: 2436210 | F30: 595250.71
A31: Fuzzy | C31: 114025.33 | D31: 0 | E31: 326934 | F31: 150676.02
A32: NSGA3 | C32: 319736.18 | D32: 0 | E32: 1384651 | F32: 342739.57
A33: MQGA | C33: 265511.52 | D33: 0 | E33: 1821911 | F33: 396491.65
A34: Greedy | C34: 385188.17 | D34: 0 | E34: 1440068 | F34: 394752.06
A35: MOPSO | C35: 308046.17 | D35: 0 | E35: 1305736 | F35: 351008.01
A36: RL | C36: 338308.1 | D36: 0 | E36: 1464210 | F36: 365114.49
A39: Average data for chart
A40: Algorithms | B40: 1 | C40: 2 | D40: 3
A41: QUEST | B41: 522634.7 | C41: 1168546.8 | D41: 1272526.2
A42: QUEST_NDVFS | B42: 307149.5 | C42: 814585.15 | D42: 1086681.5
A43: Fuzzy | B43: 0 | C43: 15142 | D43: 326934
A44: NSGA3 | B44: 200746.65 | C44: 258405.05 | D44: 500056.85
A45: MQGA | B45: 15213.95 | C45: 182651.15 | D45: 598669.45
A46: Greedy | B46: 210146.95 | C46: 404985.45 | D46: 540432.1
A47: MOPSO | B47: 205786.65 | C47: 282384.15 | D47: 435967.7
A48: RL | B48: 178842 | C48: 374363.9 | D48: 461718.4
A51: All data for chart
A52: Algorithms | B52: 1 | C52: 1 | D52: 1 | E52: 1 | F52: 1 | G52: 1 | H52: 1 | I52: 1 | J52: 1 | K52: 1 | L52: 1 | M52: 1 | N52: 1 | O52: 1 | P52: 1 | Q52: 1 | R52: 1 | S52: 1 | T52: 1 | U52: 1 | V52: 2 | W52: 2 | X52: 2 | Y52: 2 | Z52: 2 | AA52: 2 | AB52: 2 | AC52: 2 | AD52: 2 | AE52: 2 | AF52: 2 | AG52: 2 | AH52: 2 | AI52: 2 | AJ52: 2 | AK52: 2 | AL52: 2 | AM52: 2 | AN52: 2 | AO52: 2 | AP52: 3 | AQ52: 3 | AR52: 3 | AS52: 3 | AT52: 3 | AU52: 3 | AV52: 3 | AW52: 3 | AX52: 3 | AY52: 3 | AZ52: 3 | BA52: 3 | BB52: 3 | BC52: 3 | BD52: 3 | BE52: 3 | BF52: 3 | BG52: 3 | BH52: 3 | BI52: 3
A53: QUEST | B53: 1090331 | C53: 517225 | D53: 22563 | E53: 893163 | F53: 0 | G53: 519190 | H53: 0 | I53: 13363 | J53: 22563 | K53: 1072934 | L53: 525765 | M53: 944326 | N53: 1079229 | O53: 975386 | P53: 319513 | Q53: 437813 | R53: 510370 | S53: 404313 | T53: 535210 | U53: 569437 | V53: 0 | W53: 1657117 | X53: 662650 | Y53: 1229401 | Z53: 1452461 | AA53: 997364 | AB53: 896101 | AC53: 913514 | AD53: 2313022 | AE53: 1565126 | AF53: 895451 | AG53: 931026 | AH53: 476513 | AI53: 0 | AJ53: 1449536 | AK53: 972526 | AL53: 1531293 | AM53: 1139328 | AN53: 2675083 | AO53: 1613424 | AP53: 471426 | AQ53: 1787528 | AR53: 1256564 | AS53: 1318313 | AT53: 987064 | AU53: 2380323 | AV53: 2159742 | AW53: 3031419 | AX53: 580125 | AY53: 690242 | AZ53: 1197230 | BA53: 565914 | BB53: 533488 | BC53: 1732236 | BD53: 1836589 | BE53: 1109763 | BF53: 979063 | BG53: 681126 | BH53: 96722 | BI53: 2055648
A54: QUEST_NDVFS | B54: 0 | C54: 306917 | D54: 446009 | E54: 259134 | F54: 4459 | G54: 326093 | H54: 879486 | I54: 8984 | J54: 269609 | K54: 213009 | L54: 14684 | M54: 440810 | N54: 19017 | O54: 0 | P54: 495525 | Q54: 290801 | R54: 14792 | S54: 1628152 | T54: 510650 | U54: 14859 | V54: 412575 | W54: 829493 | X54: 884159 | Y54: 1065826 | Z54: 896835 | AA54: 747302 | AB54: 416000 | AC54: 945884 | AD54: 2099877 | AE54: 0 | AF54: 565226 | AG54: 864034 | AH54: 1067627 | AI54: 326484 | AJ54: 1473051 | AK54: 1103809 | AL54: 1479093 | AM54: 0 | AN54: 505760 | AO54: 608668 | AP54: 2436210 | AQ54: 2248103 | AR54: 1491118 | AS54: 429259 | AT54: 1492903 | AU54: 515318 | AV54: 1306770 | AW54: 1196952 | AX54: 15342 | AY54: 675659 | AZ54: 679969 | BA54: 905101 | BB54: 1758001 | BC54: 855268 | BD54: 752117 | BE54: 1028518 | BF54: 860584 | BG54: 557101 | BH54: 1701860 | BI54: 827477
A55: Fuzzy | B55: 0 | C55: 0 | D55: 0 | E55: 0 | F55: 0 | G55: 0 | H55: 0 | I55: 0 | J55: 0 | K55: 0 | L55: 0 | M55: 0 | N55: 0 | O55: 0 | P55: 0 | Q55: 0 | R55: 0 | S55: 0 | T55: 0 | U55: 0 | V55: 15142 | W55: 15142 | X55: 15142 | Y55: 15142 | Z55: 15142 | AA55: 15142 | AB55: 15142 | AC55: 15142 | AD55: 15142 | AE55: 15142 | AF55: 15142 | AG55: 15142 | AH55: 15142 | AI55: 15142 | AJ55: 15142 | AK55: 15142 | AL55: 15142 | AM55: 15142 | AN55: 15142 | AO55: 15142 | AP55: 326934 | AQ55: 326934 | AR55: 326934 | AS55: 326934 | AT55: 326934 | AU55: 326934 | AV55: 326934 | AW55: 326934 | AX55: 326934 | AY55: 326934 | AZ55: 326934 | BA55: 326934 | BB55: 326934 | BC55: 326934 | BD55: 326934 | BE55: 326934 | BF55: 326934 | BG55: 326934 | BH55: 326934 | BI55: 326934
A56: NSGA3 | B56: 14684 | C56: 19317 | D56: 4675 | E56: 425309 | F56: 0 | G56: 4809 | H56: 0 | I56: 0 | J56: 440101 | K56: 363451 | L56: 441502 | M56: 432659 | N56: 0 | O56: 765400 | P56: 276742 | Q56: 521984 | R56: 304300 | S56: 0 | T56: 0 | U56: 0 | V56: 482467 | W56: 0 | X56: 330159 | Y56: 14550 | Z56: 8250 | AA56: 925342 | AB56: 4075 | AC56: 30367 | AD56: 0 | AE56: 411409 | AF56: 552209 | AG56: 30817 | AH56: 4409 | AI56: 8742 | AJ56: 265384 | AK56: 1023593 | AL56: 30243 | AM56: 4734 | AN56: 466942 | AO56: 574409 | AP56: 442626 | AQ56: 431575 | AR56: 1143785 | AS56: 3842 | AT56: 4550 | AU56: 8000 | AV56: 1145767 | AW56: 236884 | AX56: 464609 | AY56: 725817 | AZ56: 1384651 | BA56: 590893 | BB56: 436917 | BC56: 544718 | BD56: 290950 | BE56: 8784 | BF56: 428092 | BG56: 663067 | BH56: 760701 | BI56: 284909
A57: MQGA | B57: 4109 | C57: 0 | D57: 0 | E57: 0 | F57: 4109 | G57: 0 | H57: 0 | I57: 0 | J57: 0 | K57: 0 | L57: 0 | M57: 4525 | N57: 15192 | O57: 8717 | P57: 4109 | Q57: 0 | R57: 254750 | S57: 4384 | T57: 4384 | U57: 0 | V57: 997617 | W57: 0 | X57: 49601 | Y57: 0 | Z57: 15042 | AA57: 4117 | AB57: 402767 | AC57: 975901 | AD57: 8850 | AE57: 0 | AF57: 0 | AG57: 0 | AH57: 15242 | AI57: 539368 | AJ57: 4275 | AK57: 15225 | AL57: 0 | AM57: 0 | AN57: 14550 | AO57: 610468 | AP57: 428317 | AQ57: 444601 | AR57: 1316861 | AS57: 0 | AT57: 375985 | AU57: 562634 | AV57: 23926 | AW57: 966994 | AX57: 907368 | AY57: 1821911 | AZ57: 392017 | BA57: 305209 | BB57: 642601 | BC57: 407210 | BD57: 23917 | BE57: 546893 | BF57: 738900 | BG57: 851451 | BH57: 735101 | BI57: 481493
...

Sheet Loads
A1: Average data for chart
B2: Edge | C2: Edge | D2: Edge | E2: Edge | F2: Edge | G2: Edge | H2: Edge | I2: Edge | J2: Edge | K2: Edge | L2: Edge | M2: Edge | N2: Edge | O2: Edge | P2: Edge | Q2: Edge | R2: Edge | S2: Edge | T2: Edge | U2: Edge | V2: Edge | W2: Edge | X2: Edge | Y2: Edge | Z2: Edge | AA2: Edge | AB2: Edge | AC2: Edge | AD2: Edge | AE2: Edge | AF2: Cloud | AG2: Edge | AH2: Edge | AI2: Edge | AJ2: Edge | AK2: Edge | AL2: Edge | AM2: Edge | AN2: Edge | AO2: Edge | AP2: Edge | AQ2: Edge | AR2: Edge | AS2: Edge | AT2: Edge | AU2: Edge | AV2: Edge | AW2: Edge | AX2: Edge | AY2: Edge | AZ2: Edge | BA2: Edge | BB2: Edge | BC2: Edge | BD2: Edge | BE2: Edge | BF2: Edge | BG2: Edge | BH2: Edge | BI2: Edge | BJ2: Edge | BK2: Cloud | BL2: Edge | BM2: Edge | BN2: Edge | BO2: Edge | BP2: Edge | BQ2: Edge | BR2: Edge | BS2: Edge | BT2: Edge | BU2: Edge | BV2: Edge | BW2: Edge | BX2: Edge | BY2: Edge | BZ2: Edge | CA2: Edge | CB2: Edge | CC2: Edge | CD2: Edge | CE2: Edge | CF2: Edge | CG2: Edge | CH2: Edge | CI2: Edge | CJ2: Edge | CK2: Edge | CL2: Edge | CM2: Edge | CN2: Edge | CO2: Edge | CP2: Cloud
B3: 1 | C3: 1 | D3: 1 | E3: 1 | F3: 1 | G3: 1 | H3: 1 | I3: 1 | J3: 1 | K3: 1 | L3: 1 | M3: 1 | N3: 1 | O3: 1 | P3: 1 | Q3: 1 | R3: 1 | S3: 1 | T3: 1 | U3: 1 | V3: 1 | W3: 1 | X3: 1 | Y3: 1 | Z3: 1 | AA3: 1 | AB3: 1 | AC3: 1 | AD3: 1 | AE3: 1 | AF3: 1 | AG3: 2 | AH3: 2 | AI3: 2 | AJ3: 2 | AK3: 2 | AL3: 2 | AM3: 2 | AN3: 2 | AO3: 2 | AP3: 2 | AQ3: 2 | AR3: 2 | AS3: 2 | AT3: 2 | AU3: 2 | AV3: 2 | AW3: 2 | AX3: 2 | AY3: 2 | AZ3: 2 | BA3: 2 | BB3: 2 | BC3: 2 | BD3: 2 | BE3: 2 | BF3: 2 | BG3: 2 | BH3: 2 | BI3: 2 | BJ3: 2 | BK3: 2 | BL3: 3 | BM3: 3 | BN3: 3 | BO3: 3 | BP3: 3 | BQ3: 3 | BR3: 3 | BS3: 3 | BT3: 3 | BU3: 3 | BV3: 3 | BW3: 3 | BX3: 3 | BY3: 3 | BZ3: 3 | CA3: 3 | CB3: 3 | CC3: 3 | CD3: 3 | CE3: 3 | CF3: 3 | CG3: 3 | CH3: 3 | CI3: 3 | CJ3: 3 | CK3: 3 | CL3: 3 | CM3: 3 | CN3: 3 | CO3: 3 | CP3: 3
A4: Algorithms | B4: 1 | C4: 2 | D4: 3 | E4: 4 | F4: 5 | G4: 6 | H4: 7 | I4: 8 | J4: 9 | K4: 10 | L4: 11 | M4: 12 | N4: 13 | O4: 14 | P4: 15 | Q4: 16 | R4: 17 | S4: 18 | T4: 19 | U4: 20 | V4: 21 | W4: 22 | X4: 23 | Y4: 24 | Z4: 25 | AA4: 26 | AB4: 27 | AC4: 28 | AD4: 29 | AE4: 30 | AF4: 31 | AG4: 1 | AH4: 2 | AI4: 3 | AJ4: 4 | AK4: 5 | AL4: 6 | AM4: 7 | AN4: 8 | AO4: 9 | AP4: 10 | AQ4: 11 | AR4: 12 | AS4: 13 | AT4: 14 | AU4: 15 | AV4: 16 | AW4: 17 | AX4: 18 | AY4: 19 | AZ4: 20 | BA4: 21 | BB4: 22 | BC4: 23 | BD4: 24 | BE4: 25 | BF4: 26 | BG4: 27 | BH4: 28 | BI4: 29 | BJ4: 30 | BK4: 31 | BL4: 1 | BM4: 2 | BN4: 3 | BO4: 4 | BP4: 5 | BQ4: 6 | BR4: 7 | BS4: 8 | BT4: 9 | BU4: 10 | BV4: 11 | BW4: 12 | BX4: 13 | BY4: 14 | BZ4: 15 | CA4: 16 | CB4: 17 | CC4: 18 | CD4: 19 | CE4: 20 | CF4: 21 | CG4: 22 | CH4: 23 | CI4: 24 | CJ4: 25 | CK4: 26 | CL4: 27 | CM4: 28 | CN4: 29 | CO4: 30 | CP4: 31
A5: QUEST | B5: 164668.26 | C5: 244221.61 | D5: 268174.71 | E5: 180642.65 | F5: 321289.16 | G5: 267340.16 | H5: 235283.52 | I5: 294649.87 | J5: 199084.58 | K5: 134553.68 | L5: 216924.58 | M5: 118837.26 | N5: 352315.29 | O5: 206048.55 | P5: 156521.97 | Q5: 109994.16 | R5: 54713.355 | S5: 75271.645 | T5: 56508.871 | U5: 82658.484 | V5: 36504.355 | W5: 72335.484 | X5: 4314.8387 | Y5: 58851 | Z5: 40455.548 | AA5: 21147.29 | AB5: 67412.871 | AC5: 40023.29 | AD5: 87093.065 | AE5: 57475.129 | AF5: 337183.68 | AG5: 365800.58 | AH5: 326092.29 | AI5: 309778.39 | AJ5: 318407.16 | AK5: 309696.23 | AL5: 262358.19 | AM5: 362310.39 | AN5: 231966.52 | AO5: 315935.65 | AP5: 387684.65 | AQ5: 270414.65 | AR5: 386587.52 | AS5: 336850.48 | AT5: 374787.19 | AU5: 305150.52 | AV5: 260109.58 | AW5: 207390.29 | AX5: 225809.9 | AY5: 221620.81 | AZ5: 135821.32 | BA5: 266489.26 | BB5: 202935.71 | BC5: 140595.32 | BD5: 147235.97 | BE5: 282782.03 | BF5: 191583.94 | BG5: 284809.52 | BH5: 131829.52 | BI5: 199870.68 | BJ5: 109297.03 | BK5: 753901.16 | BL5: 393385.13 | BM5: 462098.1 | BN5: 445464.03 | BO5: 371302.68 | BP5: 441572 | BQ5: 469726.52 | BR5: 520535.45 | BS5: 412397.16 | BT5: 417792.1 | BU5: 417194.55 | BV5: 418525.52 | BW5: 367961.03 | BX5: 469292.65 | BY5: 386581.68 | BZ5: 299412.13 | CA5: 738127.84 | CB5: 743762.52 | CC5: 664299.23 | CD5: 436239.68 | CE5: 484769.74 | CF5: 539949.58 | CG5: 568856.16 | CH5: 511386.23 | CI5: 840497.65 | CJ5: 684114.84 | CK5: 667694.29 | CL5: 422151.58 | CM5: 779881.42 | CN5: 689868.77 | CO5: 633971.35 | CP5: 820984.68
A6: QUEST_NDVFS | B6: 196026.29 | C6: 130959.48 | D6: 175270.68 | E6: 194120.55 | F6: 251001.94 | G6: 173480.35 | H6: 172957.9 | I6: 169569.94 | J6: 138994.65 | K6: 123616.68 | L6: 226689.03 | M6: 208332.39 | N6: 163338.68 | O6: 262575.9 | P6: 211657.61 | Q6: 67970 | R6: 54759.677 | S6: 13952.903 | T6: 39515.161 | U6: 13567.742 | V6: 79669.677 | W6: 33520 | X6: 43454.839 | Y6: 100241.29 | Z6: 19015.806 | AA6: 51849.032 | AB6: 14046.774 | AC6: 54029.677 | AD6: 47860.323 | AE6: 39527.097 | AF6: 198160.97 | AG6: 361792.29 | AH6: 258702.23 | AI6: 255153.52 | AJ6: 267884.68 | AK6: 251599.03 | AL6: 242999 | AM6: 262241.48 | AN6: 221301.35 | AO6: 228424.48 | AP6: 236598.16 | AQ6: 211390.35 | AR6: 169760.71 | AS6: 264729.03 | AT6: 259752.19 | AU6: 257623.26 | AV6: 133133.23 | AW6: 164543.23 | AX6: 242813.23 | AY6: 193828.06 | AZ6: 173070.97 | BA6: 125010.32 | BB6: 186403.55 | BC6: 128526.77 | BD6: 98956.129 | BE6: 174090.97 | BF6: 140630.97 | BG6: 132159.35 | BH6: 104776.77 | BI6: 271712.26 | BJ6: 188116.77 | BK6: 525538.81 | BL6: 199462.26 | BM6: 275318.29 | BN6: 237765.58 | BO6: 291294.77 | BP6: 306345.84 | BQ6: 281324.77 | BR6: 293796.94 | BS6: 329089.71 | BT6: 261124.26 | BU6: 324312.55 | BV6: 340145.61 | BW6: 210896.77 | BX6: 320994.1 | BY6: 379658.39 | BZ6: 270560.42 | CA6: 367005.16 | CB6: 415084.84 | CC6: 476880.97 | CD6: 466575.16 | CE6: 464079.35 | CF6: 604806.45 | CG6: 526293.87 | CH6: 562690 | CI6: 601173.87 | CJ6: 513128.06 | CK6: 491725.48 | CL6: 530684.52 | CM6: 418552.9 | CN6: 512762.9 | CO6: 584602.9 | CP6: 701084.84
A7: Fuzzy | B7: 362763.87 | C7: 336763.87 | D7: 329451.61 | E7: 319693.55 | F7: 287747.74 | G7: 279134.84 | H7: 274392.9 | I7: 224941.29 | J7: 196322.58 | K7: 188306.45 | L7: 185005.81 | M7: 178543.23 | N7: 164354.84 | O7: 137425.16 | P7: 9801.2903 | Q7: 11645.161 | R7: 11593.548 | S7: 11503.226 | T7: 11451.613 | U7: 11367.742 | V7: 11335.484 | W7: 3722.5806 | X7: 3619.3548 | Y7: 3503.2258 | Z7: 3451.6129 | AA7: 3393.5484 | AB7: 3393.5484 | AC7: 3212.9032 | AD7: 3180.6452 | AE7: 3129.0323 | AF7: 0 | AG7: 380318.06 | AH7: 379473.55 | AI7: 365968.39 | AJ7: 354769.68 | AK7: 351758.06 | AL7: 334420 | AM7: 304123.87 | AN7: 294672.9 | AO7: 269021.94 | AP7: 268467.74 | AQ7: 262678.06 | AR7: 259489.68 | AS7: 258403.23 | AT7: 256704.52 | AU7: 255425.16 | AV7: 280761.29 | AW7: 257025.81 | AX7: 249380.65 | AY7: 249096.77 | AZ7: 243870.97 | BA7: 193670.97 | BB7: 183890.32 | BC7: 175038.71 | BD7: 157722.58 | BE7: 12135.484 | BF7: 12019.355 | BG7: 11870.968 | BH7: 11800 | BI7: 11787.097 | BJ7: 11735.484 | BK7: 9769.0323 | BL7: 564436.77 | BM7: 535005.81 | BN7: 528479.35 | BO7: 526441.29 | BP7: 511565.16 | BQ7: 496941.94 | BR7: 483683.23 | BS7: 476602.58 | BT7: 461565.16 | BU7: 448866.45 | BV7: 445549.68 | BW7: 431602.58 | BX7: 414736.77 | BY7: 405645.81 | BZ7: 400119.35 | CA7: 477832.26 | CB7: 337703.23 | CC7: 327200 | CD7: 323212.9 | CE7: 320103.23 | CF7: 306709.68 | CG7: 306464.52 | CH7: 305864.52 | CI7: 301658.06 | CJ7: 299941.94 | CK7: 296683.87 | CL7: 289303.23 | CM7: 288954.84 | CN7: 286954.84 | CO7: 284670.97 | CP7: 210925.16
