Workbook

Sheet Charts
R2: AoI | S2: 1000 | T2: 2000
R3: QUEST | S3: ='Data Age'!B33 -> 229177.51 | T3: ='Data Age'!C33 -> 2234533.1
R4: QUEST_NDVFS | S4: ='Data Age'!B34 -> 200299.03 | T4: ='Data Age'!C34 -> 1725553.8
R5: Fuzzy | S5: ='Data Age'!B35 -> 401194.86 | T5: ='Data Age'!C35 -> 3093857.5
R6: NSGA3 | S6: ='Data Age'!B36 -> 392573.68 | T6: ='Data Age'!C36 -> 2783034.4
R7: MQGA | S7: ='Data Age'!B37 -> 424786.2 | T7: ='Data Age'!C37 -> 2727512.8
R8: Greedy | S8: ='Data Age'!B38 -> 369753.34 | T8: ='Data Age'!C38 -> 3232555.6
R9: MOPSO | S9: ='Data Age'!B39 -> 312586.3 | T9: ='Data Age'!C39 -> 3085228.5
R10: RL | S10: ='Data Age'!B40 -> 355443.2 | T10: ='Data Age'!C40 -> 3256922
R17: AoI | S17: 1000 | T17: 2000
R18: QUEST | S18: =S3/S3 -> 1 | T18: =T3/T3 -> 1
R19: QUEST_NDVFS | S19: =S4/S3 -> 0.87399078 | T19: =T4/T3 -> 0.77222117
R20: Fuzzy | S20: =S5/S3 -> 1.7505856 | T20: =T5/T3 -> 1.3845655
R21: NSGA3 | S21: =S6/S3 -> 1.7129677 | T21: =T6/T3 -> 1.2454657
R22: MQGA | S22: =S7/S3 -> 1.8535248 | T22: =T7/T3 -> 1.2206187
R23: Greedy | S23: =S8/S3 -> 1.6133928 | T23: =T8/T3 -> 1.4466358
R24: MOPSO | S24: =S9/S3 -> 1.3639484 | T24: =T9/T3 -> 1.3807038
R25: RL | S25: =S10/S3 -> 1.5509515 | T25: =T10/T3 -> 1.4575403
R36: Energy | S36: 1000 | T36: 2000
R37: QUEST | S37: =Energy!B33 -> 4.6322753e+09 | T37: =Energy!C33 -> 1.2127464e+10
R38: QUEST_NDVFS | S38: =Energy!B34 -> 4.5570047e+09 | T38: =Energy!C34 -> 1.5469008e+10
R39: Fuzzy | S39: =Energy!B35 -> 4.5282367e+09 | T39: =Energy!C35 -> 2.7445779e+10
R40: NSGA3 | S40: =Energy!B36 -> 6.1423804e+09 | T40: =Energy!C36 -> 2.158467e+10
R41: MQGA | S41: =Energy!B37 -> 4.8323431e+09 | T41: =Energy!C37 -> 2.0734706e+10
R42: Greedy | S42: =Energy!B38 -> 7137144755 | T42: =Energy!C38 -> 23987023595
R43: MOPSO | S43: =Energy!B39 -> 5.2834908e+09 | T43: =Energy!C39 -> 2.3434384e+10
R44: RL | S44: =Energy!B40 -> 5770288825 | T44: =Energy!C40 -> 2.5011989e+10
R51: Energy | S51: 1000 | T51: 2000
R52: QUEST | S52: =S37/S37 -> 1 | T52: =T37/T37 -> 1
R53: QUEST_NDVFS | S53: =S38/S37 -> 0.98375084 | T53: =T38/T37 -> 1.2755352
R54: Fuzzy | S54: =S39/S37 -> 0.97754049 | T54: =T39/T37 -> 2.2631095
R55: NSGA3 | S55: =S40/S37 -> 1.3259964 | T55: =T40/T37 -> 1.7798172
R56: MQGA | S56: =S41/S37 -> 1.04319 | T56: =T41/T37 -> 1.7097314
R57: Greedy | S57: =S42/S37 -> 1.5407428 | T57: =T42/T37 -> 1.9779092
R58: MOPSO | S58: =S43/S37 -> 1.1405822 | T58: =T43/T37 -> 1.93234
R59: RL | S59: =S44/S37 -> 1.2456705 | T59: =T44/T37 -> 2.0624253
R67: Makespan | S67: 1000 | T67: 2000
R68: QUEST | S68: =Makespan!B33 -> 4924963 | T68: =Makespan!C33 -> 13682956
R69: QUEST_NDVFS | S69: =Makespan!B34 -> 4774479 | T69: =Makespan!C34 -> 14641150
R70: Fuzzy | S70: =Makespan!B35 -> 4475444.5 | T70: =Makespan!C35 -> 27083949
...

Sheet Data Age
A1: Algorithm | B1: Load | C1: Average | D1: Min | E1: Max | F1: Std Dev
A2: QUEST | B2: 1 | C2: 229177.51 | D2: 224370.93 | E2: 233984.09 | F2: 4806.5816
A3: QUEST | B3: 2 | C3: 2234533.1 | D3: 2149040.5 | E3: 2320025.7 | F3: 85492.599
A4: QUEST_NDVFS | B4: 1 | C4: 200299.03 | D4: 197740.17 | E4: 202857.89 | F4: 2558.8571
A5: QUEST_NDVFS | B5: 2 | C5: 1725553.8 | D5: 1644115.2 | E5: 1806992.4 | F5: 81438.586
A6: Fuzzy | B6: 1 | C6: 401194.86 | D6: 401194.72 | E6: 401194.99 | F6: 0.13265306
A7: Fuzzy | B7: 2 | C7: 3093857.5 | D7: 3093857.1 | E7: 3093857.8 | F7: 0.3622291
A8: NSGA3 | B8: 1 | C8: 392573.68 | D8: 334760.59 | E8: 450386.77 | F8: 57813.087
A9: NSGA3 | B9: 2 | C9: 2783034.4 | D9: 2694586.8 | E9: 2871482.1 | F9: 88447.626
A10: MQGA | B10: 1 | C10: 424786.2 | D10: 403904.67 | E10: 445667.73 | F10: 20881.531
A11: MQGA | B11: 2 | C11: 2727512.8 | D11: 2497373.2 | E11: 2957652.4 | F11: 230139.64
A12: Greedy | B12: 1 | C12: 369753.34 | D12: 229153.58 | E12: 510353.1 | F12: 140599.76
A13: Greedy | B13: 2 | C13: 3232555.6 | D13: 2971137.3 | E13: 3493974 | F13: 261418.34
... A17: RL | B17: 2 | C17: 3256922 | D17: 3096250.9 | E17: 3417593.2 | F17: 160671.12
A20: Summary by Algorithm
A21: QUEST | C21: 1231855.3 | D21: 224370.93 | E21: 2320025.7 | F21: 1004504.3
A22: QUEST_NDVFS | C22: 962926.4 | D22: 197740.17 | E22: 1806992.4 | F22: 764800.56
A23: Fuzzy | C23: 1747526.2 | D23: 401194.72 | E23: 3093857.8 | F23: 1346331.3
A24: NSGA3 | C24: 1587804.1 | D24: 334760.59 | E24: 2871482.1 | F24: 1197563.5
A25: MQGA | C25: 1576149.5 | D25: 403904.67 | E25: 2957652.4 | F25: 1162900.5
A26: Greedy | C26: 1801154.5 | D26: 229153.58 | E26: 3493974 | F26: 1446707.7
A27: MOPSO | C27: 1698907.4 | D27: 265199.83 | E27: 3456930.2 | F27: 1411414.2
A28: RL | C28: 1806182.6 | D28: 313855.48 | E28: 3417593.2 | F28: 1455478.4
A31: Average data for chart
A32: Algorithms | B32: 1 | C32: 2
A33: QUEST | B33: 229177.51 | C33: 2234533.1
A34: QUEST_NDVFS | B34: 200299.03 | C34: 1725553.8
A35: Fuzzy | B35: 401194.86 | C35: 3093857.5
A36: NSGA3 | B36: 392573.68 | C36: 2783034.4
A37: MQGA | B37: 424786.2 | C37: 2727512.8
A38: Greedy | B38: 369753.34 | C38: 3232555.6
A39: MOPSO | B39: 312586.3 | C39: 3085228.5
A40: RL | B40: 355443.2 | C40: 3256922
A43: All data for chart
A44: Algorithms | B44: 1 | C44: 1 | D44: 2 | E44: 2
A45: QUEST | B45: 233984.09 | C45: 224370.93 | D45: 2149040.5 | E45: 2320025.7
A46: QUEST_NDVFS | B46: 197740.17 | C46: 202857.89 | D46: 1644115.2 | E46: 1806992.4
A47: Fuzzy | B47: 401194.72 | C47: 401194.99 | D47: 3093857.1 | E47: 3093857.8
A48: NSGA3 | B48: 450386.77 | C48: 334760.59 | D48: 2871482.1 | E48: 2694586.8
A49: MQGA | B49: 403904.67 | C49: 445667.73 | D49: 2957652.4 | E49: 2497373.2
...

Sheet Energy
A1: Algorithm | B1: Load | C1: Average | D1: Min | E1: Max | F1: Std Dev
A2: QUEST | B2: 1 | C2: 4.6322753e+09 | D2: 4.498393e+09 | E2: 4.7661576e+09 | F2: 1.3388233e+08
A3: QUEST | B3: 2 | C3: 1.2127464e+10 | D3: 1.133352e+10 | E3: 1.2921409e+10 | F3: 7.9394449e+08
A4: QUEST_NDVFS | B4: 1 | C4: 4.5570047e+09 | D4: 4.4711088e+09 | E4: 4.6429007e+09 | F4: 85895947
A5: QUEST_NDVFS | B5: 2 | C5: 1.5469008e+10 | D5: 1.4820293e+10 | E5: 1.6117722e+10 | F5: 6.487146e+08
A6: Fuzzy | B6: 1 | C6: 4.5282367e+09 | D6: 4.528228e+09 | E6: 4.5282454e+09 | F6: 8692.5
A7: Fuzzy | B7: 2 | C7: 2.7445779e+10 | D7: 2.7445751e+10 | E7: 2.7445806e+10 | F7: 27450
A8: NSGA3 | B8: 1 | C8: 6.1423804e+09 | D8: 5.5092233e+09 | E8: 6.7755376e+09 | F8: 6.3315714e+08
A9: NSGA3 | B9: 2 | C9: 2.158467e+10 | D9: 19420187290 | E9: 2.3749152e+10 | F9: 2.1644823e+09
A10: MQGA | B10: 1 | C10: 4.8323431e+09 | D10: 4.8300944e+09 | E10: 4.8345918e+09 | F10: 2248726.2
A11: MQGA | B11: 2 | C11: 2.0734706e+10 | D11: 2.0334718e+10 | E11: 21134694330 | F11: 3.9998822e+08
A12: Greedy | B12: 1 | C12: 7137144755 | D12: 6232037780 | E12: 8042251730 | F12: 905106975
A13: Greedy | B13: 2 | C13: 23987023595 | D13: 2.3868195e+10 | E13: 2.4105852e+10 | F13: 1.1882834e+08
... A17: RL | B17: 2 | C17: 2.5011989e+10 | D17: 2.1004137e+10 | E17: 29019839760 | F17: 4.0078511e+09
A20: Summary by Algorithm
A21: QUEST | C21: 8.3798698e+09 | D21: 4.498393e+09 | E21: 1.2921409e+10 | F21: 3.7905937e+09
A22: QUEST_NDVFS | C22: 1.0013006e+10 | D22: 4.4711088e+09 | E22: 1.6117722e+10 | F22: 5.4755873e+09
A23: Fuzzy | C23: 15987007800 | D23: 4.528228e+09 | E23: 2.7445806e+10 | F23: 1.1458771e+10
A24: NSGA3 | C24: 1.3863525e+10 | D24: 5.5092233e+09 | E24: 2.3749152e+10 | F24: 7.8840985e+09
A25: MQGA | C25: 12783524605 | D25: 4.8300944e+09 | E25: 21134694330 | F25: 7.9562105e+09
A26: Greedy | C26: 15562084175 | D26: 6232037780 | E26: 2.4105852e+10 | F26: 8.4496316e+09
A27: MOPSO | C27: 1.4358937e+10 | D27: 5.1227474e+09 | E27: 2.3868765e+10 | F27: 9.081354e+09
A28: RL | C28: 1.5391139e+10 | D28: 4.6169425e+09 | E28: 29019839760 | F28: 1.0062668e+10
A31: Average data for chart
A32: Algorithms | B32: 1 | C32: 2
A33: QUEST | B33: 4.6322753e+09 | C33: 1.2127464e+10
A34: QUEST_NDVFS | B34: 4.5570047e+09 | C34: 1.5469008e+10
A35: Fuzzy | B35: 4.5282367e+09 | C35: 2.7445779e+10
A36: NSGA3 | B36: 6.1423804e+09 | C36: 2.158467e+10
A37: MQGA | B37: 4.8323431e+09 | C37: 2.0734706e+10
A38: Greedy | B38: 7137144755 | C38: 23987023595
A39: MOPSO | B39: 5.2834908e+09 | C39: 2.3434384e+10
A40: RL | B40: 5770288825 | C40: 2.5011989e+10
A43: All data for chart
A44: Algorithms | B44: 1 | C44: 1 | D44: 2 | E44: 2
A45: QUEST | B45: 4.7661576e+09 | C45: 4.498393e+09 | D45: 1.133352e+10 | E45: 1.2921409e+10
A46: QUEST_NDVFS | B46: 4.6429007e+09 | C46: 4.4711088e+09 | D46: 1.6117722e+10 | E46: 1.4820293e+10
A47: Fuzzy | B47: 4.528228e+09 | C47: 4.5282454e+09 | D47: 2.7445806e+10 | E47: 2.7445751e+10
A48: NSGA3 | B48: 6.7755376e+09 | C48: 5.5092233e+09 | D48: 2.3749152e+10 | E48: 19420187290
A49: MQGA | B49: 4.8300944e+09 | C49: 4.8345918e+09 | D49: 21134694330 | E49: 2.0334718e+10
...

Sheet Makespan
A1: Algorithm | B1: Load | C1: Average | D1: Min | E1: Max | F1: Std Dev
A2: QUEST | B2: 1 | C2: 4924963 | D2: 4743314 | E2: 5106612 | F2: 181649
A3: QUEST | B3: 2 | C3: 13682956 | D3: 12692841 | E3: 14673071 | F3: 990115
A4: QUEST_NDVFS | B4: 1 | C4: 4774479 | D4: 4739047 | E4: 4809911 | F4: 35432
A5: QUEST_NDVFS | B5: 2 | C5: 14641150 | D5: 13915913 | E5: 15366387 | F5: 725237
A6: Fuzzy | B6: 1 | C6: 4475444.5 | D6: 4475435 | E6: 4475454 | F6: 9.5
A7: Fuzzy | B7: 2 | C7: 27083949 | D7: 27083919 | E7: 27083979 | F7: 30
A8: NSGA3 | B8: 1 | C8: 6506424.5 | D8: 5777195 | E8: 7235654 | F8: 729229.5
A9: NSGA3 | B9: 2 | C9: 21278784 | D9: 18951480 | E9: 23606087 | F9: 2327303.5
A10: MQGA | B10: 1 | C10: 5035398.5 | D10: 5035374 | E10: 5035423 | F10: 24.5
A11: MQGA | B11: 2 | C11: 20188805 | D11: 19682698 | E11: 20694912 | F11: 506107
A12: Greedy | B12: 1 | C12: 7541498.5 | D12: 6544116 | E12: 8538881 | F12: 997382.5
A13: Greedy | B13: 2 | C13: 23674760 | D13: 23508123 | E13: 23841397 | F13: 166637
... A17: RL | B17: 2 | C17: 25079844 | D17: 20789860 | E17: 29369828 | F17: 4289984
A20: Summary by Algorithm
A21: QUEST | C21: 9303959.5 | D21: 4743314 | E21: 14673071 | F21: 4436470.7
A22: QUEST_NDVFS | C22: 9707814.5 | D22: 4739047 | E22: 15366387 | F22: 4959981
A23: Fuzzy | C23: 15779697 | D23: 4475435 | E23: 27083979 | F23: 11304252
A24: NSGA3 | C24: 13892604 | D24: 5777195 | E24: 23606087 | F24: 7584834
A25: MQGA | C25: 12612102 | D25: 5035374 | E25: 20694912 | F25: 7585150.2
A26: Greedy | C26: 15608129 | D26: 6544116 | E26: 23841397 | F26: 8098259.2
A27: MOPSO | C27: 14319208 | D27: 5369818 | E27: 23635945 | F27: 8805912.6
A28: RL | C28: 15566482 | D28: 4739682 | E28: 29369828 | F28: 10028390
A31: Average data for chart
A32: Algorithms | B32: 1 | C32: 2
A33: QUEST | B33: 4924963 | C33: 13682956
A34: QUEST_NDVFS | B34: 4774479 | C34: 14641150
A35: Fuzzy | B35: 4475444.5 | C35: 27083949
A36: NSGA3 | B36: 6506424.5 | C36: 21278784
A37: MQGA | B37: 5035398.5 | C37: 20188805
A38: Greedy | B38: 7541498.5 | C38: 23674760
A39: MOPSO | B39: 5521605 | C39: 23116812
A40: RL | B40: 6053119 | C40: 25079844
A43: All data for chart
A44: Algorithms | B44: 1 | C44: 1 | D44: 2 | E44: 2
A45: QUEST | B45: 5106612 | C45: 4743314 | D45: 12692841 | E45: 14673071
A46: QUEST_NDVFS | B46: 4809911 | C46: 4739047 | D46: 15366387 | E46: 13915913
A47: Fuzzy | B47: 4475435 | C47: 4475454 | D47: 27083979 | E47: 27083919
A48: NSGA3 | B48: 7235654 | C48: 5777195 | D48: 23606087 | E48: 18951480
A49: MQGA | B49: 5035374 | C49: 5035423 | D49: 20694912 | E49: 19682698
...

Sheet Success Rate
A1: Algorithm | B1: Load | C1: Average | D1: Min | E1: Max | F1: Std Dev
A2: QUEST | B2: 1 | C2: 1 | D2: TRUE | E2: TRUE | F2: 0
A3: QUEST | B3: 2 | C3: 1 | D3: TRUE | E3: TRUE | F3: 0
A4: QUEST_NDVFS | B4: 1 | C4: 1 | D4: TRUE | E4: TRUE | F4: 0
A5: QUEST_NDVFS | B5: 2 | C5: 1 | D5: TRUE | E5: TRUE | F5: 0
A6: Fuzzy | B6: 1 | C6: 1 | D6: TRUE | E6: TRUE | F6: 0
A7: Fuzzy | B7: 2 | C7: 1 | D7: TRUE | E7: TRUE | F7: 0
A8: NSGA3 | B8: 1 | C8: 1 | D8: TRUE | E8: TRUE | F8: 0
A9: NSGA3 | B9: 2 | C9: 1 | D9: TRUE | E9: TRUE | F9: 0
A10: MQGA | B10: 1 | C10: 1 | D10: TRUE | E10: TRUE | F10: 0
A11: MQGA | B11: 2 | C11: 1 | D11: TRUE | E11: TRUE | F11: 0
A12: Greedy | B12: 1 | C12: 0.5 | D12: FALSE | E12: TRUE | F12: 0.5
A13: Greedy | B13: 2 | C13: 1 | D13: TRUE | E13: TRUE | F13: 0
... A17: RL | B17: 2 | C17: 1 | D17: TRUE | E17: TRUE | F17: 0
A20: Summary by Algorithm
A21: QUEST | C21: 1 | D21: TRUE | E21: TRUE | F21: 0
A22: QUEST_NDVFS | C22: 1 | D22: TRUE | E22: TRUE | F22: 0
A23: Fuzzy | C23: 1 | D23: TRUE | E23: TRUE | F23: 0
A24: NSGA3 | C24: 1 | D24: TRUE | E24: TRUE | F24: 0
A25: MQGA | C25: 1 | D25: TRUE | E25: TRUE | F25: 0
A26: Greedy | C26: 0.75 | D26: FALSE | E26: TRUE | F26: 0.4330127
A27: MOPSO | C27: 1 | D27: TRUE | E27: TRUE | F27: 0
A28: RL | C28: 1 | D28: TRUE | E28: TRUE | F28: 0
A31: Average data for chart
A32: Algorithms | B32: 1 | C32: 2
A33: QUEST | B33: 1 | C33: 1
A34: QUEST_NDVFS | B34: 1 | C34: 1
A35: Fuzzy | B35: 1 | C35: 1
A36: NSGA3 | B36: 1 | C36: 1
A37: MQGA | B37: 1 | C37: 1
A38: Greedy | B38: 0.5 | C38: 1
A39: MOPSO | B39: 1 | C39: 1
A40: RL | B40: 1 | C40: 1
A43: All data for chart
A44: Algorithms | B44: 1 | C44: 1 | D44: 2 | E44: 2
A45: QUEST | B45: TRUE | C45: TRUE | D45: TRUE | E45: TRUE
A46: QUEST_NDVFS | B46: TRUE | C46: TRUE | D46: TRUE | E46: TRUE
A47: Fuzzy | B47: TRUE | C47: TRUE | D47: TRUE | E47: TRUE
A48: NSGA3 | B48: TRUE | C48: TRUE | D48: TRUE | E48: TRUE
A49: MQGA | B49: TRUE | C49: TRUE | D49: TRUE | E49: TRUE
...

Sheet Load Edge
A1: Algorithm | B1: Load | C1: Average | D1: Min | E1: Max | F1: Std Dev
A2: QUEST | B2: 1 | C2: 447163.85 | D2: 436388.14 | E2: 457939.56 | F2: 10775.71
A3: QUEST | B3: 2 | C3: 5173595.9 | D3: 5110287.4 | E3: 5236904.4 | F3: 63308.53
A4: QUEST_NDVFS | B4: 1 | C4: 360387.88 | D4: 336481.64 | E4: 384294.12 | F4: 23906.24
A5: QUEST_NDVFS | B5: 2 | C5: 3442414.9 | D5: 3389890.1 | E5: 3494939.6 | F5: 52524.73
A6: Fuzzy | B6: 1 | C6: 347808.16 | D6: 347808.16 | E6: 347808.16 | F6: 0
A7: Fuzzy | B7: 2 | C7: 3389692.6 | D7: 3389692.6 | E7: 3389692.6 | F7: 0
A8: NSGA3 | B8: 1 | C8: 387194.57 | D8: 386548.08 | E8: 387841.06 | F8: 646.49
A9: NSGA3 | B9: 2 | C9: 3422326.8 | D9: 3374825.1 | E9: 3469828.4 | F9: 47501.64
A10: MQGA | B10: 1 | C10: 371106.75 | D10: 355081.76 | E10: 387131.74 | F10: 16024.99
A11: MQGA | B11: 2 | C11: 3423867.3 | D11: 3405882.2 | E11: 3441852.4 | F11: 17985.12
A12: Greedy | B12: 1 | C12: 385276.67 | D12: 383848.44 | E12: 386704.9 | F12: 1428.23
A13: Greedy | B13: 2 | C13: 3445783.7 | D13: 3443775.9 | E13: 3447791.5 | F13: 2007.78
... A17: RL | B17: 2 | C17: 3546089 | D17: 3531019.5 | E17: 3561158.6 | F17: 15069.56
A20: Summary by Algorithm
A21: QUEST | C21: 2810379.9 | D21: 436388.14 | E21: 5236904.4 | F21: 2363652.3
A22: QUEST_NDVFS | C22: 1901401.4 | D22: 336481.64 | E22: 3494939.6 | F22: 1541553.7
A23: Fuzzy | C23: 1868750.4 | D23: 347808.16 | E23: 3389692.6 | F23: 1520942.2
A24: NSGA3 | C24: 1904760.7 | D24: 386548.08 | E24: 3469828.4 | F24: 1517937.8
A25: MQGA | C25: 1897487 | D25: 355081.76 | E25: 3441852.4 | F25: 1526475.3
A26: Greedy | C26: 1915530.2 | D26: 383848.44 | E26: 3447791.5 | F26: 1530254.5
A27: MOPSO | C27: 1890511.1 | D27: 369421.18 | E27: 3467655.9 | F27: 1511329.6
A28: RL | C28: 1962957.2 | D28: 364214.34 | E28: 3561158.6 | F28: 1583206.2
A31: Average data for chart
A32: Algorithms | B32: 1 | C32: 2
A33: QUEST | B33: 447163.85 | C33: 5173595.9
A34: QUEST_NDVFS | B34: 360387.88 | C34: 3442414.9
A35: Fuzzy | B35: 347808.16 | C35: 3389692.6
A36: NSGA3 | B36: 387194.57 | C36: 3422326.8
A37: MQGA | B37: 371106.75 | C37: 3423867.3
A38: Greedy | B38: 385276.67 | C38: 3445783.7
A39: MOPSO | B39: 379932.97 | C39: 3401089.3
A40: RL | B40: 379825.4 | C40: 3546089
A43: All data for chart
A44: Algorithms | B44: 1 | C44: 1 | D44: 2 | E44: 2
A45: QUEST | B45: 457939.56 | C45: 436388.14 | D45: 5236904.4 | E45: 5110287.4
A46: QUEST_NDVFS | B46: 384294.12 | C46: 336481.64 | D46: 3494939.6 | E46: 3389890.1
A47: Fuzzy | B47: 347808.16 | C47: 347808.16 | D47: 3389692.6 | E47: 3389692.6
A48: NSGA3 | B48: 386548.08 | C48: 387841.06 | D48: 3374825.1 | E48: 3469828.4
A49: MQGA | B49: 387131.74 | C49: 355081.76 | D49: 3441852.4 | E49: 3405882.2
...

Sheet Load Cloud
A1: Algorithm | B1: Load | C1: Average | D1: Min | E1: Max | F1: Std Dev
A2: QUEST | B2: 1 | C2: 43738 | D2: 3338 | E2: 84138 | F2: 40400
A3: QUEST | B3: 2 | C3: 4781876 | D3: 430189 | E3: 9133563 | F3: 4351687
A4: QUEST_NDVFS | B4: 1 | C4: 1403791.5 | D4: 0 | E4: 2807583 | F4: 1403791.5
A5: QUEST_NDVFS | B5: 2 | C5: 4327263.5 | D5: 2281165 | E5: 6373362 | F5: 2046098.5
A6: Fuzzy | B6: 1 | C6: 1399 | D6: 1399 | E6: 1399 | F6: 0
A7: Fuzzy | B7: 2 | C7: 1858116 | D7: 1858116 | E7: 1858116 | F7: 0
A8: NSGA3 | B8: 1 | C8: 294922 | D8: 945 | E8: 588899 | F8: 293977
A9: NSGA3 | B9: 2 | C9: 4823247 | D9: 3141798 | E9: 6504696 | F9: 1681449
A10: MQGA | B10: 1 | C10: 675389.5 | D10: 33000 | E10: 1317779 | F10: 642389.5
A11: MQGA | B11: 2 | C11: 3603981.5 | D11: 3358322 | E11: 3849641 | F11: 245659.5
A12: Greedy | B12: 1 | C12: 0 | D12: 0 | E12: 0 | F12: 0
A13: Greedy | B13: 2 | C13: 2210021 | D13: 2028817 | E13: 2391225 | F13: 181204
... A17: RL | B17: 2 | C17: 124416 | D17: 97742 | E17: 151090 | F17: 26674
A20: Summary by Algorithm
A21: QUEST | C21: 2412807 | D21: 3338 | E21: 9133563 | F21: 3883541.4
A22: QUEST_NDVFS | C22: 2865527.5 | D22: 0 | E22: 6373362 | F22: 2283691.5
A23: Fuzzy | C23: 929757.5 | D23: 1399 | E23: 1858116 | F23: 928358.5
A24: NSGA3 | C24: 2559084.5 | D24: 945 | E24: 6504696 | F24: 2565790
A25: MQGA | C25: 2139685.5 | D25: 33000 | E25: 3849641 | F25: 1542941.7
A26: Greedy | C26: 1105010.5 | D26: 0 | E26: 2391225 | F26: 1112414.3
A27: MOPSO | C27: 2321756.2 | D27: 1391 | E27: 7440332 | F27: 2992342
A28: RL | C28: 194003 | D28: 770 | E28: 526410 | F28: 199337.1
A31: Average data for chart
A32: Algorithms | B32: 1 | C32: 2
A33: QUEST | B33: 43738 | C33: 4781876
A34: QUEST_NDVFS | B34: 1403791.5 | C34: 4327263.5
A35: Fuzzy | B35: 1399 | C35: 1858116
A36: NSGA3 | B36: 294922 | C36: 4823247
A37: MQGA | B37: 675389.5 | C37: 3603981.5
A38: Greedy | B38: 0 | C38: 2210021
A39: MOPSO | B39: 262791.5 | C39: 4380721
A40: RL | B40: 263590 | C40: 124416
A43: All data for chart
A44: Algorithms | B44: 1 | C44: 1 | D44: 2 | E44: 2
A45: QUEST | B45: 3338 | C45: 84138 | D45: 430189 | E45: 9133563
A46: QUEST_NDVFS | B46: 0 | C46: 2807583 | D46: 2281165 | E46: 6373362
A47: Fuzzy | B47: 1399 | C47: 1399 | D47: 1858116 | E47: 1858116
A48: NSGA3 | B48: 588899 | C48: 945 | D48: 6504696 | E48: 3141798
A49: MQGA | B49: 33000 | C49: 1317779 | D49: 3358322 | E49: 3849641
...

Sheet Loads
A1: Average data for chart
B2: Edge | C2: Edge | D2: Edge | E2: Edge | F2: Edge | G2: Edge | H2: Edge | I2: Edge | J2: Edge | K2: Edge | L2: Edge | M2: Edge | N2: Edge | O2: Edge | P2: Edge | Q2: Edge | R2: Edge | S2: Edge | T2: Edge | U2: Edge | V2: Edge | W2: Edge | X2: Edge | Y2: Edge | Z2: Edge | AA2: Edge | AB2: Edge | AC2: Edge | AD2: Edge | AE2: Edge | AF2: Edge | AG2: Edge | AH2: Edge | AI2: Edge | AJ2: Edge | AK2: Edge | AL2: Edge | AM2: Edge | AN2: Edge | AO2: Edge | AP2: Edge | AQ2: Edge | AR2: Edge | AS2: Edge | AT2: Edge | AU2: Edge | AV2: Edge | AW2: Edge | AX2: Edge | AY2: Edge | AZ2: Cloud | BA2: Edge | BB2: Edge | BC2: Edge | BD2: Edge | BE2: Edge | BF2: Edge | BG2: Edge | BH2: Edge | BI2: Edge | BJ2: Edge | BK2: Edge | BL2: Edge | BM2: Edge | BN2: Edge | BO2: Edge | BP2: Edge | BQ2: Edge | BR2: Edge | BS2: Edge | BT2: Edge | BU2: Edge | BV2: Edge | BW2: Edge | BX2: Edge | BY2: Edge | BZ2: Edge | CA2: Edge | CB2: Edge | CC2: Edge | CD2: Edge | CE2: Edge | CF2: Edge | CG2: Edge | CH2: Edge | CI2: Edge | CJ2: Edge | CK2: Edge | CL2: Edge | CM2: Edge | CN2: Edge | CO2: Edge | CP2: Edge | CQ2: Edge | CR2: Edge | CS2: Edge | CT2: Edge | CU2: Edge | CV2: Edge | CW2: Edge | CX2: Edge | CY2: Cloud
B3: 1 | C3: 1 | D3: 1 | E3: 1 | F3: 1 | G3: 1 | H3: 1 | I3: 1 | J3: 1 | K3: 1 | L3: 1 | M3: 1 | N3: 1 | O3: 1 | P3: 1 | Q3: 1 | R3: 1 | S3: 1 | T3: 1 | U3: 1 | V3: 1 | W3: 1 | X3: 1 | Y3: 1 | Z3: 1 | AA3: 1 | AB3: 1 | AC3: 1 | AD3: 1 | AE3: 1 | AF3: 1 | AG3: 1 | AH3: 1 | AI3: 1 | AJ3: 1 | AK3: 1 | AL3: 1 | AM3: 1 | AN3: 1 | AO3: 1 | AP3: 1 | AQ3: 1 | AR3: 1 | AS3: 1 | AT3: 1 | AU3: 1 | AV3: 1 | AW3: 1 | AX3: 1 | AY3: 1 | AZ3: 1 | BA3: 2 | BB3: 2 | BC3: 2 | BD3: 2 | BE3: 2 | BF3: 2 | BG3: 2 | BH3: 2 | BI3: 2 | BJ3: 2 | BK3: 2 | BL3: 2 | BM3: 2 | BN3: 2 | BO3: 2 | BP3: 2 | BQ3: 2 | BR3: 2 | BS3: 2 | BT3: 2 | BU3: 2 | BV3: 2 | BW3: 2 | BX3: 2 | BY3: 2 | BZ3: 2 | CA3: 2 | CB3: 2 | CC3: 2 | CD3: 2 | CE3: 2 | CF3: 2 | CG3: 2 | CH3: 2 | CI3: 2 | CJ3: 2 | CK3: 2 | CL3: 2 | CM3: 2 | CN3: 2 | CO3: 2 | CP3: 2 | CQ3: 2 | CR3: 2 | CS3: 2 | CT3: 2 | CU3: 2 | CV3: 2 | CW3: 2 | CX3: 2 | CY3: 2
A4: Algorithms | B4: 1 | C4: 2 | D4: 3 | E4: 4 | F4: 5 | G4: 6 | H4: 7 | I4: 8 | J4: 9 | K4: 10 | L4: 11 | M4: 12 | N4: 13 | O4: 14 | P4: 15 | Q4: 16 | R4: 17 | S4: 18 | T4: 19 | U4: 20 | V4: 21 | W4: 22 | X4: 23 | Y4: 24 | Z4: 25 | AA4: 26 | AB4: 27 | AC4: 28 | AD4: 29 | AE4: 30 | AF4: 31 | AG4: 32 | AH4: 33 | AI4: 34 | AJ4: 35 | AK4: 36 | AL4: 37 | AM4: 38 | AN4: 39 | AO4: 40 | AP4: 41 | AQ4: 42 | AR4: 43 | AS4: 44 | AT4: 45 | AU4: 46 | AV4: 47 | AW4: 48 | AX4: 49 | AY4: 50 | AZ4: 51 | BA4: 1 | BB4: 2 | BC4: 3 | BD4: 4 | BE4: 5 | BF4: 6 | BG4: 7 | BH4: 8 | BI4: 9 | BJ4: 10 | BK4: 11 | BL4: 12 | BM4: 13 | BN4: 14 | BO4: 15 | BP4: 16 | BQ4: 17 | BR4: 18 | BS4: 19 | BT4: 20 | BU4: 21 | BV4: 22 | BW4: 23 | BX4: 24 | BY4: 25 | BZ4: 26 | CA4: 27 | CB4: 28 | CC4: 29 | CD4: 30 | CE4: 31 | CF4: 32 | CG4: 33 | CH4: 34 | CI4: 35 | CJ4: 36 | CK4: 37 | CL4: 38 | CM4: 39 | CN4: 40 | CO4: 41 | CP4: 42 | CQ4: 43 | CR4: 44 | CS4: 45 | CT4: 46 | CU4: 47 | CV4: 48 | CW4: 49 | CX4: 50 | CY4: 51
A5: QUEST | B5: 41809.196 | C5: 41778.353 | D5: 229.35294 | E5: 28664.98 | F5: 159.07843 | G5: 90.058824 | H5: 46112.137 | I5: 10329.98 | J5: 48.411765 | K5: 161.66667 | L5: 39.215686 | M5: 161.07843 | N5: 185.80392 | O5: 393.98039 | P5: 29571.647 | Q5: 3026.6667 | R5: 144.33333 | S5: 28222.98 | T5: 48670.431 | U5: 26704.941 | V5: 67.568627 | W5: 148.39216 | X5: 87.607843 | Y5: 30.039216 | Z5: 98700.961 | AA5: 1498.1569 | AB5: 1073.7647 | AC5: 47.019608 | AD5: 112.29412 | AE5: 144.37255 | AF5: 1449.4314 | AG5: 31480.275 | AH5: 51497.49 | AI5: 1768.2549 | AJ5: 57325.863 | AK5: 50365.765 | AL5: 15360.588 | AM5: 42527.549 | AN5: 72.921569 | AO5: 1397.9216 | AP5: 15571.784 | AQ5: 5710.7255 | AR5: 13869.588 | AS5: 9616.4118 | AT5: 51320.98 | AU5: 3799.7647 | AV5: 48540.373 | AW5: 66429.373 | AX5: 100.13725 | AY5: 172.19608 | AZ5: 1715.2157 | BA5: 109348.16 | BB5: 90508.314 | BC5: 95434.529 | BD5: 222549.22 | BE5: 107745.35 | BF5: 138201.76 | BG5: 156974.14 | BH5: 139804.96 | BI5: 89681.961 | BJ5: 99557.706 | BK5: 231322 | BL5: 143759.35 | BM5: 132902.2 | BN5: 61849.961 | BO5: 136935.53 | BP5: 372490.73 | BQ5: 85993.843 | BR5: 256641.92 | BS5: 117492.24 | BT5: 164957.94 | BU5: 163638.43 | BV5: 80967.471 | BW5: 222916.22 | BX5: 180653.69 | BY5: 92545.059 | BZ5: 201323.45 | CA5: 305735.41 | CB5: 72416.804 | CC5: 388199.27 | CD5: 360331.31 | CE5: 179038.55 | CF5: 179597.04 | CG5: 105485.78 | CH5: 345916.8 | CI5: 246064.78 | CJ5: 300920.71 | CK5: 324637.51 | CL5: 542401.69 | CM5: 295032.16 | CN5: 370617.22 | CO5: 152320.96 | CP5: 321280.73 | CQ5: 345021.22 | CR5: 143331.65 | CS5: 248947 | CT5: 112704.18 | CU5: 191944.71 | CV5: 348565.45 | CW5: 168674.57 | CX5: 198924.06 | CY5: 187524.55
A6: QUEST_NDVFS | B6: 8930.7647 | C6: 6970.8039 | D6: 832.41176 | E6: 498.19608 | F6: 1129.1765 | G6: 23.098039 | H6: 42851.02 | I6: 1084.9804 | J6: 10999.647 | K6: 96.921569 | L6: 125.68627 | M6: 48.960784 | N6: 80.705882 | O6: 86.647059 | P6: 720 | Q6: 81107.333 | R6: 27958.373 | S6: 773.94118 | T6: 12565.314 | U6: 109.76471 | V6: 35.529412 | W6: 91.294118 | X6: 28614.216 | Y6: 87.960784 | Z6: 27.588235 | AA6: 375.70588 | AB6: 34219.451 | AC6: 32490.216 | AD6: 198.4902 | AE6: 43706.549 | AF6: 51321.373 | AG6: 86.666667 | AH6: 10845.765 | AI6: 77476.588 | AJ6: 560.94118 | AK6: 186.37255 | AL6: 74922.02 | AM6: 105.01961 | AN6: 1459.0784 | AO6: 30.215686 | AP6: 69.862745 | AQ6: 139.98039 | AR6: 994.62745 | AS6: 154.17647 | AT6: 105080.14 | AU6: 848.64706 | AV6: 69.647059 | AW6: 63.745098 | AX6: 44486.255 | AY6: 901.03922 | AZ6: 55050.647 | BA6: 74742.059 | BB6: 147562.27 | BC6: 41141.039 | BD6: 70597.863 | BE6: 67556.725 | BF6: 85793.157 | BG6: 175765.78 | BH6: 97997.137 | BI6: 120582.51 | BJ6: 102996.02 | BK6: 96657.431 | BL6: 101414.45 | BM6: 127343.82 | BN6: 169629.24 | BO6: 143846.47 | BP6: 185562.25 | BQ6: 151524.31 | BR6: 1492.3725 | BS6: 151640.73 | BT6: 141770.35 | BU6: 99471.706 | BV6: 77247.627 | BW6: 84734.471 | BX6: 101743.53 | BY6: 74039.98 | BZ6: 93635.02 | CA6: 242008.65 | CB6: 257309.76 | CC6: 189808.88 | CD6: 249012.1 | CE6: 230299.33 | CF6: 213347.61 | CG6: 185158.35 | CH6: 215029.51 | CI6: 241592.31 | CJ6: 57047.02 | CK6: 202661.22 | CL6: 60386.706 | CM6: 77357.255 | CN6: 171564.98 | CO6: 34076.569 | CP6: 133088.59 | CQ6: 235033.45 | CR6: 224015.02 | CS6: 183794.88 | CT6: 25989.824 | CU6: 180848 | CV6: 140083.22 | CW6: 96132.412 | CX6: 117699.1 | CY6: 169696.61
A7: Fuzzy | B7: 109904.39 | C7: 85555.725 | D7: 76762.902 | E7: 72789.922 | F7: 57095.647 | G7: 55733.451 | H7: 52355.49 | I7: 51728.784 | J7: 49161.882 | K7: 20565.608 | L7: 17872.275 | M7: 13954.941 | N7: 2482.0392 | O7: 2199.5294 | P7: 2010.3529 | Q7: 1571.6471 | R7: 1379.6078 | S7: 1343.2549 | T7: 1343.1373 | U7: 1342.9804 | V7: 983.33333 | W7: 281.84314 | X7: 271.29412 | Y7: 254.43137 | Z7: 211.05882 | AA7: 238.82353 | AB7: 182.94118 | AC7: 138.98039 | AD7: 135.52941 | AE7: 129.84314 | AF7: 124.35294 | AG7: 121.68627 | AH7: 120.82353 | AI7: 119.45098 | AJ7: 118.62745 | AK7: 117.33333 | AL7: 116.19608 | AM7: 115.13725 | AN7: 113.72549 | AO7: 112.78431 | AP7: 111.92157 | AQ7: 106.54902 | AR7: 105.21569 | AS7: 74.862745 | AT7: 74.470588 | AU7: 73.411765 | AV7: 67.843137 | AW7: 67.294118 | AX7: 67.254902 | AY7: 66.196078 | AZ7: 54.862745 | BA7: 198036.2 | BB7: 189559.92 | BC7: 183681.57 | BD7: 182256.63 | BE7: 179342.51 | BF7: 174720.08 | BG7: 169856.94 | BH7: 167792.98 | BI7: 158959.69 | BJ7: 152213.57 | BK7: 151734.63 | BL7: 149381.96 | BM7: 148351.22 | BN7: 144306.75 | BO7: 140147.1 | BP7: 138326.75 | BQ7: 136093.49 | BR7: 135534.27 | BS7: 132546.16 | BT7: 129811.37 | BU7: 128204.35 | BV7: 127397.92 | BW7: 126290.12 | BX7: 123942.35 | BY7: 122229.22 | BZ7: 146187.45 | CA7: 139728.43 | CB7: 138694 | CC7: 136098.55 | CD7: 135111.61 | CE7: 134493.14 | CF7: 129765.84 | CG7: 126465.8 | CH7: 121906.51 | CI7: 119898.71 | CJ7: 114711.1 | CK7: 113641.37 | CL7: 112277.33 | CM7: 110991.84 | CN7: 107448.08 | CO7: 105692.16 | CP7: 105229.96 | CQ7: 103836.24 | CR7: 102340.43 | CS7: 100214.86 | CT7: 92357.02 | CU7: 91231.686 | CV7: 90381.333 | CW7: 89341.255 | CX7: 87693.569 | CY7: 72867.294
A8: NSGA3 | B8: 102.29412 | C8: 104.5098 | D8: 995.23529 | E8: 1515.7059 | F8: 100.82353 | G8: 43498.235 | H8: 18 | I8: 542.03922 | J8: 128 | K8: 27951.314 | L8: 116.92157 | M8: 26181.412 | N8: 71.058824 | O8: 0 | P8: 37760.216 | Q8: 1745.7255 | R8: 134.62745 | S8: 1655.8235 | T8: 72.745098 | U8: 32236.725 | V8: 53.764706 | W8: 1263.0392 | X8: 190.05882 | Y8: 38439.843 | Z8: 9071.6863 | AA8: 66005.059 | AB8: 233.29412 | AC8: 60947.725 | AD8: 12330.373 | AE8: 134654.18 | AF8: 47.490196 | AG8: 241.7451 | AH8: 868.94118 | AI8: 65.117647 | AJ8: 33550.824 | AK8: 1008.451 | AL8: 23.058824 | AM8: 70.627451 | AN8: 141062.71 | AO8: 156.80392 | AP8: 32369.176 | AQ8: 31228.235 | AR8: 9178.3137 | AS8: 50.745098 | AT8: 29.392157 | AU8: 10764.941 | AV8: 63.72549 | AW8: 40.431373 | AX8: 159.39216 | AY8: 104.4902 | AZ8: 11565.569 | BA8: 77234.882 | BB8: 81600.373 | BC8: 75732.49 | BD8: 134481.33 | BE8: 102155.78 | BF8: 77756.588 | BG8: 5113.8039 | BH8: 193743.55 | BI8: 115299.65 | BJ8: 76966.843 | BK8: 155598.06 | BL8: 109798.24 | BM8: 158218.73 | BN8: 82553.902 | BO8: 98360.667 | BP8: 49421.784 | BQ8: 126384.31 | BR8: 149509.75 | BS8: 133540.37 | BT8: 175213.27 | BU8: 44645.647 | BV8: 45341.686 | BW8: 125302.14 | BX8: 136129.22 | BY8: 242995.12 | BZ8: 224915.37 | CA8: 100879.94 | CB8: 161507.82 | CC8: 235051.24 | CD8: 232656.37 | CE8: 187290.27 | CF8: 183093.53 | CG8: 205205.47 | CH8: 148210.73 | CI8: 165381.29 | CJ8: 132548.22 | CK8: 117405.43 | CL8: 178412.35 | CM8: 123274.02 | CN8: 202178.88 | CO8: 117498.37 | CP8: 259552.82 | CQ8: 325879.39 | CR8: 170715.98 | CS8: 84028.196 | CT8: 87900.804 | CU8: 68476.804 | CV8: 105318.63 | CW8: 89898.255 | CX8: 30066.294 | CY8: 189146.94
A9: MQGA | B9: 28571.706 | C9: 1249.5882 | D9: 25922.373 | E9: 24652.392 | F9: 1820.6863 | G9: 56.509804 | H9: 45375.039 | I9: 7023.902 | J9: 42869.412 | K9: 165.66667 | L9: 7756.1373 | M9: 26268.824 | N9: 694.03922 | O9: 78.784314 | P9: 39321.157 | Q9: 1026.6667 | R9: 802.82353 | S9: 44.901961 | T9: 42.686275 | U9: 698.90196 | V9: 43.333333 | W9: 36486.451 | X9: 82.196078 | Y9: 1097.6275 | Z9: 0 | AA9: 112.15686 | AB9: 104.68627 | AC9: 62.862745 | AD9: 80.784314 | AE9: 51510.333 | AF9: 47143.412 | AG9: 23.019608 | AH9: 1236.7059 | AI9: 156.4902 | AJ9: 104.92157 | AK9: 63.27451 | AL9: 1036.0392 | AM9: 34482.843 | AN9: 155629.69 | AO9: 29.941176 | AP9: 267.64706 | AQ9: 83.254902 | AR9: 0 | AS9: 173.64706 | AT9: 40251.02 | AU9: 69.235294 | AV9: 100287.86 | AW9: 129.54902 | AX9: 162.82353 | AY9: 2306.2941 | AZ9: 26485.863 | BA9: 20068.137 | BB9: 180663.08 | BC9: 27241.529 | BD9: 145748.88 | BE9: 82628.275 | BF9: 106265.22 | BG9: 105068.98 | BH9: 74019.196 | BI9: 168821.65 | BJ9: 87340.98 | BK9: 137317.43 | BL9: 154096.59 | BM9: 148756.88 | BN9: 141622.35 | BO9: 254064.14 | BP9: 145818.24 | BQ9: 108930.84 | BR9: 74891.725 | BS9: 77720.51 | BT9: 231923.33 | BU9: 85320.549 | BV9: 58537.02 | BW9: 43915.431 | BX9: 107502.98 | BY9: 276593.94 | BZ9: 185784.08 | CA9: 225571.92 | CB9: 134341.82 | CC9: 167500.04 | CD9: 173251.98 | CE9: 186462.25 | CF9: 111546.18 | CG9: 115157.16 | CH9: 78002.549 | CI9: 132927.41 | CJ9: 174187.71 | CK9: 51871.078 | CL9: 239097.94 | CM9: 199034.65 | CN9: 259390.63 | CO9: 207347.84 | CP9: 102389.76 | CQ9: 163478.53 | CR9: 109843.47 | CS9: 137511.51 | CT9: 93349.765 | CU9: 55576.961 | CV9: 147134.06 | CW9: 102305.1 | CX9: 115523.06 | CY9: 141332.61
A10: Greedy | B10: 731.33333 | C10: 135.60784 | D10: 125.92157 | E10: 548.17647 | F10: 26241.922 | G10: 110.92157 | H10: 74788.275 | I10: 67.960784 | J10: 42934.176 | K10: 63.176471 | L10: 51 | M10: 1124.0784 | N10: 27024.647 | O10: 76.392157 | P10: 131.56863 | Q10: 73.54902 | R10: 44187.824 | S10: 1766.1569 | T10: 24.960784 | U10: 675.09804 | V10: 54924.784 | W10: 158.7451 | X10: 55.235294 | Y10: 27973.039 | Z10: 8151.7843 | AA10: 65981.098 | AB10: 46408.294 | AC10: 12555.235 | AD10: 114.66667 | AE10: 31124.569 | AF10: 35803.843 | AG10: 82.803922 | AH10: 107489.1 | AI10: 34.196078 | AJ10: 111.84314 | AK10: 47523.471 | AL10: 283.15686 | AM10: 72.078431 | AN10: 188.05882 | AO10: 48.313725 | AP10: 133.7451 | AQ10: 0 | AR10: 2268.451 | AS10: 42450.275 | AT10: 29.392157 | AU10: 60.705882 | AV10: 31193.059 | AW10: 124.29412 | AX10: 8465.2941 | AY10: 10752.176 | AZ10: 0 | BA10: 69970.608 | BB10: 44118.608 | BC10: 127024.51 | BD10: 157200.94 | BE10: 101368.98 | BF10: 90398.059 | BG10: 91470.745 | BH10: 145130.78 | BI10: 212350.2 | BJ10: 102284.53 | BK10: 249036.02 | BL10: 172508.51 | BM10: 61522.216 | BN10: 117202.31 | BO10: 121315.29 | BP10: 156805.06 | BQ10: 126245.75 | BR10: 84853.647 | BS10: 125239.84 | BT10: 119695.29 | BU10: 197872.12 | BV10: 156741.78 | BW10: 148629.73 | BX10: 61657.294 | BY10: 117358.73 | BZ10: 177988.27 | CA10: 176696.86 | CB10: 195131.02 | CC10: 163189.51 | CD10: 131006.53 | CE10: 250583.14 | CF10: 138749.78 | CG10: 9329.549 | CH10: 74697.706 | CI10: 83986.137 | CJ10: 144889.02 | CK10: 132562.22 | CL10: 3265.3137 | CM10: 176850.2 | CN10: 4020.6667 | CO10: 92604.353 | CP10: 211883.02 | CQ10: 178520.29 | CR10: 123259.2 | CS10: 288364.65 | CT10: 174401.49 | CU10: 134015.47 | CV10: 325652.39 | CW10: 161205.92 | CX10: 45584.412 | CY10: 86667.49
A11: MOPSO | B11: 136.01961 | C11: 24639.176 | D11: 8957.902 | E11: 45.333333 | F11: 749.45098 | G11: 25258.353 | H11: 38443.098 | I11: 54.843137 | J11: 765.23529 | K11: 1992.1373 | L11: 1032.4118 | M11: 744.62745 | N11: 684.56863 | O11: 64214.059 | P11: 1102.098 | Q11: 147.72549 | R11: 34.313725 | S11: 26230.157 | T11: 51.54902 | U11: 50.215686 | V11: 26237.529 | W11: 1039.902 | X11: 79148.196 | Y11: 885.66667 | Z11: 57.901961 | AA11: 114.17647 | AB11: 65.411765 | AC11: 35.039216 | AD11: 130.21569 | AE11: 34334.804 | AF11: 120.60784 | AG11: 28.72549 | AH11: 155.58824 | AI11: 74863.608 | AJ11: 34441.314 | AK11: 142.76471 | AL11: 1325.5686 | AM11: 949.09804 | AN11: 33494.059 | AO11: 1519.902 | AP11: 2378.3529 | AQ11: 59666.196 | AR11: 10730.588 | AS11: 32.588235 | AT11: 9154.4902 | AU11: 351.03922 | AV11: 78422 | AW11: 0 | AX11: 66028.059 | AY11: 33779.941 | AZ11: 10305.549 | BA11: 87564.471 | BB11: 89196.196 | BC11: 116526.47 | BD11: 124900.08 | BE11: 238506.22 | BF11: 124749.55 | BG11: 95150.843 | BH11: 109780.12 | BI11: 100582.14 | BJ11: 17887.059 | BK11: 173865.31 | BL11: 315186.18 | BM11: 203639.84 | BN11: 63333.078 | BO11: 171247.84 | BP11: 71118.706 | BQ11: 46598.765 | BR11: 120665.41 | BS11: 118618.47 | BT11: 92316.314 | BU11: 109330.49 | BV11: 134283.71 | BW11: 107031.39 | BX11: 161554.39 | BY11: 91798.059 | BZ11: 106942.25 | CA11: 141877.51 | CB11: 185340.12 | CC11: 162968.14 | CD11: 181873.06 | CE11: 119583.9 | CF11: 238093.51 | CG11: 68638.902 | CH11: 91631.373 | CI11: 207151.45 | CJ11: 225033.04 | CK11: 149596.71 | CL11: 207453.63 | CM11: 129031.92 | CN11: 46524.373 | CO11: 243833.53 | CP11: 170818.61 | CQ11: 88829.078 | CR11: 114609.47 | CS11: 72820.02 | CT11: 102150 | CU11: 150461.84 | CV11: 181048.71 | CW11: 131503.35 | CX11: 65556.922 | CY11: 171792.98
A12: RL | B12: 36489.627 | C12: 24555.431 | D12: 467.45098 | E12: 41.490196 | F12: 986.90196 | G12: 29195.216 | H12: 8016.0588 | I12: 28.039216 | J12: 10365.275 | K12: 42777.176 | L12: 54995.176 | M12: 184.54902 | N12: 97 | O12: 83.54902 | P12: 151.37255 | Q12: 36413.078 | R12: 1097.6275 | S12: 0 | T12: 59.215686 | U12: 100.86275 | V12: 28550.51 | W12: 116.01961 | X12: 28662.176 | Y12: 77.490196 | Z12: 57.45098 | AA12: 1479.8235 | AB12: 3201.6078 | AC12: 46888.745 | AD12: 8363.3922 | AE12: 1560.9216 | AF12: 55.019608 | AG12: 42203.902 | AH12: 62898.725 | AI12: 31176.353 | AJ12: 31569.549 | AK12: 1513.8039 | AL12: 46092.078 | AM12: 72.705882 | AN12: 272.11765 | AO12: 1467.7451 | AP12: 33628.431 | AQ12: 31110.098 | AR12: 163.07843 | AS12: 65982.824 | AT12: 35.294118 | AU12: 873.45098 | AV12: 57.411765 | AW12: 0 | AX12: 30320 | AY12: 199.86275 | AZ12: 10336.863 | BA12: 221765.24 | BB12: 69986.922 | BC12: 137634.71 | BD12: 63691.294 | BE12: 75649.686 | BF12: 136540.96 | BG12: 87591.137 | BH12: 181809.96 | BI12: 120009.29 | BJ12: 123382.88 | BK12: 104989.2 | BL12: 192999 | BM12: 72782.922 | BN12: 135190.86 | BO12: 139425.37 | BP12: 75688.02 | BQ12: 2927.9804 | BR12: 82274.922 | BS12: 110666.31 | BT12: 89419.549 | BU12: 93693.804 | BV12: 48615.471 | BW12: 173271.55 | BX12: 31214.569 | BY12: 94127.686 | BZ12: 155443.61 | CA12: 180044.67 | CB12: 93188.824 | CC12: 406689.57 | CD12: 91515.765 | CE12: 147986 | CF12: 195546.69 | CG12: 145992.24 | CH12: 101080.55 | CI12: 55072.451 | CJ12: 96207.039 | CK12: 121377.73 | CL12: 47759.608 | CM12: 268373.2 | CN12: 200839.92 | CO12: 232700.47 | CP12: 221038.43 | CQ12: 144555.02 | CR12: 90143.078 | CS12: 175233.84 | CT12: 137083.43 | CU12: 306601.25 | CV12: 287979.55 | CW12: 126407.98 | CX12: 258905.53 | CY12: 4879.0588

Sheet ANOVA - AoI
A1: Anova: Two-Factor With Replication
A3: SUMMARY | B3: Load 1 | C3: Load 2 | D3: Total
A4: QUEST
A5: Count | B5: 2 | C5: 2 | D5: 4
A6: Sum | B6: 458355.02 | C6: 4469066.2 | D6: 4927421.3
A7: Average | B7: 229177.51 | C7: 2234533.1 | D7: 1231855.3
A8: Variance | B8: 46206454 | C8: 1.4617969e+10 | D8: 1.3453718e+12
A10: QUEST_NDVFS
A11: Count | B11: 2 | C11: 2 | D11: 4
A12: Sum | B12: 400598.06 | C12: 3451107.5 | D12: 3851705.6
A13: Average | B13: 200299.03 | C13: 1725553.8 | D13: 962926.4
A14: Variance | B14: 13095500 | C14: 1.3264486e+10 | D14: 7.7989321e+11
A16: Fuzzy
A17: Count | B17: 2 | C17: 2 | D17: 4
A18: Sum | B18: 802389.71 | C18: 6187715 | D18: 6990104.7
A19: Average | B19: 401194.86 | C19: 3093857.5 | D19: 1747526.2
A20: Variance | B20: 0.035193669 | C20: 0.26241984 | D20: 2.4168107e+12
A22: NSGA3
A23: Count | B23: 2 | C23: 2 | D23: 4
A24: Sum | B24: 785147.36 | C24: 5566068.9 | D24: 6351216.2
A25: Average | B25: 392573.68 | C25: 2783034.4 | D25: 1587804.1
A26: Variance | B26: 6.684706e+09 | C26: 1.5645965e+10 | D26: 1.9122111e+12
A28: MQGA
A29: Count | B29: 2 | C29: 2 | D29: 4
A30: Sum | B30: 849572.41 | C30: 5455025.6 | D30: 6304598
A31: Average | B31: 424786.2 | C31: 2727512.8 | D31: 1576149.5
A32: Variance | B32: 8.7207664e+08 | C32: 1.0592851e+11 | D32: 1.8031168e+12
A34: Greedy
A35: Count | B35: 2 | C35: 2 | D35: 4
A36: Sum | B36: 739506.68 | C36: 6465111.2 | D36: 7204617.9
A37: Average | B37: 369753.34 | C37: 3232555.6 | D37: 1801154.5
A38: Variance | B38: 3.9536585e+10 | C38: 1.3667909e+11 | D38: 2.7906175e+12
A40: MOPSO
A41: Count | B41: 2 | C41: 2 | D41: 4
A42: Sum | B42: 625172.59 | C42: 6170456.9 | D42: 6795629.5
A43: Average | B43: 312586.3 | C43: 3085228.5 | D43: 1698907.4
A44: Variance | B44: 4.490955e+09 | C44: 2.7632429e+11 | D44: 2.6561199e+12
A46: RL
A47: Count | B47: 2 | C47: 2 | D47: 4
A48: Sum | B48: 710886.41 | C48: 6513844.1 | D48: 7224730.5
...

Sheet ANOVA - Energy
A1: Anova: Two-Factor With Replication
A3: SUMMARY | B3: Load 1 | C3: Load 2 | D3: Total
A4: QUEST
A5: Count | B5: 2 | C5: 2 | D5: 4
A6: Sum | B6: 9.2645506e+09 | C6: 2.4254928e+10 | D6: 3.3519479e+10
A7: Average | B7: 4.6322753e+09 | C7: 1.2127464e+10 | D7: 8.3798698e+09
A8: Variance | B8: 3.5848956e+16 | C8: 1.2606957e+18 | D8: 1.9158134e+19
A10: QUEST_NDVFS
A11: Count | B11: 2 | C11: 2 | D11: 4
A12: Sum | B12: 9.1140094e+09 | C12: 3.0938015e+10 | D12: 4.0052025e+10
A13: Average | B13: 4.5570047e+09 | C13: 1.5469008e+10 | D13: 1.0013006e+10
A14: Variance | B14: 1.4756227e+16 | C14: 8.4166127e+17 | D14: 3.9976075e+19
A16: Fuzzy
A17: Count | B17: 2 | C17: 2 | D17: 4
A18: Sum | B18: 9.0564733e+09 | C18: 5.4891558e+10 | D18: 6.3948031e+10
A19: Average | B19: 4.5282367e+09 | C19: 2.7445779e+10 | D19: 15987007800
A20: Variance | B20: 1.5111911e+08 | C20: 1507005000 | D20: 1.7507125e+20
A22: NSGA3
A23: Count | B23: 2 | C23: 2 | D23: 4
A24: Sum | B24: 12284760835 | C24: 4.3169339e+10 | D24: 5.54541e+10
A25: Average | B25: 6.1423804e+09 | C25: 2.158467e+10 | D25: 1.3863525e+10
A26: Variance | B26: 8.0177592e+17 | C26: 9.369967e+18 | D26: 8.2878679e+19
A28: MQGA
A29: Count | B29: 2 | C29: 2 | D29: 4
A30: Sum | B30: 9.6646862e+09 | C30: 4.1469412e+10 | D30: 51134098420
A31: Average | B31: 4.8323431e+09 | C31: 2.0734706e+10 | D31: 12783524605
A32: Variance | B32: 1.0113539e+13 | C32: 3.1998115e+17 | D32: 8.4401714e+19
A34: Greedy
A35: Count | B35: 2 | C35: 2 | D35: 4
A36: Sum | B36: 14274289510 | C36: 47974047190 | D36: 62248336700
A37: Average | B37: 7137144755 | C37: 23987023595 | D37: 15562084175
A38: Variance | B38: 1.6384373e+18 | C38: 2.8240348e+16 | D38: 9.5195032e+19
A40: MOPSO
A41: Count | B41: 2 | C41: 2 | D41: 4
A42: Sum | B42: 1.0566982e+10 | C42: 4.6868767e+10 | D42: 5.7435749e+10
A43: Average | B43: 5.2834908e+09 | C43: 2.3434384e+10 | D43: 1.4358937e+10
A44: Variance | B44: 5.1676899e+16 | C44: 3.7737349e+17 | D44: 1.0996132e+20
A46: RL
A47: Count | B47: 2 | C47: 2 | D47: 4
A48: Sum | B48: 11540577650 | C48: 5.0023977e+10 | D48: 6.1564555e+10
...

Sheet ANOVA - Makespan
A1: Anova: Two-Factor With Replication
A3: SUMMARY | B3: Load 1 | C3: Load 2 | D3: Total
A4: QUEST
A5: Count | B5: 2 | C5: 2 | D5: 4
A6: Sum | B6: 9849926 | C6: 27365912 | D6: 37215838
A7: Average | B7: 4924963 | C7: 13682956 | D7: 9303959.5
A8: Variance | B8: 65992718402 | C8: 1960655426450 | D8: 2.624303e+13
A10: QUEST_NDVFS
A11: Count | B11: 2 | C11: 2 | D11: 4
A12: Sum | B12: 9548958 | C12: 29282300 | D12: 38831258
A13: Average | B13: 4774479 | C13: 14641150 | D13: 9707814.5
A14: Variance | B14: 2510853248 | C14: 1051937412338 | D14: 3.2801882e+13
A16: Fuzzy
A17: Count | B17: 2 | C17: 2 | D17: 4
A18: Sum | B18: 8950889 | C18: 54167898 | D18: 63118787
A19: Average | B19: 4475444.5 | C19: 27083949 | D19: 15779697
A20: Variance | B20: 180.5 | C20: 1800 | D20: 1.7038149e+14
A22: NSGA3
A23: Count | B23: 2 | C23: 2 | D23: 4
A24: Sum | B24: 13012849 | C24: 42557567 | D24: 55570416
A25: Average | B25: 6506424.5 | C25: 21278784 | D25: 13892604
A26: Variance | B26: 1.0635513e+12 | C26: 1.0832683e+13 | D26: 76706274971482
A28: MQGA
A29: Count | B29: 2 | C29: 2 | D29: 4
A30: Sum | B30: 10070797 | C30: 40377610 | D30: 50448407
A31: Average | B31: 5035398.5 | C31: 20188805 | D31: 12612102
A32: Variance | B32: 1200.5 | C32: 512288590898 | D32: 7.6712672e+13
A34: Greedy
A35: Count | B35: 2 | C35: 2 | D35: 4
A36: Sum | B36: 15082997 | C36: 47349520 | D36: 62432517
A37: Average | B37: 7541498.5 | C37: 23674760 | D37: 15608129
A38: Variance | B38: 1.9895437e+12 | C38: 55535779538 | D38: 8.7442402e+13
A40: MOPSO
A41: Count | B41: 2 | C41: 2 | D41: 4
A42: Sum | B42: 11043210 | C42: 46233624 | D42: 57276834
A43: Average | B43: 5521605 | C43: 23116812 | D43: 14319208
A44: Variance | B44: 46078586738 | C44: 538998143378 | D44: 1.0339213e+14
A46: RL
A47: Count | B47: 2 | C47: 2 | D47: 4
A48: Sum | B48: 12106238 | C48: 50159688 | D48: 62265926
...
