Workbook

Sheet Data Age
A1: Algorithm | B1: Load | C1: Average | D1: Min | E1: Max | F1: Std Dev
A2: QUEST | B2: 20 | C2: 2308.6 | D2: 1603.2857 | E2: 2821.1905 | F2: 258.20339
A3: QUEST | B3: 30 | C3: 2502.8003 | D3: 1935.4 | E3: 3176.1667 | F3: 238.51413
A4: QUEST | B4: 50 | C4: 2964.7332 | D4: 2309.22 | E4: 3817.62 | F4: 297.85892
A5: Fuzzy | B5: 20 | C5: 4098.9976 | D5: 1867.381 | E5: 8500.0952 | F5: 1363.3948
A6: Fuzzy | B6: 30 | C6: 5070.4663 | D6: 2542.7667 | E6: 8603.9333 | F6: 1262.2034
A7: Fuzzy | B7: 50 | C7: 7274.4954 | D7: 4104.2 | E7: 10158.88 | F7: 1429.7532
A8: NSGA3 | B8: 20 | C8: 4123.5895 | D8: 1844.4286 | E8: 8999.8095 | F8: 1468.3337
A9: NSGA3 | B9: 30 | C9: 5251.9203 | D9: 2476.8333 | E9: 9416 | F9: 1535.1581
A10: NSGA3 | B10: 50 | C10: 6919.3606 | D10: 3529.42 | E10: 10697.08 | F10: 1507.0852
A11: MQGA | B11: 20 | C11: 3375.1852 | D11: 2072.9048 | E11: 6166.1429 | F11: 914.63714
A12: MQGA | B12: 30 | C12: 3945.0767 | D12: 2547.8333 | E12: 5464.3 | F12: 653.00284
A13: MQGA | B13: 50 | C13: 5853.9684 | D13: 3988.3 | E13: 7653.42 | F13: 851.54666
... A19: MOPSO | B19: 50 | C19: 6889.6418 | D19: 4899.86 | E19: 9264.38 | F19: 938.65634
A22: Summary by Algorithm
A23: QUEST | C23: 2592.0445 | D23: 1603.2857 | E23: 3817.62 | F23: 382.74451
A24: Fuzzy | C24: 5481.3198 | D24: 1867.381 | E24: 10158.88 | F24: 1896.6014
A25: NSGA3 | C25: 5431.6235 | D25: 1844.4286 | E25: 10697.08 | F25: 1892.1441
A26: MQGA | C26: 4391.4101 | D26: 2072.9048 | E26: 7653.42 | F26: 1336.5514
A27: Greedy | C27: 5401.3508 | D27: 2105.7143 | E27: 12065.16 | F27: 2082.8375
A28: MOPSO | C28: 5205.3794 | D28: 2011.2857 | E28: 9264.38 | F28: 1681.292
A31: Average data for chart
A32: Algorithms | B32: 20 | C32: 30 | D32: 50
A33: QUEST | B33: 2308.6 | C33: 2502.8003 | D33: 2964.7332
A34: Fuzzy | B34: 4098.9976 | C34: 5070.4663 | D34: 7274.4954
A35: NSGA3 | B35: 4123.5895 | C35: 5251.9203 | D35: 6919.3606
A36: MQGA | B36: 3375.1852 | C36: 3945.0767 | D36: 5853.9684
A37: Greedy | B37: 3977.5643 | C37: 5048.0703 | D37: 7178.4178
A38: MOPSO | B38: 3769.5629 | C38: 4956.9337 | D38: 6889.6418
A41: All data for chart
A42: Algorithms | B42: 20 | C42: 20 | D42: 20 | E42: 20 | F42: 20 | G42: 20 | H42: 20 | I42: 20 | J42: 20 | K42: 20 | L42: 20 | M42: 20 | N42: 20 | O42: 20 | P42: 20 | Q42: 20 | R42: 20 | S42: 20 | T42: 20 | U42: 20 | V42: 20 | W42: 20 | X42: 20 | Y42: 20 | Z42: 20 | AA42: 20 | AB42: 20 | AC42: 20 | AD42: 20 | AE42: 20 | AF42: 20 | AG42: 20 | AH42: 20 | AI42: 20 | AJ42: 20 | AK42: 20 | AL42: 20 | AM42: 20 | AN42: 20 | AO42: 20 | AP42: 20 | AQ42: 20 | AR42: 20 | AS42: 20 | AT42: 20 | AU42: 20 | AV42: 20 | AW42: 20 | AX42: 20 | AY42: 20 | AZ42: 20 | BA42: 20 | BB42: 20 | BC42: 20 | BD42: 20 | BE42: 20 | BF42: 20 | BG42: 20 | BH42: 20 | BI42: 20 | BJ42: 20 | BK42: 20 | BL42: 20 | BM42: 20 | BN42: 20 | BO42: 20 | BP42: 20 | BQ42: 20 | BR42: 20 | BS42: 20 | BT42: 20 | BU42: 20 | BV42: 20 | BW42: 20 | BX42: 20 | BY42: 20 | BZ42: 20 | CA42: 20 | CB42: 20 | CC42: 20 | CD42: 20 | CE42: 20 | CF42: 20 | CG42: 20 | CH42: 20 | CI42: 20 | CJ42: 20 | CK42: 20 | CL42: 20 | CM42: 20 | CN42: 20 | CO42: 20 | CP42: 20 | CQ42: 20 | CR42: 20 | CS42: 20 | CT42: 20 | CU42: 20 | CV42: 20 | CW42: 20 | CX42: 30 | CY42: 30 | CZ42: 30 | DA42: 30 | DB42: 30 | DC42: 30 | DD42: 30 | DE42: 30 | DF42: 30 | DG42: 30 | DH42: 30 | DI42: 30 | DJ42: 30 | DK42: 30 | DL42: 30 | DM42: 30 | DN42: 30 | DO42: 30 | DP42: 30 | DQ42: 30 | DR42: 30 | DS42: 30 | DT42: 30 | DU42: 30 | DV42: 30 | DW42: 30 | DX42: 30 | DY42: 30 | DZ42: 30 | EA42: 30 | EB42: 30 | EC42: 30 | ED42: 30 | EE42: 30 | EF42: 30 | EG42: 30 | EH42: 30 | EI42: 30 | EJ42: 30 | EK42: 30 | EL42: 30 | EM42: 30 | EN42: 30 | EO42: 30 | EP42: 30 | EQ42: 30 | ER42: 30 | ES42: 30 | ET42: 30 | EU42: 30 | EV42: 30 | EW42: 30 | EX42: 30 | EY42: 30 | EZ42: 30 | FA42: 30 | FB42: 30 | FC42: 30 | FD42: 30 | FE42: 30 | FF42: 30 | FG42: 30 | FH42: 30 | FI42: 30 | FJ42: 30 | FK42: 30 | FL42: 30 | FM42: 30 | FN42: 30 | FO42: 30 | FP42: 30 | FQ42: 30 | FR42: 30 | FS42: 30 | FT42: 30 | FU42: 30 | FV42: 30 | FW42: 30 | FX42: 30 | FY42: 30 | FZ42: 30 | GA42: 30 | GB42: 30 | GC42: 30 | GD42: 30 | GE42: 30 | GF42: 30 | GG42: 30 | GH42: 30 | GI42: 30 | GJ42: 30 | GK42: 30 | GL42: 30 | GM42: 30 | GN42: 30 | GO42: 30 | GP42: 30 | GQ42: 30 | GR42: 30 | GS42: 30 | GT42: 50 | GU42: 50 | GV42: 50 | GW42: 50 | GX42: 50 | GY42: 50 | GZ42: 50 | HA42: 50 | HB42: 50 | HC42: 50 | HD42: 50 | HE42: 50 | HF42: 50 | HG42: 50 | HH42: 50 | HI42: 50 | HJ42: 50 | HK42: 50 | HL42: 50 | HM42: 50 | HN42: 50 | HO42: 50 | HP42: 50 | HQ42: 50 | HR42: 50 | HS42: 50 | HT42: 50 | HU42: 50 | HV42: 50 | HW42: 50 | HX42: 50 | HY42: 50 | HZ42: 50 | IA42: 50 | IB42: 50 | IC42: 50 | ID42: 50 | IE42: 50 | IF42: 50 | IG42: 50 | IH42: 50 | II42: 50 | IJ42: 50 | IK42: 50 | IL42: 50 | IM42: 50 | IN42: 50 | IO42: 50 | IP42: 50 | IQ42: 50 | IR42: 50 | IS42: 50 | IT42: 50 | IU42: 50 | IV42: 50 | IW42: 50 | IX42: 50 | IY42: 50 | IZ42: 50 | JA42: 50 | JB42: 50 | JC42: 50 | JD42: 50 | JE42: 50 | JF42: 50 | JG42: 50 | JH42: 50 | JI42: 50 | JJ42: 50 | JK42: 50 | JL42: 50 | JM42: 50 | JN42: 50 | JO42: 50 | JP42: 50 | JQ42: 50 | JR42: 50 | JS42: 50 | JT42: 50 | JU42: 50 | JV42: 50 | JW42: 50 | JX42: 50 | JY42: 50 | JZ42: 50 | KA42: 50 | KB42: 50 | KC42: 50 | KD42: 50 | KE42: 50 | KF42: 50 | KG42: 50 | KH42: 50 | KI42: 50 | KJ42: 50 | KK42: 50 | KL42: 50 | KM42: 50 | KN42: 50 | KO42: 50
A43: QUEST | B43: 2186.9048 | C43: 2615.8571 | D43: 2429.1905 | E43: 2439.0476 | F43: 2598.5238 | G43: 2243.7143 | H43: 2140.7619 | I43: 1860.7143 | J43: 2278.9524 | K43: 2231.0952 | L43: 2003.3333 | M43: 2178.5714 | N43: 2562.6667 | O43: 2330.7143 | P43: 2314.0476 | Q43: 2088.4286 | R43: 2397.5238 | S43: 2036.6667 | T43: 2011.7619 | U43: 2291.2381 | V43: 2033.2381 | W43: 1936.3333 | X43: 2737.619 | Y43: 2104.8095 | Z43: 2072.2381 | AA43: 2241.2857 | AB43: 2641.619 | AC43: 2543.6667 | AD43: 2425.8095 | AE43: 1603.2857 | AF43: 2609.7619 | AG43: 2260.5714 | AH43: 2669.2857 | AI43: 2608.1905 | AJ43: 2323.9524 | AK43: 2400.8571 | AL43: 2329 | AM43: 2510.0476 | AN43: 2182.9524 | AO43: 2794.7619 | AP43: 2674.1429 | AQ43: 2303.6667 | AR43: 1981.5238 | AS43: 1964.4286 | AT43: 2347.8095 | AU43: 2069.619 | AV43: 2048.3333 | AW43: 2208.6667 | AX43: 2329.2857 | AY43: 2798.9524 | AZ43: 2056.3333 | BA43: 2417.6667 | BB43: 2439.3333 | BC43: 2478.2381 | BD43: 2663.6667 | BE43: 1951.8571 | BF43: 2238.7143 | BG43: 2390.5238 | BH43: 2164.6667 | BI43: 2116 | BJ43: 2292.619 | BK43: 2337.7143 | BL43: 2189.2857 | BM43: 1696.7619 | BN43: 2544.381 | BO43: 2821.1905 | BP43: 1895 | BQ43: 2514.1905 | BR43: 1751.0952 | BS43: 2378.8095 | BT43: 2732.2857 | BU43: 1836.4286 | BV43: 2203.9524 | BW43: 2318 | BX43: 2669.3333 | BY43: 2433.9524 | BZ43: 2120 | CA43: 2653.4286 | CB43: 2186.7619 | CC43: 2196.8571 | CD43: 2219.3333 | CE43: 1899.1429 | CF43: 2469 | CG43: 2153.8571 | CH43: 2496.1905 | CI43: 2419.6667 | CJ43: 2457.2381 | CK43: 2080.8095 | CL43: 2552.4286 | CM43: 2507.4762 | CN43: 2434.9524 | CO43: 2478.0476 | CP43: 2606.7143 | CQ43: 2534.2381 | CR43: 2357.8571 | CS43: 2631.9048 | CT43: 1965.381 | CU43: 2320.4286 | CV43: 2267.4286 | CW43: 2323.4286 | CX43: 2593.6 | CY43: 2340.8 | CZ43: 2239.6333 | DA43: 2519.8 | DB43: 2404.1667 | DC43: 2055.7333 | DD43: 2438.2333 | DE43: 2635.6667 | DF43: 2656.5 | DG43: 2321.9333 | DH43: 2542.3667 | DI43: 2509 | DJ43: 2484.1667 | DK43: 2790.3667 | DL43: 2509.3 | DM43: 2392.6667 | DN43: 3118.8667 | DO43: 2761.8 | DP43: 1935.4 | DQ43: 2761.9333 | DR43: 2358.9333 | DS43: 2563.7 | DT43: 2565.7667 | DU43: 2746.0333 | DV43: 2712.8 | DW43: 2483.0667 | DX43: 3152.9 | DY43: 2891.4333 | DZ43: 3176.1667 | EA43: 2742.1 | EB43: 2232.7333 | EC43: 2304.4333 | ED43: 2702.9333 | EE43: 2526.9 | EF43: 2602.2 | EG43: 2862.1667 | EH43: 2294.2 | EI43: 2432.9333 | EJ43: 2178.2333 | EK43: 2713.3333 | EL43: 2763.5667 | EM43: 2164.1 | EN43: 2521.2333 | EO43: 2677.7667 | EP43: 2633.0667 | EQ43: 2034.6667 | ER43: 2322.3333 | ES43: 2624.1667 | ET43: 2781.9667 | EU43: 2353.7667 | EV43: 2284.5 | EW43: 2632.5667 | EX43: 2434.4 | EY43: 2724.0333 | EZ43: 2698.2333 | FA43: 2432.7 | FB43: 2662.9 | FC43: 2739.8 | FD43: 2204.3333 | FE43: 2333.0667 | FF43: 2686.0667 | FG43: 2586 | FH43: 2513.1667 | FI43: 2685.8 | FJ43: 2514.4333 | FK43: 2694.8333 | FL43: 2275.5 | FM43: 2607.9667 | FN43: 2766.9333 | FO43: 2426.4667 | FP43: 2340.8333 | FQ43: 2457.4667 | FR43: 2362.6 | FS43: 2165.1333 | FT43: 2649.2333 | FU43: 2689.4 | FV43: 2096.0333 | FW43: 2738.6667 | FX43: 2522.9667 | FY43: 2618.3 | FZ43: 2113 | GA43: 2369.1667 | GB43: 2726.4 | GC43: 2462.3 | GD43: 2390.4667 | GE43: 2355.9 | GF43: 2099.3667 | GG43: 2348.0333 | GH43: 2209.2333 | GI43: 2069.7 | GJ43: 2598.3333 | GK43: 2233.2333 | GL43: 2530.6 | GM43: 2745.6 | GN43: 2456.8 | GO43: 2211.9 | GP43: 2398.3 | GQ43: 2437.1 | GR43: 2537.6 | GS43: 2311.1333 | GT43: 3222.58 | GU43: 3223.32 | GV43: 2984.3 | GW43: 2844.64 | GX43: 3109.38 | GY43: 2931.58 | GZ43: 2700.34 | HA43: 3817.62 | HB43: 2568.98 | HC43: 3567.34 | HD43: 2511.52 | HE43: 3403.34 | HF43: 2549.08 | HG43: 2642.36 | HH43: 2770.02 | HI43: 2890.32 | HJ43: 2818.28 | HK43: 2846.8 | HL43: 2929.22 | HM43: 2825.24 | HN43: 2927.96 | HO43: 3319.96 | HP43: 3599.98 | HQ43: 2924.12 | HR43: 3382.84 | HS43: 3077.8 | HT43: 2955.18 | HU43: 2801.32 | HV43: 3209.92 | HW43: 2974.88 | HX43: 3254.9 | HY43: 2792.72 | HZ43: 3070.8 | IA43: 3113.86 | IB43: 3245.68 | IC43: 2413.2 | ID43: 2787.46 | IE43: 3244.92 | IF43: 2902.18 | IG43: 2474.92 | IH43: 2852.52 | II43: 3364.22 | IJ43: 3264.84 | IK43: 3023.62 | IL43: 2828.66 | IM43: 3161.52 | IN43: 2672.92 | IO43: 3332.08 | IP43: 3096.3 | IQ43: 3169.26 | IR43: 3217.22 | IS43: 2839.62 | IT43: 2928.08 | IU43: 2798.54 | IV43: 2944.02 | IW43: 3374.8 | IX43: 2817.18 | IY43: 2978.14 | IZ43: 3230.8 | JA43: 2999.4 | JB43: 2926.08 | JC43: 2309.22 | JD43: 3017.86 | JE43: 3102.14 | JF43: 3131.98 | JG43: 2558.42 | JH43: 2867.7 | JI43: 2484.2 | JJ43: 3309.36 | JK43: 2755.28 | JL43: 3149.9 | JM43: 2715.1 | JN43: 3069.88 | JO43: 2635.84 | JP43: 3313.68 | JQ43: 3030.54 | JR43: 2548.9 | JS43: 2716.32 | JT43: 2876.2 | JU43: 2614.24 | JV43: 2614.02 | JW43: 3273.52 | JX43: 2663.58 | JY43: 3646.42 | JZ43: 3619.94 | KA43: 2861.96 | KB43: 3130.84 | KC43: 2782.64 | KD43: 2816.92 | KE43: 2943.06 | KF43: 2542.6 | KG43: 2786.62 | KH43: 2465.7 | KI43: 3419.3 | KJ43: 3082.54 | KK43: 3056.56 | KL43: 2617.78 | KM43: 2863.3 | KN43: 2692.82 | KO43: 2935.76
A44: Fuzzy | B44: 4055.381 | C44: 3608.1905 | D44: 3623.7619 | E44: 3387.3333 | F44: 3444.5714 | G44: 5811.9524 | H44: 3500.0476 | I44: 2125.9048 | J44: 6402.9048 | K44: 3219.9048 | L44: 2907.2381 | M44: 3168.3333 | N44: 4433.6667 | O44: 3677.3333 | P44: 2746.2381 | Q44: 3888.381 | R44: 2458.9524 | S44: 4015.8095 | T44: 4565.381 | U44: 3115.0476 | V44: 4229.9048 | W44: 2806.7619 | X44: 5500.0952 | Y44: 3967.1905 | Z44: 2987.3333 | AA44: 4665.7619 | AB44: 5258.8571 | AC44: 3609.8095 | AD44: 3232.0952 | AE44: 1867.381 | AF44: 4802.7619 | AG44: 2308.381 | AH44: 7990.2857 | AI44: 4440.3333 | AJ44: 3067.5714 | AK44: 6230.6667 | AL44: 4748.0476 | AM44: 2934.1429 | AN44: 5990.0476 | AO44: 5270.381 | AP44: 4272.4762 | AQ44: 4416.2381 | AR44: 4578 | AS44: 2308.381 | AT44: 3935.5238 | AU44: 3759.2857 | AV44: 2090.6667 | AW44: 3931.5238 | AX44: 2931.9048 | AY44: 4347.381 | AZ44: 3611 | BA44: 3563.3333 | BB44: 4139.6667 | BC44: 6514.0476 | BD44: 3886.9524 | BE44: 2886.1429 | BF44: 6480.619 | BG44: 7485.5714 | BH44: 2447.0476 | BI44: 6091.1905 | BJ44: 5537.1429 | BK44: 4304.5714 | BL44: 3371.7619 | BM44: 3445.4286 | BN44: 3348.0476 | BO44: 4616.7619 | BP44: 4776.0476 | BQ44: 4490.6667 | BR44: 3563 | BS44: 3129.8095 | BT44: 3009.619 | BU44: 2523.619 | BV44: 3770.9524 | BW44: 2625.8095 | BX44: 5560.7143 | BY44: 5670.7143 | BZ44: 2515.0476 | CA44: 3000.0476 | CB44: 2412.8095 | CC44: 2525.5238 | CD44: 2764.1905 | CE44: 4532.9048 | CF44: 3609.2857 | CG44: 3975.1429 | CH44: 7057.7143 | CI44: 4283.7619 | CJ44: 5000.5714 | CK44: 4027.7143 | CL44: 6525.8095 | CM44: 4305.6667 | CN44: 2749.0476 | CO44: 8500.0952 | CP44: 3406.5238 | CQ44: 6085.7143 | CR44: 6733.3333 | CS44: 4277 | CT44: 3454.619 | CU44: 3200.0476 | CV44: 4432.8095 | CW44: 3038.619 | CX44: 3542 | CY44: 5027.6 | CZ44: 3703.7667 | DA44: 6905.4 | DB44: 4967.9 | DC44: 6256.5 | DD44: 5740.3 | DE44: 5913.4667 | DF44: 4216.3 | DG44: 6111.7 | DH44: 3849.6667 | DI44: 3927.2667 | DJ44: 6067.5333 | DK44: 6563.4 | DL44: 4349.6 | DM44: 3527.1667 | DN44: 4487.5667 | DO44: 5147.2667 | DP44: 4710.0667 | DQ44: 5308.9667 | DR44: 5784.6667 | DS44: 6858.2667 | DT44: 5541.6333 | DU44: 4778.8667 | DV44: 3690.6333 | DW44: 6101.8333 | DX44: 6301.0333 | DY44: 8582.2333 | DZ44: 5703.9 | EA44: 4027.4 | EB44: 3331.6667 | EC44: 4893.4333 | ED44: 5895.1667 | EE44: 5617.5667 | EF44: 4562.1 | EG44: 6868.8333 | EH44: 6043.7 | EI44: 4745.2667 | EJ44: 5157.3 | EK44: 5106.6333 | EL44: 5782.9 | EM44: 4864.2333 | EN44: 6109.8667 | EO44: 6470.8 | EP44: 6382.4 | EQ44: 3027.6333 | ER44: 3599.3667 | ES44: 5647.2333 | ET44: 4988.6333 | EU44: 4024.4667 | EV44: 3809.5333 | EW44: 4702.5667 | EX44: 3493.1333 | EY44: 6122.3 | EZ44: 5914.9333 | FA44: 4912.6333 | FB44: 4836.3333 | FC44: 5134.4 | FD44: 3529.7 | FE44: 5154.1 | FF44: 3215.2667 | FG44: 5110.5 | FH44: 5353.6 | FI44: 3988.9333 | FJ44: 4765.5333 | FK44: 6257.8667 | FL44: 6593.2333 | FM44: 6286.9 | FN44: 5955.5 | FO44: 4412.5667 | FP44: 3587.6333 | FQ44: 5773.3 | FR44: 4177.3667 | FS44: 4312.5333 | FT44: 7520.8667 | FU44: 4190.3333 | FV44: 4799.4 | FW44: 5534.5333 | FX44: 5381.7 | FY44: 4611.6 | FZ44: 5571.0667 | GA44: 4255.8 | GB44: 4215.5667 | GC44: 3368.4333 | GD44: 3954.8 | GE44: 3564.3667 | GF44: 3184.6 | GG44: 2962.5333 | GH44: 3927 | GI44: 5055.5333 | GJ44: 5622.4333 | GK44: 2542.7667 | GL44: 3910.3 | GM44: 4965.6333 | GN44: 3159.3667 | GO44: 4878 | GP44: 7058.5 | GQ44: 7784.2333 | GR44: 8209.8667 | GS44: 8603.9333 | GT44: 6784.56 | GU44: 6158.96 | GV44: 5698.06 | GW44: 9609.28 | GX44: 5462.82 | GY44: 9873.9 | GZ44: 5633.54 | HA44: 8629.84 | HB44: 4646.24 | HC44: 9534.7 | HD44: 6583.08 | HE44: 7569.46 | HF44: 5948.3 | HG44: 7952.14 | HH44: 7902.62 | HI44: 5711.46 | HJ44: 8840.58 | HK44: 5616.22 | HL44: 6763.44 | HM44: 7599.64 | HN44: 8279.58 | HO44: 6186.2 | HP44: 10158.88 | HQ44: 6623.42 | HR44: 9185.48 | HS44: 6674.76 | HT44: 5273 | HU44: 6988.08 | HV44: 9531.66 | HW44: 9304.54 | HX44: 9532.88 | HY44: 7905.82 | HZ44: 9062.62 | IA44: 6041.1 | IB44: 5786.92 | IC44: 4104.2 | ID44: 7938.1 | IE44: 9612.7 | IF44: 5010.84 | IG44: 6771.52 | IH44: 6544.12 | II44: 6480.44 | IJ44: 7485.38 | IK44: 7926.18 | IL44: 8339.38 | IM44: 8226.22 | IN44: 7803.64 | IO44: 7368.18 | IP44: 5140.02 | IQ44: 6994.68 | IR44: 9317.12 | IS44: 7494.02 | IT44: 8592.26 | IU44: 7731.32 | IV44: 6125.36 | IW44: 7962.58 | IX44: 5072.34 | IY44: 6223.62 | IZ44: 8795.24 | JA44: 7298.68 | JB44: 8594.6 | JC44: 5145.68 | JD44: 9473.24 | JE44: 7593.06 | JF44: 7764.86 | JG44: 5304.42 | JH44: 5072.36 | JI44: 5198.1 | JJ44: 8805.36 | JK44: 9237.32 | JL44: 6982.22 | JM44: 7536.06 | JN44: 7962.94 | JO44: 8224.78 | JP44: 8922.14 | JQ44: 8591.82 | JR44: 5824.96 | JS44: 6165.96 | JT44: 8520.14 | JU44: 6004.2 | JV44: 7613.88 | JW44: 6370.2 | JX44: 6966.08 | JY44: 8364.14 | JZ44: 5831.3 | KA44: 5561.64 | KB44: 9047.7 | KC44: 7614.26 | KD44: 7897.54 | KE44: 7761.92 | KF44: 6967.98 | KG44: 8599.68 | KH44: 6706.12 | KI44: 7808.48 | KJ44: 4323.62 | KK44: 7189.22 | KL44: 5575.98 | KM44: 7741.38 | KN44: 5924.84 | KO44: 7247.44
A45: NSGA3 | B45: 2614.3333 | C45: 5223.9524 | D45: 8937.381 | E45: 3335.8095 | F45: 2952.5714 | G45: 5112.9048 | H45: 2290.4762 | I45: 4778.5238 | J45: 5260.381 | K45: 3865.381 | L45: 3780.1905 | M45: 3652.381 | N45: 4661.8571 | O45: 3822.1429 | P45: 2880.9524 | Q45: 6502.2381 | R45: 2549 | S45: 3026.5238 | T45: 6096.9524 | U45: 3958.9048 | V45: 2717.2857 | W45: 2834.4762 | X45: 3753.7143 | Y45: 3624 | Z45: 3790.5238 | AA45: 4695.9524 | AB45: 3466.8571 | AC45: 4562.9048 | AD45: 3119.619 | AE45: 4833.4286 | AF45: 4370.619 | AG45: 2421.5238 | AH45: 3736.9524 | AI45: 4307.619 | AJ45: 3175.1429 | AK45: 5383.9048 | AL45: 3725.7143 | AM45: 5712.619 | AN45: 2244 | AO45: 3347.619 | AP45: 5466.4762 | AQ45: 2535.4762 | AR45: 6180.619 | AS45: 2316.2381 | AT45: 4361.1905 | AU45: 4366.9524 | AV45: 2211.4762 | AW45: 2807.9524 | AX45: 6783.6667 | AY45: 3986.8095 | AZ45: 3677.7619 | BA45: 4736.8095 | BB45: 5738.5714 | BC45: 4950.4762 | BD45: 6459 | BE45: 2751.8095 | BF45: 4386.1905 | BG45: 7178.2857 | BH45: 4075.3333 | BI45: 2331.4762 | BJ45: 3620.0952 | BK45: 4280.9524 | BL45: 2797.9048 | BM45: 1844.4286 | BN45: 3567.2381 | BO45: 3791.8571 | BP45: 2568.9524 | BQ45: 3690.8571 | BR45: 4006.5714 | BS45: 7695.8571 | BT45: 4366.5238 | BU45: 3396.4286 | BV45: 2714.2857 | BW45: 5736.619 | BX45: 5486.1429 | BY45: 3746.381 | BZ45: 5092.7143 | CA45: 2774.2857 | CB45: 6128.1429 | CC45: 4161 | CD45: 2387.8095 | CE45: 3599.9048 | CF45: 3299.9048 | CG45: 4812.0952 | CH45: 8999.8095 | CI45: 8006.619 | CJ45: 3963.9524 | CK45: 3708.2381 | CL45: 5276.5714 | CM45: 5274.1429 | CN45: 3334 | CO45: 2584.3333 | CP45: 2818.1429 | CQ45: 2635.381 | CR45: 2432.1905 | CS45: 4221.2857 | CT45: 3851.7619 | CU45: 5417 | CV45: 3393.2381 | CW45: 2445.4286 | CX45: 3836.2333 | CY45: 5718.1 | CZ45: 4916.3667 | DA45: 4114.0667 | DB45: 3876.5 | DC45: 4740.3 | DD45: 3206.6667 | DE45: 7676.9667 | DF45: 5160.3333 | DG45: 4754.5333 | DH45: 3897.6 | DI45: 5881.1667 | DJ45: 5202 | DK45: 5783.6667 | DL45: 4664.1667 | DM45: 2476.8333 | DN45: 7172.5 | DO45: 6330.7333 | DP45: 2688.2667 | DQ45: 7296.1 | DR45: 3921.9333 | DS45: 6938.9333 | DT45: 7410.9 | DU45: 4291.8333 | DV45: 5141.9 | DW45: 6854.3 | DX45: 4034.9 | DY45: 5095.6667 | DZ45: 5859.3333 | EA45: 5267.8333 | EB45: 3827.8667 | EC45: 4471.7 | ED45: 4203.9 | EE45: 7258.3 | EF45: 8437.4667 | EG45: 7345.9333 | EH45: 6691.5 | EI45: 4329.9667 | EJ45: 2916.1667 | EK45: 4422.6667 | EL45: 5669.8333 | EM45: 3357.3333 | EN45: 7289.2 | EO45: 4378.1333 | EP45: 5884.1667 | EQ45: 4164.3 | ER45: 4475.6 | ES45: 7111.3333 | ET45: 4634.6333 | EU45: 5936.9 | EV45: 3843 | EW45: 5417.2667 | EX45: 6675.4667 | EY45: 4054.8 | EZ45: 7069.9333 | FA45: 3531.9 | FB45: 5476.1333 | FC45: 4201.0667 | FD45: 3569.1667 | FE45: 8718.5333 | FF45: 6896.5333 | FG45: 4305.2333 | FH45: 3432.8 | FI45: 6350.0333 | FJ45: 9416 | FK45: 5025.0667 | FL45: 4054.7333 | FM45: 3573.8 | FN45: 7941.2667 | FO45: 4423.6333 | FP45: 3937.3667 | FQ45: 5894.8 | FR45: 6030.6667 | FS45: 6336.5 | FT45: 4499.8333 | FU45: 6269.4667 | FV45: 2518 | FW45: 6123.3 | FX45: 4036.2 | FY45: 7932.6333 | FZ45: 3280.4667 | GA45: 7511.7333 | GB45: 3223.5 | GC45: 5419.8 | GD45: 7123.6333 | GE45: 3438.3667 | GF45: 5730.1333 | GG45: 3421.8 | GH45: 4431.0333 | GI45: 3736.4333 | GJ45: 3929.2667 | GK45: 6925.3 | GL45: 4768.3667 | GM45: 6868.8333 | GN45: 5465.6667 | GO45: 4613.6 | GP45: 3122.8 | GQ45: 6111.1 | GR45: 6359.1333 | GS45: 7138.4 | GT45: 4590.18 | GU45: 8469.1 | GV45: 5873.88 | GW45: 7767.52 | GX45: 8531.86 | GY45: 3529.42 | GZ45: 4621.1 | HA45: 8029.02 | HB45: 6234.5 | HC45: 6862 | HD45: 6982.08 | HE45: 5936.18 | HF45: 6425.48 | HG45: 7569.88 | HH45: 5017.22 | HI45: 9449.62 | HJ45: 7149.5 | HK45: 9245.32 | HL45: 6156.54 | HM45: 7926.24 | HN45: 9648.96 | HO45: 8709.42 | HP45: 8254.94 | HQ45: 5000.56 | HR45: 7909.78 | HS45: 10697.08 | HT45: 9005.78 | HU45: 7056.9 | HV45: 7104.58 | HW45: 7282.48 | HX45: 7635.64 | HY45: 7258.08 | HZ45: 9768.04 | IA45: 6696.92 | IB45: 6413.84 | IC45: 5741.7 | ID45: 6391.38 | IE45: 9438.02 | IF45: 9375.56 | IG45: 6974.06 | IH45: 5548.26 | II45: 7145.86 | IJ45: 4466.88 | IK45: 6062.2 | IL45: 5711.08 | IM45: 6646.64 | IN45: 5192.52 | IO45: 8291.28 | IP45: 6590.68 | IQ45: 10077.38 | IR45: 5842.12 | IS45: 6058.6 | IT45: 5382.34 | IU45: 6258.3 | IV45: 7982.44 | IW45: 8540 | IX45: 9167.76 | IY45: 6497.48 | IZ45: 6625.36 | JA45: 6072.12 | JB45: 5605.1 | JC45: 6016.58 | JD45: 4172.94 | JE45: 7293.62 | JF45: 6171.24 | JG45: 4888.42 | JH45: 9604.64 | JI45: 4655.04 | JJ45: 6473.88 | JK45: 4117.7 | JL45: 7209.46 | JM45: 5937.18 | JN45: 10273.86 | JO45: 6963.96 | JP45: 6204.32 | JQ45: 6187.94 | JR45: 5608.02 | JS45: 7529.02 | JT45: 4297.18 | JU45: 7808.4 | JV45: 6185.94 | JW45: 8306.8 | JX45: 6800 | JY45: 7700.54 | JZ45: 6802.32 | KA45: 8179.52 | KB45: 6138.94 | KC45: 9341.28 | KD45: 7367.24 | KE45: 7412.38 | KF45: 6034.66 | KG45: 6110.16 | KH45: 5674.92 | KI45: 6400.92 | KJ45: 6634.88 | KK45: 6996.88 | KL45: 7747.96 | KM45: 4700.64 | KN45: 6837.62 | KO45: 6654.3
A46: MQGA | B46: 4912.1429 | C46: 3687.9524 | D46: 6019.619 | E46: 3074.5238 | F46: 2951.381 | G46: 3781.9048 | H46: 2410.2381 | I46: 3274.4762 | J46: 2395.1905 | K46: 2300.4286 | L46: 3069.0476 | M46: 2311.2857 | N46: 4645.6667 | O46: 3843.4286 | P46: 3073.7619 | Q46: 3450.2381 | R46: 2474.7619 | S46: 3448.8095 | T46: 3146.6667 | U46: 2426.8571 | V46: 2195.7143 | W46: 2618.5714 | X46: 2777.3333 | Y46: 2353.4286 | Z46: 3392.0952 | AA46: 2338.4762 | AB46: 3806.3333 | AC46: 4205.3333 | AD46: 5217.1905 | AE46: 2086.8571 | AF46: 3725.0952 | AG46: 3664.8095 | AH46: 4966.3333 | AI46: 4873.6667 | AJ46: 2420.9048 | AK46: 2580.4762 | AL46: 3525.4762 | AM46: 3632.0476 | AN46: 4619.0952 | AO46: 3697.2857 | AP46: 3968.8095 | AQ46: 3389.381 | AR46: 2106.8095 | AS46: 6166.1429 | AT46: 3064.381 | AU46: 4317.0476 | AV46: 3254.0476 | AW46: 3927.2381 | AX46: 4130.7619 | AY46: 3632.4762 | AZ46: 3587.4762 | BA46: 2833.3333 | BB46: 2569.5238 | BC46: 2914.3333 | BD46: 2946.9524 | BE46: 3240.7143 | BF46: 3117.4762 | BG46: 2683.619 | BH46: 2332.8571 | BI46: 2730.619 | BJ46: 3184.4762 | BK46: 2517.2381 | BL46: 4223.6667 | BM46: 2696.6667 | BN46: 3738 | BO46: 5076 | BP46: 2432.381 | BQ46: 3226.8095 | BR46: 2562.0476 | BS46: 2888.0476 | BT46: 3174.7143 | BU46: 3321.6667 | BV46: 4713.9524 | BW46: 3510.9524 | BX46: 2800.2381 | BY46: 2834.5714 | BZ46: 5186.1905 | CA46: 3303.9524 | CB46: 2622.7619 | CC46: 2761.6667 | CD46: 2263.1905 | CE46: 5126 | CF46: 4629.0952 | CG46: 3959.2381 | CH46: 2841.4286 | CI46: 3453.381 | CJ46: 3293.7619 | CK46: 2655.381 | CL46: 2811 | CM46: 5937.6667 | CN46: 3942.2381 | CO46: 2863.2857 | CP46: 3695.8095 | CQ46: 2786.9048 | CR46: 2488.8095 | CS46: 2748.0952 | CT46: 2072.9048 | CU46: 3740.0952 | CV46: 4061.7619 | CW46: 3063.5714 | CX46: 4576.0667 | CY46: 3226.5667 | CZ46: 4152.2333 | DA46: 3669.4 | DB46: 3775 | DC46: 3793.3333 | DD46: 4521.5667 | DE46: 4427.2667 | DF46: 3833.6 | DG46: 3053.3333 | DH46: 4659.2333 | DI46: 4019.1667 | DJ46: 4104.8667 | DK46: 5337.2667 | DL46: 4183.9667 | DM46: 3774.9 | DN46: 4759.0667 | DO46: 3518.7333 | DP46: 3486.8333 | DQ46: 3346.8 | DR46: 3294.5667 | DS46: 3018.4667 | DT46: 4552.7 | DU46: 4352.3333 | DV46: 4624.2333 | DW46: 2991.3 | DX46: 5093.7333 | DY46: 3905.9333 | DZ46: 4542.7333 | EA46: 4040.3333 | EB46: 3343.2333 | EC46: 3648.6 | ED46: 4199.7333 | EE46: 3847.3667 | EF46: 4781.9667 | EG46: 4538.8333 | EH46: 4254.2333 | EI46: 3970.7667 | EJ46: 3083.7333 | EK46: 3636.4667 | EL46: 3906.8667 | EM46: 2547.8333 | EN46: 3382.7333 | EO46: 3625.2333 | EP46: 4675.1 | EQ46: 2997.3667 | ER46: 3375.2667 | ES46: 3308.8667 | ET46: 4143.9667 | EU46: 4286.6333 | EV46: 3678.7667 | EW46: 4101.6333 | EX46: 3865.6 | EY46: 5146.4667 | EZ46: 5464.3 | FA46: 4878.8 | FB46: 4387.5667 | FC46: 4676 | FD46: 2759.5667 | FE46: 4010.2667 | FF46: 3084.4 | FG46: 3055.7 | FH46: 3678.9333 | FI46: 4009.0333 | FJ46: 3390.8333 | FK46: 5147 | FL46: 3136.8 | FM46: 5059.9667 | FN46: 3943.6333 | FO46: 3760.7 | FP46: 3005.7667 | FQ46: 3961.1 | FR46: 3046.8667 | FS46: 3369.2667 | FT46: 4434.4333 | FU46: 4733.3333 | FV46: 3646.7333 | FW46: 4209.9333 | FX46: 4845.0333 | FY46: 4998.9667 | FZ46: 3642.0667 | GA46: 3604.4 | GB46: 3653.7 | GC46: 3843.9667 | GD46: 3228.5 | GE46: 3496.8333 | GF46: 4090.8333 | GG46: 4054.5667 | GH46: 2971.8 | GI46: 2900.0333 | GJ46: 4339.7 | GK46: 4199.9333 | GL46: 3748.2333 | GM46: 4436.4 | GN46: 3315.7333 | GO46: 3403.5 | GP46: 4872.7667 | GQ46: 4682.9 | GR46: 4955.6 | GS46: 3388.4667 | GT46: 5930.92 | GU46: 7016.44 | GV46: 6537.02 | GW46: 7255.56 | GX46: 6856.58 | GY46: 5798.12 | GZ46: 5568.62 | HA46: 5509.62 | HB46: 4871.72 | HC46: 4948.2 | HD46: 5097.86 | HE46: 6414.16 | HF46: 5027.18 | HG46: 7653.42 | HH46: 4856.9 | HI46: 5861.2 | HJ46: 4833.24 | HK46: 5101.22 | HL46: 5547.82 | HM46: 5501.78 | HN46: 6608.58 | HO46: 6815.4 | HP46: 7519.86 | HQ46: 4977.76 | HR46: 4997.8 | HS46: 5802.8 | HT46: 5165.78 | HU46: 5347.36 | HV46: 6664.76 | HW46: 5607.16 | HX46: 7008.6 | HY46: 6397.3 | HZ46: 6266.4 | IA46: 5491.22 | IB46: 6412.48 | IC46: 4709.3 | ID46: 6653.16 | IE46: 6351.56 | IF46: 5234 | IG46: 4554.08 | IH46: 5758.08 | II46: 7643.84 | IJ46: 5724.14 | IK46: 5339.96 | IL46: 5024.16 | IM46: 5487.6 | IN46: 5474.16 | IO46: 5542.28 | IP46: 5449.84 | IQ46: 6479.98 | IR46: 6131.2 | IS46: 6002.02 | IT46: 5185.78 | IU46: 6123.14 | IV46: 6383.48 | IW46: 6789.46 | IX46: 6128.28 | IY46: 5879.22 | IZ46: 5770.88 | JA46: 5663.68 | JB46: 7237.26 | JC46: 4395.36 | JD46: 6072.12 | JE46: 6479.2 | JF46: 4032.08 | JG46: 5450.18 | JH46: 6547.9 | JI46: 4094.28 | JJ46: 5858.86 | JK46: 5710.1 | JL46: 6357.56 | JM46: 7043.54 | JN46: 6042.18 | JO46: 7216.72 | JP46: 6256.66 | JQ46: 6490.92 | JR46: 6776.12 | JS46: 5360.7 | JT46: 7292.64 | JU46: 4414.82 | JV46: 5142.38 | JW46: 5362.12 | JX46: 4912.04 | JY46: 7072.46 | JZ46: 6818.16 | KA46: 6171.5 | KB46: 5456.52 | KC46: 4773.26 | KD46: 4792.12 | KE46: 4845.02 | KF46: 6068.24 | KG46: 6827.16 | KH46: 6923.52 | KI46: 6955.6 | KJ46: 4893.6 | KK46: 6328.28 | KL46: 3988.3 | KM46: 5591.66 | KN46: 5024.02 | KO46: 5567.56
A47: Greedy | B47: 3725.7143 | C47: 4499.2857 | D47: 4546.3333 | E47: 3430.0952 | F47: 3679.5238 | G47: 2342.8571 | H47: 3795.2857 | I47: 2105.7143 | J47: 3196.7143 | K47: 2457.0476 | L47: 4575.0476 | M47: 2418.8095 | N47: 6506.0476 | O47: 2781.9524 | P47: 2318.1905 | Q47: 2703.1905 | R47: 3422.0476 | S47: 2996.7143 | T47: 2424.619 | U47: 2809.7619 | V47: 4198.3333 | W47: 3471.8095 | X47: 3225 | Y47: 4544.9048 | Z47: 2604.9048 | AA47: 6191.9048 | AB47: 6112.7143 | AC47: 2850.8571 | AD47: 3381.7143 | AE47: 4814.0476 | AF47: 3324.3333 | AG47: 4458.7143 | AH47: 4634.381 | AI47: 2947.2857 | AJ47: 4012.8571 | AK47: 2720.5714 | AL47: 4082.1429 | AM47: 5344.0476 | AN47: 2416.3333 | AO47: 4537.8095 | AP47: 4137.1905 | AQ47: 4137.619 | AR47: 2759.0476 | AS47: 3224.4286 | AT47: 2410.8571 | AU47: 4318.9524 | AV47: 2917.1429 | AW47: 3452.619 | AX47: 2910.4286 | AY47: 5256.0952 | AZ47: 4752.0952 | BA47: 2497.4286 | BB47: 4133.1429 | BC47: 4430.0952 | BD47: 4113.381 | BE47: 2235.9524 | BF47: 10827.381 | BG47: 3072.5714 | BH47: 2282.0952 | BI47: 2210.0476 | BJ47: 3745.4762 | BK47: 4249.619 | BL47: 3504.2381 | BM47: 5834.7143 | BN47: 2771.381 | BO47: 5110.7143 | BP47: 3012.0952 | BQ47: 5734.5714 | BR47: 6979.7143 | BS47: 2369.9048 | BT47: 3714 | BU47: 4895.9048 | BV47: 4323.5238 | BW47: 5915.0952 | BX47: 6412.381 | BY47: 2489.7619 | BZ47: 2248.2381 | CA47: 3614.5238 | CB47: 2443.8571 | CC47: 6467 | CD47: 4676.1905 | CE47: 3308 | CF47: 5980.8095 | CG47: 4036.5238 | CH47: 4524.1905 | CI47: 5534.8095 | CJ47: 5995.381 | CK47: 4009.381 | CL47: 10015.619 | CM47: 2732.8095 | CN47: 4604.9524 | CO47: 4741.5714 | CP47: 2733.8095 | CQ47: 6779.0952 | CR47: 2457.619 | CS47: 2705.8571 | CT47: 5416.0952 | CU47: 3731.9048 | CV47: 2817.7143 | CW47: 2429.1905 | CX47: 9034.9333 | CY47: 3165.2667 | CZ47: 4672.3667 | DA47: 2680.2333 | DB47: 4105.6 | DC47: 4888.4 | DD47: 4320.9 | DE47: 6127.8667 | DF47: 7626.5667 | DG47: 4325.9333 | DH47: 2842.9 | DI47: 5615.6333 | DJ47: 5264.1333 | DK47: 4471.8 | DL47: 6395.7333 | DM47: 4905.7333 | DN47: 3308.1 | DO47: 3917 | DP47: 2537.2333 | DQ47: 9470.1667 | DR47: 8492.2 | DS47: 3142.9333 | DT47: 6040.1667 | DU47: 5441.7 | DV47: 6384.6333 | DW47: 3152.8333 | DX47: 5961.2 | DY47: 5341.1333 | DZ47: 4744.0667 | EA47: 4689.2667 | EB47: 5135.5333 | EC47: 4531.4 | ED47: 8201.3667 | EE47: 3344.9 | EF47: 3817.7333 | EG47: 5164.2 | EH47: 7962.7333 | EI47: 3635.6333 | EJ47: 3184.6333 | EK47: 7564 | EL47: 5275.9333 | EM47: 3457.3 | EN47: 6048.0333 | EO47: 5934.8667 | EP47: 4158.8333 | EQ47: 4856.9333 | ER47: 7394.9667 | ES47: 8526.4 | ET47: 6145.6 | EU47: 6292.6 | EV47: 3817.6 | EW47: 8522.6333 | EX47: 3229.1667 | EY47: 4192.9667 | EZ47: 6537.7333 | FA47: 4126.0333 | FB47: 4152.8667 | FC47: 4613.8 | FD47: 3142.1 | FE47: 3985.5667 | FF47: 3415.0667 | FG47: 3239.0667 | FH47: 4649.4333 | FI47: 5661.0667 | FJ47: 6097.0333 | FK47: 3714.4 | FL47: 3246.7667 | FM47: 7124.3 | FN47: 4408.2 | FO47: 3513.4333 | FP47: 4371.7667 | FQ47: 6928.3667 | FR47: 3915.8 | FS47: 5334.0667 | FT47: 6964.7667 | FU47: 6322.5667 | FV47: 3014.5333 | FW47: 6226.1667 | FX47: 7224.1667 | FY47: 3718.2 | FZ47: 5084.7667 | GA47: 4513.9667 | GB47: 5656 | GC47: 5432.4667 | GD47: 3411.5 | GE47: 7987.2333 | GF47: 6672.3333 | GG47: 5398.7667 | GH47: 3058.9 | GI47: 3714.6667 | GJ47: 5400.9333 | GK47: 2937.3667 | GL47: 3512.1667 | GM47: 6148.3333 | GN47: 3612.5667 | GO47: 2655.7333 | GP47: 3004.0667 | GQ47: 6218.7667 | GR47: 6500.4333 | GS47: 4776.2 | GT47: 7256.06 | GU47: 7827.98 | GV47: 6847.72 | GW47: 9165.02 | GX47: 8406.02 | GY47: 6957.42 | GZ47: 6255.66 | HA47: 8455.1 | HB47: 5781.46 | HC47: 6226.1 | HD47: 5902.56 | HE47: 7036.62 | HF47: 7586.82 | HG47: 8805 | HH47: 3915.34 | HI47: 8147.18 | HJ47: 6957 | HK47: 6117.96 | HL47: 9313.6 | HM47: 5499.22 | HN47: 8376.22 | HO47: 6086.38 | HP47: 7819.28 | HQ47: 4436.8 | HR47: 7098.26 | HS47: 6860.04 | HT47: 3562.78 | HU47: 6587.92 | HV47: 11063.5 | HW47: 7864.14 | HX47: 8083.88 | HY47: 8684.8 | HZ47: 7796.98 | IA47: 4969.92 | IB47: 7162.22 | IC47: 6339.1 | ID47: 6614.86 | IE47: 6599.38 | IF47: 6143.98 | IG47: 5125.88 | IH47: 7272.62 | II47: 8540.26 | IJ47: 7828.1 | IK47: 7373.12 | IL47: 6038.52 | IM47: 5514.64 | IN47: 7361.64 | IO47: 5803.12 | IP47: 6876.24 | IQ47: 7963.34 | IR47: 8210.34 | IS47: 2987.4 | IT47: 7296.96 | IU47: 7971.8 | IV47: 8199.12 | IW47: 8385.74 | IX47: 3798.64 | IY47: 9180.58 | IZ47: 8965.9 | JA47: 6262.5 | JB47: 7745.66 | JC47: 6217.86 | JD47: 7433.6 | JE47: 10448.86 | JF47: 5379.48 | JG47: 5392.62 | JH47: 8529.08 | JI47: 6227.96 | JJ47: 5513.12 | JK47: 7519.38 | JL47: 8714.72 | JM47: 7768.48 | JN47: 8206.32 | JO47: 5824.14 | JP47: 9690.38 | JQ47: 9843.7 | JR47: 8775.44 | JS47: 6753.42 | JT47: 2661.64 | JU47: 7227.94 | JV47: 7905.16 | JW47: 8014.02 | JX47: 7709.14 | JY47: 7742.1 | JZ47: 8793.06 | KA47: 3893.04 | KB47: 5804.38 | KC47: 4399.06 | KD47: 8246.8 | KE47: 7642.66 | KF47: 7907.74 | KG47: 6966.74 | KH47: 7941.08 | KI47: 12065.16 | KJ47: 7570.56 | KK47: 8179.66 | KL47: 6980.62 | KM47: 8411.04 | KN47: 6278.64 | KO47: 7950.58
A48: MOPSO | B48: 6856.0476 | C48: 3347.9524 | D48: 3209.0476 | E48: 5677.1905 | F48: 3153.4286 | G48: 2372.8095 | H48: 3910.0952 | I48: 2037.381 | J48: 3048.4762 | K48: 3087.9048 | L48: 3570.619 | M48: 5431.7143 | N48: 4488.2857 | O48: 4587.1429 | P48: 3020.1429 | Q48: 2702.4286 | R48: 3224.3333 | S48: 3134.381 | T48: 3983.1429 | U48: 2721.7143 | V48: 2475.0952 | W48: 2777.7619 | X48: 3860.0952 | Y48: 2356.8571 | Z48: 6305.4762 | AA48: 3879.7619 | AB48: 3662.1429 | AC48: 3262.7143 | AD48: 3859.5238 | AE48: 2011.2857 | AF48: 8160.7143 | AG48: 4307.4286 | AH48: 7154.9524 | AI48: 3442.2381 | AJ48: 3118.3333 | AK48: 2751.2857 | AL48: 3390.4762 | AM48: 3257.381 | AN48: 3529.1905 | AO48: 3597 | AP48: 8995.7619 | AQ48: 2675.381 | AR48: 2378.619 | AS48: 2423.619 | AT48: 2385.8095 | AU48: 3862.2857 | AV48: 2440.381 | AW48: 2292.5714 | AX48: 3570.2381 | AY48: 5384.1429 | AZ48: 2573.4762 | BA48: 2678.5714 | BB48: 3195.2381 | BC48: 2418.2381 | BD48: 3019.3333 | BE48: 3303.7143 | BF48: 3548.7619 | BG48: 2978.7619 | BH48: 3707.5714 | BI48: 4689.5238 | BJ48: 2934.381 | BK48: 3561.5238 | BL48: 4207.7143 | BM48: 3237.9524 | BN48: 4526.5238 | BO48: 5233.7143 | BP48: 2481.0476 | BQ48: 4675.9048 | BR48: 3292.1429 | BS48: 3237.619 | BT48: 3563.619 | BU48: 4790.6667 | BV48: 5213.8095 | BW48: 5301.7143 | BX48: 3464.381 | BY48: 2582.4762 | BZ48: 2760.6667 | CA48: 6951.4286 | CB48: 3019.8095 | CC48: 2839.7143 | CD48: 4902.0952 | CE48: 4758.8095 | CF48: 3214.8571 | CG48: 2761.9524 | CH48: 2836.381 | CI48: 2760.9048 | CJ48: 3373.8571 | CK48: 3937.1905 | CL48: 4966.0476 | CM48: 3254.4286 | CN48: 4149.4286 | CO48: 5011 | CP48: 3014.5714 | CQ48: 6008.0476 | CR48: 3136.619 | CS48: 5098 | CT48: 3936.3333 | CU48: 4893.619 | CV48: 3850.9048 | CW48: 3968.4762 | CX48: 4769.5667 | CY48: 5794.7333 | CZ48: 4661.5333 | DA48: 4455.7333 | DB48: 4013.6 | DC48: 4806.6 | DD48: 4643.2667 | DE48: 4804.3333 | DF48: 5580.3 | DG48: 4754.4333 | DH48: 5568.1667 | DI48: 6308.3667 | DJ48: 7179.9333 | DK48: 4334.5667 | DL48: 7026.0333 | DM48: 3611.0333 | DN48: 5499.2333 | DO48: 4094.3333 | DP48: 4318.9333 | DQ48: 5396.5333 | DR48: 5691.2333 | DS48: 3593.7333 | DT48: 4882.4667 | DU48: 5668.4667 | DV48: 5103.3333 | DW48: 4980.5 | DX48: 5774.8333 | DY48: 6026 | DZ48: 7791.7667 | EA48: 6044.0333 | EB48: 3566.4333 | EC48: 5712.3 | ED48: 4883.9 | EE48: 3435.3 | EF48: 4295.7 | EG48: 3765.8333 | EH48: 4621.1 | EI48: 5615.6333 | EJ48: 4234.6667 | EK48: 5016.4 | EL48: 6172.9333 | EM48: 3395.4667 | EN48: 4547.8667 | EO48: 5771.1333 | EP48: 5146.7667 | EQ48: 4940.2 | ER48: 6809.4 | ES48: 5575.1667 | ET48: 4185.7 | EU48: 4629.1333 | EV48: 3588.9667 | EW48: 6105.0667 | EX48: 6994.6667 | EY48: 3974.5 | EZ48: 5714.9667 | FA48: 3923.3 | FB48: 3887.4667 | FC48: 4477.3333 | FD48: 3983.4667 | FE48: 4037.4 | FF48: 4246.4667 | FG48: 4052.1 | FH48: 4136.1667 | FI48: 7340.8667 | FJ48: 7138.1333 | FK48: 4701.9 | FL48: 4713.6333 | FM48: 4784.8 | FN48: 5528.7 | FO48: 4456.3 | FP48: 4896.9333 | FQ48: 6328.9667 | FR48: 3931.7333 | FS48: 4266.4667 | FT48: 4157.7667 | FU48: 5108.7 | FV48: 4568.7667 | FW48: 5934.2 | FX48: 5195.2667 | FY48: 6011.7667 | FZ48: 2747.6333 | GA48: 3935.5667 | GB48: 4321.2333 | GC48: 5101.5 | GD48: 5023.7667 | GE48: 4976.7667 | GF48: 5858.3333 | GG48: 4132.9333 | GH48: 5402.3 | GI48: 4672.4333 | GJ48: 3622.7667 | GK48: 3682.8 | GL48: 4595.0333 | GM48: 4526.1 | GN48: 5118.5333 | GO48: 4077.1667 | GP48: 5753.6667 | GQ48: 5415.2333 | GR48: 4911.0333 | GS48: 6133.1667 | GT48: 7399.48 | GU48: 8396.26 | GV48: 4899.86 | GW48: 7440.42 | GX48: 8221.72 | GY48: 7335.18 | GZ48: 6045.02 | HA48: 8055.08 | HB48: 5320 | HC48: 6707.14 | HD48: 7683.4 | HE48: 7395.22 | HF48: 6684.32 | HG48: 6899.34 | HH48: 7743.66 | HI48: 7431.44 | HJ48: 6346.84 | HK48: 5197.86 | HL48: 7670.84 | HM48: 7934.56 | HN48: 7791.7 | HO48: 6792.56 | HP48: 9264.38 | HQ48: 5712.88 | HR48: 8549.4 | HS48: 6744.46 | HT48: 5887.44 | HU48: 6796.3 | HV48: 7468.22 | HW48: 5558.46 | HX48: 8503.72 | HY48: 7602.2 | HZ48: 6108.32 | IA48: 6164.94 | IB48: 8138.68 | IC48: 6125.2 | ID48: 6474.42 | IE48: 5648.38 | IF48: 7588.82 | IG48: 4968.24 | IH48: 7443.94 | II48: 6599.4 | IJ48: 8111.62 | IK48: 6746.64 | IL48: 7631.3 | IM48: 7311.02 | IN48: 7050.1 | IO48: 8403.6 | IP48: 6337.18 | IQ48: 6377.58 | IR48: 6733.5 | IS48: 8208.96 | IT48: 6900.62 | IU48: 6224.28 | IV48: 7216.36 | IW48: 7467.22 | IX48: 8185.14 | IY48: 6286 | IZ48: 5859.02 | JA48: 6000.88 | JB48: 5659.62 | JC48: 5449.84 | JD48: 7552.22 | JE48: 5895.98 | JF48: 6290.74 | JG48: 6465.82 | JH48: 6625.74 | JI48: 5828.5 | JJ48: 7936.12 | JK48: 7063.26 | JL48: 8057.2 | JM48: 6145.38 | JN48: 7160.12 | JO48: 5706.16 | JP48: 7324.96 | JQ48: 7653.64 | JR48: 7220.4 | JS48: 7421.52 | JT48: 6228.62 | JU48: 7090.7 | JV48: 7240.04 | JW48: 6910.92 | JX48: 5331.18 | JY48: 7174.36 | JZ48: 7760.2 | KA48: 7333.64 | KB48: 7147.38 | KC48: 5547.22 | KD48: 5156.48 | KE48: 8264.2 | KF48: 7844.66 | KG48: 6918.82 | KH48: 7056.34 | KI48: 7194.44 | KJ48: 7635 | KK48: 6099.04 | KL48: 5393.16 | KM48: 6478.58 | KN48: 5601.9 | KO48: 6309.36

Sheet Energy
A1: Algorithm | B1: Load | C1: Average | D1: Min | E1: Max | F1: Std Dev
A2: QUEST | B2: 20 | C2: 11035549 | D2: 8258247.5 | E2: 14164877 | F2: 1285512
A3: QUEST | B3: 30 | C3: 14895357 | D3: 11167762 | E3: 19617054 | F3: 1667126.5
A4: QUEST | B4: 50 | C4: 24970479 | D4: 16481639 | E4: 34195294 | F4: 3462822.4
A5: Fuzzy | B5: 20 | C5: 13599391 | D5: 9226486.7 | E5: 23349176 | F5: 2427820.2
A6: Fuzzy | B6: 30 | C6: 24836193 | D6: 15639668 | E6: 39703739 | F6: 4454679.2
A7: Fuzzy | B7: 50 | C7: 50674383 | D7: 35856793 | E7: 69079344 | F7: 8000490
A8: NSGA3 | B8: 20 | C8: 13759448 | D8: 7641259.2 | E8: 24306436 | F8: 3216896
A9: NSGA3 | B9: 30 | C9: 24729021 | D9: 13461279 | E9: 37692373 | F9: 5553069.4
A10: NSGA3 | B10: 50 | C10: 48174455 | D10: 30233851 | E10: 67285402 | F10: 8465663
A11: MQGA | B11: 20 | C11: 11423413 | D11: 9037396.7 | E11: 13746418 | F11: 978654.28
A12: MQGA | B12: 30 | C12: 19925336 | D12: 16879474 | E12: 24839072 | F12: 1477886.9
A13: MQGA | B13: 50 | C13: 41946442 | D13: 34560420 | E13: 52449258 | F13: 2852232
... A19: MOPSO | B19: 50 | C19: 48080054 | D19: 39772264 | E19: 57183725 | F19: 4166576.2
A22: Summary by Algorithm
A23: QUEST | C23: 16967128 | D23: 8258247.5 | E23: 34195294 | F23: 6323302.8
A24: Fuzzy | C24: 29703322 | D24: 9226486.7 | E24: 69079344 | F24: 16457594
A25: NSGA3 | C25: 28887641 | D25: 7641259.2 | E25: 67285402 | F25: 15609719
A26: MQGA | C26: 24431730 | D26: 9037396.7 | E26: 52449258 | F26: 13007257
A27: Greedy | C27: 28795531 | D27: 7068295 | E27: 80900579 | F27: 16615719
A28: MOPSO | C28: 28162465 | D28: 9863970 | E28: 57183725 | F28: 15002361
A31: Average data for chart
A32: Algorithms | B32: 20 | C32: 30 | D32: 50
A33: QUEST | B33: 11035549 | C33: 14895357 | D33: 24970479
A34: Fuzzy | B34: 13599391 | C34: 24836193 | D34: 50674383
A35: NSGA3 | B35: 13759448 | C35: 24729021 | D35: 48174455
A36: MQGA | B36: 11423413 | C36: 19925336 | D36: 41946442
A37: Greedy | B37: 12931237 | C37: 23825663 | D37: 49629693
A38: MOPSO | B38: 12964493 | C38: 23442847 | D38: 48080054
A41: All data for chart
A42: Algorithms | B42: 20 | C42: 20 | D42: 20 | E42: 20 | F42: 20 | G42: 20 | H42: 20 | I42: 20 | J42: 20 | K42: 20 | L42: 20 | M42: 20 | N42: 20 | O42: 20 | P42: 20 | Q42: 20 | R42: 20 | S42: 20 | T42: 20 | U42: 20 | V42: 20 | W42: 20 | X42: 20 | Y42: 20 | Z42: 20 | AA42: 20 | AB42: 20 | AC42: 20 | AD42: 20 | AE42: 20 | AF42: 20 | AG42: 20 | AH42: 20 | AI42: 20 | AJ42: 20 | AK42: 20 | AL42: 20 | AM42: 20 | AN42: 20 | AO42: 20 | AP42: 20 | AQ42: 20 | AR42: 20 | AS42: 20 | AT42: 20 | AU42: 20 | AV42: 20 | AW42: 20 | AX42: 20 | AY42: 20 | AZ42: 20 | BA42: 20 | BB42: 20 | BC42: 20 | BD42: 20 | BE42: 20 | BF42: 20 | BG42: 20 | BH42: 20 | BI42: 20 | BJ42: 20 | BK42: 20 | BL42: 20 | BM42: 20 | BN42: 20 | BO42: 20 | BP42: 20 | BQ42: 20 | BR42: 20 | BS42: 20 | BT42: 20 | BU42: 20 | BV42: 20 | BW42: 20 | BX42: 20 | BY42: 20 | BZ42: 20 | CA42: 20 | CB42: 20 | CC42: 20 | CD42: 20 | CE42: 20 | CF42: 20 | CG42: 20 | CH42: 20 | CI42: 20 | CJ42: 20 | CK42: 20 | CL42: 20 | CM42: 20 | CN42: 20 | CO42: 20 | CP42: 20 | CQ42: 20 | CR42: 20 | CS42: 20 | CT42: 20 | CU42: 20 | CV42: 20 | CW42: 20 | CX42: 30 | CY42: 30 | CZ42: 30 | DA42: 30 | DB42: 30 | DC42: 30 | DD42: 30 | DE42: 30 | DF42: 30 | DG42: 30 | DH42: 30 | DI42: 30 | DJ42: 30 | DK42: 30 | DL42: 30 | DM42: 30 | DN42: 30 | DO42: 30 | DP42: 30 | DQ42: 30 | DR42: 30 | DS42: 30 | DT42: 30 | DU42: 30 | DV42: 30 | DW42: 30 | DX42: 30 | DY42: 30 | DZ42: 30 | EA42: 30 | EB42: 30 | EC42: 30 | ED42: 30 | EE42: 30 | EF42: 30 | EG42: 30 | EH42: 30 | EI42: 30 | EJ42: 30 | EK42: 30 | EL42: 30 | EM42: 30 | EN42: 30 | EO42: 30 | EP42: 30 | EQ42: 30 | ER42: 30 | ES42: 30 | ET42: 30 | EU42: 30 | EV42: 30 | EW42: 30 | EX42: 30 | EY42: 30 | EZ42: 30 | FA42: 30 | FB42: 30 | FC42: 30 | FD42: 30 | FE42: 30 | FF42: 30 | FG42: 30 | FH42: 30 | FI42: 30 | FJ42: 30 | FK42: 30 | FL42: 30 | FM42: 30 | FN42: 30 | FO42: 30 | FP42: 30 | FQ42: 30 | FR42: 30 | FS42: 30 | FT42: 30 | FU42: 30 | FV42: 30 | FW42: 30 | FX42: 30 | FY42: 30 | FZ42: 30 | GA42: 30 | GB42: 30 | GC42: 30 | GD42: 30 | GE42: 30 | GF42: 30 | GG42: 30 | GH42: 30 | GI42: 30 | GJ42: 30 | GK42: 30 | GL42: 30 | GM42: 30 | GN42: 30 | GO42: 30 | GP42: 30 | GQ42: 30 | GR42: 30 | GS42: 30 | GT42: 50 | GU42: 50 | GV42: 50 | GW42: 50 | GX42: 50 | GY42: 50 | GZ42: 50 | HA42: 50 | HB42: 50 | HC42: 50 | HD42: 50 | HE42: 50 | HF42: 50 | HG42: 50 | HH42: 50 | HI42: 50 | HJ42: 50 | HK42: 50 | HL42: 50 | HM42: 50 | HN42: 50 | HO42: 50 | HP42: 50 | HQ42: 50 | HR42: 50 | HS42: 50 | HT42: 50 | HU42: 50 | HV42: 50 | HW42: 50 | HX42: 50 | HY42: 50 | HZ42: 50 | IA42: 50 | IB42: 50 | IC42: 50 | ID42: 50 | IE42: 50 | IF42: 50 | IG42: 50 | IH42: 50 | II42: 50 | IJ42: 50 | IK42: 50 | IL42: 50 | IM42: 50 | IN42: 50 | IO42: 50 | IP42: 50 | IQ42: 50 | IR42: 50 | IS42: 50 | IT42: 50 | IU42: 50 | IV42: 50 | IW42: 50 | IX42: 50 | IY42: 50 | IZ42: 50 | JA42: 50 | JB42: 50 | JC42: 50 | JD42: 50 | JE42: 50 | JF42: 50 | JG42: 50 | JH42: 50 | JI42: 50 | JJ42: 50 | JK42: 50 | JL42: 50 | JM42: 50 | JN42: 50 | JO42: 50 | JP42: 50 | JQ42: 50 | JR42: 50 | JS42: 50 | JT42: 50 | JU42: 50 | JV42: 50 | JW42: 50 | JX42: 50 | JY42: 50 | JZ42: 50 | KA42: 50 | KB42: 50 | KC42: 50 | KD42: 50 | KE42: 50 | KF42: 50 | KG42: 50 | KH42: 50 | KI42: 50 | KJ42: 50 | KK42: 50 | KL42: 50 | KM42: 50 | KN42: 50 | KO42: 50
A43: QUEST | B43: 13974241 | C43: 12253365 | D43: 10543616 | E43: 12025990 | F43: 14164877 | G43: 12585996 | H43: 10355831 | I43: 11422640 | J43: 10662538 | K43: 11796343 | L43: 8624335 | M43: 10015137 | N43: 10500493 | O43: 8701258.3 | P43: 11175629 | Q43: 10206514 | R43: 11278467 | S43: 11395773 | T43: 11856161 | U43: 10111577 | V43: 11832828 | W43: 10290921 | X43: 11659401 | Y43: 11548986 | Z43: 12013865 | AA43: 12242807 | AB43: 11084088 | AC43: 11023656 | AD43: 12416647 | AE43: 9002540.8 | AF43: 12373032 | AG43: 12682534 | AH43: 12149327 | AI43: 11035387 | AJ43: 11184360 | AK43: 11961081 | AL43: 9955307.5 | AM43: 12081648 | AN43: 12175829 | AO43: 14142243 | AP43: 11826451 | AQ43: 8695455 | AR43: 12037932 | AS43: 10165587 | AT43: 12091281 | AU43: 10769632 | AV43: 10875480 | AW43: 12339394 | AX43: 12348902 | AY43: 11133285 | AZ43: 10015348 | BA43: 10015274 | BB43: 10449646 | BC43: 12673922 | BD43: 12674253 | BE43: 10640456 | BF43: 13423458 | BG43: 9430089.2 | BH43: 10450324 | BI43: 11549143 | BJ43: 11421420 | BK43: 9438331.7 | BL43: 11143251 | BM43: 8360613.3 | BN43: 13117783 | BO43: 11461599 | BP43: 8258247.5 | BQ43: 10918987 | BR43: 9191972.5 | BS43: 9737049.2 | BT43: 9788176.7 | BU43: 12771893 | BV43: 10072762 | BW43: 10011629 | BX43: 12052736 | BY43: 11735595 | BZ43: 12011130 | CA43: 12742185 | CB43: 11151396 | CC43: 8669271.7 | CD43: 9081941.7 | CE43: 11359975 | CF43: 11876308 | CG43: 10502024 | CH43: 9882685 | CI43: 11224781 | CJ43: 9231086.7 | CK43: 10185203 | CL43: 10394556 | CM43: 9653748.3 | CN43: 11718189 | CO43: 10404125 | CP43: 10775298 | CQ43: 10850953 | CR43: 9214255 | CS43: 10111291 | CT43: 9650001.7 | CU43: 11414366 | CV43: 10107052 | CW43: 11748468 | CX43: 13279328 | CY43: 15788362 | CZ43: 12798888 | DA43: 14511875 | DB43: 14619618 | DC43: 11703799 | DD43: 11167762 | DE43: 15169329 | DF43: 15618951 | DG43: 15029377 | DH43: 14014662 | DI43: 15930718 | DJ43: 12578722 | DK43: 17554720 | DL43: 17721878 | DM43: 13892255 | DN43: 14518627 | DO43: 13018058 | DP43: 13488718 | DQ43: 14815308 | DR43: 15617529 | DS43: 13186043 | DT43: 14397270 | DU43: 16075778 | DV43: 14579319 | DW43: 15091807 | DX43: 14828827 | DY43: 16498145 | DZ43: 17662498 | EA43: 19617054 | EB43: 13295549 | EC43: 15599096 | ED43: 18829598 | EE43: 12578982 | EF43: 14109665 | EG43: 16309795 | EH43: 15023383 | EI43: 18860389 | EJ43: 16835501 | EK43: 15077771 | EL43: 15479542 | EM43: 15146956 | EN43: 14954394 | EO43: 15079233 | EP43: 17033574 | EQ43: 13032835 | ER43: 13899997 | ES43: 16346703 | ET43: 14400916 | EU43: 12073478 | EV43: 16227310 | EW43: 14270072 | EX43: 16132706 | EY43: 16796514 | EZ43: 15766748 | FA43: 13505197 | FB43: 16642828 | FC43: 17127008 | FD43: 14595589 | FE43: 15634664 | FF43: 18143738 | FG43: 14204052 | FH43: 15443228 | FI43: 16006477 | FJ43: 14797532 | FK43: 14678314 | FL43: 16403297 | FM43: 12905558 | FN43: 15888664 | FO43: 13892121 | FP43: 13320066 | FQ43: 14708967 | FR43: 12760471 | FS43: 13744291 | FT43: 15604565 | FU43: 11900560 | FV43: 16003384 | FW43: 13739054 | FX43: 16118635 | FY43: 14047768 | FZ43: 13118802 | GA43: 13820812 | GB43: 13529988 | GC43: 11884305 | GD43: 13740394 | GE43: 15602160 | GF43: 13394732 | GG43: 16548898 | GH43: 11243544 | GI43: 14291387 | GJ43: 14334701 | GK43: 13464637 | GL43: 17608837 | GM43: 15878803 | GN43: 14324435 | GO43: 14886262 | GP43: 16758650 | GQ43: 15304778 | GR43: 14845704 | GS43: 15201895 | GT43: 30539001 | GU43: 25866917 | GV43: 29123507 | GW43: 21670922 | GX43: 25878775 | GY43: 27979479 | GZ43: 24913808 | HA43: 28554716 | HB43: 24472760 | HC43: 29778369 | HD43: 25284440 | HE43: 33155201 | HF43: 21097469 | HG43: 22560982 | HH43: 24118762 | HI43: 22861949 | HJ43: 25061381 | HK43: 21932317 | HL43: 23763572 | HM43: 28939610 | HN43: 23172340 | HO43: 30181968 | HP43: 29153788 | HQ43: 27734687 | HR43: 31295181 | HS43: 24178183 | HT43: 23222152 | HU43: 24160145 | HV43: 23627125 | HW43: 26476883 | HX43: 27105734 | HY43: 27893903 | HZ43: 31866575 | IA43: 28261482 | IB43: 31566425 | IC43: 24132606 | ID43: 26616334 | IE43: 27349532 | IF43: 23522334 | IG43: 22185762 | IH43: 20267798 | II43: 22624039 | IJ43: 27344942 | IK43: 21775853 | IL43: 24795588 | IM43: 23964991 | IN43: 25307729 | IO43: 26341098 | IP43: 22086280 | IQ43: 25390282 | IR43: 25704210 | IS43: 24164295 | IT43: 25306756 | IU43: 21774096 | IV43: 20689278 | IW43: 24804336 | IX43: 22909443 | IY43: 22596007 | IZ43: 31726812 | JA43: 22894335 | JB43: 24443721 | JC43: 20798208 | JD43: 25932837 | JE43: 28860705 | JF43: 25360085 | JG43: 16481639 | JH43: 23154697 | JI43: 17132714 | JJ43: 28165722 | JK43: 18030120 | JL43: 27175972 | JM43: 23689163 | JN43: 21775728 | JO43: 26982099 | JP43: 32836065 | JQ43: 23591113 | JR43: 21060032 | JS43: 20082268 | JT43: 22081551 | JU43: 25527037 | JV43: 24144940 | JW43: 28839734 | JX43: 20558326 | JY43: 34195294 | JZ43: 24660775 | KA43: 28157116 | KB43: 27032030 | KC43: 21513638 | KD43: 22879944 | KE43: 23318475 | KF43: 22960576 | KG43: 21435186 | KH43: 24102732 | KI43: 26283306 | KJ43: 21654022 | KK43: 23488330 | KL43: 18798374 | KM43: 26721197 | KN43: 25773231 | KO43: 23643914
A44: Fuzzy | B44: 16442139 | C44: 15124041 | D44: 16185272 | E44: 17828145 | F44: 11143787 | G44: 15000065 | H44: 12588811 | I44: 10849718 | J44: 14294524 | K44: 12162493 | L44: 11784181 | M44: 12792384 | N44: 12279379 | O44: 12536541 | P44: 12774121 | Q44: 15298571 | R44: 11031442 | S44: 12224557 | T44: 12898698 | U44: 14842545 | V44: 16102965 | W44: 13382062 | X44: 18026482 | Y44: 15369070 | Z44: 14787000 | AA44: 13243706 | AB44: 12861443 | AC44: 14557988 | AD44: 13622440 | AE44: 13172332 | AF44: 14153228 | AG44: 13241077 | AH44: 16728082 | AI44: 13306012 | AJ44: 10285178 | AK44: 15173764 | AL44: 13928627 | AM44: 13584518 | AN44: 17942258 | AO44: 18785796 | AP44: 14679099 | AQ44: 12539830 | AR44: 10685744 | AS44: 11551680 | AT44: 15968542 | AU44: 11787993 | AV44: 10027346 | AW44: 12019905 | AX44: 10405348 | AY44: 12786302 | AZ44: 12303131 | BA44: 15028665 | BB44: 14596199 | BC44: 13883556 | BD44: 11915339 | BE44: 13417563 | BF44: 18038703 | BG44: 19558170 | BH44: 10743059 | BI44: 17006914 | BJ44: 15309760 | BK44: 13835448 | BL44: 10468202 | BM44: 10101231 | BN44: 12849479 | BO44: 16321059 | BP44: 12356705 | BQ44: 16437138 | BR44: 13134602 | BS44: 13744702 | BT44: 12015226 | BU44: 14681717 | BV44: 10605751 | BW44: 14057970 | BX44: 12196820 | BY44: 15687620 | BZ44: 13746628 | CA44: 14167588 | CB44: 11075342 | CC44: 11413247 | CD44: 11600878 | CE44: 10203555 | CF44: 12104832 | CG44: 9226486.7 | CH44: 15583412 | CI44: 14683364 | CJ44: 11952638 | CK44: 14050848 | CL44: 15894269 | CM44: 9952412.5 | CN44: 10687864 | CO44: 23349176 | CP44: 10298804 | CQ44: 16640420 | CR44: 14223989 | CS44: 12485862 | CT44: 12636855 | CU44: 16089145 | CV44: 12024443 | CW44: 10765122 | CX44: 17147834 | CY44: 26755605 | CZ44: 19356448 | DA44: 27699581 | DB44: 21366304 | DC44: 23659113 | DD44: 26087668 | DE44: 25258685 | DF44: 22427546 | DG44: 24514387 | DH44: 19863380 | DI44: 21044799 | DJ44: 28976791 | DK44: 27459858 | DL44: 22893382 | DM44: 22986618 | DN44: 23409808 | DO44: 26056490 | DP44: 28059702 | DQ44: 23508868 | DR44: 23839516 | DS44: 35288403 | DT44: 24186208 | DU44: 21019279 | DV44: 21787215 | DW44: 31038138 | DX44: 27626070 | DY44: 33304957 | DZ44: 31432461 | EA44: 24673562 | EB44: 21193829 | EC44: 22807876 | ED44: 29724651 | EE44: 22943420 | EF44: 20980148 | EG44: 32013585 | EH44: 24441717 | EI44: 24991814 | EJ44: 26657039 | EK44: 29740562 | EL44: 24070616 | EM44: 21793280 | EN44: 29032756 | EO44: 28349813 | EP44: 30372608 | EQ44: 19999274 | ER44: 19302947 | ES44: 26612521 | ET44: 25288407 | EU44: 20667329 | EV44: 22212486 | EW44: 27168092 | EX44: 17213203 | EY44: 28671347 | EZ44: 24327678 | FA44: 24217043 | FB44: 28422695 | FC44: 28165935 | FD44: 20134850 | FE44: 23499226 | FF44: 20527749 | FG44: 26582850 | FH44: 29448740 | FI44: 22977458 | FJ44: 25052390 | FK44: 25797142 | FL44: 26667458 | FM44: 27605765 | FN44: 24697723 | FO44: 24599038 | FP44: 22462624 | FQ44: 22588392 | FR44: 24007362 | FS44: 22756575 | FT44: 37007151 | FU44: 21252364 | FV44: 26730121 | FW44: 24591053 | FX44: 22600163 | FY44: 22699532 | FZ44: 23465014 | GA44: 23837597 | GB44: 23394799 | GC44: 18535197 | GD44: 25090755 | GE44: 21151680 | GF44: 15639668 | GG44: 17924096 | GH44: 20315673 | GI44: 21905309 | GJ44: 28547311 | GK44: 19212718 | GL44: 21273328 | GM44: 23734472 | GN44: 17257261 | GO44: 28925193 | GP44: 24786062 | GQ44: 31883797 | GR44: 39703739 | GS44: 38638569 | GT44: 45741455 | GU44: 44584500 | GV44: 36015489 | GW44: 58337557 | GX44: 39747259 | GY44: 65504563 | GZ44: 42650016 | HA44: 62022070 | HB44: 40402727 | HC44: 62701967 | HD44: 43886339 | HE44: 53082602 | HF44: 51999410 | HG44: 54392583 | HH44: 53618833 | HI44: 39150611 | HJ44: 62883022 | HK44: 38796115 | HL44: 45753754 | HM44: 60290517 | HN44: 60202180 | HO44: 47433008 | HP44: 69079344 | HQ44: 40733016 | HR44: 58078553 | HS44: 48018093 | HT44: 44678670 | HU44: 49014197 | HV44: 60496673 | HW44: 54201662 | HX44: 55391750 | HY44: 52843329 | HZ44: 58408607 | IA44: 40551348 | IB44: 45978523 | IC44: 39398530 | ID44: 55835759 | IE44: 61110442 | IF44: 42483498 | IG44: 52865100 | IH44: 41900908 | II44: 43996842 | IJ44: 59508334 | IK44: 56362817 | IL44: 51055518 | IM44: 60766439 | IN44: 53686411 | IO44: 46255570 | IP44: 39179344 | IQ44: 55613324 | IR44: 64678408 | IS44: 52505127 | IT44: 61094092 | IU44: 50314461 | IV44: 49764454 | IW44: 58630897 | IX44: 37175633 | IY44: 48237517 | IZ44: 63148398 | JA44: 48894435 | JB44: 55192508 | JC44: 40491077 | JD44: 63239231 | JE44: 51674612 | JF44: 51387438 | JG44: 36056727 | JH44: 40713218 | JI44: 35856793 | JJ44: 55339006 | JK44: 60508257 | JL44: 46848970 | JM44: 52366699 | JN44: 55828351 | JO44: 52789081 | JP44: 61999277 | JQ44: 53802474 | JR44: 39450395 | JS44: 42882222 | JT44: 55644281 | JU44: 44595554 | JV44: 58605825 | JW44: 43896147 | JX44: 45581847 | JY44: 56430803 | JZ44: 46647408 | KA44: 44117261 | KB44: 59198875 | KC44: 43888826 | KD44: 53700589 | KE44: 52368772 | KF44: 42133181 | KG44: 57045012 | KH44: 53485923 | KI44: 53821383 | KJ44: 36648928 | KK44: 46980702 | KL44: 42839658 | KM44: 51467573 | KN44: 51749137 | KO44: 49031662
A45: NSGA3 | B45: 14054332 | C45: 17368277 | D45: 16967520 | E45: 14164188 | F45: 11021012 | G45: 16904523 | H45: 9116672.5 | I45: 10835436 | J45: 14639499 | K45: 14392872 | L45: 9842547.5 | M45: 15313687 | N45: 18911736 | O45: 9302850 | P45: 11579882 | Q45: 15724646 | R45: 11711333 | S45: 12014893 | T45: 19207487 | U45: 10016438 | V45: 12592644 | W45: 14111096 | X45: 17323392 | Y45: 11114931 | Z45: 14210150 | AA45: 14696278 | AB45: 10649294 | AC45: 19756377 | AD45: 12108301 | AE45: 17155422 | AF45: 15949687 | AG45: 10686220 | AH45: 10457147 | AI45: 14576560 | AJ45: 11479148 | AK45: 15540062 | AL45: 12213273 | AM45: 16862598 | AN45: 12907448 | AO45: 16379290 | AP45: 15096398 | AQ45: 9611075.8 | AR45: 21184803 | AS45: 13707462 | AT45: 12093773 | AU45: 14514348 | AV45: 7641259.2 | AW45: 10037100 | AX45: 20511010 | AY45: 11671036 | AZ45: 17731714 | BA45: 16784292 | BB45: 15117967 | BC45: 13595732 | BD45: 21977003 | BE45: 13243387 | BF45: 13902592 | BG45: 13764623 | BH45: 13120634 | BI45: 9823228.3 | BJ45: 11544915 | BK45: 12527751 | BL45: 11302338 | BM45: 9854626.7 | BN45: 11270008 | BO45: 16722915 | BP45: 10412323 | BQ45: 16805421 | BR45: 10669497 | BS45: 18267351 | BT45: 16320098 | BU45: 12389300 | BV45: 9777756.7 | BW45: 24306436 | BX45: 15568907 | BY45: 12767885 | BZ45: 14615485 | CA45: 11109385 | CB45: 13069988 | CC45: 12455300 | CD45: 12074358 | CE45: 11156936 | CF45: 10965792 | CG45: 12816182 | CH45: 16594730 | CI45: 17216852 | CJ45: 14126806 | CK45: 16480214 | CL45: 19713004 | CM45: 16238820 | CN45: 11083443 | CO45: 11588785 | CP45: 10045562 | CQ45: 12131363 | CR45: 11708401 | CS45: 9679537.5 | CT45: 13004612 | CU45: 17252607 | CV45: 11752142 | CW45: 9568411.7 | CX45: 18377502 | CY45: 29783694 | CZ45: 20415783 | DA45: 17772330 | DB45: 20456918 | DC45: 22337536 | DD45: 15090805 | DE45: 33600755 | DF45: 29663808 | DG45: 26913183 | DH45: 20141551 | DI45: 26226617 | DJ45: 24683034 | DK45: 28903132 | DL45: 21251503 | DM45: 17543670 | DN45: 30838715 | DO45: 25448698 | DP45: 15652934 | DQ45: 34174593 | DR45: 22843372 | DS45: 31788985 | DT45: 27297620 | DU45: 19196982 | DV45: 28036323 | DW45: 31077481 | DX45: 17682240 | DY45: 28730237 | DZ45: 27876703 | EA45: 32546650 | EB45: 18362663 | EC45: 20264078 | ED45: 21584627 | EE45: 32694953 | EF45: 32052371 | EG45: 27349367 | EH45: 30817500 | EI45: 23730950 | EJ45: 16865891 | EK45: 22725880 | EL45: 26222982 | EM45: 19616053 | EN45: 29232142 | EO45: 22544133 | EP45: 27162820 | EQ45: 21962268 | ER45: 23221616 | ES45: 28521443 | ET45: 22397139 | EU45: 26676393 | EV45: 24249977 | EW45: 32327565 | EX45: 30499470 | EY45: 19950236 | EZ45: 27340651 | FA45: 13670626 | FB45: 26468743 | FC45: 27086672 | FD45: 18603691 | FE45: 37653970 | FF45: 34955570 | FG45: 21889628 | FH45: 17376682 | FI45: 24710469 | FJ45: 37692373 | FK45: 20493193 | FL45: 21602403 | FM45: 19038072 | FN45: 29426887 | FO45: 21222379 | FP45: 18948057 | FQ45: 28594357 | FR45: 23932430 | FS45: 28800358 | FT45: 25497005 | FU45: 22276099 | FV45: 14312132 | FW45: 26532618 | FX45: 20594199 | FY45: 33874870 | FZ45: 19505132 | GA45: 29928069 | GB45: 18834896 | GC45: 26706377 | GD45: 28959768 | GE45: 19910044 | GF45: 29472835 | GG45: 19936432 | GH45: 23876927 | GI45: 18707201 | GJ45: 18032414 | GK45: 26840739 | GL45: 26089679 | GM45: 35026097 | GN45: 24413584 | GO45: 19056490 | GP45: 13461279 | GQ45: 26446848 | GR45: 29919038 | GS45: 27798220 | GT45: 41628479 | GU45: 54118352 | GV45: 46368795 | GW45: 51561982 | GX45: 60298424 | GY45: 35168101 | GZ45: 34314663 | HA45: 51827848 | HB45: 40995485 | HC45: 44142590 | HD45: 51082422 | HE45: 40740418 | HF45: 41238471 | HG45: 53585038 | HH45: 40817730 | HI45: 54047869 | HJ45: 44821161 | HK45: 55805736 | HL45: 48140811 | HM45: 62006750 | HN45: 65277673 | HO45: 52676937 | HP45: 60543082 | HQ45: 40413322 | HR45: 54776596 | HS45: 66846948 | HT45: 57251569 | HU45: 50374239 | HV45: 42956914 | HW45: 55319621 | HX45: 51097308 | HY45: 51999624 | HZ45: 63207698 | IA45: 42026001 | IB45: 49204130 | IC45: 43337552 | ID45: 49772937 | IE45: 62037513 | IF45: 53876782 | IG45: 46968866 | IH45: 42265196 | II45: 47331959 | IJ45: 37521468 | IK45: 49807113 | IL45: 47208679 | IM45: 48554245 | IN45: 34842289 | IO45: 54081345 | IP45: 39609197 | IQ45: 67285402 | IR45: 44388214 | IS45: 49244052 | IT45: 42307608 | IU45: 52613142 | IV45: 53511120 | IW45: 58677615 | IX45: 61363448 | IY45: 41393988 | IZ45: 56784543 | JA45: 41560258 | JB45: 35897328 | JC45: 38806705 | JD45: 32390576 | JE45: 53849213 | JF45: 50206602 | JG45: 35283507 | JH45: 64437017 | JI45: 38083762 | JJ45: 53989031 | JK45: 34655021 | JL45: 53944296 | JM45: 45361583 | JN45: 64585550 | JO45: 51879066 | JP45: 48877676 | JQ45: 37909797 | JR45: 37358632 | JS45: 52401822 | JT45: 30233851 | JU45: 50691040 | JV45: 37188588 | JW45: 50207526 | JX45: 47481418 | JY45: 50138354 | JZ45: 43459963 | KA45: 52401768 | KB45: 39460499 | KC45: 60884332 | KD45: 54870632 | KE45: 47966288 | KF45: 45962484 | KG45: 38819565 | KH45: 41071772 | KI45: 42097333 | KJ45: 41599612 | KK45: 44931224 | KL45: 54771120 | KM45: 37349929 | KN45: 47407244 | KO45: 45506463
